<?xml version="1.0" encoding="UTF-8"?>
<!-- -*- mode: XML -*- -->
<sdf version='1.4'>
	<model name='Sahar'>
		<link name='body'>
			<pose>0 0 0.125 0 -0 0</pose>
			<gravity>1</gravity>
			<velocity_decay>
				<linear>0</linear>
				<angular>0</angular>
			</velocity_decay>
			<self_collide>1</self_collide>
			<inertial>
				<pose>-0.72722 0.00 0.20 0 -0 0</pose>
				<mass>2500</mass>
				<inertia>
					<ixx>800.00</ixx>
					<ixy>0.00</ixy>
					<ixz>0.00</ixz>
					<iyy>1200.00</iyy>
					<iyz>0.00</iyz>
					<izz>1000.00</izz>
				</inertia>
			</inertial>
			<visual name='body_visual'>
				<pose>0 0 0 0 0 0</pose>
				<geometry>
					<mesh>
						<scale>1 1 1</scale>
						<uri>model://bobcat/meshes/body.dae</uri>
					</mesh>
				</geometry>
			</visual>
			<collision name='body_collision'>
				<pose>-0.82136 0 0.36982 0 -0.02 0</pose>
				<geometry>
					<box>
						<size>1.704 0.889 0.704</size>
					</box>
				</geometry>
			</collision>
			<collision name='body_collision_bb'>
				<pose>-2.14939 0 0.68567 0 0.08047 0</pose>
				<geometry>
					<box>
						<size>0.120 0.952 0.900</size>
					</box>
				</geometry>
			</collision>
			<collision name='body_collision_b'>
				<pose>-1.87754 0 0.671 0 0.08047 0</pose>
				<geometry>
					<box>
						<size>0.4 1.182 1.121</size>
					</box>
				</geometry>
			</collision>
			<collision name='body_collision_bd'>
				<pose>-1.81524 0 0.37981 0 0.1318 0</pose>
				<geometry>
					<box>
						<size>0.511 0.889 0.704</size>
					</box>
				</geometry>
			</collision>
			<collision name='body_collision_cabin'>
				<pose>-1.0253 0 1.24 0 0 0</pose>
				<geometry>
					<box>
						<size>1.557 0.889 1.152</size>
					</box>
				</geometry>
			</collision>
			<collision name='body_collision_top_installation_link'>
				<pose>-0.92913 0 2.04 0 0 0</pose>
				<geometry>
					<box>
						<size>0.663 0.598 0.838</size>
					</box>
				</geometry>
			</collision>
		</link>
		<link name='base_arm'>
			<pose>-1.9776 0 1.1773 0 0 0</pose>
			<inertial>
				<pose>0.066509 0 0.25686 0 -0 0</pose>
				<mass>400</mass>
				<inertia>
					<ixx>50.76</ixx>
					<ixy>0</ixy>
					<ixz>0.66798</ixz>
					<iyy>4.8017</iyy>
					<iyz>0</iyz>
					<izz>47.388</izz>
				</inertia>
			</inertial>
			<collision name='base_arm_collision'>
				<pose>0 0 0 0 -0 0</pose>
				<geometry>
					<mesh>
						<scale>1 1 1</scale>
						<uri>model://bobcat/meshes/base_arm_col.STL</uri>
					</mesh>
				</geometry>
				<surface>
					<contact>
						<ode/>
					</contact>
					<friction>
						<ode/>
					</friction>
				</surface>
			</collision>
			<visual name='base_arm_visual'>
				<pose>0 0 0 0 -0 0</pose>
				<geometry>
					<mesh>
						<scale>1 1 1</scale>
						<uri>model://bobcat/meshes/base_arm.STL</uri>
					</mesh>
				</geometry>
				<material>
					<script>
						<name>Gazebo/Grey</name>
						<uri>__default__</uri>
					</script>
				</material>
			</visual>
			<gravity>1</gravity>
			<velocity_decay>
				<linear>0</linear>
				<angular>0</angular>
			</velocity_decay>
			<self_collide>0</self_collide>
		</link>
		<joint name='base_arm_joint' type='revolute'>
			<child>base_arm</child>
			<parent>body</parent>
			<axis>
				<xyz>0 1 0</xyz>
				<!--<dynamics><friction>1</friction></dynamics>-->
			</axis>
		</joint>
		<link name='main_arm'>
			<pose>-1.75456 0 1.7035 0 -0 0</pose>
			<inertial>
				<pose>1.1865 0 -0.60466 0 -0 0</pose>
				<mass>300</mass>
				<inertia>
					<ixx>133.74</ixx>
					<ixy>0</ixy>
					<ixz>-68.753</ixz>
					<iyy>216.24</iyy>
					<iyz>0</iyz>
					<izz>268.55</izz>
				</inertia>
			</inertial>
			<collision name='main_arm_collision'>
				<pose>0 0 0 0 -0 0</pose>
				<geometry>
					<mesh>
						<scale>1 1 1</scale>
						<uri>model://bobcat/meshes/main_arm_col.STL</uri>
					</mesh>
				</geometry>
				<surface>
					<contact>
						<ode/>
					</contact>
					<friction>
						<ode/>
					</friction>
				</surface>
			</collision>
			<visual name='main_arm_visual'>
				<pose>0 0 0 0 -0 0</pose>
				<geometry>
					<mesh>
						<scale>1 1 1</scale>
						<uri>model://bobcat/meshes/main_arm.STL</uri>
					</mesh>
				</geometry>
				<material>
					<diffuse>0.9 0.9 0.89 1</diffuse>
					<ambient>0.85 0.85 0.78 1</ambient>
				</material>
			</visual>
			<gravity>1</gravity>
			<velocity_decay>
				<linear>0</linear>
				<angular>0</angular>
			</velocity_decay>
			<self_collide>0</self_collide>
		</link>
		<joint name='main_arm_joint' type='revolute'>
			<child>main_arm</child>
			<parent>base_arm</parent>
			<axis>
				<xyz>0 1 0</xyz>
				<!--<dynamics><friction>1</friction></dynamics>-->
			</axis>
		</joint>
		<link name='loader'>
			<pose>0.34384 0 0.1465 0 0 0</pose>
			<inertial>
				<pose>0.37894 0 0.067409 0 -0 0</pose>
				<mass>98.03</mass>
				<inertia>
					<ixx>29.346</ixx>
					<ixy>0</ixy>
					<ixz>-1.55</ixz>
					<iyy>9.25</iyy>
					<iyz>0</iyz>
					<izz>32.05</izz>
				</inertia>
			</inertial>
			<collision name='loader_collision'>
				<pose>0 0 0 0 -0 0</pose>
				<geometry>
					<mesh>
						<scale>1 1 1</scale>
						<uri>model://bobcat/meshes/loader_col.STL</uri>
					</mesh>
				</geometry>
				<surface>
					<contact>
						<ode/>
					</contact>
					<friction>
						<ode>
							<mu>1</mu>
							<mu2>1</mu2>
						</ode>
					</friction>
				</surface>
			</collision>
			<visual name='loader_visual'>
				<pose>0 0 0 0 -0 0</pose>
				<geometry>
					<mesh>
						<scale>1 1 1</scale>
						<uri>model://bobcat/meshes/loader.STL</uri>
					</mesh>
				</geometry>
				<material>
					<diffuse>0.2 0.2 0.2 1</diffuse>
					<ambient>0.2 0.2 0.2 1</ambient>
				</material>
			</visual>
			<gravity>1</gravity>
			<velocity_decay>
				<linear>0</linear>
				<angular>0</angular>
			</velocity_decay>
			<self_collide>1</self_collide>
		</link>
		<joint name='loader_joint' type='revolute'>
			<child>loader</child>
			<parent>main_arm</parent>
			<axis>
				<xyz>0 -1 0</xyz>
				<limit>
					<lower>-0.5</lower>
					<upper>0.5</upper>
					<!-- <lower>-0.5</lower> -->
					<effort>1e+06</effort>
					<velocity>100</velocity>
				</limit>
				<!--<dynamics><friction>1</friction></dynamics>-->
			</axis>
		</joint>
		<link name='brackets'>
			<pose>0.68217 0 0.64099 0 0 0</pose>
			<inertial>
				<pose>0.14213 0 0.33109 0 -0 0</pose>
				<mass>12.857</mass>
				<inertia>
					<ixx>2.9339</ixx>
					<ixy>0</ixy>
					<ixz>0.23718</ixz>
					<iyy>0.67251</iyy>
					<iyz>0</iyz>
					<izz>2.738</izz>
				</inertia>
			</inertial>
			<collision name='brackets_collision'>
				<pose>0 0 0 0 -0 0</pose>
				<geometry>
					<mesh>
						<scale>1 1 1</scale>
						<uri>model://bobcat/meshes/brackets_col.STL</uri>
					</mesh>
				</geometry>
				<surface>
					<contact>
						<ode/>
					</contact>
					<friction>
						<ode>
							<mu>1</mu>
							<mu2>1</mu2>
						</ode>
					</friction>
				</surface>
			</collision>
			<visual name='brackets_visual'>
				<pose>0 0 0 0 -0 0</pose>
				<geometry>
					<mesh>
						<scale>1 1 1</scale>
						<uri>model://bobcat/meshes/brackets.STL</uri>
					</mesh>
				</geometry>
				<material>
					<diffuse>0.1 0.1 0.1 1</diffuse>
					<ambient>0.1 0.1 0.1 1</ambient>
				</material>
			</visual>
			<gravity>1</gravity>
			<velocity_decay>
				<linear>0</linear>
				<angular>0</angular>
			</velocity_decay>
			<self_collide>1</self_collide>
		</link>
		<joint name='brackets_joint' type='revolute'>
			<child>brackets</child>
			<parent>loader</parent>
			<axis>
				<xyz>0 1 0</xyz>
				<limit>
					<lower>-0.5</lower>
					<upper>1</upper>
					<effort>1e+06</effort>
					<velocity>1e+06</velocity>
				</limit>
				<!--<dynamics><friction>1</friction></dynamics>-->
			</axis>
		</joint>
		<link name='supporter'>
			<pose>-1.35685 0 0.80864 0 -0.12 0</pose>
			<inertial>
				<pose>0.51341 0 -0.060486 0 -0 0</pose>
				<mass>30</mass>
				<inertia>
					<ixx>16.898</ixx>
					<ixy>0</ixy>
					<ixz>0</ixz>
					<iyy>6.6127</iyy>
					<iyz>0</iyz>
					<izz>23.301</izz>
				</inertia>
			</inertial>
			<collision name='supporter_collision'>
				<pose>0 0 0 0 -0 0</pose>
				<geometry>
					<mesh>
						<scale>1 1 1</scale>
						<uri>model://bobcat/meshes/supporter.STL</uri>
					</mesh>
				</geometry>
				<surface>
					<contact>
						<ode/>
					</contact>
					<friction>
						<ode>
							<mu>1</mu>
							<mu2>1</mu2>
						</ode>
					</friction>
				</surface>
			</collision>
			<visual name='supporter_visual'>
				<pose>0 0 0 0 -0 0</pose>
				<geometry>
					<mesh>
						<scale>1 1 1</scale>
						<uri>model://bobcat/meshes/supporter.STL</uri>
					</mesh>
				</geometry>
				<material>
					<diffuse>0.8 0.1 0.1 1</diffuse>
					<ambient>0.8 0.1 0.1 1</ambient>
				</material>
			</visual>
			<gravity>1</gravity>
			<velocity_decay>
				<linear>0</linear>
				<angular>0</angular>
			</velocity_decay>
			<self_collide>1</self_collide>
		</link>
		<joint name='supporter_joint' type='revolute'>
			<child>supporter</child>
			<parent>main_arm</parent>
			<axis>
				<xyz>0 1 0</xyz>
				<!--<dynamics><friction>1</friction></dynamics>-->
			</axis>
		</joint>
		<joint name='supporter_joint2' type='revolute'>
			<pose>1.04 0 -0.122 0 0 0</pose>
			<child>supporter</child>
			<parent>body</parent>
			<axis>
				<xyz>0 1 0</xyz>
				<!--<dynamics><friction>1</friction></dynamics>-->
			</axis>
		</joint>
		<!--HYDRAULICS-->
		<link name='Hydraulics_bottom'>
			<pose>-1.781 0 0.393 0 0.34907 0</pose>
			<inertial>
				<pose>0 0 0.5 0 -0 0</pose>
				<mass>65.29</mass>
				<inertia>
					<ixx>10</ixx>
					<ixy>0</ixy>
					<ixz>0</ixz>
					<iyy>10</iyy>
					<iyz>0</iyz>
					<izz>1</izz>
				</inertia>
			</inertial>
			<self_collide>0</self_collide>
			<visual name='Hydraulics_bottom_vis'>
				<pose>0 0 0 0 0 0</pose>
				<geometry>
					<mesh>
						<scale>1 1 1</scale>
						<uri>model://bobcat/meshes/Hydraulics_bottom.dae</uri>
					</mesh>
				</geometry>
			</visual>
		</link>
		<joint name='Hydraulics_bottom_rot' type='revolute'>
			<pose>0 0 0 0 0 0</pose>
			<child>Hydraulics_bottom</child>
			<parent>body</parent>
			<axis>
				<xyz>0 1 0</xyz>
				<!--<dynamics><friction>1</friction></dynamics>-->
			</axis>
		</joint>
		<link name='Hydraulics_top'>
			<pose>-1.480 0 1.220 0 0.34907 0</pose>
			<inertial>
				<pose>0 0 -0.5 0 -0 0</pose>
				<mass>65.29</mass>
				<inertia>
					<ixx>10</ixx>
					<ixy>0</ixy>
					<ixz>0</ixz>
					<iyy>10</iyy>
					<iyz>0</iyz>
					<izz>1</izz>
				</inertia>
			</inertial>
			<self_collide>0</self_collide>
			<visual name='Hydraulics_bottom_vis'>
				<pose>0 0 0 0 0 0</pose>
				<geometry>
					<mesh>
						<scale>1 1 1</scale>
						<uri>model://bobcat/meshes/Hydraulics_top.dae</uri>
					</mesh>
				</geometry>
			</visual>
		</link>
		<joint name='Hydraulics_top_rot' type='revolute'>
			<pose>0 0 0 0 0 0</pose>
			<child>Hydraulics_top</child>
			<parent>main_arm</parent>
			<axis>
				<xyz>0 1 0</xyz>
				<!--<dynamics><friction>1</friction></dynamics>-->
			</axis>
		</joint>
		<joint name='Hydraulics_joint' type='prismatic'>
			<pose>0 0 -0.5 0 0 0</pose>
			<child>Hydraulics_top</child>
			<parent>Hydraulics_bottom</parent>
			<axis>
				<xyz>.342024 0 0.939691</xyz>
				<!--<dynamics><friction>1</friction></dynamics>-->
			</axis>
		</joint>
		<!--WHEELS-->
		<link name='back_left_wheel'>
			<pose>-1.227 0.47558 0.300 0 0 0</pose>
			<inertial>
				<pose>7.7344e-08 0.19645 1.8868e-07 0 -0 0</pose>
				<mass>333.358</mass>
				<inertia>
					<ixx>17.0765</ixx>
					<ixy>-2.79367e-06</ixy>
					<ixz>-6.68629e-05</ixz>
					<iyy>29.6158</iyy>
					<iyz>-1.33651e-05</iyz>
					<izz>17.0765</izz>
				</inertia>
			</inertial>
			<collision name='back_left_wheel_collision'>
				<pose>0 0.2 0 1.5708 -0 0</pose>
				<geometry>
					<cylinder>
						<length>0.4</length>
						<radius>0.4</radius>
					</cylinder>
				</geometry>
				<surface>
					<contact>
						<ode/>
					</contact>
					<friction>
						<ode>
							<mu>1</mu>
							<mu2>1</mu2>
						</ode>
					</friction>
				</surface>
			</collision>
			<visual name='back_left_wheel_visual'>
				<pose>0 0 0 0 -0 0</pose>
				<geometry>
					<mesh>
						<uri>model://bobcat/meshes/back_left_wheel.stl</uri>
					</mesh>
				</geometry>
				<material>
					<ambient>0 0 0 1</ambient>
					<diffuse>0.1 0.1 0.1 1</diffuse>
					<specular>0.5 0.5 0.5 1</specular>
					<emissive>0.05 0.05 0.05 1</emissive>
				</material>
			</visual>
			<gravity>1</gravity>
			<velocity_decay>
				<linear>0</linear>
				<angular>0</angular>
			</velocity_decay>
			<self_collide>0</self_collide>
		</link>
		<joint name='back_left_wheel_joint' type='revolute'>
			<child>back_left_wheel</child>
			<parent>body</parent>
			<axis>
				<xyz>0 1 0</xyz>
				<dynamics/>
			</axis>
		</joint>
		<link name='back_right_wheel'>
			<pose>-1.227 -0.47558 0.300 0 0 0</pose>
			<inertial>
				<pose>-1.4894e-07 -0.19645 1.3751e-07 0 -0 0</pose>
				<mass>333.36</mass>
				<inertia>
					<ixx>17.0765</ixx>
					<ixy>-1.87699e-05</ixy>
					<ixz>1.23277e-05</ixz>
					<iyy>29.6158</iyy>
					<iyz>3.1578e-05</iyz>
					<izz>17.0765</izz>
				</inertia>
			</inertial>
			<collision name='back_right_wheel_collision'>
				<pose>0 -0.2 0 1.5708 -0 0</pose>
				<geometry>
					<cylinder>
						<length>0.4</length>
						<radius>0.4</radius>
					</cylinder>
				</geometry>
				<surface>
					<contact>
						<ode/>
					</contact>
					<friction>
						<ode>
							<mu>1</mu>
							<mu2>1</mu2>
						</ode>
					</friction>
				</surface>
			</collision>
			<visual name='back_right_wheel_visual'>
				<pose>0 0 0 0 -0 0</pose>
				<geometry>
					<mesh>
						<scale>1 1 1</scale>
						<uri>model://bobcat/meshes/back_right_wheel.stl</uri>
					</mesh>
				</geometry>
				<material>
					<ambient>0 0 0 1</ambient>
					<diffuse>0.1 0.1 0.1 1</diffuse>
					<specular>0.5 0.5 0.5 1</specular>
					<emissive>0.05 0.05 0.05 1</emissive>
				</material>
			</visual>
			<gravity>1</gravity>
			<velocity_decay>
				<linear>0</linear>
				<angular>0</angular>
			</velocity_decay>
			<self_collide>1</self_collide>
		</link>
		<joint name='back_right_wheel_joint' type='revolute'>
			<child>back_right_wheel</child>
			<parent>body</parent>
			<axis>
				<xyz>0 1 0</xyz>
				<dynamics/>
			</axis>
		</joint>
		<link name='front_left_wheel'>
			<pose>-0.22722 0.47558 0.300 0 0 0</pose>
			<inertial>
				<pose>2.0502e-07 0.19645 -3.6566e-09 0 -0 0</pose>
				<mass>333.358</mass>
				<inertia>
					<ixx>17.0765</ixx>
					<ixy>-4.02019e-05</ixy>
					<ixz>7.57982e-05</ixz>
					<iyy>29.6158</iyy>
					<iyz>-6.64195e-06</iyz>
					<izz>17.0765</izz>
				</inertia>
			</inertial>
			<collision name='front_left_wheel_collision'>
				<pose>0 0.2 0 1.5708 -0 0</pose>
				<geometry>
					<cylinder>
						<length>0.4</length>
						<radius>0.4</radius>
					</cylinder>
				</geometry>
				<surface>
					<contact>
						<ode/>
					</contact>
					<friction>
						<ode>
							<mu>1</mu>
							<mu2>1</mu2>
						</ode>
					</friction>
				</surface>
			</collision>
			<visual name='front_left_wheel_visual'>
				<pose>0 0 0 0 -0 0</pose>
				<geometry>
					<mesh>
						<scale>1 1 1</scale>
						<uri>model://bobcat/meshes/front_left_wheel.stl</uri>
					</mesh>
				</geometry>
				<material>
					<ambient>0 0 0 1</ambient>
					<diffuse>0.1 0.1 0.1 1</diffuse>
					<specular>0.5 0.5 0.5 1</specular>
					<emissive>0.05 0.05 0.05 1</emissive>
				</material>
			</visual>
			<gravity>1</gravity>
			<velocity_decay>
				<linear>0</linear>
				<angular>0</angular>
			</velocity_decay>
			<self_collide>1</self_collide>
		</link>
		<joint name='front_left_wheel_joint' type='revolute'>
			<child>front_left_wheel</child>
			<parent>body</parent>
			<axis>
				<xyz>0 1 0</xyz>
				<dynamics/>
			</axis>
		</joint>
		<link name='front_right_wheel'>
			<pose>-0.22722 -0.47558 0.300 0 0 0</pose>
			<inertial>
				<pose>-2.0519e-07 -0.19645 -4.3198e-09 0 -0 0</pose>
				<mass>333.358</mass>
				<inertia>
					<ixx>17.0765</ixx>
					<ixy>-3.66954e-05</ixy>
					<ixz>-7.5494e-05</ixz>
					<iyy>29.6158</iyy>
					<iyz>1.22098e-05</iyz>
					<izz>17.0765</izz>
				</inertia>
			</inertial>
			<collision name='front_right_wheel_collision'>
				<pose>0 -0.2 0 1.5708 -0 0</pose>
				<geometry>
					<cylinder>
						<length>0.4</length>
						<radius>0.4</radius>
					</cylinder>
				</geometry>
				<surface>
					<contact>
						<ode/>
					</contact>
					<friction>
						<ode>
							<mu>1</mu>
							<mu2>1</mu2>
						</ode>
					</friction>
				</surface>
			</collision>
			<visual name='front_right_wheel_visual'>
				<pose>0 0 0 0 -0 0</pose>
				<geometry>
					<mesh>
						<scale>1 1 1</scale>
						<uri>model://bobcat/meshes/front_right_wheel.stl</uri>
					</mesh>
				</geometry>
				<material>
					<ambient>0 0 0 1</ambient>
					<diffuse>0.1 0.1 0.1 1</diffuse>
					<specular>0.5 0.5 0.5 1</specular>
					<emissive>0.05 0.05 0.05 1</emissive>
				</material>
			</visual>
			<gravity>1</gravity>
			<velocity_decay>
				<linear>0</linear>
				<angular>0</angular>
			</velocity_decay>
			<self_collide>1</self_collide>
		</link>
		<joint name='front_right_wheel_joint' type='revolute'>
			<child>front_right_wheel</child>
			<parent>body</parent>
			<axis>
				<xyz>0 1 0</xyz>
				<dynamics/>
			</axis>
		</joint>
		<plugin name="bobcat_drive_control" filename="libbobcat_drive_plugin.so">
		      <IP>127.0.0.1</IP>
		      <PortUDPLP>4660</PortUDPLP>
		      <PortUDPRP>5355</PortUDPRP>
	       </plugin>
		<plugin name="bobcat_arm" filename="libbobcat_arm_plugin.so"/>>
		<plugin name="joint_state_publisher" filename="libgazebo_ros_joint_state_publisher.so">
			<robotNamespace>/Sahar</robotNamespace>
			<jointName>base_arm_joint, main_arm_joint, Hydraulics_bottom_rot, Hydraulics_joint, Hydraulics_top_rot, loader_joint, brackets_joint, supporter_joint, supporter_joint2, back_left_wheel_joint, back_right_wheel_joint, front_left_wheel_joint, front_right_wheel_joint</jointName>
			<updateRate>50.0</updateRate>
			<alwaysOn>true</alwaysOn>
		</plugin>
		<!-- IPON Sensor-->
		<include>
			<uri>model://IPON</uri>
			<pose>-0.790 -0.155 2.000 0.000 0.000 0.000</pose>
			<!-- position of the GPS antena , orintation of the INS sensor-->
			<name>IPON</name>
		</include>
		<joint name='ipon_joint' type='revolute'>
			<child>IPON::link</child>
			<parent>body</parent>
			<axis>
				<xyz>0 1 0</xyz>
				<limit>
					<lower>0</lower>
					<upper>0</upper>
				</limit>
				<dynamics/>
			</axis>
		</joint>
		<!-- IBEO Sensor -->
		<include>
			<uri>model://IBEO</uri>
			<pose>-0.400 0.020 2.000 0.000 0.215 0.149</pose>
			<name>IBEO</name>
		</include>
		<joint name='ibeo_joint' type='revolute'>
			<child>IBEO::link</child>
			<parent>body</parent>
			<axis>
				<xyz>0 1 0</xyz>
				<limit>
					<lower>0</lower>
					<upper>0</upper>
				</limit>
				<dynamics/>
			</axis>
		</joint>
		<!-- CAM Sensors --><!-- 
		<include>
			<uri>model://FLEA3_L</uri>
			<pose>-0.3 0.25 2.02 0 0 0</pose>
			<name>left_flea3</name>
		</include>
		<joint name='left_flea3_joint' type='revolute'>
			<child>left_flea3::camera_link</child>
			<parent>body</parent>
			<axis>
				<xyz>0 1 0</xyz>
				<limit>
					<lower>0</lower>
					<upper>0</upper>
				</limit>
				<dynamics/>
			</axis>
		</joint>
		<include>
			<uri>model://FLEA3_R</uri>
			<pose>-0.3 -0.25 2.02 0 0 0</pose>
			<name>right_flea3</name>
		</include>
		<joint name='right_flea3_joint' type='revolute'>
			<child>right_flea3::camera_link</child>
			<parent>body</parent>
			<axis>
				<xyz>0 1 0</xyz>
				<limit>
					<lower>0</lower>
					<upper>0</upper>
				</limit>
				<dynamics/>
			</axis>
		</joint>  
  -->
<!-- SICK Sensors --><!--
    <include>
      <uri>model://SICK</uri>
      <pose>-0.2187 0.85 0.631 0 0 1.57</pose>
      <name>left_sick</name>
    </include>
    <joint name='left_sick_joint' type='revolute'>
      <child>left_sick::link</child>
      <parent>body</parent>
      <axis>
        <xyz>0 1 0</xyz>
        <limit>
          <lower>0</lower>
          <upper>0</upper>
        </limit>
        <dynamics/>
      </axis>
    </joint>
    
    <include> 
      <uri>model://SICK</uri>
      <pose>-0.2187 -0.85 0.631 0 0 -1.57</pose>
      <name>right_sick</name>
    </include>
    <joint name='right_sick_joint' type='revolute'>
      <child>right_sick::link</child>
      <parent>body</parent>
      <axis>
        <xyz>0 1 0</xyz>
        <limit>
          <lower>0</lower>
          <upper>0</upper>
        </limit>
        <dynamics/>
      </axis>
    </joint>
-->

<!--  Wire Sensors --><!--
    <include>
      <uri>model://wire_sensor</uri>
      <pose>-1.42 0.56 1.05 -1.6 2.3 0</pose>
      <name>arm_wire_sensor</name>
    </include> 
    <joint name='arm_wire_sensor_joint' type='revolute'>
      <child>arm_wire_sensor::link</child>
      <parent>body</parent>
      <axis>
        <xyz>0 1 0</xyz>
        <limit>
          <lower>0</lower>
          <upper>0</upper>
        </limit>
        <dynamics/>
      </axis>
    </joint>

    <include>
      <uri>model://wire_sensor_mount</uri>
      <pose>-1.31 0.56 1.28 -1.6 0 0</pose>
      <name>arm_wire_sensor_mount</name>
    </include>    
    <joint name='arm_wire_sensor_mount_joint' type='revolute'>
      <child>arm_wire_sensor_mount::link</child>
      <parent>main_arm</parent>
      <axis>
        <xyz>0 1 0</xyz>
        <limit>
          <lower>0</lower>
          <upper>0</upper>
        </limit>
        <dynamics/>
      </axis>
    </joint>

    <plugin name="arm_wire_sensor_plugin" filename="libwire_sensor.so">
      <sensor_name>Sahar::arm_wire_sensor::link</sensor_name>
      <mount_name>Sahar::arm_wire_sensor_mount::link</mount_name>
      <noise>0.1</noise>
    </plugin>    
    
        
    <include>
      <uri>model://wire_sensor_mount</uri>
      <pose>0.59 0.3 0.52 0 -1 0</pose>
      <name>blade_wire_sensor_mount</name>
    </include> 
    <joint name='blade_wire_sensor_mount_joint' type='revolute'>
      <child>blade_wire_sensor_mount::link</child>
      <parent>loader</parent>
      <axis>
        <xyz>0 1 0</xyz>
        <limit>
          <lower>0</lower>
          <upper>0</upper>
        </limit>
        <dynamics/>
      </axis>
    </joint>

    <include>
      <uri>model://wire_sensor</uri>
      <pose>0.3 0.3 0.85 0 -0.83 3.14</pose>
      <name>blade_wire_sensor</name>
    </include>    
    <joint name='blade_wire_sensor_joint' type='revolute'>
      <child>blade_wire_sensor::link</child>
      <parent>main_arm</parent>
      <axis>
        <xyz>0 1 0</xyz>
        <limit>
          <lower>0</lower>
          <upper>0</upper>
        </limit>
        <dynamics/>
      </axis>
    </joint>
    
    <plugin name="blade_wire_sensor_plugin" filename="libwire_sensor.so">
      <sensor_name>Sahar::blade_wire_sensor::link</sensor_name>
      <mount_name>Sahar::blade_wire_sensor_mount::link</mount_name>
      <noise>0.1</noise>
    </plugin>
-->

</model>
</sdf>
