<?xml version="1.0" encoding="UTF-8"?>
<!-- -*- mode: XML -*- -->
<sdf version='1.4'>
  <model name='Sahar'>
    <link name='body'>
      <pose>0 0 0.125 0 0 0</pose>
      <gravity>1</gravity>
      <velocity_decay>
        <linear>0</linear>
        <angular>0</angular>
      </velocity_decay>
      <self_collide>1</self_collide>
      <inertial>
        <pose>-0.79545 -0.0 0.68 0 -0 0</pose>
        <mass>2646.54</mass>
        <inertia>
          <ixx>818.884</ixx>
          <ixy>0</ixy>
          <ixz>0</ixz>
          <iyy>1500</iyy>
          <iyz>0</iyz>
          <izz>1018.05</izz>
        </inertia>
      </inertial>
      <visual name='body_visual'>
        <pose>0 0 0 0 0 0</pose>
        <geometry>
          <mesh>
            <scale>1 1 1</scale>
            <uri>model://bobcat_tracked_static_arm/meshes/body.dae</uri>
          </mesh>
        </geometry>
      </visual>
      <collision name='body_collision'>
        <pose>-0.82136 0 0.36982 0 -0.02 0</pose>
        <geometry>
          <box>
            <size>1.704 0.889 0.704</size>
          </box>
        </geometry>
      </collision>
      <collision name='body_collision_bb'>
        <pose>-2.14939 0 0.68567 0 0.08047 0</pose>
        <geometry>
          <box>
            <size>0.120 0.952 0.900</size>
          </box>
        </geometry>
      </collision>
      <collision name='body_collision_b'>
        <pose>-1.87754 0 0.671 0 0.08047 0</pose>
        <geometry>
          <box>
            <size>0.4 1.182 1.121</size>
          </box>
        </geometry>
      </collision>
      <collision name='body_collision_bd'>
        <pose>-1.81524 0 0.37981 0 0.1318 0</pose>
        <geometry>
          <box>
            <size>0.511 0.889 0.704</size>
          </box>
        </geometry>
      </collision>
      <collision name='body_collision_cabin'>
        <pose>-1.0253 0 1.24 0 0 0</pose>
        <geometry>
          <box>
            <size>1.557 0.889 1.152</size>
          </box>
        </geometry>
      </collision>
      <collision name='body_collision_top_installation_link'>
        <pose>-0.92913 0 2.04 0 0 0</pose>
        <geometry>
          <box>
            <size>0.663 0.598 0.838</size>
          </box>
        </geometry>
      </collision>
      <collision name='loader_collision'>
        <pose>0.782 0 0.58109 0 -0.25273  0</pose>
        <geometry>
          <box>
            <size>0.879 1.682 0.720</size>
          </box>
        </geometry>
      </collision>
    </link>
    
    
   <!--COGWHEELS-->
    <link name='cogwheel_left'>
      <pose>-1.35 0.655 0.435 0 0 0</pose>
      <inertial>
        <pose>0 0 0 0 -0 0</pose>
        <mass>1.1</mass>
        <inertia>
          <ixx>0.01</ixx>
          <ixy>-0</ixy>
          <ixz>0</ixz>
          <iyy>0.01</iyy>
          <iyz>0</iyz>
          <izz>0.01</izz>
        </inertia>
      </inertial>
      <visual name='cogwheel_left_visual'>
        <pose>0 0 0 0 0 0</pose>
        <geometry>
          <mesh>
            <scale>1 1 1</scale>
            <uri>model://bobcat_tracked_static_arm/meshes/cogwheel_left.STL</uri>
          </mesh>
        </geometry>
        <material>
          <script>
            <name>Gazebo/Grey</name>
            <uri>__default__</uri>
          </script>
        </material>
      </visual>
      <gravity>1</gravity>
      <velocity_decay>
        <linear>0</linear>
        <angular>0</angular>
      </velocity_decay>
      <self_collide>0</self_collide>
    </link>
    <joint name='cogwheel_left_joint' type='revolute'>
      <child>cogwheel_left</child>
      <parent>body</parent>
      <axis>
        <dynamics>
          <damping>0</damping>
        </dynamics>
        <xyz>0 1 0</xyz>
      </axis>
      <physics><ode><cfm>0.0000658</cfm><erp>0.01315</erp></ode></physics>
    </joint>
    <!--<joint name="gear_left" type="gearbox"><parent>back_left_wheel</parent><child>cogwheel_left</child><gearbox_ratio>-1</gearbox_ratio><gearbox_reference_body>body</gearbox_reference_body><axis><xyz>0.000000 1.000000 0.000000</xyz></axis><axis2><xyz>0.000000 1.000000 0.000000</xyz></axis2></joint>-->

    <link name='cogwheel_right'>
      <pose>-1.35 -0.655 0.435 0 0 0</pose>
      <inertial>
        <pose>0 0 0 0 -0 0</pose>
        <mass>1.1</mass>
        <inertia>
          <ixx>0.01</ixx>
          <ixy>-0</ixy>
          <ixz>0</ixz>
          <iyy>0.01</iyy>
          <iyz>0</iyz>
          <izz>0.01</izz>
        </inertia>
      </inertial>
      <visual name='cogwheel_right_visual'>
        <pose>0 0 0 0 0 0</pose>
        <geometry>
          <mesh>
            <scale>1 1 1</scale>
            <uri>model://bobcat_tracked_static_arm/meshes/cogwheel_right.STL</uri>
          </mesh>
        </geometry>
        <material>
          <script>
            <name>Gazebo/Grey</name>
            <uri>__default__</uri>
          </script>
        </material>
      </visual>
      <gravity>1</gravity>
      <velocity_decay>
        <linear>0</linear>
        <angular>0</angular>
      </velocity_decay>
      <self_collide>1</self_collide>
    </link>
    <joint name='cogwheel_right_joint' type='revolute'>
      <child>cogwheel_right</child>
      <parent>body</parent>
      <axis>
        <dynamics>
          <damping>0</damping>
        </dynamics>
        <xyz>0 1 0</xyz>
      </axis>
      <physics><ode><cfm>0.0000658</cfm><erp>0.01315</erp></ode></physics>
    </joint>



    <!--WHEELS-->
    <link name='back_left_wheel'>
    <self_collide>0</self_collide>
      <pose>-1.53739 0.63 0.1 0  0 0</pose>
      <inertial>
        <pose>0 0 0 0 -0 0</pose>
        <mass>50</mass>
        <inertia>
          <ixx>1.175</ixx>
          <ixy>-0</ixy>
          <ixz>0</ixz>
          <iyy>1</iyy>
          <iyz>0</iyz>
          <izz>1.175</izz>
        </inertia>
      </inertial>
      <collision name='back_left_wheel_collision'>
        <pose>0 0 0 -1.5708 -0 0</pose>
        <geometry>
          <cylinder>
            <length>0.4</length>
            <radius>0.2</radius>
          </cylinder>
        </geometry>
        <surface>
          <contact>
            <ode/>
          </contact>
          <friction>
            <ode>
              <mu>0.8</mu>
              <mu2>0.8</mu2>
            </ode>
          </friction>
        </surface>
      </collision>
      <gravity>1</gravity>
      <velocity_decay>
        <linear>0</linear>
        <angular>0</angular>
      </velocity_decay>
      <self_collide>0</self_collide>
    </link>
    <joint name='back_left_wheel_joint' type='revolute'>
      <child>back_left_wheel</child>
      <parent>body</parent>
      <axis>
        <dynamics>
          <damping>1</damping>
        </dynamics>
        <xyz>0 1 0</xyz>
      </axis>
      <physics><ode><cfm>0.0000658</cfm><erp>0.01315</erp></ode></physics>
    </joint>

    <link name='back_right_wheel'>
    <self_collide>0</self_collide>
      <pose>-1.535 -0.63 0.1 0  0 0</pose>
      <inertial>
        <pose>0 0 0 0 -0 0</pose>
        <mass>50</mass>
        <inertia>
          <ixx>1.175</ixx>
          <ixy>-0</ixy>
          <ixz>0</ixz>
          <iyy>1</iyy>
          <iyz>0</iyz>
          <izz>1.175</izz>
        </inertia>
      </inertial>
      <collision name='back_right_wheel_collision'>
        <pose>0 0 0 1.5708 -0 0</pose>
        <geometry>
          <cylinder>
            <length>0.4</length>
            <radius>0.2</radius>
          </cylinder>
        </geometry>
        <surface>
          <contact>
            <ode/>
          </contact>
          <friction>
            <ode>
              <mu>0.8</mu>
              <mu2>0.8</mu2>
            </ode>
          </friction>
        </surface>
      </collision>
      <gravity>1</gravity>
      <velocity_decay>
        <linear>0</linear>
        <angular>0</angular>
      </velocity_decay>
      <self_collide>1</self_collide>
    </link>
    <joint name='back_right_wheel_joint' type='revolute'>
      <child>back_right_wheel</child>
      <parent>body</parent>
      <axis>
        <dynamics>
          <damping>1</damping>
        </dynamics>
        <xyz>0 1 0</xyz>
      </axis>
      <physics><ode><cfm>0.0000658</cfm><erp>0.01315</erp></ode></physics>
    </joint>
    <!--<joint name="gear_right" type="gearbox"><parent>back_right_wheel</parent><child>cogwheel_right</child><gearbox_ratio>-1</gearbox_ratio><gearbox_reference_body>body</gearbox_reference_body><axis><xyz>0.000000 1.000000 0.000000</xyz></axis><axis2><xyz>0.000000 1.000000 0.000000</xyz></axis2></joint>-->

    <link name='front_left_wheel'>
    <self_collide>0</self_collide>
      <pose>-0.0535 0.63 0.1 0  0 0</pose>
      <inertial>
        <pose>0 0 0 0 -0 0</pose>
        <mass>50</mass>
        <inertia>
          <ixx>1.175</ixx>
          <ixy>-0</ixy>
          <ixz>0</ixz>
          <iyy>1</iyy>
          <iyz>0</iyz>
          <izz>1.175</izz>
        </inertia>
      </inertial>
      <collision name='front_left_wheel_collision'>
        <pose>0 0 0 -1.5708 -0 0</pose>
        <geometry>
          <cylinder>
            <length>0.4</length>
            <radius>0.2</radius>
          </cylinder>
        </geometry>
        <surface>
          <contact>
            <ode/>
          </contact>
          <friction>
            <ode>
              <mu>0.8</mu>
              <mu2>0.8</mu2>
            </ode>
          </friction>
        </surface>
      </collision>
      <gravity>1</gravity>
      <velocity_decay>
        <linear>0</linear>
        <angular>0</angular>
      </velocity_decay>
      <self_collide>1</self_collide>
    </link>
    <joint name='front_left_wheel_joint' type='revolute'>
      <child>front_left_wheel</child>
      <parent>body</parent>
      <axis>
        <dynamics>
          <damping>1</damping>
        </dynamics>
        <xyz>0 1 0</xyz>
      </axis>
      <physics><ode><cfm>0.0000658</cfm><erp>0.01315</erp></ode></physics>
    </joint>

    <link name='front_right_wheel'>
    <self_collide>0</self_collide>
      <pose>-0.0535 -0.63 0.1 0 0 0</pose>
      <inertial>
        <pose>0 0 0 0 -0 0</pose>
        <mass>50</mass>
        <inertia>
          <ixx>1.175</ixx>
          <ixy>-0</ixy>
          <ixz>0</ixz>
          <iyy>1</iyy>
          <iyz>0</iyz>
          <izz>1.175</izz>
        </inertia>
      </inertial>
      <collision name='front_right_wheel_collision'>
        <pose>0 0 0 1.5708 -0 0</pose>
        <geometry>
          <cylinder>
            <length>0.4</length>
            <radius>0.2</radius>
          </cylinder>
        </geometry>
        <surface>
          <contact>
            <ode/>
          </contact>
          <friction>
            <ode>
              <mu>0.8</mu>
              <mu2>0.8</mu2>
            </ode>
          </friction>
        </surface>
      </collision>
      <gravity>1</gravity>
      <velocity_decay>
        <linear>0</linear>
        <angular>0</angular>
      </velocity_decay>
      <self_collide>1</self_collide>
    </link>
    <joint name='front_right_wheel_joint' type='revolute'>
      <child>front_right_wheel</child>
      <parent>body</parent>
      <axis>
        <dynamics>
          <damping>1</damping>
        </dynamics>
        <xyz>0 1 0</xyz>
      </axis>
      <physics><ode><cfm>0.0000658</cfm><erp>0.01315</erp></ode></physics>
    </joint>


    <link name='roller_back_right'>
    <self_collide>0</self_collide>
      <pose>-1.16582 -0.63 0.1 0 0 0</pose>
      <inertial>
        <pose>0 0 0 0 -0 0</pose>
        <mass>50</mass>
        <inertia>
          <ixx>1.175</ixx>
          <ixy>-0</ixy>
          <ixz>0</ixz>
          <iyy>1</iyy>
          <iyz>0</iyz>
          <izz>1.175</izz>
        </inertia>
      </inertial>
      <collision name='roller_back_right_collision'>
        <pose>0 0 0 1.5708 -0 0</pose>
        <geometry>
          <cylinder>
            <length>0.4</length>
            <radius>0.2</radius>
          </cylinder>
        </geometry>
        <surface>
          <contact>
            <ode/>
          </contact>
          <friction>
            <ode>
              <mu>0.8</mu>
              <mu2>0.8</mu2>
            </ode>
          </friction>
        </surface>
      </collision>
      <gravity>1</gravity>
      <velocity_decay>
        <linear>0</linear>
        <angular>0</angular>
      </velocity_decay>
      <self_collide>1</self_collide>
    </link>
    <joint name='roller_back_right_joint' type='revolute'>
      <child>roller_back_right</child>
      <parent>body</parent>
      <axis>
        <dynamics>
          <damping>1</damping>
        </dynamics>
        <xyz>0 1 0</xyz>
      </axis>
      <physics><ode><cfm>0.0000658</cfm><erp>0.01315</erp></ode></physics>
    </joint>

    <link name='roller_mid_right'>
    <self_collide>0</self_collide>
      <pose>-0.79545 -0.63 0.1 0 0 0</pose>
      <inertial>
        <pose>0 0 0 0 -0 0</pose>
        <mass>50</mass>
        <inertia>
          <ixx>1.175</ixx>
          <ixy>-0</ixy>
          <ixz>0</ixz>
          <iyy>1</iyy>
          <iyz>0</iyz>
          <izz>1.175</izz>
        </inertia>
      </inertial>
      <collision name='roller_mid_right_collision'>
        <pose>0 0 0 1.5708 -0 0</pose>
        <geometry>
          <cylinder>
            <length>0.4</length>
            <radius>0.2</radius>
          </cylinder>
        </geometry>
        <surface>
          <contact>
            <ode/>
          </contact>
          <friction>
            <ode>
              <mu>0.8</mu>
              <mu2>0.8</mu2>
            </ode>
          </friction>
        </surface>
      </collision>
      <gravity>1</gravity>
      <velocity_decay>
        <linear>0</linear>
        <angular>0</angular>
      </velocity_decay>
      <self_collide>1</self_collide>
    </link>
    <joint name='roller_mid_right_joint' type='revolute'>
      <child>roller_mid_right</child>
      <parent>body</parent>
      <axis>
        <dynamics>
          <damping>1</damping>
        </dynamics>
        <xyz>0 1 0</xyz>
      </axis>
      <physics><ode><cfm>0.0000658</cfm><erp>0.01315</erp></ode></physics>
    </joint>

    <link name='roller_front_right'>
    <self_collide>0</self_collide>
      <pose>-0.42447 -0.63 0.1 0 0 0</pose>
      <inertial>
        <pose>0 0 0 0 -0 0</pose>
        <mass>50</mass>
        <inertia>
          <ixx>1.175</ixx>
          <ixy>-0</ixy>
          <ixz>0</ixz>
          <iyy>1</iyy>
          <iyz>0</iyz>
          <izz>1.175</izz>
        </inertia>
      </inertial>
      <collision name='roller_front_right_collision'>
        <pose>0 0 0 1.5708 -0 0</pose>
        <geometry>
          <cylinder>
            <length>0.4</length>
            <radius>0.2</radius>
          </cylinder>
        </geometry>
        <surface>
          <contact>
            <ode/>
          </contact>
          <friction>
            <ode>
              <mu>0.8</mu>
              <mu2>0.8</mu2>
            </ode>
          </friction>
        </surface>
      </collision>
      <gravity>1</gravity>
      <velocity_decay>
        <linear>0</linear>
        <angular>0</angular>
      </velocity_decay>
      <self_collide>1</self_collide>
    </link>
    <joint name='roller_front_right_joint' type='revolute'>
      <child>roller_front_right</child>
      <parent>body</parent>
      <axis>
        <dynamics>
          <damping>1</damping>
        </dynamics>
        <xyz>0 1 0</xyz>
      </axis>
      <physics><ode><cfm>0.0000658</cfm><erp>0.01315</erp></ode></physics>
    </joint>

    <link name='roller_back_left'>
    <self_collide>0</self_collide>
      <pose>-1.16582 0.63 0.1 0 0 0</pose>
      <inertial>
        <pose>0 0 0 0 -0 0</pose>
        <mass>50</mass>
        <inertia>
          <ixx>1.175</ixx>
          <ixy>-0</ixy>
          <ixz>0</ixz>
          <iyy>1</iyy>
          <iyz>0</iyz>
          <izz>1.175</izz>
        </inertia>
      </inertial>
      <collision name='roller_back_left_collision'>
        <pose>0 0 0 1.5708 -0 0</pose>
        <geometry>
          <cylinder>
            <length>0.4</length>
            <radius>0.2</radius>
          </cylinder>
        </geometry>
        <surface>
          <contact>
            <ode/>
          </contact>
          <friction>
            <ode>
              <mu>0.8</mu>
              <mu2>0.8</mu2>
            </ode>
          </friction>
        </surface>
      </collision>
      <gravity>1</gravity>
      <velocity_decay>
        <linear>0</linear>
        <angular>0</angular>
      </velocity_decay>
      <self_collide>1</self_collide>
    </link>
    <joint name='roller_back_left_joint' type='revolute'>
      <child>roller_back_left</child>
      <parent>body</parent>
      <axis>
        <dynamics>
          <damping>1</damping>
        </dynamics>
        <xyz>0 1 0</xyz>
      </axis>
      <physics><ode><cfm>0.0000658</cfm><erp>0.01315</erp></ode></physics>
    </joint>

    <link name='roller_mid_left'>
    <self_collide>0</self_collide>
      <pose>-0.79545 0.63 0.1 0 0 0</pose>
      <inertial>
        <pose>0 0 0 0 -0 0</pose>
        <mass>50</mass>
        <inertia>
          <ixx>1.175</ixx>
          <ixy>-0</ixy>
          <ixz>0</ixz>
          <iyy>1</iyy>
          <iyz>0</iyz>
          <izz>1.175</izz>
        </inertia>
      </inertial>
      <collision name='roller_mid_left_collision'>
        <pose>0 0 0 1.5708 -0 0</pose>
        <geometry>
          <cylinder>
            <length>0.4</length>
            <radius>0.2</radius>
          </cylinder>
        </geometry>
        <surface>
          <contact>
            <ode/>
          </contact>
          <friction>
            <ode>
              <mu>0.8</mu>
              <mu2>0.8</mu2>
            </ode>
          </friction>
        </surface>
      </collision>
      <gravity>1</gravity>
      <velocity_decay>
        <linear>0</linear>
        <angular>0</angular>
      </velocity_decay>
      <self_collide>1</self_collide>
    </link>
    <joint name='roller_mid_left_joint' type='revolute'>
      <child>roller_mid_left</child>
      <parent>body</parent>
      <axis>
        <dynamics>
          <damping>1</damping>
        </dynamics>
        <xyz>0 1 0</xyz>
      </axis>
      <physics><ode><cfm>0.0000658</cfm><erp>0.01315</erp></ode></physics>
    </joint>

    <link name='roller_front_left'>
    <self_collide>0</self_collide>
      <pose>-0.42447 0.63 0.1 0 0 0</pose>
      <inertial>
        <pose>0 0 0 0 -0 0</pose>
        <mass>50</mass>
        <inertia>
          <ixx>1.175</ixx>
          <ixy>-0</ixy>
          <ixz>0</ixz>
          <iyy>1</iyy>
          <iyz>0</iyz>
          <izz>1.175</izz>
        </inertia>
      </inertial>
      <collision name='roller_front_left_collision'>
        <pose>0 0 0 1.5708 -0 0</pose>
        <geometry>
          <cylinder>
            <length>0.4</length>
            <radius>0.2</radius>
          </cylinder>
        </geometry>
        <surface>
          <contact>
            <ode/>
          </contact>
          <friction>
            <ode>
              <mu>0.8</mu>
              <mu2>0.8</mu2>
            </ode>
          </friction>
        </surface>
      </collision>
      <gravity>1</gravity>
      <velocity_decay>
        <linear>0</linear>
        <angular>0</angular>
      </velocity_decay>
      <self_collide>1</self_collide>
    </link>
    <joint name='roller_front_left_joint' type='revolute'>
      <child>roller_front_left</child>
      <parent>body</parent>
      <axis>
        <dynamics>
          <damping>1</damping>
        </dynamics>
        <xyz>0 1 0</xyz>
      </axis>
      <physics><ode><cfm>0.0000658</cfm><erp>0.01315</erp></ode></physics>
    </joint>


    <plugin name="bobcat_tracked_drive_control" filename="libbobcat_tracked_drive_plugin.so">
      <IP>127.0.0.1</IP>
      <PortUDPLP>4660</PortUDPLP>
      <PortUDPRP>5355</PortUDPRP>
    </plugin>
	
    <plugin name="joint_state_publisher" filename="libgazebo_ros_joint_state_publisher.so">
      <robotNamespace>/Sahar</robotNamespace>
      <jointName>cogwheel_right_joint, cogwheel_left_joint</jointName>
      <updateRate>50.0</updateRate>
      <alwaysOn>true</alwaysOn>
    </plugin>
  </model>
</sdf>
