<?xml version="1.0"?>
<robot name="bobcat">
  <link name="body">
    <inertial>
      <origin
        xyz="-0.890714078986241 0.000176354230843794 0.525609535873677"
        rpy="0 0 0" />
      <mass
        value="5018.57981030941" />
      <inertia
        ixx="1272.55944993386"
        ixy="0.30897993676798"
        ixz="-158.353301657466"
        iyy="2264.90693597666"
        iyz="-0.107097171125939"
        izz="2025.98192908188" />
    </inertial>
    <visual>
      <origin
        xyz="0 0 0"
        rpy="0 0 0" />
      <geometry>
        <mesh
          filename="package://srvss_bobcat/sdf_models/srvss_bobcat/meshes/body.STL" />
      </geometry>
      <material
        name="">
        <color
          rgba="0.647058823529412 0.619607843137255 0.588235294117647 0.5" />
      </material>
    </visual>
    <collision>
      <origin
        xyz="0 0 0"
        rpy="0 0 0" />
      <geometry>
        <mesh
          filename="package://srvss_bobcat/sdf_models/srvss_bobcat/meshes/body.STL" />
      </geometry>
    </collision>
  </link>
  <link name="front_left_wheel">
    <inertial>
      <origin
        xyz="2.0502E-07 0.19645 -3.6566E-09"
        rpy="0 0 0" />
      <mass
        value="1113.6" />
      <inertia
        ixx="57.645"
        ixy="-0.0001268"
        ixz="0.00024451"
        iyy="96.158"
        iyz="-4.2461E-05"
        izz="57.645" />
    </inertial>
    <visual>
      <origin
        xyz="0 0 0"
        rpy="0 0 0" />
      <geometry>
        <mesh
          filename="package://srvss_bobcat/sdf_models/srvss_bobcat/meshes/front_left_wheel.STL" />
      </geometry>
      <material
        name="">
        <color
          rgba="0.64706 0.61961 0.58824 1" />
      </material>
    </visual>
    <collision>
      <origin
        xyz="0 0 0"
        rpy="0 0 0" />
      <geometry>
        <mesh
          filename="package://srvss_bobcat/sdf_models/srvss_bobcat/meshes/front_left_wheel.STL" />
      </geometry>
    </collision>
  </link>
  <joint name="front_left_wheel_joint" type="continuous">
    <origin
      xyz="-0.22722 0.47558 0.125"
      rpy="0 2.1164E-16 0" />
    <parent
      link="body" />
    <child
      link="front_left_wheel" />
    <axis
      xyz="0 1 0" />
  </joint>
  <link name="front_right_wheel">
    <inertial>
      <origin
        xyz="-2.0519E-07 -0.19645 -4.3198E-09"
        rpy="0 0 0" />
      <mass
        value="1113.6" />
      <inertia
        ixx="57.645"
        ixy="-0.00012695"
        ixz="-0.00024494"
        iyy="96.158"
        iyz="4.2098E-05"
        izz="57.645" />
    </inertial>
    <visual>
      <origin
        xyz="0 0 0"
        rpy="0 0 0" />
      <geometry>
        <mesh
          filename="package://srvss_bobcat/sdf_models/srvss_bobcat/meshes/front_right_wheel.STL" />
      </geometry>
      <material
        name="">
        <color
          rgba="0.64706 0.61961 0.58824 1" />
      </material>
    </visual>
    <collision>
      <origin
        xyz="0 0 0"
        rpy="0 0 0" />
      <geometry>
        <mesh
          filename="package://srvss_bobcat/sdf_models/srvss_bobcat/meshes/front_right_wheel.STL" />
      </geometry>
    </collision>
  </link>
  <joint name="front_right_wheel_joint" type="continuous">
    <origin
      xyz="-0.22722 -0.47558 0.125"
      rpy="0 2.1164E-16 0" />
    <parent
      link="body" />
    <child
      link="front_right_wheel" />
    <axis
      xyz="0 1 0" />
  </joint>
  <link name="back_left_wheel">
    <inertial>
      <origin
        xyz="7.7344E-08 0.19645 1.8868E-07"
        rpy="0 0 0" />
      <mass
        value="1113.6" />
      <inertia
        ixx="57.645"
        ixy="-9.3672E-06"
        ixz="-0.00022863"
        iyy="96.158"
        iyz="-0.00013365"
        izz="57.645" />
    </inertial>
    <visual>
      <origin
        xyz="0 0 0"
        rpy="0 0 0" />
      <geometry>
        <mesh
          filename="package://srvss_bobcat/sdf_models/srvss_bobcat/meshes/back_left_wheel.STL" />
      </geometry>
      <material
        name="">
        <color
          rgba="0.64706 0.61961 0.58824 1" />
      </material>
    </visual>
    <collision>
      <origin
        xyz="0 0 0"
        rpy="0 0 0" />
      <geometry>
        <mesh
          filename="package://srvss_bobcat/sdf_models/srvss_bobcat/meshes/back_left_wheel.STL" />
      </geometry>
    </collision>
  </link>
  <joint name="back_left_wheel_joint" type="continuous">
    <origin
      xyz="-1.227 0.47558 0.14772"
      rpy="0 2.1164E-16 0" />
    <parent
      link="body" />
    <child
      link="back_left_wheel" />
    <axis
      xyz="0 1 0" />
  </joint>
  <link name="back_right_wheel">
    <inertial>
      <origin
        xyz="-1.4894E-07 -0.19645 1.3751E-07"
        rpy="0 0 0" />
      <mass
        value="1113.6" />
      <inertia
        ixx="57.645"
        ixy="-6.7699E-05"
        ixz="4.3277E-05"
        iyy="96.158"
        iyz="0.00011578"
        izz="57.645" />
    </inertial>
    <visual>
      <origin
        xyz="0 0 0"
        rpy="0 0 0" />
      <geometry>
        <mesh
          filename="package://srvss_bobcat/sdf_models/srvss_bobcat/meshes/back_right_wheel.STL" />
      </geometry>
      <material
        name="">
        <color
          rgba="0.64706 0.61961 0.58824 1" />
      </material>
    </visual>
    <collision>
      <origin
        xyz="0 0 0"
        rpy="0 0 0" />
      <geometry>
        <mesh
          filename="package://srvss_bobcat/sdf_models/srvss_bobcat/meshes/back_right_wheel.STL" />
      </geometry>
    </collision>
  </link>
  <joint name="back_right_wheel_joint" type="continuous">
    <origin
      xyz="-1.227 -0.47558 0.14772"
      rpy="0 2.1164E-16 0" />
    <parent
      link="body" />
    <child
      link="back_right_wheel" />
    <axis
      xyz="0 1 0" />
  </joint>
  <link name="base_arm">
    <inertial>
      <origin
        xyz="0.066509 1.9771E-12 0.25686"
        rpy="0 0 0" />
      <mass
        value="194.91" />
      <inertia
        ixx="50.76"
        ixy="-2.9264E-11"
        ixz="0.66798"
        iyy="4.8017"
        iyz="7.0403E-12"
        izz="47.388" />
    </inertial>
    <visual>
      <origin
        xyz="0 0 0"
        rpy="0 0 0" />
      <geometry>
        <mesh
          filename="package://srvss_bobcat/sdf_models/srvss_bobcat/meshes/base_arm.STL" />
      </geometry>
      <material
        name="">
        <color
          rgba="0.64706 0.61961 0.58824 1" />
      </material>
    </visual>
    <collision>
      <origin
        xyz="0 0 0"
        rpy="0 0 0" />
      <geometry>
        <mesh
          filename="package://srvss_bobcat/sdf_models/srvss_bobcat/meshes/base_arm.STL" />
      </geometry>
    </collision>
  </link>
  <joint name="base_arm_joint" type="fixed">
    <origin
      xyz="-1.9776 0 1.1773"
      rpy="0 2.1164E-16 0" />
    <parent
      link="body" />
    <child
      link="base_arm" />
  </joint>
  <link name="main_arm">
    <inertial>
      <origin
        xyz="1.1865 -4.0206E-07 -0.60466"
        rpy="0 0 0" />
      <mass
        value="369.05" />
      <inertia
        ixx="133.74"
        ixy="0.00012791"
        ixz="-68.753"
        iyy="216.24"
        iyz="-4.6593E-05"
        izz="268.55" />
    </inertial>
    <visual>
      <origin
        xyz="0 0 0"
        rpy="0 0 0" />
      <geometry>
        <mesh
          filename="package://srvss_bobcat/sdf_models/srvss_bobcat/meshes/main_arm.STL" />
      </geometry>
      <material
        name="">
        <color
          rgba="0.89412 0.91373 0.92941 1" />
      </material>
    </visual>
    <collision>
      <origin
        xyz="0 0 0"
        rpy="0 0 0" />
      <geometry>
        <mesh
          filename="package://srvss_bobcat/sdf_models/srvss_bobcat/meshes/main_arm.STL" />
      </geometry>
    </collision>
  </link>
  <joint name="main_arm_joint" type="fixed">
    <origin
      xyz="0.22304 0 0.5262"
      rpy="0 -2.1164E-16 0" />
    <parent
      link="base_arm" />
    <child
      link="main_arm" />
  </joint>
  <link name="supporter">
    <inertial>
      <origin
        xyz="0.51341 -4.9085E-16 -0.060486"
        rpy="0 0 0" />
      <mass
        value="65.29" />
      <inertia
        ixx="16.898"
        ixy="-2.3004E-13"
        ixz="-0.76501"
        iyy="6.6127"
        iyz="-2.4072E-13"
        izz="23.301" />
    </inertial>
    <visual>
      <origin
        xyz="0 0 0"
        rpy="0 0 0" />
      <geometry>
        <mesh
          filename="package://srvss_bobcat/sdf_models/srvss_bobcat/meshes/supporter.STL" />
      </geometry>
      <material
        name="">
        <color
          rgba="0.64706 0.61961 0.58824 1" />
      </material>
    </visual>
    <collision>
      <origin
        xyz="0 0 0"
        rpy="0 0 0" />
      <geometry>
        <mesh
          filename="package://srvss_bobcat/sdf_models/srvss_bobcat/meshes/supporter.STL" />
      </geometry>
    </collision>
  </link>
  <joint name="supporter_joint" type="fixed">
    <origin
      xyz="0.39771 0 -0.89486"
      rpy="0 8.0491E-16 0" />
    <parent
      link="main_arm" />
    <child
      link="supporter" />
  </joint>
  <link name="front_cylinder">
    <inertial>
      <origin
        xyz="0.16022 1.6587E-08 -0.17142"
        rpy="0 0 0" />
      <mass
        value="24.149" />
      <inertia
        ixx="4.0554"
        ixy="-4.9938E-08"
        ixz="-0.46391"
        iyy="0.95412"
        iyz="6.094E-08"
        izz="3.9926" />
    </inertial>
    <visual>
      <origin
        xyz="0 0 0"
        rpy="0 0 0" />
      <geometry>
        <mesh
          filename="package://srvss_bobcat/sdf_models/srvss_bobcat/meshes/front_cylinder.STL" />
      </geometry>
      <material
        name="">
        <color
          rgba="0.64706 0.61961 0.58824 1" />
      </material>
    </visual>
    <collision>
      <origin
        xyz="0 0 0"
        rpy="0 0 0" />
      <geometry>
        <mesh
          filename="package://srvss_bobcat/sdf_models/srvss_bobcat/meshes/front_cylinder.STL" />
      </geometry>
    </collision>
  </link>
  <joint name="front_cylinder_joint" type="fixed">
    <origin
      xyz="1.741 0 -0.80293"
      rpy="0 8.0491E-16 0" />
    <parent
      link="main_arm" />
    <child
      link="front_cylinder" />
  </joint>
  <link name="front_shaft">
    <inertial>
      <origin
        xyz="9.4954E-07 8.3283E-07 -0.19417"
        rpy="0 0 0" />
      <mass
        value="13.711" />
      <inertia
        ixx="2.4234"
        ixy="-2.5882E-07"
        ixz="1.3728E-06"
        iyy="0.41181"
        iyz="1.3005E-06"
        izz="2.0158" />
    </inertial>
    <visual>
      <origin
        xyz="0 0 0"
        rpy="0 0 0" />
      <geometry>
        <mesh
          filename="package://srvss_bobcat/sdf_models/srvss_bobcat/meshes/front_shaft.STL" />
      </geometry>
      <material
        name="">
        <color
          rgba="0.64706 0.61961 0.58824 1" />
      </material>
    </visual>
    <collision>
      <origin
        xyz="0 0 0"
        rpy="0 0 0" />
      <geometry>
        <mesh
          filename="package://srvss_bobcat/sdf_models/srvss_bobcat/meshes/front_shaft.STL" />
      </geometry>
    </collision>
  </link>
  <joint name="front_shaft_joint" type="fixed">
    <origin
      xyz="0.50479 0 -0.54009"
      rpy="-3.1416 0.75163 -3.1416" />
    <parent
      link="front_cylinder" />
    <child
      link="front_shaft" />
  </joint>
  <link name="loader">
    <inertial>
      <origin
        xyz="0.37894 2.192E-15 0.067409"
        rpy="0 0 0" />
      <mass
        value="196.06" />
      <inertia
        ixx="58.693"
        ixy="1.2282E-14"
        ixz="-3.1063"
        iyy="18.499"
        iyz="-4.2535E-15"
        izz="64.178" />
    </inertial>
    <visual>
      <origin
        xyz="0 0 0"
        rpy="0 0 0" />
      <geometry>
        <mesh
          filename="package://srvss_bobcat/sdf_models/srvss_bobcat/meshes/loader.STL" />
      </geometry>
      <material
        name="">
        <color
          rgba="0.89412 0.91373 0.92941 1" />
      </material>
    </visual>
    <collision>
      <origin
        xyz="0 0 0"
        rpy="0 0 0" />
      <geometry>
        <mesh
          filename="package://srvss_bobcat/sdf_models/srvss_bobcat/meshes/loader.STL" />
      </geometry>
    </collision>
  </link>
  <joint name="loader_joint" type="fixed">
    <origin
      xyz="2.0984 0 -1.557"
      rpy="0 2.5362E-15 0" />
    <parent
      link="main_arm" />
    <child
      link="loader" />
  </joint>
  <link name="back_cylinder">
    <inertial>
      <origin
        xyz="0.14567 5.3127E-08 0.43479"
        rpy="0 0 0" />
      <mass
        value="30.817" />
      <inertia
        ixx="10.053"
        ixy="-2.1135E-07"
        ixz="0.70965"
        iyy="2.3798"
        iyz="-5.4817E-07"
        izz="8.1729" />
    </inertial>
    <visual>
      <origin
        xyz="0 0 0"
        rpy="0 0 0" />
      <geometry>
        <mesh
          filename="package://srvss_bobcat/sdf_models/srvss_bobcat/meshes/back_cylinder.STL" />
      </geometry>
      <material
        name="">
        <color
          rgba="0.64706 0.61961 0.58824 1" />
      </material>
    </visual>
    <collision>
      <origin
        xyz="0 0 0"
        rpy="0 0 0" />
      <geometry>
        <mesh
          filename="package://srvss_bobcat/sdf_models/srvss_bobcat/meshes/back_cylinder.STL" />
      </geometry>
    </collision>
  </link>
  <joint name="back_cylinder_joint" type="fixed">
    <origin
      xyz="-1.8135 0 0.2184"
      rpy="0 8.0491E-16 0" />
    <parent
      link="body" />
    <child
      link="back_cylinder" />
  </joint>
  <link name="back_shaft">
    <inertial>
      <origin
        xyz="-1.2324E-08 -4.788E-09 -0.41004"
        rpy="0 0 0" />
      <mass
        value="20.367" />
      <inertia
        ixx="6.9354"
        ixy="-8.5203E-07"
        ixz="7.9714E-09"
        iyy="1.7047"
        iyz="-3.6983E-09"
        izz="5.2356" />
    </inertial>
    <visual>
      <origin
        xyz="0 0 0"
        rpy="0 0 0" />
      <geometry>
        <mesh
          filename="package://srvss_bobcat/sdf_models/srvss_bobcat/meshes/back_shaft.STL" />
      </geometry>
      <material
        name="">
        <color
          rgba="0.64706 0.61961 0.58824 1" />
      </material>
    </visual>
    <collision>
      <origin
        xyz="0 0 0"
        rpy="0 0 0" />
      <geometry>
        <mesh
          filename="package://srvss_bobcat/sdf_models/srvss_bobcat/meshes/back_shaft.STL" />
      </geometry>
    </collision>
  </link>
  <joint name="back_shaft_joint" type="fixed">
    <origin
      xyz="0.33441 0 0.99813"
      rpy="-5.7722E-16 0.32328 -4.9954E-16" />
    <parent
      link="back_cylinder" />
    <child
      link="back_shaft" />
  </joint>

 <!-- Transmissions for ROS Control -->
  <transmission name="tran1">
    <type>transmission_interface/SimpleTransmission</type>
    <joint name="front_right_wheel_joint">
	<hardwareInterface>EffortJointInterface</hardwareInterface>
    </joint>
    <actuator name="motor1">
      <mechanicalReduction>1</mechanicalReduction>
    </actuator>
  </transmission>

  <transmission name="tran2">
    <type>transmission_interface/SimpleTransmission</type>
    <joint name="front_left_wheel_joint">
      <hardwareInterface>EffortJointInterface</hardwareInterface>
    </joint>
    <actuator name="motor2">
      <mechanicalReduction>1</mechanicalReduction>
    </actuator>
  </transmission>

  <transmission name="tran3">
    <type>transmission_interface/SimpleTransmission</type>
    <joint name="back_right_wheel_joint">
      <hardwareInterface>EffortJointInterface</hardwareInterface>
    </joint>
    <actuator name="motor3">
      <mechanicalReduction>1</mechanicalReduction>
    </actuator>
  </transmission>

  <transmission name="tran4">
    <type>transmission_interface/SimpleTransmission</type>
    <joint name="back_left_wheel_joint">
      <hardwareInterface>EffortJointInterface</hardwareInterface>
    </joint>
    <actuator name="motor4">
      <mechanicalReduction>1</mechanicalReduction>
    </actuator>
  </transmission>

  <!-- ros_control plugin -->
  <gazebo>
    <plugin name="gazebo_ros_control" filename="libgazebo_ros_control.so">
      <robotNamespace>/srvss_bobcat</robotNamespace>
    </plugin>
  </gazebo>
  <gazebo reference="body">
    <mu1>1</mu1>
    <mu2>1</mu2>
    <selfCollide>true</selfCollide>
    <material>Gazebo/Wood</material>
  </gazebo>
  <gazebo reference="front_right_wheel">
    <mu1>1</mu1>
    <mu2>1</mu2>
    <selfCollide>true</selfCollide>
    <material>Gazebo/Grey</material>
  </gazebo>
  <gazebo reference="front_left_wheel">
    <mu1>1</mu1>
    <mu2>1</mu2>
    <selfCollide>true</selfCollide>
    <material>Gazebo/Grey</material>
  </gazebo>
  <gazebo reference="back_right_wheel">
    <mu1>1</mu1>
    <mu2>1</mu2>
    <selfCollide>true</selfCollide>
    <material>Gazebo/Grey</material>
  </gazebo>
  <gazebo reference="back_left_wheel">
    <mu1>1</mu1>
    <mu2>1</mu2>
    <material>Gazebo/Grey</material>
  </gazebo>
  <gazebo reference="base_arm">
    <mu1>1</mu1>
    <mu2>1</mu2>
    <selfCollide>true</selfCollide>
    <material>Gazebo/Grey</material>
  </gazebo>
  <gazebo reference="main_arm">
    <mu1>1</mu1>
    <mu2>1</mu2>
    <selfCollide>true</selfCollide>
    <material>Gazebo/PaintedWall</material>
  </gazebo>
  <gazebo reference="back_shaft">
    <mu1>1</mu1>
    <mu2>1</mu2>
    <selfCollide>true</selfCollide>
    <material>Gazebo/Black</material>
  </gazebo>
  <gazebo reference="supporter">
    <mu1>1</mu1>
    <mu2>1</mu2>
    <selfCollide>true</selfCollide>
    <material>Gazebo/GreyTransparent</material>
  </gazebo>
  <gazebo reference="front_cylinder">
    <mu1>1</mu1>
    <mu2>1</mu2>
    <selfCollide>true</selfCollide>
    <material>Gazebo/BlueTransparent</material>
  </gazebo>
  <gazebo reference="loader">
    <mu1>1</mu1>
    <mu2>1</mu2>
    <selfCollide>true</selfCollide>
    <material>Gazebo/Gold</material>
  </gazebo>
  <gazebo reference="front_shaft">
    <mu1>1</mu1>
    <mu2>1</mu2>
    <selfCollide>true</selfCollide>
    <material>Gazebo/Black</material>
  </gazebo>
  <gazebo reference="back_cylinder">
    <mu1>1</mu1>
    <mu2>1</mu2>
    <selfCollide>true</selfCollide>
    <material>Gazebo/BlueTransparent</material>
  </gazebo>
</robot>
