<sdf version='1.4'>
  <world name='default'>
    <model name='ground_plane'>
      <static>1</static>
      <link name='link'>
        <collision name='collision'>
          <geometry>
            <plane>
              <normal>0 0 1</normal>
              <size>100 100</size>
            </plane>
          </geometry>
          <surface>
            <friction>
              <ode>
                <mu>100</mu>
                <mu2>50</mu2>
              </ode>
            </friction>
            <bounce/>
            <contact>
              <ode/>
            </contact>
          </surface>
          <max_contacts>10</max_contacts>
        </collision>
        <visual name='visual'>
          <cast_shadows>0</cast_shadows>
          <geometry>
            <plane>
              <normal>0 0 1</normal>
              <size>100 100</size>
            </plane>
          </geometry>
          <material>
            <script>
              <uri>file://media/materials/scripts/gazebo.material</uri>
              <name>Gazebo/Grey</name>
            </script>
          </material>
        </visual>
        <velocity_decay>
          <linear>0</linear>
          <angular>0</angular>
        </velocity_decay>
        <self_collide>0</self_collide>
        <kinematic>0</kinematic>
        <gravity>1</gravity>
      </link>
    </model>
    <light name='sun' type='directional'>
      <cast_shadows>1</cast_shadows>
      <pose>0 0 10 0 -0 0</pose>
      <diffuse>0.8 0.8 0.8 1</diffuse>
      <specular>0.2 0.2 0.2 1</specular>
      <attenuation>
        <range>1000</range>
        <constant>0.9</constant>
        <linear>0.01</linear>
        <quadratic>0.001</quadratic>
      </attenuation>
      <direction>-0.5 0.1 -0.9</direction>
    </light>
    <model name='Sahar'>
      <link name='body'>
        <pose>0 0 0 0 -0 0</pose>
        <inertial>
          <pose>-0.873221 -0.0104657 0.683626 0 -0 0</pose>
          <mass>2646.54</mass>
          <inertia>
            <ixx>818.884</ixx>
            <ixy>10.9258</ixy>
            <ixz>-87.8857</ixz>
            <iyy>1232.58</iyy>
            <iyz>-8.30849</iyz>
            <izz>1018.05</izz>
          </inertia>
        </inertial>
        <collision name='body_collision'>
          <pose>0 0 0 0 -0 0</pose>
          <geometry>
            <mesh>
              <scale>1 1 1</scale>
              <uri>model://bobcat/meshes/body.STL</uri>
            </mesh>
          </geometry>
          <surface>
            <contact>
              <ode/>
            </contact>
            <friction>
              <ode>
                <mu>1</mu>
                <mu2>1</mu2>
              </ode>
            </friction>
            <bounce/>
          </surface>
          <max_contacts>10</max_contacts>
        </collision>
        <collision name='body_collision_Ibeo_link'>
          <pose>-0.29575 0.03227 1.85972 1.5708 -6.10623e-16 1.5708</pose>
          <geometry>
            <mesh>
              <scale>1 1 1</scale>
              <uri>model://bobcat/meshes/Ibeo_lite.stl</uri>
            </mesh>
          </geometry>
          <surface>
            <contact>
              <ode/>
            </contact>
            <friction>
              <ode>
                <mu>1</mu>
                <mu2>1</mu2>
              </ode>
            </friction>
            <bounce/>
          </surface>
          <max_contacts>10</max_contacts>
        </collision>
        <collision name='body_collision_cabin'>
          <pose>-0.11317 0 0.61042 0 8.0491e-16 0</pose>
          <geometry>
            <mesh>
              <scale>1 1 1</scale>
              <uri>model://bobcat/meshes/cabin.STL</uri>
            </mesh>
          </geometry>
          <surface>
            <contact>
              <ode/>
            </contact>
            <friction>
              <ode>
                <mu>1</mu>
                <mu2>1</mu2>
              </ode>
            </friction>
            <bounce/>
          </surface>
          <max_contacts>10</max_contacts>
        </collision>
        <collision name='body_collision_front_sick_link'>
          <pose>0.26113 0 0.048493 1.5708 -5.55112e-17 1.5708</pose>
          <geometry>
            <mesh>
              <scale>1 1 1</scale>
              <uri>model://bobcat/meshes/front_sick_lite.stl</uri>
            </mesh>
          </geometry>
          <surface>
            <contact>
              <ode/>
            </contact>
            <friction>
              <ode>
                <mu>1</mu>
                <mu2>1</mu2>
              </ode>
            </friction>
            <bounce/>
          </surface>
          <max_contacts>10</max_contacts>
        </collision>
        <collision name='body_collision_left_sick_link'>
          <pose>-0.21801 0.89557 0.66494 1.5708 -5.55112e-17 1.5708</pose>
          <geometry>
            <mesh>
              <scale>1 1 1</scale>
              <uri>model://bobcat/meshes/left_sick_lite.stl</uri>
            </mesh>
          </geometry>
          <surface>
            <contact>
              <ode/>
            </contact>
            <friction>
              <ode>
                <mu>1</mu>
                <mu2>1</mu2>
              </ode>
            </friction>
            <bounce/>
          </surface>
          <max_contacts>10</max_contacts>
        </collision>
        <collision name='body_collision_right_sick_link'>
          <pose>-0.2174 -0.89576 0.66494 1.5708 -5.55112e-17 1.5708</pose>
          <geometry>
            <mesh>
              <scale>1 1 1</scale>
              <uri>model://bobcat/meshes/right_sick_lite.stl</uri>
            </mesh>
          </geometry>
          <surface>
            <contact>
              <ode/>
            </contact>
            <friction>
              <ode>
                <mu>1</mu>
                <mu2>1</mu2>
              </ode>
            </friction>
            <bounce/>
          </surface>
          <max_contacts>10</max_contacts>
        </collision>
        <collision name='body_collision_supporter_hinge'>
          <pose>-0.31547 0 0.68593 1.5708 -5.55112e-17 1.5708</pose>
          <geometry>
            <mesh>
              <scale>1 1 1</scale>
              <uri>model://bobcat/meshes/supporter_hinge.STL</uri>
            </mesh>
          </geometry>
          <surface>
            <contact>
              <ode/>
            </contact>
            <friction>
              <ode>
                <mu>1</mu>
                <mu2>1</mu2>
              </ode>
            </friction>
            <bounce/>
          </surface>
          <max_contacts>10</max_contacts>
        </collision>
        <visual name='body_visual'>
          <pose>0 0 0 0 -0 0</pose>
          <geometry>
            <mesh>
              <scale>1 1 1</scale>
              <uri>model://bobcat/meshes/body.STL</uri>
            </mesh>
          </geometry>
          <material>
            <script>
              <name>Gazebo/Wood</name>
              <uri>__default__</uri>
            </script>
          </material>
        </visual>
        <visual name='body_visual_Ibeo_link'>
          <pose>-0.29575 0.03227 1.85972 1.5708 -6.10623e-16 1.5708</pose>
          <geometry>
            <mesh>
              <scale>1 1 1</scale>
              <uri>model://bobcat/meshes/Ibeo.STL</uri>
            </mesh>
          </geometry>
          <material>
            <script>
              <name>Gazebo/Grey</name>
              <uri>__default__</uri>
            </script>
          </material>
        </visual>
        <visual name='body_visual_cabin'>
          <pose>-0.11317 0 0.61042 0 8.0491e-16 0</pose>
          <geometry>
            <mesh>
              <scale>1 1 1</scale>
              <uri>model://bobcat/meshes/cabin.STL</uri>
            </mesh>
          </geometry>
        </visual>
        <visual name='body_visual_front_sick_link'>
          <pose>0.26113 0 0.048493 1.5708 -5.55112e-17 1.5708</pose>
          <geometry>
            <mesh>
              <scale>1 1 1</scale>
              <uri>model://bobcat/meshes/front_sick.STL</uri>
            </mesh>
          </geometry>
          <material>
            <script>
              <name>Gazebo/Grey</name>
              <uri>__default__</uri>
            </script>
          </material>
        </visual>
        <visual name='body_visual_left_sick_link'>
          <pose>-0.21801 0.89557 0.66494 1.5708 -5.55112e-17 1.5708</pose>
          <geometry>
            <mesh>
              <scale>1 1 1</scale>
              <uri>model://bobcat/meshes/left_sick.STL</uri>
            </mesh>
          </geometry>
          <material>
            <script>
              <name>Gazebo/Grey</name>
              <uri>__default__</uri>
            </script>
          </material>
        </visual>
        <visual name='body_visual_right_sick_link'>
          <pose>-0.2174 -0.89576 0.66494 1.5708 -5.55112e-17 1.5708</pose>
          <geometry>
            <mesh>
              <scale>1 1 1</scale>
              <uri>model://bobcat/meshes/right_sick.STL</uri>
            </mesh>
          </geometry>
          <material>
            <script>
              <name>Gazebo/Grey</name>
              <uri>__default__</uri>
            </script>
          </material>
        </visual>
        <visual name='body_visual_supporter_hinge'>
          <pose>-0.31547 0 0.68593 1.5708 -5.55112e-17 1.5708</pose>
          <geometry>
            <mesh>
              <scale>1 1 1</scale>
              <uri>model://bobcat/meshes/supporter_hinge.STL</uri>
            </mesh>
          </geometry>
          <material>
            <script>
              <name>Gazebo/GreyTransparent</name>
              <uri>__default__</uri>
            </script>
          </material>
        </visual>
        <gravity>1</gravity>
        <velocity_decay>
          <linear>0</linear>
          <angular>0</angular>
        </velocity_decay>
        <self_collide>1</self_collide>
        <kinematic>0</kinematic>
      </link>
      <link name='back_cylinder'>
        <pose>-1.8135 0 0.2184 0 8.0491e-16 0</pose>
        <inertial>
          <pose>0.14567 5.3127e-08 0.43479 0 -0 0</pose>
          <mass>30.817</mass>
          <inertia>
            <ixx>10.053</ixx>
            <ixy>-2.1135e-07</ixy>
            <ixz>0.70965</ixz>
            <iyy>2.3798</iyy>
            <iyz>-5.4817e-07</iyz>
            <izz>8.1729</izz>
          </inertia>
        </inertial>
        <collision name='back_cylinder_collision'>
          <pose>0 0 0 0 -0 0</pose>
          <geometry>
            <mesh>
              <scale>1 1 1</scale>
              <uri>model://bobcat/meshes/back_cylinder.STL</uri>
            </mesh>
          </geometry>
          <surface>
            <contact>
              <ode/>
            </contact>
            <friction>
              <ode/>
            </friction>
            <bounce/>
          </surface>
          <max_contacts>10</max_contacts>
        </collision>
        <visual name='back_cylinder_visual'>
          <pose>0 0 0 0 -0 0</pose>
          <geometry>
            <mesh>
              <scale>1 1 1</scale>
              <uri>model://bobcat/meshes/back_cylinder.STL</uri>
            </mesh>
          </geometry>
          <material>
            <script>
              <name>Gazebo/BlueTransparent</name>
              <uri>__default__</uri>
            </script>
          </material>
        </visual>
        <gravity>1</gravity>
        <velocity_decay>
          <linear>0</linear>
          <angular>0</angular>
        </velocity_decay>
        <self_collide>0</self_collide>
        <kinematic>0</kinematic>
      </link>
      <joint name='back_cylinder_joint' type='revolute'>
        <child>back_cylinder</child>
        <parent>body</parent>
        <axis>
          <xyz>0 1 0</xyz>
          <limit>
            <lower>-1.57</lower>
            <upper>1.57</upper>
            <effort>1e+06</effort>
            <velocity>100</velocity>
          </limit>
          <dynamics/>
        </axis>
      </joint>
      <link name='back_shaft'>
        <pose>-1.47909 0 1.21653 -5.7722e-16 0.32328 -4.9954e-16</pose>
        <inertial>
          <pose>-1.2324e-08 -4.788e-09 -0.41004 0 -0 0</pose>
          <mass>20.367</mass>
          <inertia>
            <ixx>6.9354</ixx>
            <ixy>-8.5203e-07</ixy>
            <ixz>7.9714e-09</ixz>
            <iyy>1.7047</iyy>
            <iyz>-3.6983e-09</iyz>
            <izz>5.2356</izz>
          </inertia>
        </inertial>
        <collision name='back_shaft_collision'>
          <pose>0 0 0 0 -0 0</pose>
          <geometry>
            <mesh>
              <scale>1 1 1</scale>
              <uri>model://bobcat/meshes/back_shaft.STL</uri>
            </mesh>
          </geometry>
          <surface>
            <contact>
              <ode/>
            </contact>
            <friction>
              <ode/>
            </friction>
            <bounce/>
          </surface>
          <max_contacts>10</max_contacts>
        </collision>
        <visual name='back_shaft_visual'>
          <pose>0 0 0 0 -0 0</pose>
          <geometry>
            <mesh>
              <scale>1 1 1</scale>
              <uri>model://bobcat/meshes/back_shaft.STL</uri>
            </mesh>
          </geometry>
          <material>
            <script>
              <name>Gazebo/Black</name>
              <uri>__default__</uri>
            </script>
          </material>
        </visual>
        <gravity>1</gravity>
        <velocity_decay>
          <linear>0</linear>
          <angular>0</angular>
        </velocity_decay>
        <self_collide>0</self_collide>
        <kinematic>0</kinematic>
      </link>
      <joint name='back_shaft_joint' type='prismatic'>
        <child>back_shaft</child>
        <parent>back_cylinder</parent>
        <axis>
          <xyz>0.317678 4.18527e-16 0.948199</xyz>
          <limit>
            <lower>-0.2</lower>
            <upper>1</upper>
            <effort>1e+06</effort>
            <velocity>100</velocity>
          </limit>
          <dynamics/>
        </axis>
      </joint>
      <link name='back_left_wheel'>
        <pose>-1.227 0.47558 0.14772 0 2.1164e-16 0</pose>
        <inertial>
          <pose>7.7344e-08 0.19645 1.8868e-07 0 -0 0</pose>
          <mass>333.358</mass>
          <inertia>
            <ixx>17.0765</ixx>
            <ixy>-2.79367e-06</ixy>
            <ixz>-6.68629e-05</ixz>
            <iyy>29.6158</iyy>
            <iyz>-1.33651e-05</iyz>
            <izz>17.0765</izz>
          </inertia>
        </inertial>
        <collision name='back_left_wheel_collision'>
          <pose>0 -0.2 0 1.5708 -0 0</pose>
          <geometry>
            <cylinder>
              <length>0.4</length>
              <radius>0.4</radius>
            </cylinder>
          </geometry>
          <surface>
            <contact>
              <ode/>
            </contact>
            <friction>
              <ode>
                <mu>0.5</mu>
                <mu2>0.5</mu2>
              </ode>
            </friction>
            <bounce/>
          </surface>
          <max_contacts>10</max_contacts>
        </collision>
        <visual name='back_left_wheel_visual'>
          <pose>0 0 0 0 -0 0</pose>
          <geometry>
            <mesh>
              <scale>1 1 1</scale>
              <uri>model://bobcat/meshes/back_left_wheel.stl</uri>
            </mesh>
          </geometry>
          <material>
            <script>
              <name>Gazebo/Grey</name>
              <uri>__default__</uri>
            </script>
          </material>
        </visual>
        <gravity>1</gravity>
        <velocity_decay>
          <linear>0</linear>
          <angular>0</angular>
        </velocity_decay>
        <self_collide>0</self_collide>
        <kinematic>0</kinematic>
      </link>
      <joint name='back_left_wheel_joint' type='revolute'>
        <child>back_left_wheel</child>
        <parent>body</parent>
        <axis>
          <xyz>0 1 0</xyz>
          <limit>
            <lower>-1e+16</lower>
            <upper>1e+16</upper>
          </limit>
          <dynamics/>
        </axis>
      </joint>
      <link name='back_right_wheel'>
        <pose>-1.227 -0.47558 0.14772 0 2.1164e-16 0</pose>
        <inertial>
          <pose>-1.4894e-07 -0.19645 1.3751e-07 0 -0 0</pose>
          <mass>333.36</mass>
          <inertia>
            <ixx>17.0765</ixx>
            <ixy>-1.87699e-05</ixy>
            <ixz>1.23277e-05</ixz>
            <iyy>29.6158</iyy>
            <iyz>3.1578e-05</iyz>
            <izz>17.0765</izz>
          </inertia>
        </inertial>
        <collision name='back_right_wheel_collision'>
          <pose>0 -0.2 0 1.5708 -0 0</pose>
          <geometry>
            <cylinder>
              <length>0.4</length>
              <radius>0.4</radius>
            </cylinder>
          </geometry>
          <surface>
            <contact>
              <ode/>
            </contact>
            <friction>
              <ode>
                <mu>0.5</mu>
                <mu2>0.5</mu2>
              </ode>
            </friction>
            <bounce/>
          </surface>
          <max_contacts>10</max_contacts>
        </collision>
        <visual name='back_right_wheel_visual'>
          <pose>0 0 0 0 -0 0</pose>
          <geometry>
            <mesh>
              <scale>1 1 1</scale>
              <uri>model://bobcat/meshes/back_right_wheel.stl</uri>
            </mesh>
          </geometry>
          <material>
            <script>
              <name>Gazebo/Grey</name>
              <uri>__default__</uri>
            </script>
          </material>
        </visual>
        <gravity>1</gravity>
        <velocity_decay>
          <linear>0</linear>
          <angular>0</angular>
        </velocity_decay>
        <self_collide>1</self_collide>
        <kinematic>0</kinematic>
      </link>
      <joint name='back_right_wheel_joint' type='revolute'>
        <child>back_right_wheel</child>
        <parent>body</parent>
        <axis>
          <xyz>0 1 0</xyz>
          <limit>
            <lower>-1e+16</lower>
            <upper>1e+16</upper>
          </limit>
          <dynamics/>
        </axis>
      </joint>
      <link name='base_arm'>
        <pose>-1.9776 0 1.1773 0 2.1164e-16 0</pose>
        <inertial>
          <pose>0.066509 1.9771e-12 0.25686 0 -0 0</pose>
          <mass>194.91</mass>
          <inertia>
            <ixx>50.76</ixx>
            <ixy>-2.9264e-11</ixy>
            <ixz>0.66798</ixz>
            <iyy>4.8017</iyy>
            <iyz>7.0403e-12</iyz>
            <izz>47.388</izz>
          </inertia>
        </inertial>
        <collision name='base_arm_collision'>
          <pose>0 0 0 0 -0 0</pose>
          <geometry>
            <mesh>
              <scale>1 1 1</scale>
              <uri>model://bobcat/meshes/base_arm.STL</uri>
            </mesh>
          </geometry>
          <surface>
            <contact>
              <ode/>
            </contact>
            <friction>
              <ode/>
            </friction>
            <bounce/>
          </surface>
          <max_contacts>10</max_contacts>
        </collision>
        <visual name='base_arm_visual'>
          <pose>0 0 0 0 -0 0</pose>
          <geometry>
            <mesh>
              <scale>1 1 1</scale>
              <uri>model://bobcat/meshes/base_arm.STL</uri>
            </mesh>
          </geometry>
          <material>
            <script>
              <name>Gazebo/Grey</name>
              <uri>__default__</uri>
            </script>
          </material>
        </visual>
        <gravity>1</gravity>
        <velocity_decay>
          <linear>0</linear>
          <angular>0</angular>
        </velocity_decay>
        <self_collide>0</self_collide>
        <kinematic>0</kinematic>
      </link>
      <joint name='base_arm_joint' type='revolute'>
        <child>base_arm</child>
        <parent>body</parent>
        <axis>
          <xyz>0 1 0</xyz>
          <limit>
            <lower>-1.57</lower>
            <upper>1.57</upper>
            <effort>1e+06</effort>
            <velocity>100</velocity>
          </limit>
          <dynamics/>
        </axis>
      </joint>
      <link name='main_arm'>
        <pose>-1.75456 0 1.7035 0 -0 0</pose>
        <inertial>
          <pose>1.1865 -4.0206e-07 -0.60466 0 -0 0</pose>
          <mass>369.05</mass>
          <inertia>
            <ixx>133.74</ixx>
            <ixy>0.00012791</ixy>
            <ixz>-68.753</ixz>
            <iyy>216.24</iyy>
            <iyz>-4.6593e-05</iyz>
            <izz>268.55</izz>
          </inertia>
        </inertial>
        <collision name='main_arm_collision'>
          <pose>0 0 0 0 -0 0</pose>
          <geometry>
            <mesh>
              <scale>1 1 1</scale>
              <uri>model://bobcat/meshes/main_arm.STL</uri>
            </mesh>
          </geometry>
          <surface>
            <contact>
              <ode/>
            </contact>
            <friction>
              <ode/>
            </friction>
            <bounce/>
          </surface>
          <max_contacts>10</max_contacts>
        </collision>
        <visual name='main_arm_visual'>
          <pose>0 0 0 0 -0 0</pose>
          <geometry>
            <mesh>
              <scale>1 1 1</scale>
              <uri>model://bobcat/meshes/main_arm.STL</uri>
            </mesh>
          </geometry>
          <material>
            <script>
              <name>Gazebo/PaintedWall</name>
              <uri>__default__</uri>
            </script>
          </material>
        </visual>
        <gravity>1</gravity>
        <velocity_decay>
          <linear>0</linear>
          <angular>0</angular>
        </velocity_decay>
        <self_collide>0</self_collide>
        <kinematic>0</kinematic>
      </link>
      <joint name='main_arm_joint' type='revolute'>
        <child>main_arm</child>
        <parent>base_arm</parent>
        <axis>
          <xyz>0 1 0</xyz>
          <limit>
            <lower>-1.57</lower>
            <upper>1.57</upper>
            <effort>1e+06</effort>
            <velocity>100</velocity>
          </limit>
          <dynamics/>
        </axis>
      </joint>
      <link name='front_cylinder'>
        <pose>-0.01356 0 0.90057 0 8.0491e-16 0</pose>
        <inertial>
          <pose>0.16022 1.6587e-08 -0.17142 0 -0 0</pose>
          <mass>24.149</mass>
          <inertia>
            <ixx>4.0554</ixx>
            <ixy>-4.9938e-08</ixy>
            <ixz>-0.46391</ixz>
            <iyy>0.95412</iyy>
            <iyz>6.094e-08</iyz>
            <izz>3.9926</izz>
          </inertia>
        </inertial>
        <collision name='front_cylinder_collision'>
          <pose>0 0 0 0 -0 0</pose>
          <geometry>
            <mesh>
              <scale>1 1 1</scale>
              <uri>model://bobcat/meshes/front_cylinder.STL</uri>
            </mesh>
          </geometry>
          <surface>
            <contact>
              <ode/>
            </contact>
            <friction>
              <ode/>
            </friction>
            <bounce/>
          </surface>
          <max_contacts>10</max_contacts>
        </collision>
        <visual name='front_cylinder_visual'>
          <pose>0 0 0 0 -0 0</pose>
          <geometry>
            <mesh>
              <scale>1 1 1</scale>
              <uri>model://bobcat/meshes/front_cylinder.STL</uri>
            </mesh>
          </geometry>
          <material>
            <script>
              <name>Gazebo/BlueTransparent</name>
              <uri>__default__</uri>
            </script>
          </material>
        </visual>
        <gravity>1</gravity>
        <velocity_decay>
          <linear>0</linear>
          <angular>0</angular>
        </velocity_decay>
        <self_collide>0</self_collide>
        <kinematic>0</kinematic>
      </link>
      <joint name='front_cylinder_joint' type='revolute'>
        <child>front_cylinder</child>
        <parent>main_arm</parent>
        <axis>
          <xyz>0 1 0</xyz>
          <limit>
            <lower>-1.57</lower>
            <upper>1.57</upper>
            <effort>1e+06</effort>
            <velocity>100</velocity>
          </limit>
          <dynamics/>
        </axis>
      </joint>
      <link name='front_shaft'>
        <pose>0.49123 0 0.36048 3.14159 0.75163 3.14159</pose>
        <inertial>
          <pose>9.4954e-07 8.3283e-07 -0.19417 0 -0 0</pose>
          <mass>13.711</mass>
          <inertia>
            <ixx>2.4234</ixx>
            <ixy>-2.5882e-07</ixy>
            <ixz>1.3728e-06</ixz>
            <iyy>0.41181</iyy>
            <iyz>1.3005e-06</iyz>
            <izz>2.0158</izz>
          </inertia>
        </inertial>
        <collision name='front_shaft_collision'>
          <pose>0 0 0 0 -0 0</pose>
          <geometry>
            <mesh>
              <scale>1 1 1</scale>
              <uri>model://bobcat/meshes/front_shaft.STL</uri>
            </mesh>
          </geometry>
          <surface>
            <contact>
              <ode/>
            </contact>
            <friction>
              <ode/>
            </friction>
            <bounce/>
          </surface>
          <max_contacts>10</max_contacts>
        </collision>
        <visual name='front_shaft_visual'>
          <pose>0 0 0 0 -0 0</pose>
          <geometry>
            <mesh>
              <scale>1 1 1</scale>
              <uri>model://bobcat/meshes/front_shaft.STL</uri>
            </mesh>
          </geometry>
          <material>
            <script>
              <name>Gazebo/Black</name>
              <uri>__default__</uri>
            </script>
          </material>
        </visual>
        <gravity>1</gravity>
        <velocity_decay>
          <linear>0</linear>
          <angular>0</angular>
        </velocity_decay>
        <self_collide>0</self_collide>
        <kinematic>0</kinematic>
      </link>
      <joint name='front_shaft_joint' type='prismatic'>
        <child>front_shaft</child>
        <parent>front_cylinder</parent>
        <axis>
          <xyz>0.682831 2.33006e-06 -0.730577</xyz>
          <limit>
            <lower>-0.1</lower>
            <upper>0.6</upper>
            <effort>1e+06</effort>
            <velocity>100</velocity>
          </limit>
          <dynamics/>
        </axis>
      </joint>
      <link name='loader'>
        <pose>0.34384 0 0.1465 0 2.5362e-15 0</pose>
        <inertial>
          <pose>0.37894 2.192e-15 0.067409 0 -0 0</pose>
          <mass>98.03</mass>
          <inertia>
            <ixx>29.346</ixx>
            <ixy>0</ixy>
            <ixz>-1.55</ixz>
            <iyy>9.25</iyy>
            <iyz>0</iyz>
            <izz>32.05</izz>
          </inertia>
        </inertial>
        <collision name='loader_collision'>
          <pose>0 0 0 0 -0 0</pose>
          <geometry>
            <mesh>
              <scale>1 1 1</scale>
              <uri>model://bobcat/meshes/loader.STL</uri>
            </mesh>
          </geometry>
          <surface>
            <contact>
              <ode/>
            </contact>
            <friction>
              <ode>
                <mu>1</mu>
                <mu2>1</mu2>
              </ode>
            </friction>
            <bounce/>
          </surface>
          <max_contacts>10</max_contacts>
        </collision>
        <visual name='loader_visual'>
          <pose>0 0 0 0 -0 0</pose>
          <geometry>
            <mesh>
              <scale>1 1 1</scale>
              <uri>model://bobcat/meshes/loader.STL</uri>
            </mesh>
          </geometry>
          <material>
            <script>
              <name>Gazebo/Gold</name>
              <uri>__default__</uri>
            </script>
          </material>
        </visual>
        <gravity>1</gravity>
        <velocity_decay>
          <linear>0</linear>
          <angular>0</angular>
        </velocity_decay>
        <self_collide>1</self_collide>
        <kinematic>0</kinematic>
      </link>
      <joint name='loader_joint' type='revolute'>
        <child>loader</child>
        <parent>main_arm</parent>
        <axis>
          <xyz>0 1 0</xyz>
          <limit>
            <lower>0</lower>
            <upper>1.57</upper>
            <effort>1e+06</effort>
            <velocity>100</velocity>
          </limit>
          <dynamics/>
        </axis>
      </joint>
      <link name='brackets'>
        <pose>0.68217 0 0.64099 0 2.5362e-15 0</pose>
        <inertial>
          <pose>0.14213 -1.579e-16 0.33109 0 -0 0</pose>
          <mass>12.857</mass>
          <inertia>
            <ixx>2.9339</ixx>
            <ixy>-2.9653e-16</ixy>
            <ixz>0.23718</ixz>
            <iyy>0.67251</iyy>
            <iyz>3.0656e-16</iyz>
            <izz>2.738</izz>
          </inertia>
        </inertial>
        <collision name='brackets_collision'>
          <pose>0 0 0 0 -0 0</pose>
          <geometry>
            <mesh>
              <scale>1 1 1</scale>
              <uri>model://bobcat/meshes/brackets.STL</uri>
            </mesh>
          </geometry>
          <surface>
            <contact>
              <ode/>
            </contact>
            <friction>
              <ode>
                <mu>1</mu>
                <mu2>1</mu2>
              </ode>
            </friction>
            <bounce/>
          </surface>
          <max_contacts>10</max_contacts>
        </collision>
        <visual name='brackets_visual'>
          <pose>0 0 0 0 -0 0</pose>
          <geometry>
            <mesh>
              <scale>1 1 1</scale>
              <uri>model://bobcat/meshes/brackets.STL</uri>
            </mesh>
          </geometry>
          <material>
            <script>
              <name>Gazebo/Grey</name>
              <uri>__default__</uri>
            </script>
          </material>
        </visual>
        <gravity>1</gravity>
        <velocity_decay>
          <linear>0</linear>
          <angular>0</angular>
        </velocity_decay>
        <self_collide>1</self_collide>
        <kinematic>0</kinematic>
      </link>
      <joint name='brackets_joint' type='revolute'>
        <child>brackets</child>
        <parent>loader</parent>
        <axis>
          <xyz>0 1 0</xyz>
          <limit>
            <lower>0</lower>
            <upper>1</upper>
            <effort>1e+06</effort>
            <velocity>1e+06</velocity>
          </limit>
          <dynamics/>
        </axis>
      </joint>
      <link name='supporter'>
        <pose>-1.35685 0 0.80864 0 8.0491e-16 0</pose>
        <inertial>
          <pose>0.51341 -4.9085e-16 -0.060486 0 -0 0</pose>
          <mass>65.29</mass>
          <inertia>
            <ixx>16.898</ixx>
            <ixy>-2.3004e-13</ixy>
            <ixz>-0.76501</ixz>
            <iyy>6.6127</iyy>
            <iyz>-2.4072e-13</iyz>
            <izz>23.301</izz>
          </inertia>
        </inertial>
        <collision name='supporter_collision'>
          <pose>0 0 0 0 -0 0</pose>
          <geometry>
            <mesh>
              <scale>1 1 1</scale>
              <uri>model://bobcat/meshes/supporter.STL</uri>
            </mesh>
          </geometry>
          <surface>
            <contact>
              <ode/>
            </contact>
            <friction>
              <ode>
                <mu>1</mu>
                <mu2>1</mu2>
              </ode>
            </friction>
            <bounce/>
          </surface>
          <max_contacts>10</max_contacts>
        </collision>
        <visual name='supporter_visual'>
          <pose>0 0 0 0 -0 0</pose>
          <geometry>
            <mesh>
              <scale>1 1 1</scale>
              <uri>model://bobcat/meshes/supporter.STL</uri>
            </mesh>
          </geometry>
          <material>
            <script>
              <name>Gazebo/GreyTransparent</name>
              <uri>__default__</uri>
            </script>
          </material>
        </visual>
        <gravity>1</gravity>
        <velocity_decay>
          <linear>0</linear>
          <angular>0</angular>
        </velocity_decay>
        <self_collide>1</self_collide>
        <kinematic>0</kinematic>
      </link>
      <joint name='supporter_joint' type='revolute'>
        <child>supporter</child>
        <parent>main_arm</parent>
        <axis>
          <xyz>0 1 0</xyz>
          <limit>
            <lower>-0.2</lower>
            <upper>1</upper>
            <effort>1e+06</effort>
            <velocity>100</velocity>
          </limit>
          <dynamics/>
        </axis>
      </joint>
      <link name='front_left_wheel'>
        <pose>-0.22722 0.47558 0.125 0 2.1164e-16 0</pose>
        <inertial>
          <pose>2.0502e-07 0.19645 -3.6566e-09 0 -0 0</pose>
          <mass>333.358</mass>
          <inertia>
            <ixx>17.0765</ixx>
            <ixy>-4.02019e-05</ixy>
            <ixz>7.57982e-05</ixz>
            <iyy>29.6158</iyy>
            <iyz>-6.64195e-06</iyz>
            <izz>17.0765</izz>
          </inertia>
        </inertial>
        <collision name='front_left_wheel_collision'>
          <pose>0 0.2 0 1.5708 -0 0</pose>
          <geometry>
            <cylinder>
              <length>0.4</length>
              <radius>0.4</radius>
            </cylinder>
          </geometry>
          <surface>
            <contact>
              <ode/>
            </contact>
            <friction>
              <ode>
                <mu>0.5</mu>
                <mu2>0.5</mu2>
              </ode>
            </friction>
            <bounce/>
          </surface>
          <max_contacts>10</max_contacts>
        </collision>
        <visual name='front_left_wheel_visual'>
          <pose>0 0 0 0 -0 0</pose>
          <geometry>
            <mesh>
              <scale>1 1 1</scale>
              <uri>model://bobcat/meshes/front_left_wheel.stl</uri>
            </mesh>
          </geometry>
          <material>
            <script>
              <name>Gazebo/Grey</name>
              <uri>__default__</uri>
            </script>
          </material>
        </visual>
        <gravity>1</gravity>
        <velocity_decay>
          <linear>0</linear>
          <angular>0</angular>
        </velocity_decay>
        <self_collide>1</self_collide>
        <kinematic>0</kinematic>
      </link>
      <joint name='front_left_wheel_joint' type='revolute'>
        <child>front_left_wheel</child>
        <parent>body</parent>
        <axis>
          <xyz>0 1 0</xyz>
          <limit>
            <lower>-1e+16</lower>
            <upper>1e+16</upper>
          </limit>
          <dynamics/>
        </axis>
      </joint>
      <link name='front_right_wheel'>
        <pose>-0.22722 -0.47558 0.125 0 2.1164e-16 0</pose>
        <inertial>
          <pose>-2.0519e-07 -0.19645 -4.3198e-09 0 -0 0</pose>
          <mass>333.358</mass>
          <inertia>
            <ixx>17.0765</ixx>
            <ixy>-3.66954e-05</ixy>
            <ixz>-7.5494e-05</ixz>
            <iyy>29.6158</iyy>
            <iyz>1.22098e-05</iyz>
            <izz>17.0765</izz>
          </inertia>
        </inertial>
        <collision name='front_right_wheel_collision'>
          <pose>0 0.2 0 1.5708 -0 0</pose>
          <geometry>
            <cylinder>
              <length>0.4</length>
              <radius>0.4</radius>
            </cylinder>
          </geometry>
          <surface>
            <contact>
              <ode/>
            </contact>
            <friction>
              <ode>
                <mu>0.5</mu>
                <mu2>0.5</mu2>
              </ode>
            </friction>
            <bounce/>
          </surface>
          <max_contacts>10</max_contacts>
        </collision>
        <visual name='front_right_wheel_visual'>
          <pose>0 0 0 0 -0 0</pose>
          <geometry>
            <mesh>
              <scale>1 1 1</scale>
              <uri>model://bobcat/meshes/front_right_wheel.stl</uri>
            </mesh>
          </geometry>
          <material>
            <script>
              <name>Gazebo/Grey</name>
              <uri>__default__</uri>
            </script>
          </material>
        </visual>
        <gravity>1</gravity>
        <velocity_decay>
          <linear>0</linear>
          <angular>0</angular>
        </velocity_decay>
        <self_collide>1</self_collide>
        <kinematic>0</kinematic>
      </link>
      <joint name='front_right_wheel_joint' type='revolute'>
        <child>front_right_wheel</child>
        <parent>body</parent>
        <axis>
          <xyz>0 1 0</xyz>
          <limit>
            <lower>-1e+16</lower>
            <upper>1e+16</upper>
          </limit>
          <dynamics/>
        </axis>
      </joint>
      <plugin name='gazebo_chain_plugin' filename='libchain_pagebo_plugin.so'>
        <robotNamespace>/Sahar</robotNamespace>
        <link1>back_shaft</link1>
        <link2>main_arm</link2>
        <joint>back_shaft_sheker</joint>
      </plugin>
      <plugin name='gazebo_chain_plugin' filename='libchain_pagebo_plugin.so'>
        <robotNamespace>/Sahar</robotNamespace>
        <link1>front_shaft</link1>
        <link2>loader</link2>
        <joint>front_shaft_sheker</joint>
      </plugin>
      <static>0</static>
      <plugin name='gazebo_ros_control' filename='libgazebo_ros_control.so'>
        <robotNamespace>/Sahar</robotNamespace>
      </plugin>
      <link name='left_sick::link'>
        <gravity>0</gravity>
        <visual name='visual'>
          <pose>0 0 0 1.57 5.55112e-17 -1.57</pose>
          <geometry>
            <mesh>
              <uri>model://sick/meshes/LMS.STL</uri>
            </mesh>
          </geometry>
        </visual>
        <sensor name='laser' type='gpu_ray'>
          <pose>0.01 0.04 0.0051 0 -0 0</pose>
          <ray>
            <scan>
              <horizontal>
                <samples>760</samples>
                <resolution>1</resolution>
                <min_angle>-1.658</min_angle>
                <max_angle>1.658</max_angle>
              </horizontal>
            </scan>
            <range>
              <min>0.1</min>
              <max>65</max>
              <resolution>1</resolution>
            </range>
          </ray>
          <plugin name='laser' filename='libsick_gpu.so'/>
          <always_on>1</always_on>
          <update_rate>30</update_rate>
          <visualize>0</visualize>
        </sensor>
        <velocity_decay>
          <linear>0</linear>
          <angular>0</angular>
        </velocity_decay>
        <pose>-0.2187 0.85 0.631 0 -0 1.57</pose>
        <self_collide>0</self_collide>
        <inertial>
          <inertia>
            <ixx>1</ixx>
            <ixy>0</ixy>
            <ixz>0</ixz>
            <iyy>1</iyy>
            <iyz>0</iyz>
            <izz>1</izz>
          </inertia>
          <mass>1</mass>
        </inertial>
        <kinematic>0</kinematic>
      </link>
      <link name='right_sick::link'>
        <gravity>0</gravity>
        <visual name='visual'>
          <pose>0 0 0 1.57 5.55112e-17 -1.57</pose>
          <geometry>
            <mesh>
              <uri>model://sick/meshes/LMS.STL</uri>
            </mesh>
          </geometry>
        </visual>
        <sensor name='laser' type='gpu_ray'>
          <pose>0.01 0.04 0.0051 0 -0 0</pose>
          <ray>
            <scan>
              <horizontal>
                <samples>760</samples>
                <resolution>1</resolution>
                <min_angle>-1.658</min_angle>
                <max_angle>1.658</max_angle>
              </horizontal>
            </scan>
            <range>
              <min>0.1</min>
              <max>65</max>
              <resolution>1</resolution>
            </range>
          </ray>
          <plugin name='laser' filename='libsick_gpu.so'/>
          <always_on>1</always_on>
          <update_rate>30</update_rate>
          <visualize>0</visualize>
        </sensor>
        <velocity_decay>
          <linear>0</linear>
          <angular>0</angular>
        </velocity_decay>
        <pose>-0.2187 -0.85 0.631 0 0 -1.57</pose>
        <self_collide>0</self_collide>
        <inertial>
          <inertia>
            <ixx>1</ixx>
            <ixy>0</ixy>
            <ixz>0</ixz>
            <iyy>1</iyy>
            <iyz>0</iyz>
            <izz>1</izz>
          </inertia>
          <mass>1</mass>
        </inertial>
        <kinematic>0</kinematic>
      </link>
      <link name='gps_ins::link'>
        <gravity>0</gravity>
        <visual name='visual'>
          <pose>0 0 0 1.57 -5.55112e-17 1.57</pose>
          <geometry>
            <mesh>
              <uri>model://GPS_INS/meshes/GNSS.STL</uri>
            </mesh>
          </geometry>
        </visual>
        <sensor name='imu_component' type='imu'>
          <pose>0.01 0.04 0.007 0 -0.014 0</pose>
          <imu>
            <topic>ODED</topic>
          </imu>
          <always_on>1</always_on>
          <update_rate>30</update_rate>
          <visualize>1</visualize>
        </sensor>
        <velocity_decay>
          <linear>0</linear>
          <angular>0</angular>
        </velocity_decay>
        <pose>0 0 0.5 0 -0 0</pose>
        <self_collide>0</self_collide>
        <inertial>
          <inertia>
            <ixx>1</ixx>
            <ixy>0</ixy>
            <ixz>0</ixz>
            <iyy>1</iyy>
            <iyz>0</iyz>
            <izz>1</izz>
          </inertia>
          <mass>1</mass>
        </inertial>
        <kinematic>0</kinematic>
      </link>
      <plugin name='GPS_INS' filename='libgps_ins.so'>
        <start_latitude>31.2622</start_latitude>
        <start_longitude>34.803611</start_longitude>
        <frequency>20</frequency>
      </plugin>
      <link name='ibeo::link'>
        <gravity>0</gravity>
        <visual name='visual'>
          <pose>0 0 0 1.57 -5.55112e-17 1.57</pose>
          <geometry>
            <mesh>
              <uri>model://IBEO/meshes/IBEO.STL</uri>
            </mesh>
          </geometry>
        </visual>
        <sensor name='ibeo-t1' type='gpu_ray'>
          <pose>0.01 0.04 0.005 0 -0.014 0</pose>
          <ray>
            <scan>
              <horizontal>
                <samples>760</samples>
                <resolution>1</resolution>
                <min_angle>-1.04719</min_angle>
                <max_angle>0.69813</max_angle>
              </horizontal>
            </scan>
            <range>
              <min>0.3</min>
              <max>35</max>
              <resolution>1</resolution>
            </range>
          </ray>
          <always_on>1</always_on>
          <update_rate>30</update_rate>
          <visualize>1</visualize>
        </sensor>
        <sensor name='ibeo-t2' type='gpu_ray'>
          <pose>0.01 0.04 0.006 0 -0.028 0</pose>
          <ray>
            <scan>
              <horizontal>
                <samples>760</samples>
                <resolution>1</resolution>
                <min_angle>-1.04719</min_angle>
                <max_angle>0.69813</max_angle>
              </horizontal>
            </scan>
            <range>
              <min>0.3</min>
              <max>35</max>
              <resolution>1</resolution>
            </range>
          </ray>
          <always_on>1</always_on>
          <update_rate>30</update_rate>
          <visualize>1</visualize>
        </sensor>
        <sensor name='ibeo-b1' type='gpu_ray'>
          <pose>0.01 0.04 0.007 0 0.014 0</pose>
          <ray>
            <scan>
              <horizontal>
                <samples>760</samples>
                <resolution>1</resolution>
                <min_angle>-0.872661</min_angle>
                <max_angle>0.872661</max_angle>
              </horizontal>
            </scan>
            <range>
              <min>0.3</min>
              <max>35</max>
              <resolution>1</resolution>
            </range>
            <noise>
              <type>gaussian</type>
              <mean>0</mean>
              <stddev>0.007</stddev>
            </noise>
          </ray>
          <always_on>1</always_on>
          <update_rate>30</update_rate>
          <visualize>1</visualize>
        </sensor>
        <sensor name='ibeo-b2' type='gpu_ray'>
          <pose>0.01 0.04 0.008 0 0.028 0</pose>
          <ray>
            <scan>
              <horizontal>
                <samples>760</samples>
                <resolution>1</resolution>
                <min_angle>-0.872661</min_angle>
                <max_angle>0.872661</max_angle>
              </horizontal>
            </scan>
            <range>
              <min>0.3</min>
              <max>35</max>
              <resolution>1</resolution>
            </range>
            <noise>
              <type>gaussian</type>
              <mean>0</mean>
              <stddev>0.007</stddev>
            </noise>
          </ray>
          <always_on>1</always_on>
          <update_rate>30</update_rate>
          <visualize>1</visualize>
        </sensor>
        <velocity_decay>
          <linear>0</linear>
          <angular>0</angular>
        </velocity_decay>
        <pose>-0.375 0.055 1.89 0 0.284 0</pose>
        <self_collide>0</self_collide>
        <inertial>
          <inertia>
            <ixx>1</ixx>
            <ixy>0</ixy>
            <ixz>0</ixz>
            <iyy>1</iyy>
            <iyz>0</iyz>
            <izz>1</izz>
          </inertia>
          <mass>1</mass>
        </inertial>
        <kinematic>0</kinematic>
      </link>
      <plugin name='IBEOPLUGIN' filename='libibeo_gpu.so'/>
      <link name='left_flea3::camera_link'>
        <visual name='visual'>
          <geometry>
            <mesh>
              <uri>model://FLEA3/meshes/FLEA3.STL</uri>
            </mesh>
          </geometry>
          <pose>-0.03 -0.015 0.015 0 1.57 0</pose>
        </visual>
        <sensor name='flea3cam' type='camera'>
          <visualize>1</visualize>
          <update_rate>15</update_rate>
          <camera name='head'>
            <horizontal_fov>1.39626</horizontal_fov>
            <image>
              <width>1624</width>
              <height>1224</height>
              <format>R8G8B8</format>
            </image>
            <clip>
              <near>0.02</near>
              <far>300</far>
            </clip>
            <noise>
              <type>gaussian</type>
              <mean>0</mean>
              <stddev>0.007</stddev>
            </noise>
          </camera>
          <plugin name='camera_controller' filename='libgazebo_ros_camera.so'>
            <alwaysOn>true</alwaysOn>
            <updateRate>30.0</updateRate>
            <cameraName>flea3/cameraL</cameraName>
            <imageTopicName>/SENSORS/CAM/L</imageTopicName>
            <cameraInfoTopicName>camera_info</cameraInfoTopicName>
            <frameName>cameraL_frame</frameName>
            <hackBaseline>0.07</hackBaseline>
            <distortionK1>0.0</distortionK1>
            <distortionK2>0.0</distortionK2>
            <distortionK3>0.0</distortionK3>
            <distortionT1>0.0</distortionT1>
            <distortionT2>0.0</distortionT2>
          </plugin>
        </sensor>
        <self_collide>0</self_collide>
        <kinematic>0</kinematic>
        <gravity>0</gravity>
        <velocity_decay>
          <linear>0</linear>
          <angular>0</angular>
        </velocity_decay>
        <pose>-0.35 0.3334 2.02 0 -0 0</pose>
        <inertial>
          <inertia>
            <ixx>1</ixx>
            <ixy>0</ixy>
            <ixz>0</ixz>
            <iyy>1</iyy>
            <iyz>0</iyz>
            <izz>1</izz>
          </inertia>
          <mass>1</mass>
        </inertial>
      </link>
      <static>0</static>
      <plugin name='CameraTF' filename='libcameraTF.so'/>
      <link name='right_flea3::camera_link'>
        <visual name='visual'>
          <geometry>
            <mesh>
              <uri>model://FLEA3/meshes/FLEA3.STL</uri>
            </mesh>
          </geometry>
          <pose>-0.03 -0.015 0.015 0 1.57 0</pose>
        </visual>
        <sensor name='flea3cam' type='camera'>
          <visualize>1</visualize>
          <update_rate>15</update_rate>
          <camera name='head'>
            <horizontal_fov>1.39626</horizontal_fov>
            <image>
              <width>1624</width>
              <height>1224</height>
              <format>R8G8B8</format>
            </image>
            <clip>
              <near>0.02</near>
              <far>300</far>
            </clip>
            <noise>
              <type>gaussian</type>
              <mean>0</mean>
              <stddev>0.007</stddev>
            </noise>
          </camera>
          <plugin name='camera_controller' filename='libgazebo_ros_camera.so'>
            <alwaysOn>true</alwaysOn>
            <updateRate>30.0</updateRate>
            <cameraName>flea3/cameraR</cameraName>
            <imageTopicName>/SENSORS/CAM/R</imageTopicName>
            <cameraInfoTopicName>camera_info</cameraInfoTopicName>
            <frameName>cameraR_frame</frameName>
            <hackBaseline>0.07</hackBaseline>
            <distortionK1>0.0</distortionK1>
            <distortionK2>0.0</distortionK2>
            <distortionK3>0.0</distortionK3>
            <distortionT1>0.0</distortionT1>
            <distortionT2>0.0</distortionT2>
          </plugin>
        </sensor>
        <self_collide>0</self_collide>
        <kinematic>0</kinematic>
        <gravity>0</gravity>
        <velocity_decay>
          <linear>0</linear>
          <angular>0</angular>
        </velocity_decay>
        <pose>-0.35 -0.2 2.02 0 -0 0</pose>
        <inertial>
          <inertia>
            <ixx>1</ixx>
            <ixy>0</ixy>
            <ixz>0</ixz>
            <iyy>1</iyy>
            <iyz>0</iyz>
            <izz>1</izz>
          </inertia>
          <mass>1</mass>
        </inertial>
      </link>
      <static>0</static>
      <plugin name='CameraTF' filename='libcameraTF.so'/>
      <link name='arm_wire_sensor::link'>
        <gravity>0</gravity>
        <visual name='visual'>
          <pose>0 0 0 1.57 -5.55112e-17 1.57</pose>
          <geometry>
            <mesh>
              <uri>model://wire_sensor/meshes/wire_sensor.STL</uri>
            </mesh>
          </geometry>
        </visual>
        <velocity_decay>
          <linear>0</linear>
          <angular>0</angular>
        </velocity_decay>
        <pose>-1.42 0.56 1.05 1.54159 0.841593 3.14159</pose>
        <self_collide>0</self_collide>
        <inertial>
          <inertia>
            <ixx>1</ixx>
            <ixy>0</ixy>
            <ixz>0</ixz>
            <iyy>1</iyy>
            <iyz>0</iyz>
            <izz>1</izz>
          </inertia>
          <mass>1</mass>
        </inertial>
        <kinematic>0</kinematic>
      </link>
      <link name='arm_wire_sensor_mount::link'>
        <gravity>0</gravity>
        <visual name='visual'>
          <pose>0 0 0 1.57 -5.55112e-17 1.57</pose>
          <geometry>
            <mesh>
              <uri>model://wire_sensor_mount/meshes/wire_sensor_mount.STL</uri>
            </mesh>
          </geometry>
        </visual>
        <velocity_decay>
          <linear>0</linear>
          <angular>0</angular>
        </velocity_decay>
        <pose>-1.31 0.56 1.28 -1.6 0 0</pose>
        <self_collide>0</self_collide>
        <inertial>
          <inertia>
            <ixx>1</ixx>
            <ixy>0</ixy>
            <ixz>0</ixz>
            <iyy>1</iyy>
            <iyz>0</iyz>
            <izz>1</izz>
          </inertia>
          <mass>1</mass>
        </inertial>
        <kinematic>0</kinematic>
      </link>
      <link name='blade_wire_sensor::link'>
        <gravity>0</gravity>
        <visual name='visual'>
          <pose>0 0 0 1.57 -5.55112e-17 1.57</pose>
          <geometry>
            <mesh>
              <uri>model://wire_sensor/meshes/wire_sensor.STL</uri>
            </mesh>
          </geometry>
        </visual>
        <velocity_decay>
          <linear>0</linear>
          <angular>0</angular>
        </velocity_decay>
        <pose>0.3 0.3 0.85 1.60652e-19 -0.83 3.14</pose>
        <self_collide>0</self_collide>
        <inertial>
          <inertia>
            <ixx>1</ixx>
            <ixy>0</ixy>
            <ixz>0</ixz>
            <iyy>1</iyy>
            <iyz>0</iyz>
            <izz>1</izz>
          </inertia>
          <mass>1</mass>
        </inertial>
        <kinematic>0</kinematic>
      </link>
      <link name='blade_wire_sensor_mount::link'>
        <gravity>0</gravity>
        <visual name='visual'>
          <pose>0 0 0 1.57 -5.55112e-17 1.57</pose>
          <geometry>
            <mesh>
              <uri>model://wire_sensor_mount/meshes/wire_sensor_mount.STL</uri>
            </mesh>
          </geometry>
        </visual>
        <velocity_decay>
          <linear>0</linear>
          <angular>0</angular>
        </velocity_decay>
        <pose>0.59 0.3 0.52 0 -1 0</pose>
        <self_collide>0</self_collide>
        <inertial>
          <inertia>
            <ixx>1</ixx>
            <ixy>0</ixy>
            <ixz>0</ixz>
            <iyy>1</iyy>
            <iyz>0</iyz>
            <izz>1</izz>
          </inertia>
          <mass>1</mass>
        </inertial>
        <kinematic>0</kinematic>
      </link>
      <joint name='left_sick_joint' type='revolute'>
        <child>left_sick::link</child>
        <parent>body</parent>
        <axis>
          <xyz>0 1 0</xyz>
          <limit>
            <lower>0</lower>
            <upper>0</upper>
          </limit>
          <dynamics/>
        </axis>
      </joint>
      <joint name='right_sick_joint' type='revolute'>
        <child>right_sick::link</child>
        <parent>body</parent>
        <axis>
          <xyz>0 1 0</xyz>
          <limit>
            <lower>0</lower>
            <upper>0</upper>
          </limit>
          <dynamics/>
        </axis>
      </joint>
      <joint name='gps_ins_joint' type='revolute'>
        <child>gps_ins::link</child>
        <parent>body</parent>
        <axis>
          <xyz>0 1 0</xyz>
          <limit>
            <lower>0</lower>
            <upper>0</upper>
          </limit>
          <dynamics/>
        </axis>
      </joint>
      <joint name='ibeo' type='revolute'>
        <child>ibeo::link</child>
        <parent>body</parent>
        <axis>
          <xyz>0 1 0</xyz>
          <limit>
            <lower>0</lower>
            <upper>0</upper>
          </limit>
          <dynamics/>
        </axis>
      </joint>
      <joint name='left_flea3' type='revolute'>
        <child>left_flea3::camera_link</child>
        <parent>body</parent>
        <axis>
          <xyz>0 1 0</xyz>
          <limit>
            <lower>0</lower>
            <upper>0</upper>
          </limit>
          <dynamics/>
        </axis>
      </joint>
      <joint name='right_flea3' type='revolute'>
        <child>right_flea3::camera_link</child>
        <parent>body</parent>
        <axis>
          <xyz>0 1 0</xyz>
          <limit>
            <lower>0</lower>
            <upper>0</upper>
          </limit>
          <dynamics/>
        </axis>
      </joint>
      <joint name='arm_wire_sensor_joint' type='revolute'>
        <child>arm_wire_sensor::link</child>
        <parent>body</parent>
        <axis>
          <xyz>0 1 0</xyz>
          <limit>
            <lower>0</lower>
            <upper>0</upper>
          </limit>
          <dynamics/>
        </axis>
      </joint>
      <joint name='arm_wire_sensor_mount_joint' type='revolute'>
        <child>arm_wire_sensor_mount::link</child>
        <parent>main_arm</parent>
        <axis>
          <xyz>0 1 0</xyz>
          <limit>
            <lower>0</lower>
            <upper>0</upper>
          </limit>
          <dynamics/>
        </axis>
      </joint>
      <joint name='blade_wire_sensor_mount_joint' type='revolute'>
        <child>blade_wire_sensor_mount::link</child>
        <parent>loader</parent>
        <axis>
          <xyz>0 1 0</xyz>
          <limit>
            <lower>0</lower>
            <upper>0</upper>
          </limit>
          <dynamics/>
        </axis>
      </joint>
      <joint name='blade_wire_sensor_joint' type='revolute'>
        <child>blade_wire_sensor::link</child>
        <parent>main_arm</parent>
        <axis>
          <xyz>0 1 0</xyz>
          <limit>
            <lower>0</lower>
            <upper>0</upper>
          </limit>
          <dynamics/>
        </axis>
      </joint>
      <plugin name='arm_wire_sensor_plugin' filename='libwire_sensor.so'>
        <sensor_name>Sahar::arm_wire_sensor::link</sensor_name>
        <mount_name>Sahar::arm_wire_sensor_mount::link</mount_name>
        <noise>0.1</noise>
      </plugin>
      <plugin name='blade_wire_sensor_plugin' filename='libwire_sensor.so'>
        <sensor_name>Sahar::blade_wire_sensor::link</sensor_name>
        <mount_name>Sahar::blade_wire_sensor_mount::link</mount_name>
        <noise>0.1</noise>
      </plugin>
      <plugin name='TFpublish' filename='libTFpublisher.so'>
        <tf1frame>gps_ins</tf1frame>
        <tf1parent>body</tf1parent>
        <tf1pose>0 0 0.5 0 0 0</tf1pose>
        <tf2frame>ibeo</tf2frame>
        <tf2parent>body</tf2parent>
        <tf2pose>-0.35 0.3334 2.02 0 0 0</tf2pose>
        <tf3frame>cameraL_frame</tf3frame>
        <tf3parent>body</tf3parent>
        <tf3pose>-0.35 0.3335 1.974 0 0 0</tf3pose>
        <tf4frame>cameraR_frame</tf4frame>
        <tf4parent>body</tf4parent>
        <tf4pose>-0.35 -0.2 2.02 0 0 0</tf4pose>
        <livetf1frame>body</livetf1frame>
        <livetf1parent>world</livetf1parent>
        <update_rate>20</update_rate>
      </plugin>
      <pose>0 0 0.3 0 -0 1</pose>
    </model>
    <physics type='ode'>
      <max_step_size>0.005</max_step_size>
      <real_time_factor>1</real_time_factor>
      <real_time_update_rate>1000</real_time_update_rate>
      <gravity>0 0 -9.8</gravity>
    </physics>
    <scene>
      <ambient>0.4 0.4 0.4 1</ambient>
      <background>0.7 0.7 0.7 1</background>
      <shadows>1</shadows>
    </scene>
    <model name='bookshelf'>
      <static>1</static>
      <link name='link'>
        <inertial>
          <mass>1</mass>
        </inertial>
        <collision name='back'>
          <pose>0 0.005 0.6 0 -0 0</pose>
          <geometry>
            <box>
              <size>0.9 0.01 1.2</size>
            </box>
          </geometry>
          <max_contacts>10</max_contacts>
          <surface>
            <bounce/>
            <friction>
              <ode/>
            </friction>
            <contact>
              <ode/>
            </contact>
          </surface>
        </collision>
        <visual name='visual1'>
          <pose>0 0.005 0.6 0 -0 0</pose>
          <geometry>
            <box>
              <size>0.9 0.01 1.2</size>
            </box>
          </geometry>
          <material>
            <script>
              <uri>file://media/materials/scripts/gazebo.material</uri>
              <name>Gazebo/Wood</name>
            </script>
          </material>
        </visual>
        <collision name='left_side'>
          <pose>0.45 -0.195 0.6 0 -0 0</pose>
          <geometry>
            <box>
              <size>0.02 0.4 1.2</size>
            </box>
          </geometry>
          <max_contacts>10</max_contacts>
          <surface>
            <bounce/>
            <friction>
              <ode/>
            </friction>
            <contact>
              <ode/>
            </contact>
          </surface>
        </collision>
        <visual name='visual2'>
          <pose>0.45 -0.195 0.6 0 -0 0</pose>
          <geometry>
            <box>
              <size>0.02 0.4 1.2</size>
            </box>
          </geometry>
          <material>
            <script>
              <uri>file://media/materials/scripts/gazebo.material</uri>
              <name>Gazebo/Wood</name>
            </script>
          </material>
        </visual>
        <collision name='right_side'>
          <pose>-0.45 -0.195 0.6 0 -0 0</pose>
          <geometry>
            <box>
              <size>0.02 0.4 1.2</size>
            </box>
          </geometry>
          <max_contacts>10</max_contacts>
          <surface>
            <bounce/>
            <friction>
              <ode/>
            </friction>
            <contact>
              <ode/>
            </contact>
          </surface>
        </collision>
        <visual name='visual3'>
          <pose>-0.45 -0.195 0.6 0 -0 0</pose>
          <geometry>
            <box>
              <size>0.02 0.4 1.2</size>
            </box>
          </geometry>
          <material>
            <script>
              <uri>file://media/materials/scripts/gazebo.material</uri>
              <name>Gazebo/Wood</name>
            </script>
          </material>
        </visual>
        <collision name='bottom'>
          <pose>0 -0.195 0.03 0 -0 0</pose>
          <geometry>
            <box>
              <size>0.88 0.4 0.06</size>
            </box>
          </geometry>
          <max_contacts>10</max_contacts>
          <surface>
            <bounce/>
            <friction>
              <ode/>
            </friction>
            <contact>
              <ode/>
            </contact>
          </surface>
        </collision>
        <visual name='visual4'>
          <pose>0 -0.195 0.03 0 -0 0</pose>
          <geometry>
            <box>
              <size>0.88 0.4 0.06</size>
            </box>
          </geometry>
          <material>
            <script>
              <uri>file://media/materials/scripts/gazebo.material</uri>
              <name>Gazebo/Wood</name>
            </script>
          </material>
        </visual>
        <collision name='top'>
          <pose>0 -0.195 1.19 0 -0 0</pose>
          <geometry>
            <box>
              <size>0.88 0.4 0.02</size>
            </box>
          </geometry>
          <max_contacts>10</max_contacts>
          <surface>
            <bounce/>
            <friction>
              <ode/>
            </friction>
            <contact>
              <ode/>
            </contact>
          </surface>
        </collision>
        <visual name='visual5'>
          <pose>0 -0.195 1.19 0 -0 0</pose>
          <geometry>
            <box>
              <size>0.88 0.4 0.02</size>
            </box>
          </geometry>
          <material>
            <script>
              <uri>file://media/materials/scripts/gazebo.material</uri>
              <name>Gazebo/Wood</name>
            </script>
          </material>
        </visual>
        <collision name='low_shelf'>
          <pose>0 -0.195 0.43 0 -0 0</pose>
          <geometry>
            <box>
              <size>0.88 0.4 0.02</size>
            </box>
          </geometry>
          <max_contacts>10</max_contacts>
          <surface>
            <bounce/>
            <friction>
              <ode/>
            </friction>
            <contact>
              <ode/>
            </contact>
          </surface>
        </collision>
        <visual name='visual6'>
          <pose>0 -0.195 0.43 0 -0 0</pose>
          <geometry>
            <box>
              <size>0.88 0.4 0.02</size>
            </box>
          </geometry>
          <material>
            <script>
              <uri>file://media/materials/scripts/gazebo.material</uri>
              <name>Gazebo/Wood</name>
            </script>
          </material>
        </visual>
        <collision name='high_shelf'>
          <pose>0 -0.195 0.8 0 -0 0</pose>
          <geometry>
            <box>
              <size>0.88 0.4 0.02</size>
            </box>
          </geometry>
          <max_contacts>10</max_contacts>
          <surface>
            <bounce/>
            <friction>
              <ode/>
            </friction>
            <contact>
              <ode/>
            </contact>
          </surface>
        </collision>
        <visual name='visual7'>
          <pose>0 -0.195 0.8 0 -0 0</pose>
          <geometry>
            <box>
              <size>0.88 0.4 0.02</size>
            </box>
          </geometry>
          <material>
            <script>
              <uri>file://media/materials/scripts/gazebo.material</uri>
              <name>Gazebo/Wood</name>
            </script>
          </material>
        </visual>
        <velocity_decay>
          <linear>0</linear>
          <angular>0</angular>
        </velocity_decay>
        <self_collide>0</self_collide>
        <kinematic>0</kinematic>
        <gravity>1</gravity>
      </link>
      <pose>2 6 0 0 -0 0</pose>
    </model>
    <model name='bookshelf_0'>
      <static>1</static>
      <link name='link'>
        <inertial>
          <mass>1</mass>
        </inertial>
        <collision name='back'>
          <pose>0 0.005 0.6 0 -0 0</pose>
          <geometry>
            <box>
              <size>0.9 0.01 1.2</size>
            </box>
          </geometry>
          <max_contacts>10</max_contacts>
          <surface>
            <bounce/>
            <friction>
              <ode/>
            </friction>
            <contact>
              <ode/>
            </contact>
          </surface>
        </collision>
        <visual name='visual1'>
          <pose>0 0.005 0.6 0 -0 0</pose>
          <geometry>
            <box>
              <size>0.9 0.01 1.2</size>
            </box>
          </geometry>
          <material>
            <script>
              <uri>file://media/materials/scripts/gazebo.material</uri>
              <name>Gazebo/Wood</name>
            </script>
          </material>
        </visual>
        <collision name='left_side'>
          <pose>0.45 -0.195 0.6 0 -0 0</pose>
          <geometry>
            <box>
              <size>0.02 0.4 1.2</size>
            </box>
          </geometry>
          <max_contacts>10</max_contacts>
          <surface>
            <bounce/>
            <friction>
              <ode/>
            </friction>
            <contact>
              <ode/>
            </contact>
          </surface>
        </collision>
        <visual name='visual2'>
          <pose>0.45 -0.195 0.6 0 -0 0</pose>
          <geometry>
            <box>
              <size>0.02 0.4 1.2</size>
            </box>
          </geometry>
          <material>
            <script>
              <uri>file://media/materials/scripts/gazebo.material</uri>
              <name>Gazebo/Wood</name>
            </script>
          </material>
        </visual>
        <collision name='right_side'>
          <pose>-0.45 -0.195 0.6 0 -0 0</pose>
          <geometry>
            <box>
              <size>0.02 0.4 1.2</size>
            </box>
          </geometry>
          <max_contacts>10</max_contacts>
          <surface>
            <bounce/>
            <friction>
              <ode/>
            </friction>
            <contact>
              <ode/>
            </contact>
          </surface>
        </collision>
        <visual name='visual3'>
          <pose>-0.45 -0.195 0.6 0 -0 0</pose>
          <geometry>
            <box>
              <size>0.02 0.4 1.2</size>
            </box>
          </geometry>
          <material>
            <script>
              <uri>file://media/materials/scripts/gazebo.material</uri>
              <name>Gazebo/Wood</name>
            </script>
          </material>
        </visual>
        <collision name='bottom'>
          <pose>0 -0.195 0.03 0 -0 0</pose>
          <geometry>
            <box>
              <size>0.88 0.4 0.06</size>
            </box>
          </geometry>
          <max_contacts>10</max_contacts>
          <surface>
            <bounce/>
            <friction>
              <ode/>
            </friction>
            <contact>
              <ode/>
            </contact>
          </surface>
        </collision>
        <visual name='visual4'>
          <pose>0 -0.195 0.03 0 -0 0</pose>
          <geometry>
            <box>
              <size>0.88 0.4 0.06</size>
            </box>
          </geometry>
          <material>
            <script>
              <uri>file://media/materials/scripts/gazebo.material</uri>
              <name>Gazebo/Wood</name>
            </script>
          </material>
        </visual>
        <collision name='top'>
          <pose>0 -0.195 1.19 0 -0 0</pose>
          <geometry>
            <box>
              <size>0.88 0.4 0.02</size>
            </box>
          </geometry>
          <max_contacts>10</max_contacts>
          <surface>
            <bounce/>
            <friction>
              <ode/>
            </friction>
            <contact>
              <ode/>
            </contact>
          </surface>
        </collision>
        <visual name='visual5'>
          <pose>0 -0.195 1.19 0 -0 0</pose>
          <geometry>
            <box>
              <size>0.88 0.4 0.02</size>
            </box>
          </geometry>
          <material>
            <script>
              <uri>file://media/materials/scripts/gazebo.material</uri>
              <name>Gazebo/Wood</name>
            </script>
          </material>
        </visual>
        <collision name='low_shelf'>
          <pose>0 -0.195 0.43 0 -0 0</pose>
          <geometry>
            <box>
              <size>0.88 0.4 0.02</size>
            </box>
          </geometry>
          <max_contacts>10</max_contacts>
          <surface>
            <bounce/>
            <friction>
              <ode/>
            </friction>
            <contact>
              <ode/>
            </contact>
          </surface>
        </collision>
        <visual name='visual6'>
          <pose>0 -0.195 0.43 0 -0 0</pose>
          <geometry>
            <box>
              <size>0.88 0.4 0.02</size>
            </box>
          </geometry>
          <material>
            <script>
              <uri>file://media/materials/scripts/gazebo.material</uri>
              <name>Gazebo/Wood</name>
            </script>
          </material>
        </visual>
        <collision name='high_shelf'>
          <pose>0 -0.195 0.8 0 -0 0</pose>
          <geometry>
            <box>
              <size>0.88 0.4 0.02</size>
            </box>
          </geometry>
          <max_contacts>10</max_contacts>
          <surface>
            <bounce/>
            <friction>
              <ode/>
            </friction>
            <contact>
              <ode/>
            </contact>
          </surface>
        </collision>
        <visual name='visual7'>
          <pose>0 -0.195 0.8 0 -0 0</pose>
          <geometry>
            <box>
              <size>0.88 0.4 0.02</size>
            </box>
          </geometry>
          <material>
            <script>
              <uri>file://media/materials/scripts/gazebo.material</uri>
              <name>Gazebo/Wood</name>
            </script>
          </material>
        </visual>
        <velocity_decay>
          <linear>0</linear>
          <angular>0</angular>
        </velocity_decay>
        <self_collide>0</self_collide>
        <kinematic>0</kinematic>
        <gravity>1</gravity>
      </link>
      <pose>4.44782 3 0 0 -0 0</pose>
    </model>
    <state world_name='default'>
      <sim_time>71 897000000</sim_time>
      <real_time>76 505000583</real_time>
      <wall_time>1404905784 686078468</wall_time>
      <model name='Sahar'>
        <pose>0.251913 -0.475169 0.280172 -4.5e-05 -0.022711 0.613496</pose>
        <link name='arm_wire_sensor::link'>
          <pose>-1.25076 -0.848307 1.29766 1.5416 0.864313 -2.52809</pose>
          <velocity>-0.012459 -0.004656 0.000877 -0.002573 -0.002957 -0.00208</velocity>
          <acceleration>0 0 0 0 -0 0</acceleration>
          <wrench>0 0 0 0 -0 0</wrench>
        </link>
        <link name='arm_wire_sensor_mount::link'>
          <pose>-1.11869 -0.755236 1.42235 -1.60005 0.080531 0.613524</pose>
          <velocity>0.0636 0.05287 -0.043365 0.026146 -0.033604 -0.00392</velocity>
          <acceleration>0 0 0 0 -0 0</acceleration>
          <wrench>0 0 0 0 -0 0</wrench>
        </link>
        <link name='back_cylinder'>
          <pose>-1.23458 -1.52179 0.45733 -7e-06 0.034617 0.613495</pose>
          <velocity>-0.021766 -0.008782 0.006167 -0.138993 0.191176 -0.002257</velocity>
          <acceleration>0 0 0 0 -0 0</acceleration>
          <wrench>0 0 0 0 -0 0</wrench>
        </link>
        <link name='back_left_wheel'>
          <pose>-1.02764 -0.794461 0.4 -2.4e-05 -0.831955 0.61351</pose>
          <velocity>-0.017629 -0.01237 -0.001291 0.022653 -0.035025 -0.001954</velocity>
          <acceleration>0 0 0 0 -0 0</acceleration>
          <wrench>0 0 0 0 -0 0</wrench>
        </link>
        <link name='back_right_wheel'>
          <pose>-0.480012 -1.57215 0.4 0 -0.707798 0.613495</pose>
          <velocity>-0.019134 -0.013483 0.003066 0.033525 -0.048413 -0.001709</velocity>
          <acceleration>0 0 0 0 -0 0</acceleration>
          <wrench>0 0 0 0 -0 0</wrench>
        </link>
        <link name='back_shaft'>
          <pose>-0.952504 -1.32318 1.37972 -1.1e-05 0.357889 0.613484</pose>
          <velocity>0.150783 0.113792 -0.092576 -0.14062 0.191526 -0.002416</velocity>
          <acceleration>0 0 0 0 -0 0</acceleration>
          <wrench>0 0 0 0 -0 0</wrench>
        </link>
        <link name='base_arm'>
          <pose>-1.38654 -1.62877 1.41225 -3e-06 0.190088 0.613461</pose>
          <velocity>-0.012618 -0.005538 0.008599 -0.112718 0.148553 0.00044</velocity>
          <acceleration>0 0 0 0 -0 0</acceleration>
          <wrench>0 0 0 0 -0 0</wrench>
        </link>
        <link name='blade_wire_sensor::link'>
          <pose>0.314849 -0.063794 0.864248 0.000293 -0.91053 -2.52988</pose>
          <velocity>0.085099 0.061879 0.022947 0.026141 -0.033595 -0.003907</velocity>
          <acceleration>0 0 0 0 -0 0</acceleration>
          <wrench>0 0 0 0 -0 0</wrench>
        </link>
        <link name='blade_wire_sensor_mount::link'>
          <pose>0.53523 0.091368 0.508066 -8.2e-05 -0.906552 0.613587</pose>
          <velocity>0.121356 0.087741 0.018244 -0.006354 0.012374 -0.003532</velocity>
          <acceleration>0 0 0 0 -0 0</acceleration>
          <wrench>0 0 0 0 -0 0</wrench>
        </link>
        <link name='body'>
          <pose>0.251913 -0.475169 0.280172 -4.5e-05 -0.022711 0.613496</pose>
          <velocity>-0.016313 -0.012022 -0.005466 -0.001359 0.006901 -0.004549</velocity>
          <acceleration>0 0 0 0 -0 0</acceleration>
          <wrench>0 0 0 0 -0 0</wrench>
        </link>
        <link name='brackets'>
          <pose>0.799046 -0.089776 0.621718 -4.8e-05 0.123561 0.613522</pose>
          <velocity>0.070179 0.053061 0.003979 0.119952 -0.16907 -0.004971</velocity>
          <acceleration>0 0 0 0 -0 0</acceleration>
          <wrench>0 0 0 0 -0 0</wrench>
        </link>
        <link name='front_cylinder'>
          <pose>0.233962 -0.487657 0.940178 -0.000104 0.069484 0.613506</pose>
          <velocity>0.075278 0.057189 0.010852 0.064849 -0.067249 0.000126</velocity>
          <acceleration>0 0 0 0 -0 0</acceleration>
          <wrench>0 0 0 0 -0 0</wrench>
        </link>
        <link name='front_left_wheel'>
          <pose>-0.209987 -0.218723 0.400004 -1.4e-05 -0.883102 0.613503</pose>
          <velocity>-0.016128 -0.014617 -0.010563 0.014599 -0.027105 -0.002182</velocity>
          <acceleration>0 0 0 0 -0 0</acceleration>
          <wrench>0 0 0 0 -0 0</wrench>
        </link>
        <link name='front_right_wheel'>
          <pose>0.337653 -0.996408 0.400002 -1.2e-05 -0.969971 0.613504</pose>
          <velocity>-0.01763 -0.015867 -0.006764 0.020627 -0.036406 -0.002509</velocity>
          <acceleration>0 0 0 0 -0 0</acceleration>
          <wrench>0 0 0 0 -0 0</wrench>
        </link>
        <link name='front_shaft'>
          <pose>0.61839 -0.217032 0.361372 -3.1415 0.682176 -2.52801</pose>
          <velocity>0.125377 0.10165 0.030876 0.054177 -0.066126 -0.003033</velocity>
          <acceleration>0 0 0 0 -0 0</acceleration>
          <wrench>0 0 0 0 -0 0</wrench>
        </link>
        <link name='gps_ins::link'>
          <pose>0.242619 -0.481674 0.780071 -8e-06 -0.022716 0.613492</pose>
          <velocity>-0.014645 -0.012269 -0.010845 -0.011144 0.009192 -0.002102</velocity>
          <acceleration>0 0 0 0 -0 0</acceleration>
          <wrench>0 0 0 0 -0 0</wrench>
        </link>
        <link name='ibeo::link'>
          <pose>-0.121417 -0.670722 2.16119 -8e-06 0.26128 0.61349</pose>
          <velocity>-0.007148 0.000495 -0.007122 -0.002583 -0.002959 -0.002098</velocity>
          <acceleration>0 0 0 0 -0 0</acceleration>
          <wrench>0 0 0 0 -0 0</wrench>
        </link>
        <link name='left_flea3::camera_link'>
          <pose>-0.263679 -0.430401 2.29172 -8e-06 -0.022712 0.613492</pose>
          <velocity>-0.005899 0.001924 -0.008395 -0.011058 0.009085 -0.002093</velocity>
          <acceleration>0 0 0 0 -0 0</acceleration>
          <wrench>0 0 0 0 -0 0</wrench>
        </link>
        <link name='left_sick::link'>
          <pose>-0.427955 0.08573 0.90606 -0.022714 -1e-05 2.18349</pose>
          <velocity>-0.012727 -0.009767 -0.011951 -0.011105 0.009122 -0.002107</velocity>
          <acceleration>0 0 0 0 -0 0</acceleration>
          <wrench>0 0 0 0 -0 0</wrench>
        </link>
        <link name='loader'>
          <pose>0.479079 -0.3151 0.159178 -4.9e-05 0.093445 0.613507</pose>
          <velocity>0.115885 0.083297 0.022888 -0.008525 0.014776 -0.000712</velocity>
          <acceleration>0 0 0 0 -0 0</acceleration>
          <wrench>0 0 0 0 -0 0</wrench>
        </link>
        <link name='main_arm'>
          <pose>-1.13073 -1.4486 1.88028 -4.8e-05 0.080537 0.613526</pose>
          <velocity>0.044127 0.042463 -0.063466 0.026193 -0.03531 -0.005214</velocity>
          <acceleration>0 0 0 0 -0 0</acceleration>
          <wrench>0 0 0 0 -0 0</wrench>
        </link>
        <link name='right_flea3::camera_link'>
          <pose>0.043413 -0.866532 2.29173 -8e-06 -0.022713 0.613492</pose>
          <velocity>-0.006809 0.001286 -0.006364 -0.01107 0.009109 -0.002087</velocity>
          <acceleration>0 0 0 0 -0 0</acceleration>
          <wrench>0 0 0 0 -0 0</wrench>
        </link>
        <link name='right_sick::link'>
          <pose>0.55078 -1.30426 0.906074 0.022714 -2.6e-05 -0.956508</pose>
          <velocity>-0.015652 -0.011824 -0.005453 -0.011102 0.009125 -0.002105</velocity>
          <acceleration>0 0 0 0 -0 0</acceleration>
          <wrench>0 0 0 0 -0 0</wrench>
        </link>
        <link name='supporter'>
          <pose>-0.875995 -1.26871 0.95621 0.000614 -0.120034 0.613221</pose>
          <velocity>0.04621 -0.042953 0.130645 -0.140092 -0.021466 0.058276</velocity>
          <acceleration>0 0 0 0 -0 0</acceleration>
          <wrench>0 0 0 0 -0 0</wrench>
        </link>
      </model>
      <model name='bookshelf'>
        <pose>2 6 0 0 -0 0</pose>
        <link name='link'>
          <pose>2 6 0 0 -0 0</pose>
          <velocity>0 0 0 0 -0 0</velocity>
          <acceleration>0 0 0 0 -0 0</acceleration>
          <wrench>0 0 0 0 -0 0</wrench>
        </link>
      </model>
      <model name='bookshelf_0'>
        <pose>4.44782 3 0 0 -0 1.64</pose>
        <link name='link'>
          <pose>4.44782 3 0 0 -0 1.64</pose>
          <velocity>0 0 0 0 -0 0</velocity>
          <acceleration>0 0 0 0 -0 0</acceleration>
          <wrench>0 0 0 0 -0 0</wrench>
        </link>
      </model>
      <model name='fence1'>
        <pose>6 7 0 0 -0 0</pose>
        <link name='link'>
          <pose>6 7 0 0 -0 0</pose>
          <velocity>0 0 0 0 -0 0</velocity>
          <acceleration>0 0 0 0 -0 0</acceleration>
          <wrench>0 0 0 0 -0 0</wrench>
        </link>
      </model>
      <model name='grey_wall'>
        <pose>7.45785 -5.55777 0 0 -0 0</pose>
        <link name='link'>
          <pose>7.45785 -5.55777 1.4 0 -0 0</pose>
          <velocity>0 0 0 0 -0 0</velocity>
          <acceleration>0 0 0 0 -0 0</acceleration>
          <wrench>0 0 0 0 -0 0</wrench>
        </link>
      </model>
      <model name='ground_plane'>
        <pose>0 0 0 0 -0 0</pose>
        <link name='link'>
          <pose>0 0 0 0 -0 0</pose>
          <velocity>0 0 0 0 -0 0</velocity>
          <acceleration>0 0 0 0 -0 0</acceleration>
          <wrench>0 0 0 0 -0 0</wrench>
        </link>
      </model>
    </state>
    <gui fullscreen='0'>
      <camera name='user_camera'>
        <pose>21.9109 -16.7813 8.29751 0 0.275643 2.35619</pose>
        <view_controller>orbit</view_controller>
      </camera>
    </gui>
    <model name='fence1'>
      <static>1</static>
      <link name='link'>
        <pose>0 0 0 0 -0 0</pose>
        <collision name='collision'>
          <geometry>
            <mesh>
              <uri>model://fence1/models/fence.dae</uri>
            </mesh>
          </geometry>
          <max_contacts>10</max_contacts>
          <surface>
            <bounce/>
            <friction>
              <ode/>
            </friction>
            <contact>
              <ode/>
            </contact>
          </surface>
        </collision>
        <visual name='visual'>
          <geometry>
            <mesh>
              <uri>model://fence1/models/fence.dae</uri>
            </mesh>
          </geometry>
        </visual>
        <velocity_decay>
          <linear>0</linear>
          <angular>0</angular>
        </velocity_decay>
        <self_collide>0</self_collide>
        <kinematic>0</kinematic>
        <gravity>1</gravity>
      </link>
      <pose>6 7 0 0 -0 0</pose>
    </model>
    <model name='grey_wall'>
      <static>1</static>
      <link name='link'>
        <pose>0 0 1.4 0 -0 0</pose>
        <collision name='collision'>
          <geometry>
            <box>
              <size>7.5 0.2 2.8</size>
            </box>
          </geometry>
          <max_contacts>10</max_contacts>
          <surface>
            <bounce/>
            <friction>
              <ode/>
            </friction>
            <contact>
              <ode/>
            </contact>
          </surface>
        </collision>
        <visual name='visual'>
          <cast_shadows>0</cast_shadows>
          <geometry>
            <box>
              <size>7.5 0.2 2.8</size>
            </box>
          </geometry>
          <material>
            <script>
              <uri>model://grey_wall/materials/scripts</uri>
              <uri>model://grey_wall/materials/textures</uri>
              <name>vrc/grey_wall</name>
            </script>
          </material>
        </visual>
        <velocity_decay>
          <linear>0</linear>
          <angular>0</angular>
        </velocity_decay>
        <self_collide>0</self_collide>
        <kinematic>0</kinematic>
        <gravity>1</gravity>
      </link>
      <pose>7.45785 -5.55777 0 0 -0 0</pose>
    </model>
  </world>
</sdf>
