<?xml version="1.0" encoding="UTF-8"?>

<sdf version='1.4'>
<model name='Sahar'>


<link name='body'>
	<pose>0 0 0 0 -0 0</pose>	
	<gravity>1</gravity>
	<velocity_decay>
	  <linear>0</linear>
	  <angular>0</angular>
	</velocity_decay>
	<self_collide>1</self_collide>
	<inertial>
	    <pose>-1.00 0.00 0.20 0 -0 0</pose>
	    <mass>2500</mass>
	    <inertia>
		<ixx>800.00</ixx>
		<ixy>0.00</ixy>
		<ixz>0.00</ixz>
		<iyy>1200.00</iyy>
		<iyz>0.00</iyz>
		<izz>1000.00</izz>
	    </inertia>
	</inertial>
	<collision name='body_collision'>
	    <pose>0 0 0 0 -0 0</pose>
	    <geometry>
	      <mesh>
		<scale>1 1 1</scale>
		<uri>model://bobtank_static_arm/meshes/body.STL</uri>
	      </mesh>
	    </geometry>
	    <surface>
	      <contact>
		<ode/>
	      </contact>
	      <friction>
		<ode>
		  <mu>1</mu>
		  <mu2>1</mu2>
		</ode>
	      </friction>
	    </surface>
	</collision>
	<visual name='body_visual'>
	    <pose>0 0 0 0 -0 0</pose>
	    <geometry>
	    <mesh>
	    <scale>1 1 1</scale>
	    <uri>model://bobtank_static_arm/meshes/body.STL</uri>
	    </mesh>
	    </geometry>
	    <material>
	    <script>
	      <name>Gazebo/Wood</name>
	      <uri>__default__</uri>
	    </script>
	    </material>
	</visual>
	
	<collision name='body_collision_cabin'>
	    <pose>-0.11317 0 0.61042 0 8.0491e-16 0</pose>
	    <geometry>
	    <mesh>
	    <scale>1 1 1</scale>
	    <uri>model://bobtank_static_arm/meshes/cabin.STL</uri>
	    </mesh>
	    </geometry>
	    <surface>
	    <contact>
	    <ode/>
	    </contact>
	    <friction>
	    <ode>
	    <mu>1</mu>
	    <mu2>1</mu2>
	    </ode>
	    </friction>
	    </surface>
	</collision>
	<visual name='body_visual_cabin'>
	    <pose>-0.11317 0 0.61042 0 8.0491e-16 0</pose>
	    <geometry>
		<mesh>
		    <scale>1 1 1</scale>
		    <uri>model://bobtank_static_arm/meshes/cabin.STL</uri>
		</mesh>
	    </geometry>
	    <material>
		<script>
		<name>Gazebo/Grey</name>
		<uri>__default__</uri>
		</script>
	    </material>
	</visual>

	<collision name='body_collision_supporter_hinge'>
	    <pose>-0.31547 0 0.68593 1.5708 -5.55112e-17 1.5708</pose>
	    <geometry>
	    <mesh>
	    <scale>1 1 1</scale>
	    <uri>model://bobtank_static_arm/meshes/supporter_hinge.STL</uri>
	    </mesh>
	    </geometry>
	    <surface>
	    <contact>
	    <ode/>
	    </contact>
	    <friction>
	    <ode>
	    <mu>1</mu>
	    <mu2>1</mu2>
	    </ode>
	    </friction>
	    </surface>
	</collision>
	<visual name='body_visual_supporter_hinge'>
	    <pose>-0.31547 0 0.68593 1.5708 -5.55112e-17 1.5708</pose>
	    <geometry>
		<mesh>
		<scale>1 1 1</scale>
		<uri>model://bobtank_static_arm/meshes/supporter_hinge.STL</uri>
		</mesh>
	    </geometry>
	    <material>
		<script>
		<name>Gazebo/GreyTransparent</name>
		<uri>__default__</uri>
		</script>
	    </material>
	</visual>
	
	<collision name='body_collision_top_installation_link'>
	    <pose>-0.29575 0.03227 1.85972 1.5708 -6.10623e-16 1.5708</pose>
	    <geometry>
		<mesh>
		  <scale>1 1 1</scale>
		  <uri>model://bobtank_static_arm/meshes/top_installation.STL</uri>
		</mesh>
	    </geometry>
	    <surface>
		<contact>
		  <ode/>
		</contact>
		<friction>
		<ode>
		  <mu>1</mu>
		  <mu2>1</mu2>
		</ode>
		</friction>
	    </surface>
	</collision>
	<visual name='body_visual_top_installation_link'>
	    <pose>-0.29575 0.03227 1.85972 1.5708 -6.10623e-16 1.5708</pose>
	    <geometry>
	      <mesh>
		<scale>1 1 1</scale>
		<uri>model://bobtank_static_arm/meshes/top_installation.STL</uri>
	      </mesh>
	    </geometry>
	    <material>
	      <script>
		<name>Gazebo/Grey</name>
		<uri>__default__</uri>
	      </script>
	    </material>
	</visual>

	
	<collision name='base_arm_collision'>
	    <pose>-1.9776 0 1.1773 0 0 0</pose>
	    <geometry>
	      <mesh>
		<scale>1 1 1</scale>
		<uri>model://bobtank_static_arm/meshes/base_arm.STL</uri>
	      </mesh>
	    </geometry>
	    <surface>
	      <contact>
		<ode/>
	      </contact>
	      <friction>
		<ode/>
	      </friction>
	    </surface>
	</collision>
	<visual name='base_arm_visual'>
	    <pose>-1.9776 0 1.1773 0 0 0</pose>
	    <geometry>
	      <mesh>
		<scale>1 1 1</scale>
		<uri>model://bobtank_static_arm/meshes/base_arm.STL</uri>
	      </mesh>
	    </geometry>
	    <material>
	      <script>
		<name>Gazebo/Grey</name>
		<uri>__default__</uri>
	      </script>
	    </material>
	</visual>
      
	<collision name='main_arm_collision'>
	    <pose>-1.75456 0 1.7035 0 -0 0</pose>
	    <geometry>
		<mesh>
		<scale>1 1 1</scale>
		<uri>model://bobtank_static_arm/meshes/main_arm.STL</uri>
		</mesh>
	    </geometry>
	    <surface>
		<contact>
		  <ode/>
		</contact>
		<friction>
		  <ode/>
		</friction>
	    </surface>
	</collision>
	<visual name='main_arm_visual'>
	    <pose>-1.75456 0 1.7035 0 -0 0</pose>
	    <geometry>
		<mesh>
		    <scale>1 1 1</scale>
		    <uri>model://bobtank_static_arm/meshes/main_arm.STL</uri>
		</mesh>
	    </geometry>
	    <material>
		<script>
		<name>Gazebo/PaintedWall</name>
		<uri>__default__</uri>
		</script>
	    </material>
	</visual>

	<collision name='loader_collision'>
	    <pose>0.34384 0 0.1465 0 0 0</pose>
	    <geometry>
		<mesh>
		<scale>1 1 1</scale>
		<uri>model://bobtank_static_arm/meshes/loader.STL</uri>
		</mesh>
	    </geometry>
	    <surface>
	    <contact>
	    <ode/>
	    </contact>
	    <friction>
	    <ode>
	    <mu>1</mu>
	    <mu2>1</mu2>
	    </ode>
	    </friction>
	    </surface>
	</collision>
	<visual name='loader_visual'>
	    <pose>0.34384 0 0.1465 0 0 0</pose>
	    <geometry>
		<mesh>
		<scale>1 1 1</scale>
		<uri>model://bobtank_static_arm/meshes/loader.STL</uri>
		</mesh>
	    </geometry>
	    <material>
	      <script>
		<name>Gazebo/Gold</name>
		<uri>__default__</uri>
	      </script>
	    </material>
	</visual>
	  
	<collision name='brackets_collision'>
	  <pose>0.68217 0 0.64099 0 0 0</pose>
	  <geometry>
	      <mesh>
	      <scale>1 1 1</scale>
	      <uri>model://bobtank_static_arm/meshes/brackets.STL</uri>
	      </mesh>
	  </geometry>
	  <surface>
	    <contact>
	      <ode/>
	    </contact>
	    <friction>
	      <ode>
		<mu>1</mu>
		<mu2>1</mu2>
	      </ode>
	    </friction>
	  </surface>
	</collision>
	<visual name='brackets_visual'>
	    <pose>0.68217 0 0.64099 0 0 0</pose>
	    <geometry>
		<mesh>
		<scale>1 1 1</scale>
		<uri>model://bobtank_static_arm/meshes/brackets.STL</uri>
		</mesh>
	    </geometry>
	    <material>
		<script>
		    <name>Gazebo/Grey</name>
		    <uri>__default__</uri>
		</script>
	    </material>
	</visual>
	
	<collision name='supporter_collision'>
	    <pose>-1.35685 0 0.80864 0 0 0</pose>
	    <geometry>
	      <mesh>
		<scale>1 1 1</scale>
		<uri>model://bobtank_static_arm/meshes/supporter.STL</uri>
	      </mesh>
	    </geometry>
	    <surface>
	      <contact>
		<ode/>
	      </contact>
	      <friction>
		<ode>
		  <mu>1</mu>
		  <mu2>1</mu2>
		</ode>
	      </friction>
	    </surface>
	</collision>
	<visual name='supporter_visual'>
	<pose>-1.35685 0 0.80864 0 0 0</pose>
	<geometry>
	  <mesh>
	    <scale>1 1 1</scale>
	    <uri>model://bobtank_static_arm/meshes/supporter.STL</uri>
	  </mesh>
	</geometry>
	<material>
	  <script>
	    <name>Gazebo/GreyTransparent</name>
	    <uri>__default__</uri>
	  </script>
	</material>
    </visual>	
</link>

<link name='left_wheel'>
<pose>-1.109 1 0.535 -1.1939 4.44089e-16 -1.5708</pose>
<inertial>
    <pose>0.142856 -3.8144e-11 5.83339e-10 0 -0 0</pose>
    <mass>5.49731</mass>
    <inertia>
      <ixx>0.0331572</ixx>
      <ixy>-3.76043e-11</ixy>
      <ixz>3.34299e-11</ixz>
      <iyy>0.0750084</iyy>
      <iyz>4.7148e-13</iyz>
      <izz>0.0750084</izz>
    </inertia>
</inertial>
<collision name='left_wheel_collision'>
    <pose>0.15 0 0 -1.57079 1.57079 3.14159</pose>
    <geometry>
      <box>
	<size>0.15 0.3 0.15</size>
      </box>
    </geometry>
    <surface>
	<contact>
	  <ode/>
	</contact>
	<friction>
	  <ode>
	    <mu>1e+07</mu>
	    <mu2>1e+07</mu2>
	  </ode>
	</friction>
    </surface>
</collision>
<collision name='left_wheel_collision_left_wheel_1'>
    <pose>0.15 0 0 -7.96765e-17 0.8 1.5708</pose>
    <geometry>
      <box>
	<size>0.15 0.3 0.15</size>
      </box>
    </geometry>
    <surface>
	<contact>
	  <ode/>
	</contact>
	<friction>
	  <ode>
	    <mu>1e+07</mu>
	    <mu2>1e+07</mu2>
	  </ode>
	</friction>
    </surface>
</collision>
<collision name='left_wheel_collision_left_wheel_2'>
    <pose>-0.091 0 0 3.14159 1.57079 3.14159</pose>
    <geometry>
      <cylinder>
	<length>0.1</length>
	<radius>0.3</radius>
      </cylinder>
    </geometry>
    <surface>
      <contact>
	<ode/>
      </contact>
      <friction>
	<ode>
	  <mu>1e+07</mu>
	  <mu2>1e+07</mu2>
	</ode>
      </friction>
    </surface>
</collision>
<collision name='left_wheel_collision_left_wheel_3'>
    <pose>0.35 0 0 3.14159 1.57079 3.14159</pose>
    <geometry>
	<cylinder>
	  <length>0.02</length>
	  <radius>0.3</radius>
	</cylinder>
    </geometry>
    <surface>
	<contact>
	  <ode/>
	</contact>
	<friction>
	  <ode>
	    <mu>1e+07</mu>
	    <mu2>1e+07</mu2>
	  </ode>
	</friction>
    </surface>
</collision>
<visual name='left_wheel_visual'>
    <pose>0 0 0 0 -0 0</pose>
    <geometry>
      <mesh>
	<scale>1 1 1</scale>
	<uri>model://bobtank_static_arm/meshes/left_wheel.STL</uri>
      </mesh>
    </geometry>
    <material>
      <script>
      <name>Gazebo/Grey</name>
      <uri>__default__</uri>
      </script>
    </material>
</visual>
<gravity>1</gravity>
<velocity_decay>
    <linear>0</linear>
    <angular>0</angular>
</velocity_decay>
<self_collide>1</self_collide>
</link>
<joint name='left_wheel_joint' type='revolute'>
    <child>left_wheel</child>
    <parent>body</parent>
    <axis>
	<xyz>3.67321e-06 1 4.44089e-16</xyz>
	<dynamics/>
    </axis>
</joint>

<link name='right_wheel'>
    <pose>-1.109 -1 0.535 1.5708 5.55112e-17 -1.5708</pose>
    <inertial>
	<pose>-0.725 0 0 0 -0 0</pose>
	<mass>5.49731</mass>
	<inertia>
	  <ixx>0.0331572</ixx>
	  <ixy>4.74592e-11</ixy>
	  <ixz>-7.11778e-12</ixz>
	  <iyy>0.0750084</iyy>
	  <iyz>-3.1357e-12</iyz>
	  <izz>0.0750084</izz>
	</inertia>
    </inertial>
    <collision name='right_wheel_collision'>
	<pose>-0.15 0 0 -1.57079 1.57079 3.14159</pose>
	<geometry>
	  <box>
	    <size>0.15 0.3 0.15</size>
	  </box>
	</geometry>
	<surface>
	  <contact>
	    <ode/>
	  </contact>
	  <friction>
	    <ode>
	      <mu>1e+07</mu>
	      <mu2>1e+07</mu2>
	    </ode>
	  </friction>
	</surface>
    </collision>
    <collision name='right_wheel_collision_right_wheel_1'>
	<pose>-0.15 0 0 -7.96765e-17 0.8 1.5708</pose>
	<geometry>
	  <box>
	    <size>0.15 0.3 0.15</size>
	  </box>
	</geometry>
	<surface>
	  <contact>
	    <ode/>
	  </contact>
	  <friction>
	    <ode>
	      <mu>1e+07</mu>
	      <mu2>1e+07</mu2>
	    </ode>
	  </friction>
	</surface>
    </collision>
    <collision name='right_wheel_collision_right_wheel_2'>
	<pose>0.091 0 0 3.14159 1.57079 3.14159</pose>
	<geometry>
	  <cylinder>
	    <length>0.1</length>
	    <radius>0.3</radius>
	  </cylinder>
	</geometry>
	<surface>
	  <contact>
	    <ode/>
	  </contact>
	  <friction>
	    <ode>
	      <mu>1e+07</mu>
	      <mu2>1e+07</mu2>
	    </ode>
	  </friction>
	</surface>
    </collision>
    <collision name='right_wheel_collision_right_wheel_3'>
	<pose>-0.35 0 0 3.14159 1.57079 3.14159</pose>
	<geometry>
	  <cylinder>
	    <length>0.02</length>
	    <radius>0.3</radius>
	  </cylinder>
	</geometry>
	<surface>
	  <contact>
	    <ode/>
	  </contact>
	  <friction>
	    <ode>
	      <mu>1e+07</mu>
	      <mu2>1e+07</mu2>
	    </ode>
	  </friction>
	</surface>
    </collision>
    <visual name='right_wheel_visual'>
	<pose>0 0 0 0 -0 0</pose>
	<geometry>
	  <mesh>
	    <scale>1 1 1</scale>
	    <uri>model://bobtank_static_arm/meshes/right_wheel.STL</uri>
	  </mesh>
	</geometry>
	<material>
	  <script>
	    <name>Gazebo/Grey</name>
	    <uri>__default__</uri>
	  </script>
	</material>
    </visual>
    <gravity>1</gravity>
    <velocity_decay>
      <linear>0</linear>
      <angular>0</angular>
    </velocity_decay>
    <self_collide>1</self_collide>
</link>
<joint name='right_wheel_joint' type='revolute'>
    <child>right_wheel</child>
    <parent>body</parent>
    <axis>
      <xyz>3.67321e-06 1 0</xyz>
      
	
	
      
      <dynamics/>
    </axis>
</joint>

<link name='front_left_boggie'>
    <pose>-0.183 0.92 0.069 -0.022723 1.73472e-18 1.5708</pose>
    <inertial>
	<pose>-0.0729895 2.22045e-16 0 0 -0 0</pose>
	<mass>3.90657</mass>
	<inertia>
	  <ixx>0.0402751</ixx>
	  <ixy>-7.48895e-18</ixy>
	  <ixz>-5.75771e-19</ixz>
	  <iyy>0.0265901</iyy>
	  <iyz>1.19262e-18</iyz>
	  <izz>0.0265901</izz>
	</inertia>
    </inertial>
    <collision name='front_left_boggie_collision'>
	<pose>0.1 0 0 3.14159 1.57079 3.14159</pose>
	<geometry>
	  <cylinder>
	    <length>0.5</length>
	    <radius>0.135</radius>
	  </cylinder>
	</geometry>
    </collision>
    <collision name='front_left_boggie_collision_front_left_boggie_1'>
	<pose>0.12 0 0 3.14159 1.57079 3.14159</pose>
	<geometry>
	  <cylinder>
	    <length>0.02</length>
	    <radius>0.17</radius>
	  </cylinder>
	</geometry>
    </collision>
    <collision name='front_left_boggie_collision_front_left_boggie_2'>
	<pose>-0.265 0 0 3.14159 1.57079 3.14159</pose>
	<geometry>
	  <cylinder>
	    <length>0.02</length>
	    <radius>0.17</radius>
	  </cylinder>
	</geometry>
    </collision>
    <visual name='front_left_boggie_visual'>
      <pose>0 0 0 0 -0 0</pose>
      <geometry>
	<mesh>
	  <scale>1 1 1</scale>
	  <uri>model://bobtank_static_arm/meshes/front_left_boggie.STL</uri>
	</mesh>
      </geometry>
    </visual>
    <velocity_decay>
    <linear>0</linear>
    <angular>0</angular>
    </velocity_decay>
</link>
<joint name='front_left_boggie_joint' type='revolute'>
    <child>front_left_boggie</child>
    <parent>body</parent>
    <axis>
	<xyz>-3.67321e-06 1 -1.73472e-18</xyz>
	<dynamics/>
    </axis>
</joint>

<link name='front_right_boggie'>
    <pose>-0.183 -0.92 0.069 1.5708 5.55112e-17 -1.5708</pose>
    <inertial>
	<pose>-0.0729895 0 0 0 -0 0</pose>
	<mass>3.90657</mass>
	<inertia>
	  <ixx>0.0402751</ixx>
	  <ixy>-1.95495e-19</ixy>
	  <ixz>-3.88713e-19</ixz>
	  <iyy>0.0265901</iyy>
	  <iyz>6.78191e-18</iyz>
	  <izz>0.0265901</izz>
	</inertia>
    </inertial>
    <collision name='front_right_boggie_collision'>
	<pose>-0.1 0 0 3.14159 1.57079 3.14159</pose>
	<geometry>
	<cylinder>
	<length>0.5</length>
	<radius>0.135</radius>
	</cylinder>
	</geometry>
    </collision>
    <collision name='front_right_boggie_collision_front_right_boggie_1'>
	<pose>0.12 0 0 3.14159 1.57079 3.14159</pose>
	<geometry>
	<cylinder>
	<length>0.02</length>
	<radius>0.17</radius>
	</cylinder>
	</geometry>
    </collision>
    <collision name='front_right_boggie_collision_front_right_boggie_2'>
	<pose>-0.265 0 0 3.14159 1.57079 3.14159</pose>
	<geometry>
	<cylinder>
	<length>0.02</length>
	<radius>0.17</radius>
	</cylinder>
	</geometry>
    </collision>
    <visual name='front_right_boggie_visual'>
	<pose>0 0 0 0 -0 0</pose>
	<geometry>
	<mesh>
	<scale>1 1 1</scale>
	<uri>model://bobtank_static_arm/meshes/front_right_boggie.STL</uri>
	</mesh>
	</geometry>
    </visual>
    <velocity_decay>
      <linear>0</linear>
      <angular>0</angular>
    </velocity_decay>
</link>
<joint name='front_right_boggie_joint' type='revolute'>
    <child>front_right_boggie</child>
    <parent>body</parent>
    <axis>
	<xyz>3.67321e-06 1 0</xyz>
	<dynamics/>
    </axis>
</joint>

<link name='back_left_boggie'>
      <pose>-1.47 0.77 0.093 -0.022723 -1.73472e-18 -1.5708</pose>
      <inertial>
	  <pose>-0.0729895 0 0 0 -0 0</pose>
	  <mass>3.90657</mass>
	  <inertia>
	    <ixx>0.0402751</ixx>
	    <ixy>8.65587e-18</ixy>
	    <ixz>-2.08858e-19</ixz>
	    <iyy>0.0265901</iyy>
	    <iyz>1.30104e-18</iyz>
	    <izz>0.0265901</izz>
	  </inertia>
      </inertial>
      <collision name='back_left_boggie_collision'>
	  <pose>0.1 0 0 3.14159 1.57079 3.14159</pose>
	    <geometry>
	    <cylinder>
	      <length>0.5</length>
	      <radius>0.135</radius>
	    </cylinder>
	  </geometry>
      </collision>
      <collision name='back_left_boggie_collision_back_left_boggie_1'>
	  <pose>0.12 0 0 3.14159 1.57079 3.14159</pose>
	  <geometry>
	    <cylinder>
	      <length>0.02</length>
	      <radius>0.17</radius>
	    </cylinder>
	  </geometry>
      </collision>
      <collision name='back_left_boggie_collision_back_left_boggie_2'>
	  <pose>-0.265 0 0 3.14159 1.57079 3.14159</pose>
	  <geometry>
	    <cylinder>
	      <length>0.02</length>
	      <radius>0.17</radius>
	    </cylinder>
	  </geometry>
      </collision>
      <visual name='back_left_boggie_visual'>
	<pose>0 0 0 0 -0 0</pose>
	<geometry>
	  <mesh>
	    <scale>1 1 1</scale>
	    <uri>model://bobtank_static_arm/meshes/back_left_boggie.STL</uri>
	  </mesh>
	</geometry>
      </visual>
      <velocity_decay>
	  <linear>0</linear>
	  <angular>0</angular>
      </velocity_decay>      
</link>
<joint name='back_left_boggie_joint' type='revolute'>
      <child>back_left_boggie</child>
      <parent>body</parent>
      <axis>
	  <xyz>3.67321e-06 1 -1.73472e-18</xyz>
	  
	    
	    
	  
	  <dynamics/>
      </axis>
</joint>

<link name='back_right_boggie'>
      <pose>-1.47 -0.92 0.093 1.5708 5.55112e-17 -1.5708</pose>     
      <inertial>
	  <pose>-0.0729895 0 0 0 -0 0</pose>
	  <mass>3.90657</mass>
	  <inertia>
	      <ixx>0.0402751</ixx>
	      <ixy>-6.18564e-22</ixy>
	      <ixz>4.9916e-18</ixz>
	      <iyy>0.0265901</iyy>
	      <iyz>3.6043e-20</iyz>
	      <izz>0.0265901</izz>
	  </inertia>
      </inertial>
      <collision name='back_right_boggie_collision'>
	  <pose>-0.1 0 0 3.14159 1.57079 3.14159</pose>
	  <geometry>
	  <cylinder>
	  <length>0.5</length>
	  <radius>0.135</radius>
	  </cylinder>
	  </geometry>
      </collision>    
      <collision name='back_right_boggie_collision_back_right_boggie_1'>
	  <pose>0.12 0 0 3.14159 1.57079 3.14159</pose>
	  <geometry>
	  <cylinder>
	  <length>0.02</length>
	  <radius>0.17</radius>
	  </cylinder>
	  </geometry>
      </collision>
      <collision name='back_right_boggie_collision_back_right_boggie_2'>
	  <pose>-0.265 0 0 3.14159 1.57079 3.14159</pose>
	  <geometry>
	  <cylinder>
	  <length>0.02</length>
	  <radius>0.17</radius>
	  </cylinder>
	  </geometry>
      </collision>
      <visual name='back_right_boggie_visual'>
	  <pose>0 0 0 0 -0 0</pose>
	  <geometry>
	  <mesh>
	  <scale>1 1 1</scale>
	  <uri>model://bobtank_static_arm/meshes/back_right_boggie.STL</uri>
	  </mesh>
	  </geometry>
      </visual>
      <velocity_decay>
	  <linear>0</linear>
	  <angular>0</angular>
      </velocity_decay> 
</link>
<joint name='back_right_boggie_joint' type='revolute'>
    <child>back_right_boggie</child>
    <parent>body</parent>
    <axis>
	<xyz>3.67321e-06 1 0</xyz>
	<dynamics/>
    </axis>
</joint>

<include>
    <uri>model://tracks</uri>
    <pose>-1.25 -0.84 0.6 0 3.95 3.14159</pose>
    <name>tracks_right</name>
</include>

<include>
    <uri>model://tracks</uri>
    <pose>-1.25 0.84 0.6 0 3.95 3.14159</pose>
    <name>tracks_left</name>
</include>  

        
<plugin name="bobtank_drive_control" filename="libbobtank_drive_plugin.so"/> 
    


  <plugin name="joint_state_publisher" filename="libgazebo_ros_joint_state_publisher.so">
    <robotNamespace>/Sahar</robotNamespace>
    <jointName>right_wheel_joint,  front_left_boggie_joint, front_right_boggie_joint, back_left_boggie_joint, back_right_boggie_joint</jointName>
    <updateRate>50.0</updateRate>
    <alwaysOn>true</alwaysOn>
  </plugin>

  
  
<!-- IPON Sensor--> <!---->
    <include>
      <uri>model://IPON</uri>
      <pose>-0.616 -0.155 2.223 0 0.020 0</pose>
      <name>IPON</name>
    </include>
    <joint name='ipon_joint' type='revolute'>
      <child>IPON::link</child>
      <parent>body</parent>
      <axis>
        <xyz>0 1 0</xyz>
        <limit>
          <lower>0</lower>
          <upper>0</upper>
        </limit>
        <dynamics/>
      </axis>
    </joint>    
       

<!-- IBEO Sensor --> <!---->
    <include>
      <uri>model://IBEO</uri>
      <pose>-0.360 0.014 1.992 0.005 0.221 0.107</pose>
      <name>IBEO</name>
    </include>
    <joint name='ibeo_joint' type='revolute'>
      <child>IBEO::link</child>
      <parent>body</parent>
      <axis>
        <xyz>0 1 0</xyz>
        <limit>
          <lower>0</lower>
          <upper>0</upper>
        </limit>
        <dynamics/>
      </axis>
    </joint>


<!-- CAM Sensors --> <!--
    <include>
      <uri>model://FLEA3_L</uri>
      <pose>-0.3 0.25 2.02 0 0 0</pose>
      <name>left_flea3</name>
    </include>
    <joint name='left_flea3_joint' type='revolute'>
      <child>left_flea3::camera_link</child>
      <parent>body</parent>
      <axis>
        <xyz>0 1 0</xyz>
        <limit>
          <lower>0</lower>
          <upper>0</upper>
        </limit>
        <dynamics/>
      </axis>
    </joint>
    
    <include>
      <uri>model://FLEA3_R</uri>
      <pose>-0.3 -0.25 2.02 0 0 0</pose>
      <name>right_flea3</name>
    </include>    
    <joint name='right_flea3_joint' type='revolute'>
      <child>right_flea3::camera_link</child>
      <parent>body</parent>
      <axis>
        <xyz>0 1 0</xyz>
        <limit>
          <lower>0</lower>
          <upper>0</upper>
        </limit>
        <dynamics/>
      </axis>
    </joint>
-->

<!-- SICK Sensors --><!--
    <include>
      <uri>model://SICK</uri>
      <pose>-0.2187 0.85 0.631 0 0 1.57</pose>
      <name>left_sick</name>
    </include>
    <joint name='left_sick_joint' type='revolute'>
      <child>left_sick::link</child>
      <parent>body</parent>
      <axis>
        <xyz>0 1 0</xyz>
        <limit>
          <lower>0</lower>
          <upper>0</upper>
        </limit>
        <dynamics/>
      </axis>
    </joint>
    
    <include> 
      <uri>model://SICK</uri>
      <pose>-0.2187 -0.85 0.631 0 0 -1.57</pose>
      <name>right_sick</name>
    </include>
    <joint name='right_sick_joint' type='revolute'>
      <child>right_sick::link</child>
      <parent>body</parent>
      <axis>
        <xyz>0 1 0</xyz>
        <limit>
          <lower>0</lower>
          <upper>0</upper>
        </limit>
        <dynamics/>
      </axis>
    </joint>
-->

<!--  Wire Sensors --><!--
    <include>
      <uri>model://wire_sensor</uri>
      <pose>-1.42 0.56 1.05 -1.6 2.3 0</pose>
      <name>arm_wire_sensor</name>
    </include> 
    <joint name='arm_wire_sensor_joint' type='revolute'>
      <child>arm_wire_sensor::link</child>
      <parent>body</parent>
      <axis>
        <xyz>0 1 0</xyz>
        <limit>
          <lower>0</lower>
          <upper>0</upper>
        </limit>
        <dynamics/>
      </axis>
    </joint>

    <include>
      <uri>model://wire_sensor_mount</uri>
      <pose>-1.31 0.56 1.28 -1.6 0 0</pose>
      <name>arm_wire_sensor_mount</name>
    </include>    
    <joint name='arm_wire_sensor_mount_joint' type='revolute'>
      <child>arm_wire_sensor_mount::link</child>
      <parent>main_arm</parent>
      <axis>
        <xyz>0 1 0</xyz>
        <limit>
          <lower>0</lower>
          <upper>0</upper>
        </limit>
        <dynamics/>
      </axis>
    </joint>

    <plugin name="arm_wire_sensor_plugin" filename="libwire_sensor.so">
      <sensor_name>Sahar::arm_wire_sensor::link</sensor_name>
      <mount_name>Sahar::arm_wire_sensor_mount::link</mount_name>
      <noise>0.1</noise>
    </plugin>    
    
        
    <include>
      <uri>model://wire_sensor_mount</uri>
      <pose>0.59 0.3 0.52 0 -1 0</pose>
      <name>blade_wire_sensor_mount</name>
    </include> 
    <joint name='blade_wire_sensor_mount_joint' type='revolute'>
      <child>blade_wire_sensor_mount::link</child>
      <parent>loader</parent>
      <axis>
        <xyz>0 1 0</xyz>
        <limit>
          <lower>0</lower>
          <upper>0</upper>
        </limit>
        <dynamics/>
      </axis>
    </joint>

    <include>
      <uri>model://wire_sensor</uri>
      <pose>0.3 0.3 0.85 0 -0.83 3.14</pose>
      <name>blade_wire_sensor</name>
    </include>    
    <joint name='blade_wire_sensor_joint' type='revolute'>
      <child>blade_wire_sensor::link</child>
      <parent>main_arm</parent>
      <axis>
        <xyz>0 1 0</xyz>
        <limit>
          <lower>0</lower>
          <upper>0</upper>
        </limit>
        <dynamics/>
      </axis>
    </joint>
    
    <plugin name="blade_wire_sensor_plugin" filename="libwire_sensor.so">
      <sensor_name>Sahar::blade_wire_sensor::link</sensor_name>
      <mount_name>Sahar::blade_wire_sensor_mount::link</mount_name>
      <noise>0.1</noise>
    </plugin>
-->

</model>
</sdf>
