<?xml version="1.0" ?>
<robot name="Sahar">
  <joint name="Sahar__base_arm_joint" type="fixed">
    <parent link="Sahar__body"/>
    <child link="Sahar__base_arm"/>
    <origin rpy="0  0  0" xyz="-1.9776  0      1.1773"/>
    <axis xyz="0  1  0"/>
    <limit effort="0" lower="0" upper="0" velocity="0"/>
  </joint>
  <joint name="Sahar__main_arm_joint" type="fixed">
    <parent link="Sahar__base_arm"/>
    <child link="Sahar__main_arm"/>
    <origin rpy="0  0  0" xyz="0.22304  0       0.5262"/>
    <axis xyz="0  1  0"/>
    <limit effort="0" lower="0" upper="0" velocity="0"/>
  </joint>
  <joint name="Sahar__loader_joint" type="revolute">
    <parent link="Sahar__main_arm"/>
    <child link="Sahar__loader"/>
    <origin rpy="0  0  0" xyz="2.09839  0      -1.557"/>
    <axis xyz="0 -1  0"/>
    <limit effort="1000000.0" lower="-0.5" upper="0.5" velocity="100.0"/>
  </joint>
  <joint name="Sahar__brackets_joint" type="revolute">
    <parent link="Sahar__loader"/>
    <child link="Sahar__brackets"/>
    <origin rpy="0  0  0" xyz="0.33833  0       0.49449"/>
    <axis xyz="0  1  0"/>
    <limit effort="1000000.0" lower="-0.5" upper="1.0" velocity="1000000.0"/>
  </joint>
  <joint name="Sahar__supporter_joint" type="fixed">
    <parent link="Sahar__main_arm"/>
    <child link="Sahar__supporter"/>
    <origin rpy="0   -0.12  0" xyz="0.39771  0      -0.89486"/>
    <axis xyz="0  1  0"/>
    <limit effort="0" lower="0" upper="0" velocity="0"/>
  </joint>
  <joint name="Sahar__supporter_joint2" type="fixed">
    <parent link="Sahar__body"/>
    <child link="Sahar__supporter"/>
    <origin rpy="0   -0.12  0" xyz="-0.30972  0       0.81201"/>
    <axis xyz="0  1  0"/>
    <limit effort="0" lower="0" upper="0" velocity="0"/>
  </joint>
  <joint name="Sahar__Hydraulic_bottom_rot" type="fixed">
    <parent link="Sahar__body"/>
    <child link="Sahar__Hydraulic_bottom"/>
    <origin rpy="0       0.34907  0" xyz="-1.781  0     0.393"/>
    <axis xyz="0  1  0"/>
    <limit effort="0" lower="0" upper="0" velocity="0"/>
  </joint>
  <joint name="Sahar__Hydraulic_top_rot" type="fixed">
    <parent link="Sahar__main_arm"/>
    <child link="Sahar__Hydraulic_top"/>
    <origin rpy="0       0.34907  0" xyz="0.27456  0      -0.4835"/>
    <axis xyz="0  1  0"/>
    <limit effort="0" lower="0" upper="0" velocity="0"/>
  </joint>
  <joint name="Sahar__Hydraulics_joint" type="prismatic">
    <parent link="Sahar__Hydraulic_bottom"/>
    <child link="Sahar__Hydraulic_top"/>
    <origin rpy="0  0  0" xyz="0       0       0.38007"/>
    <axis xyz="0  0  1"/>
    <limit effort="0" lower="0" upper="0" velocity="0"/>
  </joint>
  <joint name="Sahar__cogwheel_left_joint" type="fixed">
    <parent link="Sahar__body"/>
    <child link="Sahar__cogwheel_left"/>
    <origin rpy="0  0  0" xyz="-1.35   0.655  0.435"/>
    <axis xyz="0  1  0"/>
    <limit effort="0" lower="0" upper="0" velocity="0"/>
  </joint>
  <joint name="Sahar__cogwheel_right_joint" type="fixed">
    <parent link="Sahar__body"/>
    <child link="Sahar__cogwheel_right"/>
    <origin rpy="0  0  0" xyz="-1.35  -0.655  0.435"/>
    <axis xyz="0  1  0"/>
    <limit effort="0" lower="0" upper="0" velocity="0"/>
  </joint>
  <joint name="Sahar__back_left_wheel_joint" type="fixed">
    <parent link="Sahar__body"/>
    <child link="Sahar__back_left_wheel"/>
    <origin rpy="0  0  0" xyz="-1.53739  0.63     0.1"/>
    <axis xyz="0  1  0"/>
    <limit effort="0" lower="0" upper="0" velocity="0"/>
  </joint>
  <joint name="Sahar__back_right_wheel_joint" type="fixed">
    <parent link="Sahar__body"/>
    <child link="Sahar__back_right_wheel"/>
    <origin rpy="0  0  0" xyz="-1.535 -0.63   0.1"/>
    <axis xyz="0  1  0"/>
    <limit effort="0" lower="0" upper="0" velocity="0"/>
  </joint>
  <joint name="Sahar__front_left_wheel_joint" type="fixed">
    <parent link="Sahar__body"/>
    <child link="Sahar__front_left_wheel"/>
    <origin rpy="0  0  0" xyz="-0.0535  0.63    0.1"/>
    <axis xyz="0  1  0"/>
    <limit effort="0" lower="0" upper="0" velocity="0"/>
  </joint>
  <joint name="Sahar__front_right_wheel_joint" type="fixed">
    <parent link="Sahar__body"/>
    <child link="Sahar__front_right_wheel"/>
    <origin rpy="0  0  0" xyz="-0.0535 -0.63    0.1"/>
    <axis xyz="0  1  0"/>
    <limit effort="0" lower="0" upper="0" velocity="0"/>
  </joint>
  <joint name="Sahar__roller_back_right_joint" type="fixed">
    <parent link="Sahar__body"/>
    <child link="Sahar__roller_back_right"/>
    <origin rpy="0  0  0" xyz="-1.16582 -0.63     0.1"/>
    <axis xyz="0  1  0"/>
    <limit effort="0" lower="0" upper="0" velocity="0"/>
  </joint>
  <joint name="Sahar__roller_mid_right_joint" type="fixed">
    <parent link="Sahar__body"/>
    <child link="Sahar__roller_mid_right"/>
    <origin rpy="0  0  0" xyz="-0.79545 -0.63     0.1"/>
    <axis xyz="0  1  0"/>
    <limit effort="0" lower="0" upper="0" velocity="0"/>
  </joint>
  <joint name="Sahar__roller_front_right_joint" type="fixed">
    <parent link="Sahar__body"/>
    <child link="Sahar__roller_front_right"/>
    <origin rpy="0  0  0" xyz="-0.42447 -0.63     0.1"/>
    <axis xyz="0  1  0"/>
    <limit effort="0" lower="0" upper="0" velocity="0"/>
  </joint>
  <joint name="Sahar__roller_back_left_joint" type="fixed">
    <parent link="Sahar__body"/>
    <child link="Sahar__roller_back_left"/>
    <origin rpy="0  0  0" xyz="-1.16582  0.63     0.1"/>
    <axis xyz="0  1  0"/>
    <limit effort="0" lower="0" upper="0" velocity="0"/>
  </joint>
  <joint name="Sahar__roller_mid_left_joint" type="fixed">
    <parent link="Sahar__body"/>
    <child link="Sahar__roller_mid_left"/>
    <origin rpy="0  0  0" xyz="-0.79545  0.63     0.1"/>
    <axis xyz="0  1  0"/>
    <limit effort="0" lower="0" upper="0" velocity="0"/>
  </joint>
  <joint name="Sahar__roller_front_left_joint" type="fixed">
    <parent link="Sahar__body"/>
    <child link="Sahar__roller_front_left"/>
    <origin rpy="0  0  0" xyz="-0.42447  0.63     0.1"/>
    <axis xyz="0  1  0"/>
    <limit effort="0" lower="0" upper="0" velocity="0"/>
  </joint>
  <link name="Sahar__body">
    <inertial>
      <mass value="2000"/>
      <origin rpy="0  0  0" xyz="-0.79545  0       0.805"/>
      <inertia ixx="750" ixy="0" ixz="0" iyy="1200" iyz="0" izz="900"/>
    </inertial>
    <collision name="Sahar__body_collision">
      <origin rpy="0   -0.02  0" xyz="-0.82136  0       0.49482"/>
      <geometry>
        <box size="1.704 0.889 0.704"/>
      </geometry>
    </collision>
    <collision name="Sahar__body_collision_bb">
      <origin rpy="0       0.08047  0" xyz="-2.14939  0       0.81067"/>
      <geometry>
        <box size="0.120 0.952 0.900"/>
      </geometry>
    </collision>
    <collision name="Sahar__body_collision_b">
      <origin rpy="0       0.08047  0" xyz="-1.87754  0       0.796"/>
      <geometry>
        <box size="0.4 1.182 1.121"/>
      </geometry>
    </collision>
    <collision name="Sahar__body_collision_bd">
      <origin rpy="0      0.1318  0" xyz="-1.81524  0       0.50481"/>
      <geometry>
        <box size="0.511 0.889 0.704"/>
      </geometry>
    </collision>
    <collision name="Sahar__body_collision_cabin">
      <origin rpy="0  0  0" xyz="-1.0253  0      1.365"/>
      <geometry>
        <box size="1.557 0.889 1.152"/>
      </geometry>
    </collision>
    <collision name="Sahar__body_collision_top_installation_link">
      <origin rpy="0  0  0" xyz="-0.92913  0       2.165"/>
      <geometry>
        <box size="0.663 0.598 0.838"/>
      </geometry>
    </collision>
    <visual name="Sahar__body_visual">
      <origin rpy="0  0  0" xyz="0     0     0.125"/>
      <geometry>
        <mesh filename="package://PATHTOMESHES/meshes/body.dae" scale="1 1 1"/>
      </geometry>
    </visual>
  </link>
  <link name="Sahar__base_arm">
    <inertial>
      <mass value="400"/>
      <origin rpy="0  0  0" xyz="0.0665   0       0.25685"/>
      <inertia ixx="50.76" ixy="0" ixz="0.66798" iyy="4.8017" iyz="0" izz="47.388"/>
    </inertial>
    <collision name="Sahar__base_arm_collision">
      <origin rpy="0  0  0" xyz="0  0  0"/>
      <geometry>
        <mesh filename="package://PATHTOMESHES/meshes/base_arm_col.STL" scale="1 1 1"/>
      </geometry>
    </collision>
    <visual name="Sahar__base_arm_visual">
      <origin rpy="0  0  0" xyz="0  0  0"/>
      <geometry>
        <mesh filename="package://PATHTOMESHES/meshes/base_arm.STL" scale="1 1 1"/>
      </geometry>
    </visual>
  </link>
  <link name="Sahar__main_arm">
    <inertial>
      <mass value="300"/>
      <origin rpy="0  0  0" xyz="1.1865   0      -0.60466"/>
      <inertia ixx="133.74" ixy="0" ixz="-68.753" iyy="216.24" iyz="0" izz="268.55"/>
    </inertial>
    <collision name="Sahar__main_arm_collision">
      <origin rpy="0  0  0" xyz="0  0  0"/>
      <geometry>
        <mesh filename="package://PATHTOMESHES/meshes/main_arm_col.STL" scale="1 1 1"/>
      </geometry>
    </collision>
    <visual name="Sahar__main_arm_visual">
      <origin rpy="0  0  0" xyz="0  0  0"/>
      <geometry>
        <mesh filename="package://PATHTOMESHES/meshes/main_arm.STL" scale="1 1 1"/>
      </geometry>
    </visual>
  </link>
  <link name="Sahar__loader">
    <inertial>
      <mass value="98.03"/>
      <origin rpy="0  0  0" xyz="0.37894  0       0.0674"/>
      <inertia ixx="29.346" ixy="0" ixz="-1.55" iyy="9.25" iyz="0" izz="32.05"/>
    </inertial>
    <collision name="Sahar__loader_collision">
      <origin rpy="0  0  0" xyz="0  0  0"/>
      <geometry>
        <mesh filename="package://PATHTOMESHES/meshes/loader_col.STL" scale="1 1 1"/>
      </geometry>
    </collision>
    <visual name="Sahar__loader_visual">
      <origin rpy="0  0  0" xyz="0  0  0"/>
      <geometry>
        <mesh filename="package://PATHTOMESHES/meshes/loader.STL" scale="1 1 1"/>
      </geometry>
    </visual>
  </link>
  <link name="Sahar__brackets">
    <inertial>
      <mass value="12.857"/>
      <origin rpy="0  0  0" xyz="0.14213  0       0.33109"/>
      <inertia ixx="2.9339" ixy="0" ixz="0.23718" iyy="0.67251" iyz="0" izz="2.738"/>
    </inertial>
    <collision name="Sahar__brackets_collision">
      <origin rpy="0  0  0" xyz="0  0  0"/>
      <geometry>
        <mesh filename="package://PATHTOMESHES/meshes/brackets_col.STL" scale="1 1 1"/>
      </geometry>
    </collision>
    <visual name="Sahar__brackets_visual">
      <origin rpy="0  0  0" xyz="0  0  0"/>
      <geometry>
        <mesh filename="package://PATHTOMESHES/meshes/brackets.STL" scale="1 1 1"/>
      </geometry>
    </visual>
  </link>
  <link name="Sahar__supporter">
    <inertial>
      <mass value="30"/>
      <origin rpy="0  0  0" xyz="-0.52659  0       0.06151"/>
      <inertia ixx="16.898" ixy="0" ixz="0" iyy="6.6127" iyz="0" izz="23.301"/>
    </inertial>
    <collision name="Sahar__supporter_collision">
      <origin rpy="0  0  0" xyz="-1.04   0     0.122"/>
      <geometry>
        <mesh filename="package://PATHTOMESHES/meshes/supporter.STL" scale="1 1 1"/>
      </geometry>
    </collision>
    <visual name="Sahar__supporter_visual">
      <origin rpy="0  0  0" xyz="-1.04   0     0.122"/>
      <geometry>
        <mesh filename="package://PATHTOMESHES/meshes/supporter.STL" scale="1 1 1"/>
      </geometry>
    </visual>
  </link>
  <link name="Sahar__Hydraulic_bottom">
    <inertial>
      <mass value="65.29"/>
      <origin rpy="0  0  0" xyz="0   0   0.5"/>
      <inertia ixx="10" ixy="0" ixz="0" iyy="10" iyz="0" izz="1"/>
    </inertial>
    <visual name="Sahar__Hydraulic_bottom_vis">
      <origin rpy="0  0  0" xyz="0  0  0"/>
      <geometry>
        <mesh filename="package://PATHTOMESHES/meshes/Hydraulics_bottom.dae" scale="1 1 1"/>
      </geometry>
    </visual>
  </link>
  <link name="Sahar__Hydraulic_top">
    <inertial>
      <mass value="65.29"/>
      <origin rpy="0  0  0" xyz="0  0  0"/>
      <inertia ixx="10" ixy="0" ixz="0" iyy="10" iyz="0" izz="1"/>
    </inertial>
    <visual name="Sahar__Hydraulic_bottom_vis">
      <origin rpy="0  0  0" xyz="0   0   0.5"/>
      <geometry>
        <mesh filename="package://PATHTOMESHES/meshes/Hydraulics_top.dae" scale="1 1 1"/>
      </geometry>
    </visual>
  </link>
  <link name="Sahar__cogwheel_left">
    <inertial>
      <mass value="1.1"/>
      <origin rpy="0  0  0" xyz="0  0  0"/>
      <inertia ixx="0.01" ixy="-0" ixz="0" iyy="0.01" iyz="0" izz="0.01"/>
    </inertial>
    <visual name="Sahar__cogwheel_left_visual">
      <origin rpy="0  0  0" xyz="0  0  0"/>
      <geometry>
        <mesh filename="package://PATHTOMESHES/meshes/cogwheel_left.STL" scale="1 1 1"/>
      </geometry>
    </visual>
  </link>
  <link name="Sahar__cogwheel_right">
    <inertial>
      <mass value="1.1"/>
      <origin rpy="0  0  0" xyz="0  0  0"/>
      <inertia ixx="0.01" ixy="-0" ixz="0" iyy="0.01" iyz="0" izz="0.01"/>
    </inertial>
    <visual name="Sahar__cogwheel_right_visual">
      <origin rpy="0  0  0" xyz="0  0  0"/>
      <geometry>
        <mesh filename="package://PATHTOMESHES/meshes/cogwheel_right.STL" scale="1 1 1"/>
      </geometry>
    </visual>
  </link>
  <link name="Sahar__back_left_wheel">
    <inertial>
      <mass value="50"/>
      <origin rpy="0  0  0" xyz="0  0  0"/>
      <inertia ixx="1.175" ixy="-0" ixz="0" iyy="1" iyz="0" izz="1.175"/>
    </inertial>
    <collision name="Sahar__back_left_wheel_collision">
      <origin rpy="-1.5708  0      0" xyz="0  0  0"/>
      <geometry>
        <cylinder length="0.4" radius="0.2"/>
      </geometry>
    </collision>
  </link>
  <link name="Sahar__back_right_wheel">
    <inertial>
      <mass value="50"/>
      <origin rpy="0  0  0" xyz="0  0  0"/>
      <inertia ixx="1.175" ixy="-0" ixz="0" iyy="1" iyz="0" izz="1.175"/>
    </inertial>
    <collision name="Sahar__back_right_wheel_collision">
      <origin rpy="1.5708  0      0" xyz="0  0  0"/>
      <geometry>
        <cylinder length="0.4" radius="0.2"/>
      </geometry>
    </collision>
  </link>
  <link name="Sahar__front_left_wheel">
    <inertial>
      <mass value="50"/>
      <origin rpy="0  0  0" xyz="0  0  0"/>
      <inertia ixx="1.175" ixy="-0" ixz="0" iyy="1" iyz="0" izz="1.175"/>
    </inertial>
    <collision name="Sahar__front_left_wheel_collision">
      <origin rpy="-1.5708  0      0" xyz="0  0  0"/>
      <geometry>
        <cylinder length="0.4" radius="0.2"/>
      </geometry>
    </collision>
  </link>
  <link name="Sahar__front_right_wheel">
    <inertial>
      <mass value="50"/>
      <origin rpy="0  0  0" xyz="0  0  0"/>
      <inertia ixx="1.175" ixy="-0" ixz="0" iyy="1" iyz="0" izz="1.175"/>
    </inertial>
    <collision name="Sahar__front_right_wheel_collision">
      <origin rpy="1.5708  0      0" xyz="0  0  0"/>
      <geometry>
        <cylinder length="0.4" radius="0.2"/>
      </geometry>
    </collision>
  </link>
  <link name="Sahar__roller_back_right">
    <inertial>
      <mass value="50"/>
      <origin rpy="0  0  0" xyz="0  0  0"/>
      <inertia ixx="1.175" ixy="-0" ixz="0" iyy="1" iyz="0" izz="1.175"/>
    </inertial>
    <collision name="Sahar__roller_back_right_collision">
      <origin rpy="1.5708  0      0" xyz="0  0  0"/>
      <geometry>
        <cylinder length="0.4" radius="0.2"/>
      </geometry>
    </collision>
  </link>
  <link name="Sahar__roller_mid_right">
    <inertial>
      <mass value="50"/>
      <origin rpy="0  0  0" xyz="0  0  0"/>
      <inertia ixx="1.175" ixy="-0" ixz="0" iyy="1" iyz="0" izz="1.175"/>
    </inertial>
    <collision name="Sahar__roller_mid_right_collision">
      <origin rpy="1.5708  0      0" xyz="0  0  0"/>
      <geometry>
        <cylinder length="0.4" radius="0.2"/>
      </geometry>
    </collision>
  </link>
  <link name="Sahar__roller_front_right">
    <inertial>
      <mass value="50"/>
      <origin rpy="0  0  0" xyz="0  0  0"/>
      <inertia ixx="1.175" ixy="-0" ixz="0" iyy="1" iyz="0" izz="1.175"/>
    </inertial>
    <collision name="Sahar__roller_front_right_collision">
      <origin rpy="1.5708  0      0" xyz="0  0  0"/>
      <geometry>
        <cylinder length="0.4" radius="0.2"/>
      </geometry>
    </collision>
  </link>
  <link name="Sahar__roller_back_left">
    <inertial>
      <mass value="50"/>
      <origin rpy="0  0  0" xyz="0  0  0"/>
      <inertia ixx="1.175" ixy="-0" ixz="0" iyy="1" iyz="0" izz="1.175"/>
    </inertial>
    <collision name="Sahar__roller_back_left_collision">
      <origin rpy="1.5708  0      0" xyz="0  0  0"/>
      <geometry>
        <cylinder length="0.4" radius="0.2"/>
      </geometry>
    </collision>
  </link>
  <link name="Sahar__roller_mid_left">
    <inertial>
      <mass value="50"/>
      <origin rpy="0  0  0" xyz="0  0  0"/>
      <inertia ixx="1.175" ixy="-0" ixz="0" iyy="1" iyz="0" izz="1.175"/>
    </inertial>
    <collision name="Sahar__roller_mid_left_collision">
      <origin rpy="1.5708  0      0" xyz="0  0  0"/>
      <geometry>
        <cylinder length="0.4" radius="0.2"/>
      </geometry>
    </collision>
  </link>
  <link name="Sahar__roller_front_left">
    <inertial>
      <mass value="50"/>
      <origin rpy="0  0  0" xyz="0  0  0"/>
      <inertia ixx="1.175" ixy="-0" ixz="0" iyy="1" iyz="0" izz="1.175"/>
    </inertial>
    <collision name="Sahar__roller_front_left_collision">
      <origin rpy="1.5708  0      0" xyz="0  0  0"/>
      <geometry>
        <cylinder length="0.4" radius="0.2"/>
      </geometry>
    </collision>
  </link>
</robot>
