<?xml version="1.0" encoding="UTF-8"?>

<!-- -*- mode: XML -*- -->

<sdf version='1.4'>
<model name='Sahar'>


<link name='body'>
	<pose>0 0 0 0 -0 0</pose>	
	<gravity>1</gravity>
	<velocity_decay>
	  <linear>0</linear>
	  <angular>0</angular>
	</velocity_decay>
	<self_collide>1</self_collide>
	<inertial>
	    <pose>-1.00 0.00 0.20 0 -0 0</pose>
	    <mass>2500</mass>
	    <inertia>
		<ixx>800.00</ixx>
		<ixy>0.00</ixy>
		<ixz>0.00</ixz>
		<iyy>1200.00</iyy>
		<iyz>0.00</iyz>
		<izz>1000.00</izz>
	    </inertia>
	</inertial>
	<collision name='body_collision'>
	    <pose>0 0 0 0 -0 0</pose>
	    <geometry>
	      <mesh>
		<scale>1 1 1</scale>
		<uri>model://bobcat_tracked/meshes/body_col.STL</uri>
	      </mesh>
	    </geometry>
	    <surface>
	      <contact>
		<ode/>
	      </contact>
	      <friction>
		<ode>
		  <mu>1</mu>
		  <mu2>1</mu2>
		</ode>
	      </friction>
	    </surface>
	</collision>
	<visual name='body_visual'>
	    <pose>0 0 0 0 -0 0</pose>
	    <geometry>
	    <mesh>
	    <scale>1 1 1</scale>
	    <uri>model://bobcat_tracked/meshes/body.STL</uri>
	    </mesh>
	    </geometry>
	    <material>
	    <script>
	      <name>Gazebo/Wood</name>
	      <uri>__default__</uri>
	    </script>
	    </material>
	</visual>
	
	<collision name='body_collision_cabin'>
	    <pose>-0.11317 0 0.61042 0 8.0491e-16 0</pose>
	    <geometry>
	    <mesh>
	    <scale>1 1 1</scale>
	    <uri>model://bobcat_tracked/meshes/cabin_col.STL</uri>
	    </mesh>
	    </geometry>
	    <surface>
	    <contact>
	    <ode/>
	    </contact>
	    <friction>
	    <ode>
	    <mu>1</mu>
	    <mu2>1</mu2>
	    </ode>
	    </friction>
	    </surface>
	</collision>
	<visual name='body_visual_cabin'>
	    <pose>-0.11317 0 0.61042 0 8.0491e-16 0</pose>
	    <geometry>
		<mesh>
		    <scale>1 1 1</scale>
		    <uri>model://bobcat_tracked/meshes/cabin.STL</uri>
		</mesh>
	    </geometry>
	    <material>
		<script>
		<name>Gazebo/Grey</name>
		<uri>__default__</uri>
		</script>
	    </material>
	</visual>
	<visual name='body_tracks_visual'>
	    <pose>-0 0 0 0 0 0</pose>
	    <geometry>
		<mesh>
		    <scale>1 1 1</scale>
		    <uri>model://bobcat_tracked/meshes/tracks.STL</uri>
		</mesh>
	    </geometry>
  <material>
    <ambient>0.2 0.2 0.2 1</ambient>
    <diffuse>0.1 0.1 0.1 1</diffuse>
    <specular>1 1 1 1</specular>
    <emissive>0 0 0 1</emissive>
  </material>
	</visual>
	<visual name='body_visual_supporter_hinge'>
	    <pose>-0.31547 0 0.68593 1.5708 -5.55112e-17 1.5708</pose>
	    <geometry>
		<mesh>
		<scale>1 1 1</scale>
		<uri>model://bobcat_tracked/meshes/supporter_hinge.STL</uri>
		</mesh>
	    </geometry>
	    <material>
		<script>
		<name>Gazebo/Grey</name>
		<uri>__default__</uri>
		</script>
	    </material>
	</visual>
	
	<collision name='body_collision_top_installation_link'>
	    <pose>-0.29575 0.03227 1.85972 1.5708 -6.10623e-16 1.5708</pose>
	    <geometry>
		<mesh>
		  <scale>1 1 1</scale>
		  <uri>model://bobcat_tracked/meshes/top_installation.STL</uri>
		</mesh>
	    </geometry>
	    <surface>
		<contact>
		  <ode/>
		</contact>
		<friction>
		<ode>
		  <mu>1</mu>
		  <mu2>1</mu2>
		</ode>
		</friction>
	    </surface>
	</collision>
	<visual name='body_visual_top_installation_link'>
	    <pose>-0.29575 0.03227 1.85972 1.5708 -6.10623e-16 1.5708</pose>
	    <geometry>
	      <mesh>
		<scale>1 1 1</scale>
		<uri>model://bobcat_tracked/meshes/top_installation.STL</uri>
	      </mesh>
	    </geometry>
	    <material>
	      <script>
		<name>Gazebo/Grey</name>
		<uri>__default__</uri>
	      </script>
	    </material>
	</visual>
</link>


<link name='base_arm'>
    <pose>-1.9776 0 1.1773 0 2.1164e-16 0</pose>
    <inertial>
	<pose>0.066509 1.9771e-12 0.25686 0 -0 0</pose>
	<mass>194.91</mass>
	<inertia>
	    <ixx>50.76</ixx>
	    <ixy>-2.9264e-11</ixy>
	    <ixz>0.66798</ixz>
	    <iyy>4.8017</iyy>
	    <iyz>7.0403e-12</iyz>
	    <izz>47.388</izz>
	</inertia>
    </inertial>
    <collision name='base_arm_collision'>
	<pose>0 0 0 0 -0 0</pose>
	<geometry>
	  <mesh>
	    <scale>1 1 1</scale>
	    <uri>model://bobcat_tracked/meshes/base_arm_col.STL</uri>
	  </mesh>
	</geometry>
	<surface>
	  <contact>
	    <ode/>
	  </contact>
	  <friction>
	    <ode/>
	  </friction>
	</surface>
    </collision>
    <visual name='base_arm_visual'>
	<pose>0 0 0 0 -0 0</pose>
	<geometry>
	  <mesh>
	    <scale>1 1 1</scale>
	    <uri>model://bobcat_tracked/meshes/base_arm.STL</uri>
	  </mesh>
	</geometry>
	<material>
	  <script>
	    <name>Gazebo/Grey</name>
	    <uri>__default__</uri>
	  </script>
	</material>
    </visual>
    <gravity>1</gravity>
    <velocity_decay>
      <linear>0</linear>
      <angular>0</angular>
    </velocity_decay>
    <self_collide>0</self_collide>
</link>
<joint name='base_arm_joint' type='revolute'> 
    <child>base_arm</child>
    <parent>body</parent>
    <axis>
    <xyz>0 1 0</xyz>
    <limit>
	<lower>-1.57</lower>
	<upper>0.0</upper>
	<!--<upper>1.57</upper>-->
	<effort>1e+06</effort>
	<velocity>100</velocity>
    </limit>
    <!--<dynamics><friction>1</friction></dynamics>-->
    </axis>
</joint>

<link name='main_arm'>
    <pose>-1.75456 0 1.7035 0 -0 0</pose>
    <inertial>
	<pose>1.1865 -4.0206e-07 -0.60466 0 -0 0</pose>
	<mass>369.05</mass>
	<inertia>
	    <ixx>133.74</ixx>
	    <ixy>0.00012791</ixy>
	    <ixz>-68.753</ixz>
	    <iyy>216.24</iyy>
	    <iyz>-4.6593e-05</iyz>
	    <izz>268.55</izz>
	</inertia>
    </inertial>
    <collision name='main_arm_collision'>
	<pose>0 0 0 0 -0 0</pose>
	<geometry>
	    <mesh>
	    <scale>1 1 1</scale>
	    <uri>model://bobcat_tracked/meshes/main_arm_col.STL</uri>
	    </mesh>
	</geometry>
	<surface>
	    <contact>
	      <ode/>
	    </contact>
	    <friction>
	      <ode/>
	    </friction>
	</surface>
    </collision>
    <visual name='main_arm_visual'>
	<pose>0 0 0 0 -0 0</pose>
	<geometry>
	    <mesh>
		<scale>1 1 1</scale>
		<uri>model://bobcat_tracked/meshes/main_arm.STL</uri>
	    </mesh>
	</geometry>
	<material>
	    <script>
	    <name>Gazebo/PaintedWall</name>
	    <uri>__default__</uri>
	    </script>
	</material>
    </visual>
    <gravity>1</gravity>
    <velocity_decay>
	<linear>0</linear>
	<angular>0</angular>
    </velocity_decay>
    <self_collide>0</self_collide>
</link>
<joint name='main_arm_joint' type='revolute'>
    <child>main_arm</child>
    <parent>base_arm</parent>
    <axis>
	<xyz>0 1 0</xyz>
	<limit>
	    <lower>-1.57</lower>
	    <upper>1.57</upper>
	    <effort>1e+06</effort>
	    <velocity>100</velocity>
	</limit>
	<!--<dynamics><friction>1</friction></dynamics>-->
    </axis>
</joint>

<link name='loader'>
    <pose>0.34384 0 0.1465 0 2.5362e-15 0</pose>
    <inertial>
	<pose>0.37894 2.192e-15 0.067409 0 -0 0</pose>
	<mass>98.03</mass>
	<inertia>
	    <ixx>29.346</ixx>
	    <ixy>0</ixy>
	    <ixz>-1.55</ixz>
	    <iyy>9.25</iyy>
	    <iyz>0</iyz>
	    <izz>32.05</izz>
	</inertia>
    </inertial>
    <collision name='loader_collision'>
	<pose>0 0 0 0 -0 0</pose>
	<geometry>
	    <mesh>
	    <scale>1 1 1</scale>
	    <uri>model://bobcat_tracked/meshes/loader_col.STL</uri>
	    </mesh>
	</geometry>
	<surface>
	<contact>
	<ode/>
	</contact>
	<friction>
	<ode>
	<mu>1</mu>
	<mu2>1</mu2>
	</ode>
	</friction>
	</surface>
    </collision>
    <visual name='loader_visual'>
	<pose>0 0 0 0 -0 0</pose>
	<geometry>
	    <mesh>
	    <scale>1 1 1</scale>
	    <uri>model://bobcat_tracked/meshes/loader.STL</uri>
	    </mesh>
	</geometry>
	<material>
	  <script>
	    <name>Gazebo/Gold</name>
	    <uri>__default__</uri>
	  </script>
	</material>
    </visual>
    <gravity>1</gravity>
    <velocity_decay>
	<linear>0</linear>
	<angular>0</angular>
    </velocity_decay>
    <self_collide>1</self_collide>
</link>
<joint name='loader_joint' type='revolute'>
    <child>loader</child>
    <parent>main_arm</parent>
    <axis>
	<xyz>0 1 0</xyz>
	<limit>
	  <lower>-0.5</lower>
	  <upper>0.5</upper>
	  <!-- <lower>-0.5</lower> -->
	  <effort>1e+06</effort>
	  <velocity>100</velocity>
	</limit>
	<!--<dynamics><friction>1</friction></dynamics>-->
	</axis>
</joint>

<link name='brackets'>
    <pose>0.68217 0 0.64099 0 2.5362e-15 0</pose>
    <inertial>
	<pose>0.14213 -1.579e-16 0.33109 0 -0 0</pose>
	<mass>12.857</mass>
	<inertia>
	    <ixx>2.9339</ixx>
	    <ixy>-2.9653e-16</ixy>
	    <ixz>0.23718</ixz>
	    <iyy>0.67251</iyy>
	    <iyz>3.0656e-16</iyz>
	    <izz>2.738</izz>
	</inertia>
    </inertial>
    <collision name='brackets_collision'>
    <pose>0 0 0 0 -0 0</pose>
    <geometry>
	<mesh>
	<scale>1 1 1</scale>
	<uri>model://bobcat_tracked/meshes/brackets_col.STL</uri>
	</mesh>
    </geometry>
    <surface>
      <contact>
	<ode/>
      </contact>
      <friction>
	<ode>
	  <mu>1</mu>
	  <mu2>1</mu2>
	</ode>
      </friction>
    </surface>
    </collision>
    <visual name='brackets_visual'>
	<pose>0 0 0 0 -0 0</pose>
	<geometry>
	    <mesh>
	    <scale>1 1 1</scale>
	    <uri>model://bobcat_tracked/meshes/brackets.STL</uri>
	    </mesh>
	</geometry>
	<material>
	    <script>
		<name>Gazebo/Grey</name>
		<uri>__default__</uri>
	    </script>
	</material>
    </visual>
    <gravity>1</gravity>
    <velocity_decay>
	<linear>0</linear>
	<angular>0</angular>
    </velocity_decay>
    <self_collide>1</self_collide>
</link>
<joint name='brackets_joint' type='revolute'>
    <child>brackets</child>
    <parent>loader</parent>
    <axis>
    <xyz>0 1 0</xyz>
    <limit>
	<lower>0</lower>
	<upper>1</upper>
	<effort>1e+06</effort>
	<velocity>1e+06</velocity>
    </limit>
    <!--<dynamics><friction>1</friction></dynamics>-->
    </axis>
</joint>

<link name='supporter'>
    <pose>-1.35685 0 0.80864 0 8.0491e-16 0</pose>
    <inertial>
	<pose>0.51341 -4.9085e-16 -0.060486 0 -0 0</pose>
	<mass>65.29</mass>
	<inertia>
	    <ixx>16.898</ixx>
	    <ixy>-2.3004e-13</ixy>
	    <ixz>-0.76501</ixz>
	    <iyy>6.6127</iyy>
	    <iyz>-2.4072e-13</iyz>
	    <izz>23.301</izz>
	</inertia>
    </inertial>
    <collision name='supporter_collision'>
	<pose>0 0 0 0 -0 0</pose>
	<geometry>
	  <mesh>
	    <scale>1 1 1</scale>
	    <uri>model://bobcat_tracked/meshes/supporter.STL</uri>
	  </mesh>
	</geometry>
	<surface>
	  <contact>
	    <ode/>
	  </contact>
	  <friction>
	    <ode>
	      <mu>1</mu>
	      <mu2>1</mu2>
	    </ode>
	  </friction>
	</surface>
    </collision>
    <visual name='supporter_visual'>
	<pose>0 0 0 0 -0 0</pose>
	<geometry>
	  <mesh>
	    <scale>1 1 1</scale>
	    <uri>model://bobcat_tracked/meshes/supporter.STL</uri>
	  </mesh>
	</geometry>
	<material>
	  <script>
	    <name>Gazebo/GreyTransparent</name>
	    <uri>__default__</uri>
	  </script>
	</material>
    </visual>
    <gravity>1</gravity>
    <velocity_decay>
      <linear>0</linear>
      <angular>0</angular>
    </velocity_decay>
    <self_collide>1</self_collide>
</link>
<joint name='supporter_joint' type='revolute'>
    <child>supporter</child>
    <parent>main_arm</parent>
    <axis>
	<xyz>0 1 0</xyz>
	<limit>
	  <lower>-0.5</lower>
	  <upper>1.5</upper>
	  <effort>1e+06</effort>
	  <velocity>100</velocity>
	</limit>
	<!--<dynamics><friction>1</friction></dynamics>-->
    </axis>
</joint>
<joint name='supporter_joint2' type='revolute'>
<pose>1.04 0 -0.122 0 0 0</pose>
    <child>supporter</child>
    <parent>body</parent>
    <axis>
	<xyz>0 1 0</xyz>
	<limit>
	  <lower>-0.5</lower>
	  <upper>1.5</upper>
	  <effort>1e+06</effort>
	  <velocity>100</velocity>
	</limit>
	<!--<dynamics><friction>1</friction></dynamics>-->
    </axis>
</joint>


<link name='back_left_wheel'>
    <pose>-1.53739 0.655 -0.02866 0 0 0</pose>
      <inertial>
<pose>0 0 0 0 -0 0</pose>
	    <mass>100</mass>
	    <inertia>
		<ixx>2.33</ixx>
		<ixy>-0</ixy>
		<ixz>0</ixz>
		<iyy>2</iyy>
		<iyz>0</iyz>
		<izz>2.33</izz>
	    </inertia>
      </inertial>
      <collision name='back_left_wheel_collision'>
	  <pose>0 0 0 -1.5708 -0 0</pose>
	  <geometry>
	    <cylinder>
	      <length>0.4</length>
	      <radius>0.2</radius>
	    </cylinder>
	  </geometry>
	  <surface>
	      <contact>
	      <ode/>
	      </contact>
	      <friction>
		<ode>
		  <mu>1</mu>
		  <mu2>1</mu2>
		</ode>
	      </friction>
	  </surface>
      </collision>

      <gravity>1</gravity>	
      <velocity_decay>
	  <linear>0</linear>
	  <angular>0</angular>
      </velocity_decay>
      <self_collide>0</self_collide>
</link>
<joint name='back_left_wheel_joint' type='revolute'>
    <child>back_left_wheel</child>
    <parent>body</parent>
    <axis>
	<xyz>0 1 0</xyz>
	<limit>
	  <lower>-1e+16</lower>
	  <upper>1e+16</upper>
	</limit>
	<!--<dynamics><friction>1</friction></dynamics>-->
    </axis>
</joint>

<link name='back_right_wheel'>
    <pose>-1.535 -0.66 -0.025 0 0 0</pose>
    <inertial>
<pose>0 0 0 0 -0 0</pose>
	<mass>100</mass>
	<inertia>
		<ixx>2.33</ixx>
		<ixy>-0</ixy>
		<ixz>0</ixz>
		<iyy>2</iyy>
		<iyz>0</iyz>
		<izz>2.33</izz>
	</inertia>
    </inertial>
    <collision name='back_right_wheel_collision'>
	    <pose>0 0 0 1.5708 -0 0</pose>
	    <geometry>
	      <cylinder>
		<length>0.4</length>
		<radius>0.2</radius>
	      </cylinder>
	    </geometry>
	<surface>
	    <contact>
		<ode/>
	    </contact>
	    <friction>
	      <ode>
		<mu>10</mu>
		<mu2>10</mu2>
	      </ode>
	    </friction>
	</surface>
    </collision>

    <gravity>1</gravity>
    <velocity_decay>
	<linear>0</linear>
	<angular>0</angular>
    </velocity_decay>
    <self_collide>1</self_collide>
</link>
<joint name='back_right_wheel_joint' type='revolute'>
    <child>back_right_wheel</child>
    <parent>body</parent>
    <axis>
	<xyz>0 1 0</xyz>
	<limit>
	    <lower>-1e+16</lower>
	    <upper>1e+16</upper>
	</limit>
	<!--<dynamics><friction>1</friction></dynamics>-->
    </axis>
</joint>

<link name='front_left_wheel'>
    <pose>-0.0535 0.655 0.01 0 0 0</pose>
    <inertial>
<pose>0 0 0 0 -0 0</pose>
	<mass>100</mass>
	<inertia>
	    <ixx>2.76</ixx>
	    <ixy>-0</ixy>
	    <ixz>-0</ixz>
	    <iyy>2.76</iyy>
	    <iyz>0</iyz>
	    <izz>2.76</izz>
	</inertia>
    </inertial>
    <collision name='front_left_wheel_collision'>
	<pose>0 0 0 -1.5708 -0 0</pose>
	<geometry>
	    <cylinder>
	      <length>0.4</length>
	      <radius>0.235</radius>
	    </cylinder>
	</geometry>
	<surface>
	    <contact>
	      <ode/>
	    </contact>
	    <friction>
	      <ode>
		<mu>10</mu>
		<mu2>10</mu2>
	      </ode>
	    </friction>
	</surface>
    </collision>

    <gravity>1</gravity>
    <velocity_decay>
	<linear>0</linear>
	<angular>0</angular>
    </velocity_decay>
    <self_collide>1</self_collide>
</link>
<joint name='front_left_wheel_joint' type='revolute'>
    <child>front_left_wheel</child>
    <parent>body</parent>
    <axis>
	<xyz>0 1 0</xyz>
	  <limit>
	    <lower>-1e+16</lower>
	    <upper>1e+16</upper>
	  </limit>
	<!--<dynamics><friction>1</friction></dynamics>-->
    </axis>
</joint>

<link name='front_right_wheel'>
    <pose>-0.0535 -0.66 0.01 0 0 0</pose>
    <inertial>
<pose>0 0 0 0 -0 0</pose>
	<mass>100</mass>
	<inertia>
	    <ixx>2.76</ixx>
	    <ixy>-0</ixy>
	    <ixz>-0</ixz>
	    <iyy>2.76</iyy>
	    <iyz>0</iyz>
	    <izz>2.76</izz>
	</inertia>
    </inertial>
    <collision name='front_right_wheel_collision'>
	<pose>0 0 0 1.5708 -0 0</pose>
	<geometry>
	    <cylinder>
	      <length>0.4</length>
	      <radius>0.235</radius>
	    </cylinder>
	</geometry>
	<surface>
	    <contact>
	      <ode/>
	    </contact>
	    <friction>
		<ode>
		  <mu>1</mu>
		  <mu2>1</mu2>
		</ode>
	    </friction>
	</surface>
    </collision>

    <gravity>1</gravity>
    <velocity_decay>
	<linear>0</linear>
	<angular>0</angular>
    </velocity_decay>
    <self_collide>1</self_collide>
</link>
<joint name='front_right_wheel_joint' type='revolute'>
  
<child>front_right_wheel</child>
<parent>body</parent>
<axis>
<xyz>0 1 0</xyz>
<limit>
<lower>-1e+16</lower>
<upper>1e+16</upper>
</limit>
<!--<dynamics><friction>1</friction></dynamics>-->
</axis>
</joint>

<link name='roller_back_right'>
    <pose>-1.15 -0.65 -0.075 0 0 0</pose>
    <inertial>
<pose>0 0 0 0 -0 0</pose>
	<mass>50</mass>
	<inertia>
		<ixx>0.95</ixx>
		<ixy>-0</ixy>
		<ixz>0</ixz>
		<iyy>0.5625</iyy>
		<iyz>0</iyz>
		<izz>0.95</izz>
	</inertia>
    </inertial>
    <collision name='roller_back_right_collision'>
	    <pose>0 0 0 1.5708 -0 0</pose>
	    <geometry>
	      <cylinder>
		<length>0.4</length>
		<radius>0.15</radius>
	      </cylinder>
	    </geometry>
	<surface>
	    <contact>
		<ode/>
	    </contact>
	    <friction>
	      <ode>
		<mu>10</mu>
		<mu2>10</mu2>
	      </ode>
	    </friction>
	</surface>
    </collision>

    <gravity>1</gravity>
    <velocity_decay>
	<linear>0</linear>
	<angular>0</angular>
    </velocity_decay>
    <self_collide>1</self_collide>
</link>
<joint name='roller_back_right_joint' type='revolute'>
    <child>roller_back_right</child>
    <parent>body</parent>
    <axis>
	<xyz>0 1 0</xyz>
	<limit>
	    <lower>-1e+16</lower>
	    <upper>1e+16</upper>
	</limit>
	<!--<dynamics><friction>1</friction></dynamics>-->
    </axis>
</joint>
<joint name="gear_roller_back_right" type="gearbox">
            <parent>back_right_wheel</parent>
            <child>roller_back_right</child>
            <gearbox_ratio>-1.333333333</gearbox_ratio>
            <gearbox_reference_body>body</gearbox_reference_body>
            <axis>
              <xyz>0.000000 1.000000 0.000000</xyz>
            </axis>
            <axis2>
              <xyz>0.000000 1.000000 0.000000</xyz>
            </axis2>
</joint>

<link name='roller_mid_right'>
    <pose>-0.81 -0.65 -0.075 0 0 0</pose>
    <inertial>
<pose>0 0 0 0 -0 0</pose>
	<mass>50</mass>
	<inertia>
		<ixx>0.95</ixx>
		<ixy>-0</ixy>
		<ixz>0</ixz>
		<iyy>0.5625</iyy>
		<iyz>0</iyz>
		<izz>0.95</izz>
	</inertia>
    </inertial>
    <collision name='roller_mid_right_collision'>
	    <pose>0 0 0 1.5708 -0 0</pose>
	    <geometry>
	      <cylinder>
		<length>0.4</length>
		<radius>0.15</radius>
	      </cylinder>
	    </geometry>
	<surface>
	    <contact>
		<ode/>
	    </contact>
	    <friction>
	      <ode>
		<mu>10</mu>
		<mu2>10</mu2>
	      </ode>
	    </friction>
	</surface>
    </collision>

    <gravity>1</gravity>
    <velocity_decay>
	<linear>0</linear>
	<angular>0</angular>
    </velocity_decay>
    <self_collide>1</self_collide>
</link>
<joint name='roller_mid_right_joint' type='revolute'>
    <child>roller_mid_right</child>
    <parent>body</parent>
    <axis>
	<xyz>0 1 0</xyz>
	<limit>
	    <lower>-1e+16</lower>
	    <upper>1e+16</upper>
	</limit>
	<!--<dynamics><friction>1</friction></dynamics>-->
    </axis>
</joint>
<joint name="gear_roller_mid_right" type="gearbox">
            <parent>back_right_wheel</parent>
            <child>roller_mid_right</child>
            <gearbox_ratio>-1.333333333</gearbox_ratio>
            <gearbox_reference_body>body</gearbox_reference_body>
            <axis>
              <xyz>0.000000 1.000000 0.000000</xyz>
            </axis>
            <axis2>
              <xyz>0.000000 1.000000 0.000000</xyz>
            </axis2>
</joint>
<link name='roller_front_right'>
    <pose>-0.46 -0.65 -0.075 0 0 0</pose>
    <inertial>
<pose>0 0 0 0 -0 0</pose>
	<mass>50</mass>
	<inertia>
		<ixx>0.95</ixx>
		<ixy>-0</ixy>
		<ixz>0</ixz>
		<iyy>0.5625</iyy>
		<iyz>0</iyz>
		<izz>0.95</izz>
	</inertia>
    </inertial>
    <collision name='roller_front_right_collision'>
	    <pose>0 0 0 1.5708 -0 0</pose>
	    <geometry>
	      <cylinder>
		<length>0.4</length>
		<radius>0.15</radius>
	      </cylinder>
	    </geometry>
	<surface>
	    <contact>
		<ode/>
	    </contact>
	    <friction>
	      <ode>
		<mu>10</mu>
		<mu2>10</mu2>
	      </ode>
	    </friction>
	</surface>
    </collision>

    <gravity>1</gravity>
    <velocity_decay>
	<linear>0</linear>
	<angular>0</angular>
    </velocity_decay>
    <self_collide>1</self_collide>
</link>
<joint name='roller_front_right_joint' type='revolute'>
    <child>roller_front_right</child>
    <parent>body</parent>
    <axis>
	<xyz>0 1 0</xyz>
	<limit>
	    <lower>-1e+16</lower>
	    <upper>1e+16</upper>
	</limit>
	<!--<dynamics><friction>1</friction></dynamics>-->
    </axis>
</joint>
<joint name="gear_roller_front_right" type="gearbox">
            <parent>back_right_wheel</parent>
            <child>roller_front_right</child>
            <gearbox_ratio>-1.333333333</gearbox_ratio>
            <gearbox_reference_body>body</gearbox_reference_body>
            <axis>
              <xyz>0.000000 1.000000 0.000000</xyz>
            </axis>
            <axis2>
              <xyz>0.000000 1.000000 0.000000</xyz>
            </axis2>
</joint>

<link name='roller_back_left'>
    <pose>-1.15 0.65 -0.075 0 0 0</pose>
    <inertial>
<pose>0 0 0 0 -0 0</pose>
	<mass>50</mass>
	<inertia>
		<ixx>0.95</ixx>
		<ixy>-0</ixy>
		<ixz>0</ixz>
		<iyy>0.5625</iyy>
		<iyz>0</iyz>
		<izz>0.95</izz>
	</inertia>
    </inertial>
    <collision name='roller_back_left_collision'>
	    <pose>0 0 0 1.5708 -0 0</pose>
	    <geometry>
	      <cylinder>
		<length>0.4</length>
		<radius>0.15</radius>
	      </cylinder>
	    </geometry>
	<surface>
	    <contact>
		<ode/>
	    </contact>
	    <friction>
	      <ode>
		<mu>10</mu>
		<mu2>10</mu2>
	      </ode>
	    </friction>
	</surface>
    </collision>

    <gravity>1</gravity>
    <velocity_decay>
	<linear>0</linear>
	<angular>0</angular>
    </velocity_decay>
    <self_collide>1</self_collide>
</link>
<joint name='roller_back_left_joint' type='revolute'>
    <child>roller_back_left</child>
    <parent>body</parent>
    <axis>
	<xyz>0 1 0</xyz>
	<limit>
	    <lower>-1e+16</lower>
	    <upper>1e+16</upper>
	</limit>
	<!--<dynamics><friction>1</friction></dynamics>-->
    </axis>
</joint>
<joint name="gear_roller_back_left" type="gearbox">
            <parent>back_left_wheel</parent>
            <child>roller_back_left</child>
            <gearbox_ratio>-1.333333333</gearbox_ratio>
            <gearbox_reference_body>body</gearbox_reference_body>
            <axis>
              <xyz>0.000000 1.000000 0.000000</xyz>
            </axis>
            <axis2>
              <xyz>0.000000 1.000000 0.000000</xyz>
            </axis2>
</joint>

<link name='roller_mid_left'>
    <pose>-0.81 0.65 -0.075 0 0 0</pose>
    <inertial>
<pose>0 0 0 0 -0 0</pose>
	<mass>50</mass>
	<inertia>
		<ixx>0.95</ixx>
		<ixy>-0</ixy>
		<ixz>0</ixz>
		<iyy>0.5625</iyy>
		<iyz>0</iyz>
		<izz>0.95</izz>
	</inertia>
    </inertial>
    <collision name='roller_mid_left_collision'>
	    <pose>0 0 0 1.5708 -0 0</pose>
	    <geometry>
	      <cylinder>
		<length>0.4</length>
		<radius>0.15</radius>
	      </cylinder>
	    </geometry>
	<surface>
	    <contact>
		<ode/>
	    </contact>
	    <friction>
	      <ode>
		<mu>10</mu>
		<mu2>10</mu2>
	      </ode>
	    </friction>
	</surface>
    </collision>

    <gravity>1</gravity>
    <velocity_decay>
	<linear>0</linear>
	<angular>0</angular>
    </velocity_decay>
    <self_collide>1</self_collide>
</link>
<joint name='roller_mid_left_joint' type='revolute'>
    <child>roller_mid_left</child>
    <parent>body</parent>
    <axis>
	<xyz>0 1 0</xyz>
	<limit>
	    <lower>-1e+16</lower>
	    <upper>1e+16</upper>
	</limit>
	<!--<dynamics><friction>1</friction></dynamics>-->
    </axis>
</joint>
<joint name="gear_roller_mid_left" type="gearbox">
            <parent>back_left_wheel</parent>
            <child>roller_mid_left</child>
            <gearbox_ratio>-1.333333333</gearbox_ratio>
            <gearbox_reference_body>body</gearbox_reference_body>
            <axis>
              <xyz>0.000000 1.000000 0.000000</xyz>
            </axis>
            <axis2>
              <xyz>0.000000 1.000000 0.000000</xyz>
            </axis2>
</joint>

<link name='roller_front_left'>
    <pose>-0.46 0.65 -0.075 0 0 0</pose>
    <inertial>
<pose>0 0 0 0 -0 0</pose>
	<mass>50</mass>
	<inertia>
		<ixx>0.95</ixx>
		<ixy>-0</ixy>
		<ixz>0</ixz>
		<iyy>0.5625</iyy>
		<iyz>0</iyz>
		<izz>0.95</izz>
	</inertia>
    </inertial>
    <collision name='roller_front_left_collision'>
	    <pose>0 0 0 1.5708 -0 0</pose>
	    <geometry>
	      <cylinder>
		<length>0.4</length>
		<radius>0.15</radius>
	      </cylinder>
	    </geometry>
	<surface>
	    <contact>
		<ode/>
	    </contact>
	    <friction>
	      <ode>
		<mu>10</mu>
		<mu2>10</mu2>
	      </ode>
	    </friction>
	</surface>
    </collision>

    <gravity>1</gravity>
    <velocity_decay>
	<linear>0</linear>
	<angular>0</angular>
    </velocity_decay>
    <self_collide>1</self_collide>
</link>
<joint name='roller_front_left_joint' type='revolute'>
    <child>roller_front_left</child>
    <parent>body</parent>
    <axis>
	<xyz>0 1 0</xyz>
	<limit>
	    <lower>-1e+16</lower>
	    <upper>1e+16</upper>
	</limit>
	<!--<dynamics><friction>1</friction></dynamics>-->
    </axis>
</joint>
<joint name="gear_roller_front_left" type="gearbox">
            <parent>back_left_wheel</parent>
            <child>roller_front_left</child>
            <gearbox_ratio>-1.333333333</gearbox_ratio>
            <gearbox_reference_body>body</gearbox_reference_body>
            <axis>
              <xyz>0.000000 1.000000 0.000000</xyz>
            </axis>
            <axis2>
              <xyz>0.000000 1.000000 0.000000</xyz>
            </axis2>
</joint>



<joint name="gear_right" type="gearbox">
            <!--
              theta_1 = joint angle in the direction specified by <axis> from <gearbox_refrence_body> to <parent>
              theta_2 = joint angle in the direction specified by <axis2> from <gearbox_refrence_body> to <child>
              this gearbox constraint enforces that
              theta_2 = - <gearbox_ratio> * theta_1
            -->
            <parent>back_right_wheel</parent>
            <child>front_right_wheel</child>
            <gearbox_ratio>-0.851</gearbox_ratio>
            <gearbox_reference_body>body</gearbox_reference_body>
            <axis>
              <xyz>0.000000 1.000000 0.000000</xyz>
            </axis>
            <axis2>
              <xyz>0.000000 1.000000 0.000000</xyz>
            </axis2>
</joint>
<joint name="gear_left" type="gearbox">
            <!--
              theta_1 = joint angle in the direction specified by <axis> from <gearbox_refrence_body> to <parent>
              theta_2 = joint angle in the direction specified by <axis2> from <gearbox_refrence_body> to <child>
              this gearbox constraint enforces that
              theta_2 = - <gearbox_ratio> * theta_1
            -->
            <parent>back_left_wheel</parent>
            <child>front_left_wheel</child>
            <gearbox_ratio>-0.851</gearbox_ratio>
            <gearbox_reference_body>body</gearbox_reference_body>
            <axis>
              <xyz>0.000000 1.000000 0.000000</xyz>
            </axis>
            <axis2>
              <xyz>0.000000 1.000000 0.000000</xyz>
            </axis2>
</joint>

<plugin name="bobcat_drive_control" filename="libbobcat_drive_plugin.so"/> 
    

<!-- bobcat arm controllers --> <!-- 
  <plugin name='gazebo_ros_control' filename='libgazebo_ros_control.so'>
    <robotNamespace>/Sahar</robotNamespace>
  </plugin>


  <plugin name="joint_state_publisher" filename="libgazebo_ros_joint_state_publisher.so">
    <robotNamespace>/Sahar</robotNamespace>
    <jointName>main_arm_joint, base_arm_joint, back_left_wheel_joint, back_right_wheel_joint, front_left_wheel_joint, front_right_wheel_joint</jointName>
    <updateRate>50.0</updateRate>
    <alwaysOn>true</alwaysOn>
  </plugin>
-->

</model>
</sdf>
