<?xml version="1.0" encoding="UTF-8"?>

<!-- -*- mode: XML -*- -->

<sdf version='1.4'>
<model name='Sahar'>


<link name='body'>
	<pose>0 0 0 0 -0 0</pose>	
	<gravity>1</gravity>
	<velocity_decay>
	  <linear>0</linear>
	  <angular>0</angular>
	</velocity_decay>
	<self_collide>1</self_collide>
	<inertial>
	    <pose>-1.00 0.00 0.20 0 -0 0</pose>
	    <mass>2500</mass>
	    <inertia>
		<ixx>800.00</ixx>
		<ixy>0.00</ixy>
		<ixz>0.00</ixz>
		<iyy>1200.00</iyy>
		<iyz>0.00</iyz>
		<izz>1000.00</izz>
	    </inertia>
	</inertial>
	<collision name='body_collision'>
	    <pose>0 0 0 0 -0 0</pose>
	    <geometry>
	      <mesh>
		<scale>1 1 1</scale>
		<uri>model://bobcat_static_arm/meshes/body.STL</uri>
	      </mesh>
	    </geometry>
	    <surface>
	      <contact>
		<ode/>
	      </contact>
	      <friction>
		<ode>
		  <mu>1</mu>
		  <mu2>1</mu2>
		</ode>
	      </friction>
	    </surface>
	</collision>
	<visual name='body_visual'>
	    <pose>0 0 0 0 -0 0</pose>
	    <geometry>
	    <mesh>
	    <scale>1 1 1</scale>
	    <uri>model://bobcat_static_arm/meshes/body.STL</uri>
	    </mesh>
	    </geometry>
	    <material>
	    <script>
	      <name>Gazebo/Wood</name>
	      <uri>__default__</uri>
	    </script>
	    </material>
	</visual>
	
	<collision name='body_collision_cabin'>
	    <pose>-0.11317 0 0.61042 0 8.0491e-16 0</pose>
	    <geometry>
	    <mesh>
	    <scale>1 1 1</scale>
	    <uri>model://bobcat_static_arm/meshes/cabin.STL</uri>
	    </mesh>
	    </geometry>
	    <surface>
	    <contact>
	    <ode/>
	    </contact>
	    <friction>
	    <ode>
	    <mu>1</mu>
	    <mu2>1</mu2>
	    </ode>
	    </friction>
	    </surface>
	</collision>
	<visual name='body_visual_cabin'>
	    <pose>-0.11317 0 0.61042 0 8.0491e-16 0</pose>
	    <geometry>
		<mesh>
		    <scale>1 1 1</scale>
		    <uri>model://bobcat_static_arm/meshes/cabin.STL</uri>
		</mesh>
	    </geometry>
	    <material>
		<script>
		<name>Gazebo/Grey</name>
		<uri>__default__</uri>
		</script>
	    </material>
	</visual>

	<collision name='body_collision_supporter_hinge'>
	    <pose>-0.31547 0 0.68593 1.5708 -5.55112e-17 1.5708</pose>
	    <geometry>
	    <mesh>
	    <scale>1 1 1</scale>
	    <uri>model://bobcat_static_arm/meshes/supporter_hinge.STL</uri>
	    </mesh>
	    </geometry>
	    <surface>
	    <contact>
	    <ode/>
	    </contact>
	    <friction>
	    <ode>
	    <mu>1</mu>
	    <mu2>1</mu2>
	    </ode>
	    </friction>
	    </surface>
	</collision>
	<visual name='body_visual_supporter_hinge'>
	    <pose>-0.31547 0 0.68593 1.5708 -5.55112e-17 1.5708</pose>
	    <geometry>
		<mesh>
		<scale>1 1 1</scale>
		<uri>model://bobcat_static_arm/meshes/supporter_hinge.STL</uri>
		</mesh>
	    </geometry>
	    <material>
		<script>
		<name>Gazebo/GreyTransparent</name>
		<uri>__default__</uri>
		</script>
	    </material>
	</visual>
	
	<collision name='body_collision_top_installation'>
	    <pose>-0.29575 0.03227 1.85972 1.5708 -6.10623e-16 1.5708</pose>
	    <geometry>
		<mesh>
		  <scale>1 1 1</scale>
		  <uri>model://bobcat_static_arm/meshes/top_installation.STL</uri>
		</mesh>
	    </geometry>
	    <surface>
		<contact>
		  <ode/>
		</contact>
		<friction>
		<ode>
		  <mu>1</mu>
		  <mu2>1</mu2>
		</ode>
		</friction>
	    </surface>
	</collision>
	<visual name='body_visual_top_installation'>
	    <pose>-0.29575 0.03227 1.85972 1.5708 -6.10623e-16 1.5708</pose>
	    <geometry>
	      <mesh>
		<scale>1 1 1</scale>
		<uri>model://bobcat_static_arm/meshes/top_installation.STL</uri>
	      </mesh>
	    </geometry>
	    <material>
	      <script>
		<name>Gazebo/Grey</name>
		<uri>__default__</uri>
	      </script>
	    </material>
	</visual>
	

	
	<collision name='base_arm_collision'>
	    <pose>-1.9776 0 1.1773 0 0 0</pose>
	    <geometry>
	      <mesh>
		<scale>1 1 1</scale>
		<uri>model://bobcat_static_arm/meshes/base_arm.STL</uri>
	      </mesh>
	    </geometry>
	    <surface>
	      <contact>
		<ode/>
	      </contact>
	      <friction>
		<ode/>
	      </friction>
	    </surface>
	</collision>
	<visual name='base_arm_visual'>
	    <pose>-1.9776 0 1.1773 0 0 0</pose>
	    <geometry>
	      <mesh>
		<scale>1 1 1</scale>
		<uri>model://bobcat_static_arm/meshes/base_arm.STL</uri>
	      </mesh>
	    </geometry>
	    <material>
	      <script>
		<name>Gazebo/Grey</name>
		<uri>__default__</uri>
	      </script>
	    </material>
	</visual>
      
	<collision name='main_arm_collision'>
	    <pose>-1.75456 0 1.7035 0 -0 0</pose>
	    <geometry>
		<mesh>
		<scale>1 1 1</scale>
		<uri>model://bobcat_static_arm/meshes/main_arm.STL</uri>
		</mesh>
	    </geometry>
	    <surface>
		<contact>
		  <ode/>
		</contact>
		<friction>
		  <ode/>
		</friction>
	    </surface>
	</collision>
	<visual name='main_arm_visual'>
	    <pose>-1.75456 0 1.7035 0 -0 0</pose>
	    <geometry>
		<mesh>
		    <scale>1 1 1</scale>
		    <uri>model://bobcat_static_arm/meshes/main_arm.STL</uri>
		</mesh>
	    </geometry>
	    <material>
		<script>
		<name>Gazebo/PaintedWall</name>
		<uri>__default__</uri>
		</script>
	    </material>
	</visual>

	<collision name='loader_collision'>
	    <pose>0.34384 0 0.1465 0 0 0</pose>
	    <geometry>
		<mesh>
		<scale>1 1 1</scale>
		<uri>model://bobcat_static_arm/meshes/loader.STL</uri>
		</mesh>
	    </geometry>
	    <surface>
	    <contact>
	    <ode/>
	    </contact>
	    <friction>
	    <ode>
	    <mu>1</mu>
	    <mu2>1</mu2>
	    </ode>
	    </friction>
	    </surface>
	</collision>
	<visual name='loader_visual'>
	    <pose>0.34384 0 0.1465 0 0 0</pose>
	    <geometry>
		<mesh>
		<scale>1 1 1</scale>
		<uri>model://bobcat_static_arm/meshes/loader.STL</uri>
		</mesh>
	    </geometry>
	    <material>
	      <script>
		<name>Gazebo/Gold</name>
		<uri>__default__</uri>
	      </script>
	    </material>
	</visual>
	  
	<collision name='brackets_collision'>
	  <pose>0.68217 0 0.64099 0 0 0</pose>
	  <geometry>
	      <mesh>
	      <scale>1 1 1</scale>
	      <uri>model://bobcat_static_arm/meshes/brackets.STL</uri>
	      </mesh>
	  </geometry>
	  <surface>
	    <contact>
	      <ode/>
	    </contact>
	    <friction>
	      <ode>
		<mu>1</mu>
		<mu2>1</mu2>
	      </ode>
	    </friction>
	  </surface>
	</collision>
	<visual name='brackets_visual'>
	    <pose>0.68217 0 0.64099 0 0 0</pose>
	    <geometry>
		<mesh>
		<scale>1 1 1</scale>
		<uri>model://bobcat_static_arm/meshes/brackets.STL</uri>
		</mesh>
	    </geometry>
	    <material>
		<script>
		    <name>Gazebo/Grey</name>
		    <uri>__default__</uri>
		</script>
	    </material>
	</visual>
	
	<collision name='supporter_collision'>
	    <pose>-1.35685 0 0.80864 0 0 0</pose>
	    <geometry>
	      <mesh>
		<scale>1 1 1</scale>
		<uri>model://bobcat_static_arm/meshes/supporter.STL</uri>
	      </mesh>
	    </geometry>
	    <surface>
	      <contact>
		<ode/>
	      </contact>
	      <friction>
		<ode>
		  <mu>1</mu>
		  <mu2>1</mu2>
		</ode>
	      </friction>
	    </surface>
	</collision>
	<visual name='supporter_visual'>
	<pose>-1.35685 0 0.80864 0 0 0</pose>
	<geometry>
	  <mesh>
	    <scale>1 1 1</scale>
	    <uri>model://bobcat_static_arm/meshes/supporter.STL</uri>
	  </mesh>
	</geometry>
	<material>
	  <script>
	    <name>Gazebo/GreyTransparent</name>
	    <uri>__default__</uri>
	  </script>
	</material>
    </visual>
	
</link>


<link name='back_left_wheel'>
      <pose>-1.227 0.47558 0.14772 0 2.1164e-16 0</pose>
      <inertial>
	    <pose>7.7344e-08 0.19645 1.8868e-07 0 -0 0</pose>
	    <mass>333.358</mass>
	    <inertia>
		<ixx>17.0765</ixx>
		<ixy>-2.79367e-06</ixy>
		<ixz>-6.68629e-05</ixz>
		<iyy>29.6158</iyy>
		<iyz>-1.33651e-05</iyz>
		<izz>17.0765</izz>
	    </inertia>
      </inertial>
      <collision name='back_left_wheel_collision'>
	  <pose>0 0.2 0 1.5708 -0 0</pose>
	  <geometry>
	    <cylinder>
	      <length>0.4</length>
	      <radius>0.4</radius>
	    </cylinder>
	  </geometry>
	  <surface>
	      <contact>
	      <ode/>
	      </contact>
	      <friction>
		<ode>
                  <mu>1</mu>
                  <mu2>1</mu2>
		</ode>
	      </friction>
	  </surface>
      </collision>
      <visual name='back_left_wheel_visual'>
	  <pose>0 0 0 0 -0 0</pose>
	  <geometry>
	      <mesh>
		<uri>model://bobcat_static_arm/meshes/back_left_wheel.stl</uri>
	      </mesh>
	  </geometry>
	  <material>
	      <script>
		<name>Gazebo/Grey</name>
		<uri>__default__</uri>
	      </script>
	  </material>
      </visual>
      <gravity>1</gravity>	
      <velocity_decay>
	  <linear>0</linear>
	  <angular>0</angular>
      </velocity_decay>
      <self_collide>0</self_collide>
</link>
<joint name='back_left_wheel_joint' type='revolute'>
    <child>back_left_wheel</child>
    <parent>body</parent>
    <axis>
	<xyz>0 1 0</xyz>
	
	  
	  
	
	<dynamics/>
    </axis>
</joint>

<link name='back_right_wheel'>
    <pose>-1.227 -0.47558 0.14772 0 2.1164e-16 0</pose>
    <inertial>
	<pose>-1.4894e-07 -0.19645 1.3751e-07 0 -0 0</pose>
	<mass>333.36</mass>
	<inertia>
	    <ixx>17.0765</ixx>
	    <ixy>-1.87699e-05</ixy>
	    <ixz>1.23277e-05</ixz>
	    <iyy>29.6158</iyy>
	    <iyz>3.1578e-05</iyz>
	    <izz>17.0765</izz>
	</inertia>
    </inertial>
    <collision name='back_right_wheel_collision'>
	    <pose>0 -0.2 0 1.5708 -0 0</pose>
	    <geometry>
	      <cylinder>
		<length>0.4</length>
		<radius>0.4</radius>
	      </cylinder>
	    </geometry>
	<surface>
	    <contact>
		<ode/>
	    </contact>
	    <friction>
	      <ode>
                <mu>1</mu>
                <mu2>1</mu2>
	      </ode>
	    </friction>
	</surface>
    </collision>
    <visual name='back_right_wheel_visual'>
	<pose>0 0 0 0 -0 0</pose>
	<geometry>
	    <mesh>
	      <scale>1 1 1</scale>
	      <uri>model://bobcat_static_arm/meshes/back_right_wheel.stl</uri>
	    </mesh>
	</geometry>
	<material>
	  <script>
	    <name>Gazebo/Grey</name>
	    <uri>__default__</uri>
	  </script>
	</material>
    </visual>
    <gravity>1</gravity>
    <velocity_decay>
	<linear>0</linear>
	<angular>0</angular>
    </velocity_decay>
    <self_collide>1</self_collide>
</link>
<joint name='back_right_wheel_joint' type='revolute'>
    <child>back_right_wheel</child>
    <parent>body</parent>
    <axis>
	<xyz>0 1 0</xyz>
	
	    
	    
	
	<dynamics/>
    </axis>
</joint>

<link name='front_left_wheel'>
    <pose>-0.22722 0.47558 0.125 0 2.1164e-16 0</pose>
    <inertial>
	<pose>2.0502e-07 0.19645 -3.6566e-09 0 -0 0</pose>
	<mass>333.358</mass>
	<inertia>
	    <ixx>17.0765</ixx>
	    <ixy>-4.02019e-05</ixy>
	    <ixz>7.57982e-05</ixz>
	    <iyy>29.6158</iyy>
	    <iyz>-6.64195e-06</iyz>
	    <izz>17.0765</izz>
	</inertia>
    </inertial>
    <collision name='front_left_wheel_collision'>
	<pose>0 0.2 0 1.5708 -0 0</pose>
	<geometry>
	    <cylinder>
	      <length>0.4</length>
	      <radius>0.4</radius>
	    </cylinder>
	</geometry>
	<surface>
	    <contact>
	      <ode/>
	    </contact>
	    <friction>
	      <ode>
                <mu>1</mu>
                <mu2>1</mu2>
	      </ode>
	    </friction>
	</surface>
    </collision>
    <visual name='front_left_wheel_visual'>
	<pose>0 0 0 0 -0 0</pose>
	<geometry>
	    <mesh>
	    <scale>1 1 1</scale>
	    <uri>model://bobcat_static_arm/meshes/front_left_wheel.stl</uri>
	    </mesh>
	</geometry>
	<material>
	    <script>
	      <name>Gazebo/Grey</name>
	      <uri>__default__</uri>
	    </script>
	</material>
    </visual>
    <gravity>1</gravity>
    <velocity_decay>
	<linear>0</linear>
	<angular>0</angular>
    </velocity_decay>
    <self_collide>1</self_collide>
</link>
<joint name='front_left_wheel_joint' type='revolute'>
    <child>front_left_wheel</child>
    <parent>body</parent>
    <axis>
	<xyz>0 1 0</xyz>
	<dynamics/>
    </axis>
</joint>

<link name='front_right_wheel'>
    <pose>-0.22722 -0.47558 0.125 0 2.1164e-16 0</pose>
    <inertial>
	<pose>-2.0519e-07 -0.19645 -4.3198e-09 0 -0 0</pose>
	<mass>333.358</mass>
	<inertia>
	    <ixx>17.0765</ixx>
	    <ixy>-3.66954e-05</ixy>
	    <ixz>-7.5494e-05</ixz>
	    <iyy>29.6158</iyy>
	    <iyz>1.22098e-05</iyz>
	    <izz>17.0765</izz>
	</inertia>
    </inertial>
    <collision name='front_right_wheel_collision'>
	<pose>0 -0.2 0 1.5708 -0 0</pose>
	<geometry>
	    <cylinder>
	      <length>0.4</length>
	      <radius>0.4</radius>
	    </cylinder>
	</geometry>
	<surface>
	    <contact>
	      <ode/>
	    </contact>
	    <friction>
		<ode>
                  <mu>1</mu>
                  <mu2>1</mu2>
		</ode>
	    </friction>
	</surface>
    </collision>
    <visual name='front_right_wheel_visual'>
	<pose>0 0 0 0 -0 0</pose>
	<geometry>
	    <mesh>
	    <scale>1 1 1</scale>
	    <uri>model://bobcat_static_arm/meshes/front_right_wheel.stl</uri>
	    </mesh>
	</geometry>
	<material>
	    <script>
	      <name>Gazebo/Grey</name>
	      <uri>__default__</uri>
	    </script>
	</material>
    </visual>
    <gravity>1</gravity>
    <velocity_decay>
	<linear>0</linear>
	<angular>0</angular>
    </velocity_decay>
    <self_collide>1</self_collide>
</link>
<joint name='front_right_wheel_joint' type='revolute'>
    <child>front_right_wheel</child>
    <parent>body</parent>
    <axis>
      <xyz>0 1 0</xyz>
      <dynamics/>
    </axis>
</joint>


<plugin name="bobcat_drive_control" filename="libbobcat_drive_plugin.so"/> 
    

<plugin name="joint_state_publisher" filename="libgazebo_ros_joint_state_publisher.so">
  <robotNamespace>/Sahar</robotNamespace>
  <jointName>back_left_wheel_joint, back_right_wheel_joint, front_left_wheel_joint, front_right_wheel_joint</jointName>
  <updateRate>50.0</updateRate>
  <alwaysOn>true</alwaysOn>
</plugin>


</model>
</sdf>
