<?xml version="1.0" encoding="UTF-8"?>
<!-- -*- mode: XML -*- -->
<sdf version='1.4'>
	<model name='Sahar'>
		<link name='body'>
			<pose>0 0 0.125 0 0 0</pose>
			<gravity>1</gravity>
			<velocity_decay>
				<linear>0</linear>
				<angular>0</angular>
			</velocity_decay>
			<self_collide>1</self_collide>
			<inertial>
				<pose>-0.873221 -0.0104657 0.683626 0 -0 0</pose>
				<mass>2646.54</mass>
				<inertia>
					<ixx>818.884</ixx>
					<ixy>0</ixy>
					<ixz>0</ixz>
					<iyy>1500</iyy>
					<iyz>0</iyz>
					<izz>1018.05</izz>
				</inertia>
			</inertial>
			<collision name='body_collision'>
				<pose>-0.82136 0 0.36982 0 -0.02 0</pose>
				<geometry>
					<box>
						<size>1.704 0.889 0.704</size>
					</box>
				</geometry>
			</collision>
			<collision name='body_collision_bb'>
				<pose>-2.14939 0 0.68567 0 0.08047 0</pose>
				<geometry>
					<box>
						<size>0.120 0.952 0.900</size>
					</box>
				</geometry>
			</collision>
			<collision name='body_collision_b'>
				<pose>-1.87754 0 0.671 0 0.08047 0</pose>
				<geometry>
					<box>
						<size>0.4 1.182 1.121</size>
					</box>
				</geometry>
			</collision>
			<collision name='body_collision_bd'>
				<pose>-1.81524 0 0.37981 0 0.1318 0</pose>
				<geometry>
					<box>
						<size>0.511 0.889 0.704</size>
					</box>
				</geometry>
			</collision>
			<visual name='body_visual'>
				<pose>0 0 0 0 0 0</pose>
				<geometry>
					<mesh>
						<scale>1 1 1</scale>
						<uri>model://bobcat_static_arm/meshes/body.dae</uri>
					</mesh>
				</geometry>
			</visual>
			<collision name='body_collision_cabin'>
				<pose>-1.0253 0 1.24 0 0 0</pose>
				<geometry>
					<box>
						<size>1.557 0.889 1.152</size>
					</box>
				</geometry>
			</collision>
			<collision name='body_collision_top_installation_link'>
				<pose>-0.92913 0 2.04 0 0 0</pose>
				<geometry>
					<box>
						<size>0.663 0.598 0.838</size>
					</box>
				</geometry>
			</collision>
			<collision name='loader_collision'>
				<pose>0.782 0 0.58109 0 -0.25273  0</pose>
				<geometry>
					<box>
						<size>0.879 1.682 0.720</size>
					</box>
				</geometry>
			</collision>
		</link>
		
		<!--WHEELS-->
		<link name='back_left_wheel'>
			<pose>-1.227 0.47558 0.300 0 0 0</pose>
			<inertial>
				<pose>7.7344e-08 0.19645 1.8868e-07 0 -0 0</pose>
				<mass>333.358</mass>
				<inertia>
					<ixx>17.0765</ixx>
					<ixy>-2.79367e-06</ixy>
					<ixz>-6.68629e-05</ixz>
					<iyy>29.6158</iyy>
					<iyz>-1.33651e-05</iyz>
					<izz>17.0765</izz>
				</inertia>
			</inertial>
			<collision name='back_left_wheel_collision'>
				<pose>0 0.2 0 1.5708 -0 0</pose>
				<geometry>
					<cylinder>
						<length>0.4</length>
						<radius>0.4</radius>
					</cylinder>
				</geometry>
				<surface>
					<contact>
						<ode/>
					</contact>
					<friction>
						<ode>
							<mu>1</mu>
							<mu2>1</mu2>
						</ode>
					</friction>
				</surface>
			</collision>
			<visual name='back_left_wheel_visual'>
				<pose>0 0 0 0 -0 0</pose>
				<geometry>
					<mesh>
						<uri>model://bobcat_static_arm/meshes/back_left_wheel.stl</uri>
					</mesh>
				</geometry>
				<material>
					<ambient>0 0 0 1</ambient>
					<diffuse>0.1 0.1 0.1 1</diffuse>
					<specular>0.5 0.5 0.5 1</specular>
					<emissive>0.05 0.05 0.05 1</emissive>
				</material>
			</visual>
			<gravity>1</gravity>
			<velocity_decay>
				<linear>0</linear>
				<angular>0</angular>
			</velocity_decay>
			<self_collide>0</self_collide>
		</link>
		<joint name='back_left_wheel_joint' type='revolute'>
			<child>back_left_wheel</child>
			<parent>body</parent>
			<axis>
				<xyz>0 1 0</xyz>
				<dynamics/>
			</axis>
		</joint>
		<link name='back_right_wheel'>
			<pose>-1.227 -0.47558 0.300 0 0 0</pose>
			<inertial>
				<pose>-1.4894e-07 -0.19645 1.3751e-07 0 -0 0</pose>
				<mass>333.36</mass>
				<inertia>
					<ixx>17.0765</ixx>
					<ixy>-1.87699e-05</ixy>
					<ixz>1.23277e-05</ixz>
					<iyy>29.6158</iyy>
					<iyz>3.1578e-05</iyz>
					<izz>17.0765</izz>
				</inertia>
			</inertial>
			<collision name='back_right_wheel_collision'>
				<pose>0 -0.2 0 1.5708 -0 0</pose>
				<geometry>
					<cylinder>
						<length>0.4</length>
						<radius>0.4</radius>
					</cylinder>
				</geometry>
				<surface>
					<contact>
						<ode/>
					</contact>
					<friction>
						<ode>
							<mu>1</mu>
							<mu2>1</mu2>
						</ode>
					</friction>
				</surface>
			</collision>
			<visual name='back_right_wheel_visual'>
				<pose>0 0 0 0 -0 0</pose>
				<geometry>
					<mesh>
						<scale>1 1 1</scale>
						<uri>model://bobcat_static_arm/meshes/back_right_wheel.stl</uri>
					</mesh>
				</geometry>
				<material>
					<ambient>0 0 0 1</ambient>
					<diffuse>0.1 0.1 0.1 1</diffuse>
					<specular>0.5 0.5 0.5 1</specular>
					<emissive>0.05 0.05 0.05 1</emissive>
				</material>
			</visual>
			<gravity>1</gravity>
			<velocity_decay>
				<linear>0</linear>
				<angular>0</angular>
			</velocity_decay>
			<self_collide>1</self_collide>
		</link>
		<joint name='back_right_wheel_joint' type='revolute'>
			<child>back_right_wheel</child>
			<parent>body</parent>
			<axis>
				<xyz>0 1 0</xyz>
				<dynamics/>
			</axis>
		</joint>
		<link name='front_left_wheel'>
			<pose>-0.22722 0.47558 0.300 0 0 0</pose>
			<inertial>
				<pose>2.0502e-07 0.19645 -3.6566e-09 0 -0 0</pose>
				<mass>333.358</mass>
				<inertia>
					<ixx>17.0765</ixx>
					<ixy>-4.02019e-05</ixy>
					<ixz>7.57982e-05</ixz>
					<iyy>29.6158</iyy>
					<iyz>-6.64195e-06</iyz>
					<izz>17.0765</izz>
				</inertia>
			</inertial>
			<collision name='front_left_wheel_collision'>
				<pose>0 0.2 0 1.5708 -0 0</pose>
				<geometry>
					<cylinder>
						<length>0.4</length>
						<radius>0.4</radius>
					</cylinder>
				</geometry>
				<surface>
					<contact>
						<ode/>
					</contact>
					<friction>
						<ode>
							<mu>1</mu>
							<mu2>1</mu2>
						</ode>
					</friction>
				</surface>
			</collision>
			<visual name='front_left_wheel_visual'>
				<pose>0 0 0 0 -0 0</pose>
				<geometry>
					<mesh>
						<scale>1 1 1</scale>
						<uri>model://bobcat_static_arm/meshes/front_left_wheel.stl</uri>
					</mesh>
				</geometry>
				<material>
					<ambient>0 0 0 1</ambient>
					<diffuse>0.1 0.1 0.1 1</diffuse>
					<specular>0.5 0.5 0.5 1</specular>
					<emissive>0.05 0.05 0.05 1</emissive>
				</material>
			</visual>
			<gravity>1</gravity>
			<velocity_decay>
				<linear>0</linear>
				<angular>0</angular>
			</velocity_decay>
			<self_collide>1</self_collide>
		</link>
		<joint name='front_left_wheel_joint' type='revolute'>
			<child>front_left_wheel</child>
			<parent>body</parent>
			<axis>
				<xyz>0 1 0</xyz>
				<dynamics/>
			</axis>
		</joint>
		<link name='front_right_wheel'>
			<pose>-0.22722 -0.47558 0.300 0 0 0</pose>
			<inertial>
				<pose>-2.0519e-07 -0.19645 -4.3198e-09 0 -0 0</pose>
				<mass>333.358</mass>
				<inertia>
					<ixx>17.0765</ixx>
					<ixy>-3.66954e-05</ixy>
					<ixz>-7.5494e-05</ixz>
					<iyy>29.6158</iyy>
					<iyz>1.22098e-05</iyz>
					<izz>17.0765</izz>
				</inertia>
			</inertial>
			<collision name='front_right_wheel_collision'>
				<pose>0 -0.2 0 1.5708 -0 0</pose>
				<geometry>
					<cylinder>
						<length>0.4</length>
						<radius>0.4</radius>
					</cylinder>
				</geometry>
				<surface>
					<contact>
						<ode/>
					</contact>
					<friction>
						<ode>
							<mu>1</mu>
							<mu2>1</mu2>
						</ode>
					</friction>
				</surface>
			</collision>
			<visual name='front_right_wheel_visual'>
				<pose>0 0 0 0 -0 0</pose>
				<geometry>
					<mesh>
						<scale>1 1 1</scale>
						<uri>model://bobcat_static_arm/meshes/front_right_wheel.stl</uri>
					</mesh>
				</geometry>
				<material>
					<ambient>0 0 0 1</ambient>
					<diffuse>0.1 0.1 0.1 1</diffuse>
					<specular>0.5 0.5 0.5 1</specular>
					<emissive>0.05 0.05 0.05 1</emissive>
				</material>
			</visual>
			<gravity>1</gravity>
			<velocity_decay>
				<linear>0</linear>
				<angular>0</angular>
			</velocity_decay>
			<self_collide>1</self_collide>
		</link>
		<joint name='front_right_wheel_joint' type='revolute'>
			<child>front_right_wheel</child>
			<parent>body</parent>
			<axis>
				<xyz>0 1 0</xyz>
				<dynamics/>
			</axis>
		</joint>
		<plugin name="bobcat_drive_control" filename="libbobcat_drive_plugin.so">
		      <IP>127.0.0.1</IP>
		      <PortUDPLP>4660</PortUDPLP>
      		      <PortUDPRP>5355</PortUDPRP>
    		</plugin>

		<plugin name="joint_state_publisher" filename="libgazebo_ros_joint_state_publisher.so">
			<robotNamespace>/Sahar</robotNamespace>
			<jointName>back_left_wheel_joint, back_right_wheel_joint, front_left_wheel_joint, front_right_wheel_joint</jointName>
			<updateRate>50.0</updateRate>
			<alwaysOn>true</alwaysOn>
		</plugin>
	</model>
</sdf>
