<?xml version="1.0"?>
<robot
  name="Sahar">
  <link
    name="body">
    <inertial>
      <origin
        xyz="-0.890714078986241 0.000176354230843794 0.525609535873677"
        rpy="0 0 0" />
      <mass
        value="2112.2632057713" />
      <inertia
        ixx="330.451427275626"
        ixy="0.1258707518716585"
        ixz="-85.8115001993615"
        iyy="750.047261721269"
        iyz="-0.001202697501709275"
        izz="817.534535636717" />
    </inertial>
    <visual>
      <origin
        xyz="0 0 0"
        rpy="0 0 0" />
      <geometry>
        <mesh
          filename="package://bobcat/meshes/body.STL" />
      </geometry>
      <material
        name="">
        <color
          rgba="0.647058823529412 0.619607843137255 0.588235294117647 0.5" />
      </material>
    </visual>
    <collision>
      <origin
        xyz="0 0 0"
        rpy="0 0 0" />
      <geometry>
        <mesh
          filename="package://bobcat/meshes/body.STL" />
      </geometry>
    </collision>
  </link>

  <link
    name="base_arm">
    <inertial>
      <origin
        xyz="0.066509 1.9771E-12 0.25686"
        rpy="0 0 0" />
      <mass
        value="194.91" />
      <inertia
        ixx="50.76"
        ixy="-2.9264E-11"
        ixz="0.66798"
        iyy="4.8017"
        iyz="7.0403E-12"
        izz="47.388" />
    </inertial>
    <visual>
      <origin
        xyz="0 0 0"
        rpy="0 0 0" />
      <geometry>
        <mesh
          filename="package://bobcat/meshes/base_arm.STL" />
      </geometry>
      <material
        name="">
        <color
          rgba="0.64706 0.61961 0.58824 1" />
      </material>
    </visual>
    <collision>
      <origin
        xyz="0 0 0"
        rpy="0 0 0" />
      <geometry>
        <mesh
          filename="package://bobcat/meshes/base_arm.STL" />
      </geometry>
    </collision>
  </link>
  <joint
    name="base_arm_joint"
    type="revolute">
    <origin
      xyz="-1.9776 0 1.1773"
      rpy="0 2.1164E-16 0" />
    <parent
      link="body" />
    <child
      link="base_arm" />
    <axis
      xyz="0 1 0" />
    <limit
      lower="-1.57"
      upper="1.57"
      effort="1000000"
      velocity="100" />
  </joint>
  <link
    name="main_arm">
    <inertial>
      <origin
        xyz="1.1865 -4.0206E-07 -0.60466"
        rpy="0 0 0" />
      <mass
        value="369.05" />
      <inertia
        ixx="133.74"
        ixy="0.00012791"
        ixz="-68.753"
        iyy="216.24"
        iyz="-4.6593E-05"
        izz="268.55" />
    </inertial>
    <visual>
      <origin
        xyz="0 0 0"
        rpy="0 0 0" />
      <geometry>
        <mesh
          filename="package://bobcat/meshes/main_arm.STL" />
      </geometry>
      <material
        name="">
        <color
          rgba="0.89412 0.91373 0.92941 1" />
      </material>
    </visual>
    <collision>
      <origin
        xyz="0 0 0"
        rpy="0 0 0" />
      <geometry>
        <mesh
          filename="package://bobcat/meshes/main_arm.STL" />
      </geometry>
    </collision>
  </link>
  <joint
    name="main_arm_joint"
    type="revolute">
    <origin
      xyz="0.22304 0 0.5262"
      rpy="0 -2.1164E-16 0" />
    <parent
      link="base_arm" />
    <child
      link="main_arm" />
    <axis
      xyz="0 1 0" />
    <limit
      lower="-1.57"
      upper="1.57"
      effort="1000000"
      velocity="100" />
  </joint>
  <link
    name="supporter">
    <inertial>
      <origin
        xyz="0.51341 -4.9085E-16 -0.060486"
        rpy="0 0 0" />
      <mass
        value="65.29" />
      <inertia
        ixx="16.898"
        ixy="-2.3004E-13"
        ixz="-0.76501"
        iyy="6.6127"
        iyz="-2.4072E-13"
        izz="23.301" />
    </inertial>
    <visual>
      <origin
        xyz="0 0 0"
        rpy="0 0 0" />
      <geometry>
        <mesh
          filename="package://bobcat/meshes/supporter.STL" />
      </geometry>
      <material
        name="">
        <color
          rgba="0.64706 0.61961 0.58824 1" />
      </material>
    </visual>
    <collision>
      <origin
        xyz="0 0 0"
        rpy="0 0 0" />
      <geometry>
        <mesh
          filename="package://bobcat/meshes/supporter.STL" />
      </geometry>
    </collision>
  </link>
  <joint
    name="supporter_joint"
    type="revolute">
    <origin
      xyz="0.39771 0 -0.89486"
      rpy="0 8.0491E-16 0" />
    <parent
      link="main_arm" />
    <child
      link="supporter" />
    <axis
      xyz="0 1 0" />
    <limit
      lower="-0.2"
      upper="1.5"
      effort="1000000"
      velocity="100" />
  </joint>

  <link
    name="loader">
    <inertial>
      <origin
        xyz="0.37894 2.192E-15 0.067409"
        rpy="0 0 0" />
      <mass
        value="98.03" />
      <inertia
        ixx="29.346"
        ixy="0"
        ixz="-1.55"
        iyy="9.25"
        iyz="0"
        izz="32.05" />
    </inertial>
    <visual>
      <origin
        xyz="0 0 0"
        rpy="0 0 0" />
      <geometry>
        <mesh
          filename="package://bobcat/meshes/loader.STL" />
      </geometry>
      <material
        name="">
        <color
          rgba="0.89412 0.91373 0.92941 1" />
      </material>
    </visual>
    <collision>
      <origin
        xyz="0 0 0"
        rpy="0 0 0" />
      <geometry>
        <mesh
          filename="package://bobcat/meshes/loader.STL" />
      </geometry>
    </collision>
  </link>
  <joint
    name="loader_joint"
    type="revolute">
    <origin
      xyz="2.0984 0 -1.557"
      rpy="0 2.5362E-15 0" />
    <parent
      link="main_arm" />
    <child
      link="loader" />
    <axis
      xyz="0 1 0" />
    <limit
      lower="0"
      upper="1.57"
      effort="1000000"
      velocity="100" />
  </joint>
  <link
    name="brackets">
    <inertial>
      <origin
        xyz="0.14213 -1.579E-16 0.33109"
        rpy="0 0 0" />
      <mass
        value="12.857" />
      <inertia
        ixx="2.9339"
        ixy="-2.9653E-16"
        ixz="0.23718"
        iyy="0.67251"
        iyz="3.0656E-16"
        izz="2.738" />
    </inertial>
    <visual>
      <origin
        xyz="0 0 0"
        rpy="0 0 0" />
      <geometry>
        <mesh
          filename="package://bobcat/meshes/brackets.STL" />
      </geometry>
      <material
        name="">
        <color
          rgba="0.79216 0.81961 0.93333 1" />
      </material>
    </visual>
    <collision>
      <origin
        xyz="0 0 0"
        rpy="0 0 0" />
      <geometry>
        <mesh
          filename="package://bobcat/meshes/brackets.STL" />
      </geometry>
    </collision>
  </link>
  <joint
    name="brackets_joint"
    type="revolute">
    <origin
      xyz="0.33833 0 0.49449"
      rpy="0 0 0" />
    <parent
      link="loader" />
    <child
      link="brackets" />
    <axis
      xyz="0 1 0" />
    <limit
      lower="0"
      upper="1"
      effort="1000000"
      velocity="1000000" />
  </joint>

<link
    name="cabin">
    <inertial>
      <origin
        xyz="-0.70338 -5.738E-08 0.72817"
        rpy="0 0 0" />
      <mass
        value="496.33" />
      <inertia
        ixx="138.34"
        ixy="-1.1017E-06"
        ixz="8.4609"
        iyy="150.8"
        iyz="-2.3341E-06"
        izz="117.01" />
    </inertial>
    <visual>
      <origin
        xyz="0 0 0"
        rpy="0 0 0" />
      <geometry>
        <mesh
          filename="package://bobcat/meshes/cabin.STL" />
      </geometry>
      <material
        name="">
        <color
          rgba="0.64706 0.61961 0.58824 1" />
      </material>
    </visual>
    <collision>
      <origin
        xyz="0 0 0"
        rpy="0 0 0" />
      <geometry>
        <mesh
          filename="package://bobcat/meshes/cabin.STL" />
      </geometry>
    </collision>
  </link>
  <joint
    name="cabin_joint"
    type="fixed">
    <origin
      xyz="-0.11317 0 0.61042"
      rpy="0 8.0491E-16 0" />
    <parent
      link="body" />
    <child
      link="cabin" />
    <axis
      xyz="0 1 0" />
  </joint>
  <link
    name="Ibeo_link">
    <inertial>
      <origin
        xyz="-0.50455 -0.03223 -1.3338"
        rpy="0 0 0" />
      <mass
        value="10.460" />
      <inertia
        ixx="8.1287"
        ixy="0"
        ixz="0.55289"
        iyy="8.9548"
        iyz="0"
        izz="6.4192" />
    </inertial>
    <visual>
      <origin
        xyz="0 0 0"
        rpy="0 0 0" />
      <geometry>
        <mesh
          filename="package://bobcat/meshes/Ibeo.STL" />
      </geometry>
      <material
        name="">
        <color
          rgba="1 1 1 1" />
      </material>
    </visual>
    <collision>
      <origin
        xyz="0 0 0"
        rpy="0 0 0" />
      <geometry>
        <mesh
          filename="package://bobcat/meshes/Ibeo_lite.stl" />
      </geometry>
    </collision>
  </link>
  <joint
    name="Ibeo_joint"
    type="fixed">
    <origin
      xyz="-0.18258 0.03227 1.2493"
      rpy="1.570796327 -5.9328E-16 1.570796327" />
    <parent
      link="cabin" />
    <child
      link="Ibeo_link" />
    <axis
      xyz="0 0 0" />
  </joint>
  <link
    name="left_sick_link">
    <inertial>
      <origin
        xyz="-0.89565 0.58058 -0.24712"
        rpy="0 0 0" />
      <mass
        value="10.642" />
      <inertia
        ixx="5.5107"
        ixy="-0.00022597"
        ixz="0.000019765"
        iyy="4.5364"
        iyz="0.67063"
        izz="6.5674" />
    </inertial>
    <visual>
      <origin
        xyz="0 0 0"
        rpy="0 0 0" />
      <geometry>
        <mesh
          filename="package://bobcat/meshes/left_sick.STL" />
      </geometry>
      <material
        name="">
        <color
          rgba="0.79216 0.81961 0.93333 1" />
      </material>
    </visual>
    <collision>
      <origin
        xyz="0 0 0"
        rpy="0 0 0" />
      <geometry>
        <mesh
          filename="package://bobcat/meshes/left_sick_lite.stl" />
      </geometry>
    </collision>
  </link>
  <joint
    name="left_sick_joint"
    type="fixed">
    <origin
      xyz="-0.21801 0.89557 0.66494"
      rpy="1.5708 0 1.5708" />
    <parent
      link="body" />
    <child
      link="left_sick_link" />
    <axis
      xyz="0 -1 0" />
  </joint>
  <link
    name="right_sick_link">
    <inertial>
      <origin
        xyz="-0.89568 -0.58119 -0.24712"
        rpy="0 0 0" />
      <mass
        value="10.642" />
      <inertia
        ixx="5.5107"
        ixy="-0.00022597"
        ixz="-0.000019765"
        iyy="4.5364"
        iyz="-0.67063"
        izz="6.5674" />
    </inertial>
    <visual>
      <origin
        xyz="0 0 0"
        rpy="0 0 0" />
      <geometry>
        <mesh
          filename="package://bobcat/meshes/right_sick.STL" />
      </geometry>
      <material
        name="">
        <color
          rgba="0.79216 0.81961 0.93333 1" />
      </material>
    </visual>
    <collision>
      <origin
        xyz="0 0 0"
        rpy="0 0 0" />
      <geometry>
        <mesh
          filename="package://bobcat/meshes/right_sick_lite.stl" />
      </geometry>
    </collision>
  </link>
  <joint
    name="right_sick_joint"
    type="fixed">
    <origin
      xyz="-0.2174 -0.89576 0.66494"
      rpy="1.5708 0 1.5708" />
    <parent
      link="body" />
    <child
      link="right_sick_link" />
    <axis
      xyz="0 -1 0" />
  </joint>
  <link
    name="front_sick_link">
    <inertial>
      <origin
        xyz="-0.89885 0.00019572 0.43638"
        rpy="0 0 0" />
      <mass
        value="4.5223" />
      <inertia
        ixx="0.77018"
        ixy="0.00031619"
        ixz="-0.20002"
        iyy="1.747"
        iyz="-0.0000281"
        izz="1.9059" />
    </inertial>
    <visual>
      <origin
        xyz="0 0 0"
        rpy="0 0 0" />
      <geometry>
        <mesh
          filename="package://bobcat/meshes/front_sick.STL" />
      </geometry>
      <material
        name="">
        <color
          rgba="0.64706 0.61961 0.58824 1" />
      </material>
    </visual>
    <collision>
      <origin
        xyz="0 0 0"
        rpy="0 0 0" />
      <geometry>
        <mesh
          filename="package://bobcat/meshes/front_sick_lite.stl" />
      </geometry>
    </collision>
  </link>
  <joint
    name="front_sick_joint"
    type="fixed">
    <origin
      xyz="0.26113 0 0.048493"
      rpy="1.5708 0 1.5708" />
    <parent
      link="body" />
    <child
      link="front_sick_link" />
    <axis
      xyz="0 1 0" />
  </joint>
  <link
    name="supporter_hinge">
    <inertial>
      <origin
        xyz="-6.2676E-16 -2.2204E-16 1.1102E-16"
        rpy="0 0 0" />
      <mass
        value="1.6828" />
      <inertia
        ixx="0.00017338"
        ixy="-6.163E-33"
        ixz="-1.9205E-35"
        iyy="0.42748"
        iyz="6.6217E-37"
        izz="0.42748" />
    </inertial>
    <visual>
      <origin
        xyz="0 0 0"
        rpy="0 0 0" />
      <geometry>
        <mesh
          filename="package://bobcat/meshes/supporter_hinge.STL" />
      </geometry>
      <material
        name="">
        <color
          rgba="0.64706 0.61961 0.58824 1" />
      </material>
    </visual>
    <collision>
      <origin
        xyz="0 0 0"
        rpy="0 0 0" />
      <geometry>
        <mesh
          filename="package://bobcat/meshes/supporter_hinge.STL" />
      </geometry>
    </collision>
  </link>
  <joint
    name="supporter_hinge_joint"
    type="fixed">
    <origin
      xyz="-0.31547 0 0.68593"
      rpy="1.5708 0 1.5708" />
    <parent
      link="body" />
    <child
      link="supporter_hinge" />
    <axis
      xyz="1 0 0" />
  </joint>


<!-- add by Or-->



<link
    name="right_wheel">
    <inertial>
      <origin
        xyz="-0.725 0 0"
        rpy="0 0 0" />
      <mass
        value="5.4973106115847" />
      <inertia
        ixx="0.0331571866222433"
        ixy="4.74591956306214E-11"
        ixz="-7.11777670092528E-12"
        iyy="0.0750084493873789"
        iyz="-3.13569619781006E-12"
        izz="0.0750084493853636" />
    </inertial>
    <visual>
      <origin
        xyz="0 0 0"
        rpy="0 0 0" />
      <geometry>
        <mesh
          filename="package://bobcat_gazebo/meshes_bobcat_with_boggies/right_wheel.STL" />
      </geometry>
      <material
        name="">
        <color
          rgba="0.792156862745098 0.819607843137255 0.933333333333333 1" />
      </material>
    </visual>


    <collision>
      <origin
        xyz="-0.15 0 0"
        rpy="1.5708 1.5708 0" />
      <geometry>
        <box size="0.15 0.3 0.15"/> 
         </geometry>
    </collision>

  <collision>
      <origin
        xyz="-0.15 0 0"
        rpy="0 0.8 1.5708" />
      <geometry>
        <box size="0.15 0.3 0.15"/> 
         </geometry>
    </collision>

    <collision>
      <origin
        xyz="0.091 0 0"
        rpy="0 1.5708 0" />
      <geometry>
        <cylinder length="0.1" radius="0.3" 

          />

      </geometry>
    </collision>

    <collision>
      <origin
        xyz="-0.35 0 0"
        rpy="0 1.5708 0" />
      <geometry>
        <cylinder length="0.02" radius="0.3" 
          />

      </geometry>
    </collision>

  </link>
  <joint
    name="right_wheel_joint"
    type="continuous">
    <origin
      xyz="-1.109 -1 0.535"
      rpy="1.5708 0 -1.5708" />
    <parent
      link="body" />
    <child
      link="right_wheel" />
    <axis
      xyz="-1 0 0" />

  </joint>
  


<!--  -->

<link
    name="front_right_boggie">
    <inertial>
      <origin
        xyz="-0.072989545637314 0 0"
        rpy="0 0 0" />
      <mass
        value="3.90657046473891" />
      <inertia
        ixx="0.0402750730112348"
        ixy="-1.95495404144972E-19"
        ixz="-3.8871286104849E-19"
        iyy="0.0265900500882693"
        iyz="6.78191046434944E-18"
        izz="0.0265900500882693" />
    </inertial>
    <visual>
      <origin
        xyz="0 0 0"
        rpy="0 0 0" />
      <geometry>
        <mesh
          filename="package://bobcat_gazebo/meshes_bobcat_with_boggies/front_right_boggie.STL" />
      </geometry>
      <material
        name="">
        <color
          rgba="0.792156862745098 0.819607843137255 0.933333333333333 1" />
      </material>
    </visual>


    <collision>
      <origin
        xyz="-0.1 0 0"
        rpy="0 1.5708 0" />
      <geometry>
        <cylinder length="0.5" radius="0.14" 
          />
      </geometry>
    </collision>

    <collision>
      <origin
        xyz="0.12 0 0"
        rpy="0 1.5708 0" />
      <geometry>
        <cylinder length="0.02" radius="0.17" 
          />
      </geometry>
    </collision>

    <collision>
      <origin
        xyz="-0.265 0 0"
        rpy="0 1.5708 0" />
      <geometry>
        <cylinder length="0.02" radius="0.17" 
          />

      </geometry>
    </collision>

  </link>
  <joint
    name="front_right_boggie_joint"
    type="continuous">
    <origin
      xyz="-0.183 -0.92 0.069"
      rpy="1.5708 0 -1.5708" />
    <parent
      link="body" />
    <child
      link="front_right_boggie" />
    <axis
      xyz="-1 0 0" />

  </joint>
  <link
    name="back_right_boggie">
    <inertial>
      <origin
        xyz="-0.0729895456373141 0 0"
        rpy="0 0 0" />
      <mass
        value="3.90657046473891" />
      <inertia
        ixx="0.0402750730112348"
        ixy="-6.18564037846812E-22"
        ixz="4.99160466967745E-18"
        iyy="0.0265900500882693"
        iyz="3.6043016557644E-20"
        izz="0.0265900500882693" />
    </inertial>
    <visual>
      <origin
        xyz="0 0 0"
        rpy="0 0 0" />
      <geometry>
        <mesh
          filename="package://bobcat_gazebo/meshes_bobcat_with_boggies/back_right_boggie.STL" />
      </geometry>
      <material
        name="">
        <color
          rgba="0.792156862745098 0.819607843137255 0.933333333333333 1" />
      </material>
    </visual>


    <collision>
      <origin
        xyz="-0.1 0 0"
        rpy="0 1.5708 0" />
      <geometry>
        <cylinder length="0.5" radius="0.14" 
          />
      </geometry>
    </collision>

     <collision>
      <origin
        xyz="0.12 0 0"
        rpy="0 1.5708 0" />
      <geometry>
        <cylinder length="0.02" radius="0.17" 
          />
      </geometry>
    </collision>

    <collision>
      <origin
        xyz="-0.265 0 0"
        rpy="0 1.5708 0" />
      <geometry>
        <cylinder length="0.02" radius="0.17" 
          />

      </geometry>
    </collision>

  </link>
  <joint
    name="back_right_boggie_joint"
    type="continuous">
    <origin
      xyz="-1.47 -0.92 0.093"
      rpy="1.5708 0 -1.5708" />
    <parent
      link="body" />
    <child
      link="back_right_boggie" />
    <axis
      xyz="-1 0 0" />

  </joint>
<!-- end of right side-->

<!-- begining of left side-->

 <link
    name="left_wheel">
    <inertial>
      <origin
        xyz="0.142856176942976 -3.81439602126221E-11 5.83338988224824E-10"
        rpy="0 0 0" />
      <mass
        value="5.49731061158471" />
      <inertia
        ixx="0.0331571866215895"
        ixy="-3.76042672089463E-11"
        ixz="3.34298670147488E-11"
        iyy="0.0750084493824547"
        iyz="4.71480493535736E-13"
        izz="0.0750084493896341" />
    </inertial>
    <visual>
      <origin
        xyz="0 0 0"
        rpy="0 0 0" />
      <geometry>
        <mesh
          filename="package://bobcat_gazebo/meshes_bobcat_with_boggies/left_wheel.STL" />
      </geometry>
      <material
        name="">
        <color
          rgba="0.792156862745098 0.819607843137255 0.933333333333333 1" />
      </material>
    </visual>



   <collision>
      <origin
        xyz="0.15 0 0"
        rpy="1.5708 1.5708 0" />
      <geometry>
        <box size="0.15 0.3 0.15"/> 
         </geometry>
    </collision>

  <collision>
      <origin
        xyz="0.15 0 0"
        rpy="0 0.8 1.5708" />
      <geometry>
        <box size="0.15 0.3 0.15"/> 
         </geometry>
    </collision>

    <collision>
      <origin
        xyz="-0.091 0 0"
        rpy="0 1.5708 0" />
      <geometry>
        <cylinder length="0.1" radius="0.3" 
          />

      </geometry>
    </collision>

    <collision>
      <origin
        xyz="0.35 0 0"
        rpy="0 1.5708 0" />
      <geometry>
        <cylinder length="0.02" radius="0.3" 
          />

      </geometry>
    </collision>

  </link>
  <joint
    name="left_wheel_joint"
    type="continuous">
    <origin
      xyz="-1.109 1 0.535"
      rpy="-1.1939 3.4487E-16 -1.5708" />
    <parent
      link="body" />
    <child
      link="left_wheel" />
    <axis
      xyz="-1 0 0" />

  </joint>

<!--  -->

<link
    name="front_left_boggie">
    <inertial>
      <origin
        xyz="-0.072989545637314 2.22044604925031E-16 0"
        rpy="0 0 0" />
      <mass
        value="3.90657046473891" />
      <inertia
        ixx="0.0402750730112348"
        ixy="-7.48894709617106E-18"
        ixz="-5.75771465104378E-19"
        iyy="0.0265900500882693"
        iyz="1.19262238973405E-18"
        izz="0.0265900500882693" />
    </inertial>
    <visual>
      <origin
        xyz="0 0 0"
        rpy="0 0 0" />
      <geometry>
        <mesh
          filename="package://bobcat_gazebo/meshes_bobcat_with_boggies/front_left_boggie.STL" />
      </geometry>
      <material
        name="">
        <color
          rgba="0.792156862745098 0.819607843137255 0.933333333333333 1" />
      </material>
    </visual>

    <collision>
      <origin
        xyz="0.1 0 0"
        rpy="0 1.5708 0" />
      <geometry>
        <cylinder length="0.5" radius="0.14" 
          />
      </geometry>
    </collision>


    <collision>
      <origin
        xyz="0.12 0 0"
        rpy="0 1.5708 0" />
      <geometry>
        <cylinder length="0.02" radius="0.17" 
          />
      </geometry>
    </collision>

    <collision>
      <origin
        xyz="-0.265 0 0"
        rpy="0 1.5708 0" />
      <geometry>
        <cylinder length="0.02" radius="0.17" 
          />

      </geometry>
    </collision>


  </link>
  <joint
    name="front_left_boggie_joint"
    type="continuous">
    <origin
     xyz="-0.183 0.92 0.069"
      rpy="-0.022723 -2.5348E-29 1.5708" />
    <parent
      link="body" />
    <child
      link="front_left_boggie" />
    <axis
      xyz="1 0 0" />

  </joint>
  <link
    name="back_left_boggie">
    <inertial>
      <origin
        xyz="-0.072989545637314 0 0"
        rpy="0 0 0" />
      <mass
        value="3.90657046473891" />
      <inertia
        ixx="0.0402750730112348"
        ixy="8.65586547893248E-18"
        ixz="-2.0885755126839E-19"
        iyy="0.0265900500882693"
        iyz="1.30104260698261E-18"
        izz="0.0265900500882693" />
    </inertial>
    <visual>
      <origin
        xyz="0 0 0"
        rpy="0 0 0" />
      <geometry>
        <mesh
          filename="package://bobcat_gazebo/meshes_bobcat_with_boggies/back_left_boggie.STL" />
      </geometry>
      <material
        name="">
        <color
          rgba="0.792156862745098 0.819607843137255 0.933333333333333 1" />
      </material>
    </visual>


    <collision>
      <origin
        xyz="0.1 0 0"
        rpy="0 1.5708 0" />
      <geometry>
        <cylinder length="0.5" radius="0.14" 
          />
      </geometry>
    </collision>

    <collision>
      <origin
        xyz="0.12 0 0"
        rpy="0 1.5708 0" />
      <geometry>
        <cylinder length="0.02" radius="0.17" 
          />
      </geometry>
    </collision>

    <collision>
      <origin
        xyz="-0.265 0 0"
        rpy="0 1.5708 0" />
      <geometry>
        <cylinder length="0.02" radius="0.17" 
          />

      </geometry>
    </collision>

  </link>
  <joint
    name="back_left_boggie_joint"
    type="continuous">
    <origin
      xyz="-1.47 0.92 0.093"
      rpy="-0.022723 -2.5348E-29 1.5708" />
    <parent
      link="body" />
    <child
      link="back_left_boggie" />
    <axis
      xyz="-1 0 0" />

  </joint>

<!-- end of edd by or-->



 <!-- Transmissions for ROS Control -->
  <transmission name="tran1">
    <type>transmission_interface/SimpleTransmission</type>
    <joint name="right_wheel_joint">
      <hardwareInterface>EffortJointInterface</hardwareInterface>
    </joint>
    <actuator name="motor1">
      <mechanicalReduction>1</mechanicalReduction>
    </actuator>
  </transmission>

  <transmission name="tran2">
    <type>transmission_interface/SimpleTransmission</type>
    <joint name="left_wheel_joint">
      <hardwareInterface>EffortJointInterface</hardwareInterface>
    </joint>
    <actuator name="motor2">
      <mechanicalReduction>1</mechanicalReduction>
    </actuator>
  </transmission>

  <transmission name="tran5">
    <type>transmission_interface/SimpleTransmission</type>
    <joint name="base_arm_joint">
      <hardwareInterface>EffortJointInterface</hardwareInterface>
    </joint>
    <actuator name="motor5">
      <mechanicalReduction>1</mechanicalReduction>
    </actuator>
  </transmission>

  <transmission name="tran6">
    <type>transmission_interface/SimpleTransmission</type>
    <joint name="main_arm_joint">
      <hardwareInterface>EffortJointInterface</hardwareInterface>
    </joint>
    <actuator name="motor6">
      <mechanicalReduction>1</mechanicalReduction>
    </actuator>
  </transmission>

  <transmission name="tran8">
    <type>transmission_interface/SimpleTransmission</type>
    <joint name="supporter_joint">
      <hardwareInterface>EffortJointInterface</hardwareInterface>
    </joint>
    <actuator name="motor8">
      <mechanicalReduction>1</mechanicalReduction>
    </actuator>
  </transmission>

  <transmission name="tran10">
    <type>transmission_interface/SimpleTransmission</type>
    <joint name="loader_joint">
      <hardwareInterface>EffortJointInterface</hardwareInterface>
    </joint>
    <actuator name="motor10">
      <mechanicalReduction>1</mechanicalReduction>
    </actuator>
  </transmission>

  <transmission name="tran12">
    <type>transmission_interface/SimpleTransmission</type>
    <joint name="brackets_joint">
      <hardwareInterface>EffortJointInterface</hardwareInterface>
    </joint>
    <actuator name="motor12">
      <mechanicalReduction>1</mechanicalReduction>
    </actuator>
  </transmission>

  <!-- ros_control plugin -->
  <gazebo>
    <plugin name="gazebo_ros_control" filename="libgazebo_ros_control.so">
      <robotNamespace>/Sahar</robotNamespace>
    </plugin>
  </gazebo>
  <gazebo reference="body">
    <mu1>1</mu1>
    <mu2>1</mu2>
    <selfCollide>true</selfCollide>
    <material>Gazebo/Wood</material>
  </gazebo>

  <gazebo reference="right_wheel">
    <mu1>1000000</mu1>
    <mu2>1000000</mu2>
    <selfCollide>true</selfCollide>
    <material>Gazebo/Grey</material>
  </gazebo>

  <gazebo reference="left_wheel">
    <mu1>1000000</mu1>
    <mu2>1000000</mu2>
    <selfCollide>true</selfCollide>
    <material>Gazebo/Grey</material>
  </gazebo>


  <gazebo reference="base_arm">
    <material>Gazebo/Grey</material>
  </gazebo>
  <gazebo reference="main_arm">
    <material>Gazebo/PaintedWall</material>
  </gazebo>

  <gazebo reference="supporter">
    <mu1>1</mu1>
    <mu2>1</mu2>
    <selfCollide>true</selfCollide>
    <material>Gazebo/GreyTransparent</material>
  </gazebo>
  <gazebo reference="front_cylinder">
    <material>Gazebo/BlueTransparent</material>
  </gazebo>
  <gazebo reference="loader">
    <mu1>1</mu1>
    <mu2>1</mu2>
    <selfCollide>true</selfCollide>
    <material>Gazebo/Gold</material>
  </gazebo>
  <gazebo reference="front_shaft">
    <material>Gazebo/Black</material>
  </gazebo>

  <gazebo reference="brackets">
    <mu1>1</mu1>
    <mu2>1</mu2>
    <selfCollide>true</selfCollide>
    <material>Gazebo/Grey</material>
  </gazebo>
  <gazebo reference="Ibeo">
    <material>Gazebo/Grey</material>
  </gazebo>
  <gazebo reference="left_sick">
    <material>Gazebo/Grey</material>
  </gazebo>
  <gazebo reference="right_sick">
    <material>Gazebo/Grey</material>
  </gazebo>
  <gazebo reference="front_sick">
    <material>Gazebo/Grey</material>
  </gazebo>

</robot>

