<?xml version="1.0"?>
<robot name="Sahar">
  <!--<link name="body">
  <inertial>
     <origin xyz="0 0 0.125" rpy="0 0 0"/>>
     <mass value="1"/>
     <inertia ixx="1"  ixy="0"  ixz="0" iyy="1" iyz="0" izz="1" />
   </inertial>
    <visual>
     <origin xyz="0 0 0" rpy="0 0 0" />
     <geometry>
          <mesh filename="package://sdf_models/bobcat_tracked_static_arm/meshes/body.dae"/>
      </geometry>
   </visual>-->
   </link> 
   		<link name='body'>
			<pose>0 0 0.125 0 -0 0</pose>
			<self_collide>1</self_collide>
      <inertial>
        <pose>-0.79545 -0.0 0.68 0 -0 0</pose>
        <mass>2000</mass>
        <inertia>
          <ixx>750</ixx>
          <ixy>0</ixy>
          <ixz>0</ixz>
          <iyy>1200</iyy>
          <iyz>0</iyz>
          <izz>900</izz>
        </inertia>
      </inertial>
			  <visual name='body_visual'>
        <pose>0 0 0 0 0 0</pose>
        <geometry>
          <mesh>
            <scale>1 1 1</scale>
            <uri>model://bobcat_tracked/meshes/body.dae</uri>
          </mesh>
        </geometry>
      </visual>
		</link>
		<link name='base_arm'>
			<pose>-1.9776 0 1.1773 0 0 0</pose>
			<inertial>
				<pose>0.066509 0 0.25686 0 -0 0</pose>
				<mass>400</mass>
				<inertia>
					<ixx>50.76</ixx>
					<ixy>0</ixy>
					<ixz>0.66798</ixz>
					<iyy>4.8017</iyy>
					<iyz>0</iyz>
					<izz>47.388</izz>
				</inertia>
			</inertial>
			<visual name='base_arm_visual'>
				<pose>0 0 0 0 -0 0</pose>
				<geometry>
					<mesh>
						<scale>1 1 1</scale>
						<uri>model://bobcat_tracked/meshes/base_arm.STL</uri>
					</mesh>
				</geometry>
				<material>
					<script>
						<name>Gazebo/Grey</name>
						<uri>__default__</uri>
					</script>
				</material>
			</visual>
			<gravity>1</gravity>
			<velocity_decay>
				<linear>0</linear>
				<angular>0</angular>
			</velocity_decay>
			<self_collide>0</self_collide>
		</link>
		<joint name='base_arm_joint' type='revolute'>
			<child>base_arm</child>
			<parent>body</parent>
			<axis>
				<xyz>0 1 0</xyz>
				<!--<dynamics><friction>1</friction></dynamics>-->
			</axis>
		</joint>
		<link name='main_arm'>
			<pose>-1.75456 0 1.7035 0 -0 0</pose>
			<inertial>
				<pose>1.1865 0 -0.60466 0 -0 0</pose>
				<mass>300</mass>
				<inertia>
					<ixx>133.74</ixx>
					<ixy>0</ixy>
					<ixz>-68.753</ixz>
					<iyy>216.24</iyy>
					<iyz>0</iyz>
					<izz>268.55</izz>
				</inertia>
			</inertial>
			<visual name='main_arm_visual'>
				<pose>0 0 0 0 -0 0</pose>
				<geometry>
					<mesh>
						<scale>1 1 1</scale>
						<uri>model://bobcat_tracked/meshes/main_arm.STL</uri>
					</mesh>
				</geometry>
				<material>
          <diffuse>0.9 0.9 0.89 1</diffuse>
          <ambient>0.85 0.85 0.78 1</ambient>
				</material>
			</visual>
			<gravity>1</gravity>
			<velocity_decay>
				<linear>0</linear>
				<angular>0</angular>
			</velocity_decay>
			<self_collide>0</self_collide>
		</link>
		<joint name='main_arm_joint' type='revolute'>
			<child>main_arm</child>
			<parent>base_arm</parent>
			<axis>
				<xyz>0 1 0</xyz>
				<!--<dynamics><friction>1</friction></dynamics>-->
			</axis>
		</joint>
		<link name='loader'>
			<pose>0.34384 0 0.1465 0 0 0</pose>
			<inertial>
				<pose>0.37894 0 0.067409 0 -0 0</pose>
				<mass>98.03</mass>
				<inertia>
					<ixx>29.346</ixx>
					<ixy>0</ixy>
					<ixz>-1.55</ixz>
					<iyy>9.25</iyy>
					<iyz>0</iyz>
					<izz>32.05</izz>
				</inertia>
			</inertial>
			<visual name='loader_visual'>
				<pose>0 0 0 0 -0 0</pose>
				<geometry>
					<mesh>
						<scale>1 1 1</scale>
						<uri>model://bobcat_tracked/meshes/loader.STL</uri>
					</mesh>
				</geometry>
				<material>
          <diffuse>0.2 0.2 0.2 1</diffuse>
          <ambient>0.2 0.2 0.2 1</ambient>
				</material>
			</visual>
			<gravity>1</gravity>
			<velocity_decay>
				<linear>0</linear>
				<angular>0</angular>
			</velocity_decay>
			<self_collide>1</self_collide>
		</link>
		<joint name='loader_joint' type='revolute'>
			<child>loader</child>
			<parent>main_arm</parent>
			<axis>
				<xyz>0 -1 0</xyz>
				<limit>
					<lower>-0.5</lower>
					<upper>0.5</upper>
					<!-- <lower>-0.5</lower> -->
					<effort>1e+06</effort>
					<velocity>100</velocity>
				</limit>
				<!--<dynamics><friction>1</friction></dynamics>-->
			</axis>
		</joint>
		<link name='brackets'>
			<pose>0.68217 0 0.64099 0 0 0</pose>
			<inertial>
				<pose>0.14213 0 0.33109 0 -0 0</pose>
				<mass>12.857</mass>
				<inertia>
					<ixx>2.9339</ixx>
					<ixy>0</ixy>
					<ixz>0.23718</ixz>
					<iyy>0.67251</iyy>
					<iyz>0</iyz>
					<izz>2.738</izz>
				</inertia>
			</inertial>
			<visual name='brackets_visual'>
				<pose>0 0 0 0 -0 0</pose>
				<geometry>
					<mesh>
						<scale>1 1 1</scale>
						<uri>model://bobcat_tracked/meshes/brackets.STL</uri>
					</mesh>
				</geometry>
				<material>
          <diffuse>0.1 0.1 0.1 1</diffuse>
          <ambient>0.1 0.1 0.1 1</ambient>
				</material>
			</visual>
			<gravity>1</gravity>
			<velocity_decay>
				<linear>0</linear>
				<angular>0</angular>
			</velocity_decay>
			<self_collide>1</self_collide>
		</link>
		<joint name='brackets_joint' type='revolute'>
			<child>brackets</child>
			<parent>loader</parent>
			<axis>
				<xyz>0 1 0</xyz>
				<limit>
					<lower>-0.5</lower>
					<upper>1</upper>
					<effort>1e+06</effort>
					<velocity>1e+06</velocity>
				</limit>
				<!--<dynamics><friction>1</friction></dynamics>-->
			</axis>
		</joint>
		<link name='supporter'>
			<pose>-1.35685 0 0.80864 0 -0.12 0</pose>
			<inertial>
				<pose>0.51341 0 -0.060486 0 -0 0</pose>
				<mass>30</mass>
				<inertia>
					<ixx>16.898</ixx>
					<ixy>0</ixy>
					<ixz>0</ixz>
					<iyy>6.6127</iyy>
					<iyz>0</iyz>
					<izz>23.301</izz>
				</inertia>
			</inertial>
			<visual name='supporter_visual'>
				<pose>0 0 0 0 -0 0</pose>
				<geometry>
					<mesh>
						<scale>1 1 1</scale>
						<uri>model://bobcat_tracked/meshes/supporter.STL</uri>
					</mesh>
				</geometry>
				<material>
          <diffuse>0.8 0.1 0.1 1</diffuse>
          <ambient>0.8 0.1 0.1 1</ambient>
				</material>
			</visual>
			<gravity>1</gravity>
			<velocity_decay>
				<linear>0</linear>
				<angular>0</angular>
			</velocity_decay>
			<self_collide>1</self_collide>
		</link>
		<joint name='supporter_joint' type='revolute'>
			<child>supporter</child>
			<parent>main_arm</parent>
			<axis>
				<xyz>0 1 0</xyz>
				<!--<dynamics><friction>1</friction></dynamics>-->
			</axis>
		</joint>
		<joint name='supporter_joint2' type='revolute'>
			<pose>1.04 0 -0.122 0 0 0</pose>
			<child>supporter</child>
			<parent>body</parent>
			<axis>
				<xyz>0 1 0</xyz>
				<!--<dynamics><friction>1</friction></dynamics>-->
			</axis>
		</joint>
 <!--HYDRAULICS-->
		<link name='Hydraulic_bottom'>
			<pose>-1.781 0 0.393 0 0.34907 0</pose>
			<inertial>
				<pose>0 0 0.5 0 -0 0</pose>
				<mass>65.29</mass>
				<inertia>
					<ixx>10</ixx>
					<ixy>0</ixy>
					<ixz>0</ixz>
					<iyy>10</iyy>
					<iyz>0</iyz>
					<izz>1</izz>
				</inertia>
			</inertial>
			<self_collide>0</self_collide>
      <visual name='Hydraulic_bottom_vis'>
        <pose>0 0 0 0 0 0</pose>
        <geometry>
          <mesh>
            <scale>1 1 1</scale>
            <uri>model://bobcat_tracked/meshes/Hydraulics_bottom.dae</uri>
          </mesh>
        </geometry>
      </visual>
		</link>
    <joint name='Hydraulic_bottom_rot' type='revolute'>
			<pose>0 0 0 0 0 0</pose>
			<child>Hydraulic_bottom</child>
			<parent>body</parent>
			<axis>
				<xyz>0 1 0</xyz>
				<!--<dynamics><friction>1</friction></dynamics>-->
			</axis>
		</joint>
    <link name='Hydraulic_top'>
			<pose>-1.480 0 1.220 0 0.34907 0</pose>
			<inertial>
				<pose>0 0 -0.5 0 -0 0</pose>
				<mass>65.29</mass>
				<inertia>
					<ixx>10</ixx>
					<ixy>0</ixy>
					<ixz>0</ixz>
					<iyy>10</iyy>
					<iyz>0</iyz>
					<izz>1</izz>
				</inertia>
			</inertial>
			<self_collide>0</self_collide>
      <visual name='Hydraulic_bottom_vis'>
        <pose>0 0 0 0 0 0</pose>
        <geometry>
          <mesh>
            <scale>1 1 1</scale>
            <uri>model://bobcat_tracked/meshes/Hydraulics_top.dae</uri>
          </mesh>
        </geometry>
      </visual>
		</link>
    <joint name='Hydraulic_top_rot' type='revolute'>
			<pose>0 0 0 0 0 0</pose>
			<child>Hydraulic_top</child>
			<parent>main_arm</parent>
			<axis>
				<xyz>0 1 0</xyz>
				<!--<dynamics><friction>1</friction></dynamics>-->
			</axis>
		</joint>
    <joint name='Hydraulics_joint' type='prismatic'>
			<pose>0 0 -0.5 0 0 0</pose>
			<child>Hydraulic_top</child>
			<parent>Hydraulic_bottom</parent>
			<axis>
				<xyz>.342024 0 0.939691</xyz>
				<!--<dynamics><friction>1</friction></dynamics>-->
			</axis>
		</joint> 
  <link name="cogwheel_left"/>
  <joint name="cogwheel_left_joint" type="continuous">
    <parent link="body" />
    <child link="cogwheel_left" />
    <origin xyz="-1.35 0.655 0.435" rpy="0 0 0" />
    <axis xyz="0 1 0" />
  </joint>  
  
  <link name="cogwheel_right"/>
  <joint name="cogwheel_right_joint" type="continuous">
    <parent link="body" />
    <child link="cogwheel_right" />
    <origin xyz="-1.35 -0.655 0.435" rpy="0 0 0" />
    <axis xyz="0 1 0" />
  </joint>    
</robot>

