<?xml version="1.0"?>
<robot name="Sahar">
  <link name="body"/>
  
  <link name="back_left_wheel"/>
  <joint name="back_left_wheel_joint" type="continuous">
    <parent link="body" />
    <child link="back_left_wheel" />
    <origin xyz="-1.227 0.475 0.147" rpy="0 0 0" />
    <axis xyz="0 1 0" />
  </joint>

  <link name="back_right_wheel"/>
  <joint name="back_right_wheel_joint" type="continuous">
    <parent link="body" />
    <child link="back_right_wheel" />
    <origin xyz="-1.227 -0.475 0.147" rpy="0 0 0" />
    <axis xyz="0 1 0" />
  </joint>

  <link name="front_left_wheel"/>
  <joint name="front_left_wheel_joint" type="continuous">
    <parent link="body" />
    <child link="front_left_wheel" />
    <origin xyz="-0.227 0.475 0.125" rpy="0 0 0" />
    <axis xyz="0 1 0" />
  </joint>

  <link name="front_right_wheel"/>
  <joint name="front_right_wheel_joint" type="continuous">
    <parent link="body" />
    <child link="front_right_wheel" />
    <origin xyz="-0.227 -0.475 0.125" rpy="0 0 0" />
    <axis xyz="0 1 0" />
  </joint>
 
</robot>

