<?xml version="1.0"?>
<robot name="Sahar">
  <link name="body"/>

  <link name="cabin"/>
  <joint name="cabin_joint" type="fixed">
    <parent link="body" />
    <child  link="cabin" />
    <origin xyz="-0.113 0 0.610" rpy="0 0 0" />
    <axis   xyz="0 1 0" />
  </joint>
  
  <link name="top_installation"/>
  <joint name="top_installation_joint" type="fixed">
    <parent link="cabin" />
    <child link="top_installation" />
    <origin xyz="-0.295 0.03227 1.859" rpy="1.570 0 1.570" />
    <axis xyz="0 0 0" />
  </joint>
  
  <link name="supporter_hinge"/>
  <joint name="supporter_hinge_joint" type="fixed">
    <parent link="body" />
    <child link="supporter_hinge" />
    <origin xyz="-0.315 0 0.685" rpy="1.570 0 1.570" />
    <axis xyz="1 0 0" />
  </joint>

  <link name="base_arm"/>
  <joint name="base_arm_joint" type="fixed">
    <parent link="body" />
    <child link="base_arm" />
    <origin xyz="-1.977 0 1.177" rpy="0 0 0" />
    <axis xyz="0 1 0" />
  </joint>

  <link name="main_arm"/>
  <joint name="main_arm_joint" type="fixed">
    <parent link="base_arm" />
    <child link="main_arm" />
    <origin xyz="-1.754 0 1.703" rpy="0 0 0" />
    <axis xyz="0 1 0" />
  </joint>

  <link name="supporter"/>
  <joint name="supporter_joint" type="fixed">
    <parent link="main_arm" />
    <child link="supporter" />
    <origin xyz="-1.356 0 0.808" rpy="0 0 0" />
    <axis xyz="0 1 0" />
  </joint>

  <link name="loader"/>
  <joint name="loader_joint" type="fixed">
    <parent link="main_arm" />
    <child link="loader" />
    <origin xyz="0.343 0 0.146" rpy="0 0 0" />
    <axis xyz="0 1 0" />
  </joint>
  
  <link name="brackets"/>
  <joint name="brackets_joint" type="fixed">
    <parent link="loader" />
    <child link="brackets" />
    <origin xyz="0.682 0 0.640" rpy="0 0 0" />
    <axis xyz="0 1 0" />
  </joint>

  <link name="back_left_wheel"/>
  <joint name="back_left_wheel_joint" type="continuous">
    <parent link="body" />
    <child link="back_left_wheel" />
    <origin xyz="-1.227 0.475 0.147" rpy="0 0 0" />
    <axis xyz="0 1 0" />
  </joint>

  <link name="back_right_wheel"/>
  <joint name="back_right_wheel_joint" type="continuous">
    <parent link="body" />
    <child link="back_right_wheel" />
    <origin xyz="-1.227 -0.475 0.147" rpy="0 0 0" />
    <axis xyz="0 1 0" />
  </joint>

  <link name="front_left_wheel"/>
  <joint name="front_left_wheel_joint" type="continuous">
    <parent link="body" />
    <child link="front_left_wheel" />
    <origin xyz="-0.227 0.475 0.125" rpy="0 0 0" />
    <axis xyz="0 1 0" />
  </joint>

  <link name="front_right_wheel"/>
  <joint name="front_right_wheel_joint" type="continuous">
    <parent link="body" />
    <child link="front_right_wheel" />
    <origin xyz="-0.227 -0.475 0.125" rpy="0 0 0" />
    <axis xyz="0 1 0" />
  </joint>
 
</robot>

