<?xml version="1.0"?>
<robot
  name="Sahar">
  <link
    name="body">
    <inertial>
      <origin
        xyz="-0.00736851236787186 0.205743662783451 -0.147264486358422"
        rpy="0 0 0" />
      <mass
        value="1539.59327309743" />
      <inertia
        ixx="595.204099560108"
        ixy="0.0800127114234479"
        ixz="-0.0923657576745734"
        iyy="649.603227306778"
        iyz="-56.3802149368362"
        izz="255.931353531899" />
    </inertial>
    <visual>
      <origin
        xyz="0 0 0"
        rpy="0 0 0" />
      <geometry>
        <mesh
          filename="package://bobcat_gazebo/meshes_bobcat_with_boggies/body.STL" />
      </geometry>
      <material
        name="">
        <color
          rgba="0.894117647058823 0.913725490196078 0.929411764705882 1" />
      </material>
    </visual>
    <collision>
      <origin
        xyz="0 0 0"
        rpy="0 0 0" />
      <geometry>
        <mesh
          filename="package://bobcat_gazebo/meshes_bobcat_with_boggies/body.STL" />
      </geometry>
    </collision>
  </link>
  <link
    name="right_wheel">
    <inertial>
      <origin
        xyz="-0.142856176942976 -4.5055134623162E-10 -3.28458024667633E-10"
        rpy="0 0 0" />
      <mass
        value="5.4973106115847" />
      <inertia
        ixx="0.0331571866222433"
        ixy="4.74591956306214E-11"
        ixz="-7.11777670092528E-12"
        iyy="0.0750084493873789"
        iyz="-3.13569619781006E-12"
        izz="0.0750084493853636" />
    </inertial>
    <visual>
      <origin
        xyz="0 0 0"
        rpy="0 0 0" />
      <geometry>
        <mesh
          filename="package://bobcat_gazebo/meshes_bobcat_with_boggies/right_wheel.STL" />
      </geometry>
      <material
        name="">
        <color
          rgba="0.792156862745098 0.819607843137255 0.933333333333333 1" />
      </material>
    </visual>
<!--
    <collision>
      <origin
        xyz="0 0 0"
        rpy="0 0 0" />
      <geometry>
        <mesh
          filename="package://bobcat_gazebo/meshes_bobcat_with_boggies/right_wheel.STL" />
      </geometry>

    </collision>
-->

    <collision>
      <origin
        xyz="-0.1 0 0"
        rpy="0 1.5708 0" />
      <geometry>
        <cylinder length="0.5" radius="0.1" 
          />

	
         </geometry>
    </collision>



    <collision>
      <origin
        xyz="0.091 0 0"
        rpy="0 1.5708 0" />
      <geometry>
        <cylinder length="0.1" radius="0.3" 

          />

      </geometry>
    </collision>

    <collision>
      <origin
        xyz="-0.35 0 0"
        rpy="0 1.5708 0" />
      <geometry>
        <cylinder length="0.02" radius="0.3" 
          />

      </geometry>
    </collision>



  </link>
  <joint
    name="right_wheel_joint"
    type="continuous">
    <origin
      xyz="0.067595 -0.88581 0.16637"
      rpy="1.5708 0 -1.5708" />
    <parent
      link="body" />
    <child
      link="right_wheel" />
    <axis
      xyz="-1 0 0" />

  </joint>
  <link
    name="left_wheel">
    <inertial>
      <origin
        xyz="0.142856176942976 -3.81439602126221E-11 5.83338988224824E-10"
        rpy="0 0 0" />
      <mass
        value="5.49731061158471" />
      <inertia
        ixx="0.0331571866215895"
        ixy="-3.76042672089463E-11"
        ixz="3.34298670147488E-11"
        iyy="0.0750084493824547"
        iyz="4.71480493535736E-13"
        izz="0.0750084493896341" />
    </inertial>
    <visual>
      <origin
        xyz="0 0 0"
        rpy="0 0 0" />
      <geometry>
        <mesh
          filename="package://bobcat_gazebo/meshes_bobcat_with_boggies/left_wheel.STL" />
      </geometry>
      <material
        name="">
        <color
          rgba="0.792156862745098 0.819607843137255 0.933333333333333 1" />
      </material>
    </visual>

<!--
    <collision>
      <origin
        xyz="0 0 0"
        rpy="0 0 0" />
      <geometry>
        <mesh
          filename="package://bobcat_gazebo/meshes_bobcat_with_boggies/left_wheel.STL" />
      </geometry>
    </collision>
-->
    <collision>
      <origin
        xyz="0.1 0 0"
        rpy="0 1.5708 0" />
      <geometry>
        <cylinder length="0.5" radius="0.1" 

          />
      </geometry>
    </collision>

    <collision>
      <origin
        xyz="-0.091 0 0"
        rpy="0 1.5708 0" />
      <geometry>
        <cylinder length="0.1" radius="0.3" 
          />

      </geometry>
    </collision>

    <collision>
      <origin
        xyz="0.35 0 0"
        rpy="0 1.5708 0" />
      <geometry>
        <cylinder length="0.02" radius="0.3" 
          />

      </geometry>
    </collision>

  </link>
  <joint
    name="left_wheel_joint"
    type="continuous">
    <origin
      xyz="0.067595 0.88219 0.16637"
      rpy="-1.1939 3.4487E-16 -1.5708" />
    <parent
      link="body" />
    <child
      link="left_wheel" />
    <axis
      xyz="1 0 0" />

  </joint>
  <link
    name="base_arm">
    <inertial>
      <origin
        xyz="-2.89776422923052 -0.00782184290450903 2.01394237407591"
        rpy="0 0 0" />
      <mass
        value="194.911277446129" />
      <inertia
        ixx="50.8150020254483"
        ixy="-2.55606636034685E-11"
        ixz="-0.506406234284681"
        iyy="4.8017119981411"
        iyz="-2.80700888778094E-12"
        izz="47.3329696801406" />
    </inertial>
    <visual>
      <origin
        xyz="0 0 0"
        rpy="0 0 0" />
      <geometry>
        <mesh
          filename="package://bobcat_gazebo/meshes_bobcat_with_boggies/base_arm.STL" />
      </geometry>
      <material
        name="">
        <color
          rgba="0.647058823529412 0.619607843137255 0.588235294117647 1" />
      </material>
    </visual>
    <collision>
      <origin
        xyz="0 0 0"
        rpy="0 0 0" />
      <geometry>
        <mesh
          filename="package://bobcat_gazebo/meshes_bobcat_with_boggies/base_arm.STL" />
      </geometry>
    </collision>
  </link>
  <joint
    name="base_arm_joint"
    type="revolute">
    <origin
      xyz="-1.9776 0 1.1773"
      rpy="3.1416 0.022723 3.1416" />
    <parent
      link="body" />
    <child
      link="base_arm" />
    <axis
      xyz="0 -1 0" />
    <limit
      lower="-1.57"
      upper="1.57"
      effort="1000000"
      velocity="100" />
  </joint>
  <link
    name="main_arm">
    <inertial>
      <origin
        xyz="-1.30907291542156 -4.03802317423818E-07 0.244524213108481"
        rpy="0 0 0" />
      <mass
        value="369.048456276718" />
      <inertia
        ixx="107.224896978573"
        ixy="-0.000136604321162762"
        ixz="-21.2004366371922"
        iyy="216.24084881792"
        iyz="8.45890152269129E-06"
        izz="295.068414163317" />
    </inertial>
    <visual>
      <origin
        xyz="0 0 0"
        rpy="0 0 0" />
      <geometry>
        <mesh
          filename="package://bobcat_gazebo/meshes_bobcat_with_boggies/main_arm.STL" />
      </geometry>
      <material
        name="">
        <color
          rgba="0.894117647058823 0.913725490196078 0.929411764705882 1" />
      </material>
    </visual>
    <collision>
      <origin
        xyz="0 0 0"
        rpy="0 0 0" />
      <geometry>
        <mesh
          filename="package://bobcat_gazebo/meshes_bobcat_with_boggies/main_arm.STL" />
      </geometry>
    </collision>
  </link>
  <joint
    name="main_arm_joint"
    type="revolute">
    <origin
      xyz="-2.83701268839882 -0.00782184290609528 2.31948558417386"
      rpy="3.14159265358979 -0.022722516134088 3.14159265358979" />
    <parent
      link="base_arm" />
    <child
      link="main_arm" />
    <axis
      xyz="0 1 0" />
<limit
      lower="-1.57"
      upper="1.57"
      effort="1000000"
      velocity="100" />

  </joint>
  <link
    name="supporter">
    <inertial>
      <origin
        xyz="0.509105843748937 -5.79397640976254E-16 -0.152725531800281"
        rpy="0 0 0" />
      <mass
        value="63.5021259618723" />
      <inertia
        ixx="16.8498351510607"
        ixy="-6.40688945592638E-15"
        ixz="-1.67676045503861"
        iyy="6.12110573308083"
        iyz="4.11223051006109E-15"
        izz="21.9362566994822" />
    </inertial>
    <visual>
      <origin
        xyz="0 0 0"
        rpy="0 0 0" />
      <geometry>
        <mesh
          filename="package://bobcat_gazebo/meshes_bobcat_with_boggies/supporter.STL" />
      </geometry>
      <material
        name="">
        <color
          rgba="0.647058823529412 0.619607843137255 0.588235294117647 1" />
      </material>
    </visual>
    <collision>
      <origin
        xyz="0 0 0"
        rpy="0 0 0" />
      <geometry>
        <mesh
          filename="package://bobcat_gazebo/meshes_bobcat_with_boggies/supporter.STL" />
      </geometry>
    </collision>
  </link>
  <joint
    name="supporter_joint"
    type="revolute">
    <origin
      xyz="-0.634484140606222 0 0.745904308143332"
      rpy="3.14159265358979 0.0227225161340874 3.14159265358979" />
    <parent
      link="main_arm" />
    <child
      link="supporter" />
    <axis
      xyz="0 -1 0" />
  <limit
      lower="-0.2"
      upper="1.5"
      effort="1000000"
      velocity="100" />
  </joint>
<!--  <link
    name="front_cylinder">
    <inertial>
      <origin
        xyz="0.188852843138602 -0.00999998349978863 -0.139256103957815"
        rpy="0 0 0" />
      <mass
        value="24.1491495926668" />
      <inertia
        ixx="4.07380208553037"
        ixy="-6.01554054856062E-08"
        ixz="-0.444197639915638"
        iyy="0.954124119497265"
        iyz="5.03533034136502E-08"
        izz="4.34866010618105" />
    </inertial>
    <visual>
      <origin
        xyz="0 0 0"
        rpy="0 0 0" />
      <geometry>
        <mesh
          filename="package://bobcat_gazebo/meshes_bobcat_with_boggies/front_cylinder.STL" />
      </geometry>
      <material
        name="">
        <color
          rgba="0.647058823529412 0.619607843137255 0.588235294117647 1" />
      </material>
    </visual>
    <collision>
      <origin
        xyz="0 0 0"
        rpy="0 0 0" />
      <geometry>
        <mesh
          filename="package://bobcat_gazebo/meshes_bobcat_with_boggies/front_cylinder.STL" />
      </geometry>
    </collision>
  </link>
  <joint
    name="front_cylinder_joint"
    type="revolute">
    <origin
      xyz="-1.89697070811579 0 0.277945194001941"
      rpy="3.14159265358979 0.0227225161340874 3.14159265358979" />
    <parent
      link="main_arm" />
    <child
      link="front_cylinder" />
    <axis
      xyz="0 1 0" />
    <limit
      lower="-1.57"
      upper="1.57"
      effort="1000000"
      velocity="100" />
  </joint>
  <link
    name="front_shaft">
    <inertial>
      <origin
        xyz="9.44408123482177E-07 -0.0099991693064754 -0.194165933682508"
        rpy="0 0 0" />
      <mass
        value="13.7105513004432" />
      <inertia
        ixx="2.52973806876278"
        ixy="-2.59221634712934E-07"
        ixz="1.36583505816468E-06"
        iyy="0.411807075522305"
        iyz="1.30085777462452E-06"
        izz="2.12213038409775" />
    </inertial>
    <visual>
      <origin
        xyz="0 0 0"
        rpy="0 0 0" />
      <geometry>
        <mesh
          filename="package://bobcat_gazebo/meshes_bobcat_with_boggies/front_shaft.STL" />
      </geometry>
      <material
        name="">
        <color
          rgba="0.647058823529412 0.619607843137255 0.588235294117647 1" />
      </material>
    </visual>
    <collision>
      <origin
        xyz="0 0 0"
        rpy="0 0 0" />
      <geometry>
        <mesh
          filename="package://bobcat_gazebo/meshes_bobcat_with_boggies/front_shaft.STL" />
      </geometry>
    </collision>
  </link>
  <joint
    name="front_shaft_joint"
    type="prismatic">
    <origin
      xyz="0.510901624032583 0 -0.376728258295381"
      rpy="3.14159265358979 0.935421546726849 3.14159265358979" />
    <parent
      link="front_cylinder" />
    <child
      link="front_shaft" />
    <axis
      xyz="0 0 1" />
    <limit
      lower="-0.1"
      upper="0.6"
      effort="1000000"
      velocity="100" />
  </joint>
-->
  <link
    name="loader">
    <inertial>
      <origin
        xyz="0.379082370056622 2.16320017454308E-15 0.0659422753589568"
        rpy="0 0 0" />
      <mass
        value="195.388659854928" />
      <inertia
        ixx="58.4540306754952"
        ixy="3.24456526669218E-14"
        ixz="-3.09459681005772"
        iyy="18.3748420691894"
        iyz="2.41355767340714E-15"
        izz="64.061084346089" />
    </inertial>
    <visual>
      <origin
        xyz="0 0 0"
        rpy="0 0 0" />
      <geometry>
        <mesh
          filename="package://bobcat_gazebo/meshes_bobcat_with_boggies/loader.STL" />
      </geometry>
      <material
        name="">
        <color
          rgba="0.894117647058823 0.913725490196078 0.929411764705882 1" />
      </material>
    </visual>
    <collision>
      <origin
        xyz="0 0 0"
        rpy="0 0 0" />
      <geometry>
        <mesh
          filename="package://bobcat_gazebo/meshes_bobcat_with_boggies/loader.STL" />
      </geometry>
    </collision>
  </link>
  <joint
    name="loader_joint"
    type="revolute">
    <origin
      xyz="-2.45297750534636 0 0.900222491478743"
      rpy="-3.14159265358979 0.744804047429081 -3.14159265358979" />
    <parent
      link="main_arm" />
    <child
      link="loader" />
    <axis
      xyz="0 1 0" />
    <limit
      lower="0"
      upper="1.57"
      effort="1000000"
      velocity="100" />
  </joint>
  <link
    name="brackets">
    <inertial>
      <origin
        xyz="0.249263516517755 -3.81639164714898E-16 0.207393387222123"
        rpy="0 0 0" />
      <mass
        value="34.713716241109" />
      <inertia
        ixx="7.22061625769604"
        ixy="9.97389744502976E-11"
        ixz="0.509845012607166"
        iyy="1.72816006569182"
        iyz="1.45779070606857E-10"
        izz="8.00601477219822" />
    </inertial>
    <visual>
      <origin
        xyz="0 0 0"
        rpy="0 0 0" />
      <geometry>
        <mesh
          filename="package://bobcat_gazebo/meshes_bobcat_with_boggies/brackets.STL" />
      </geometry>
      <material
        name="">
        <color
          rgba="0.894117647058823 0.913725490196078 0.929411764705882 1" />
      </material>
    </visual>
    <collision>
      <origin
        xyz="0 0 0"
        rpy="0 0 0" />
      <geometry>
        <mesh
          filename="package://bobcat_gazebo/meshes_bobcat_with_boggies/brackets.STL" />
      </geometry>
    </collision>
  </link>
  <joint
    name="brackets_joint"
    type="revolute">
    <origin
      xyz="0.338334394212607 0 0.494491423407127"
      rpy="2.35098870266482E-38 -2.94605615486648E-05 -2.35098870266482E-38" />
    <parent
      link="loader" />
    <child
      link="brackets" />
    <axis
      xyz="0 -1 0" />
    <limit
      lower="0"
      upper="1"
      effort="1000000"
      velocity="1000000" />
  </joint>
<!--
  <link
    name="back_cylinder">
    <inertial>
      <origin
        xyz="-2.46476230229391 -0.00782179007567019 0.27422731777772"
        rpy="0 0 0" />
      <mass
        value="30.81737040307" />
      <inertia
        ixx="10.1646149169929"
        ixy="-1.60881867380441E-07"
        ixz="0.530882656299446"
        iyy="2.37981293375823"
        iyz="-5.62406044661E-07"
        izz="8.06152509719766" />
    </inertial>
    <visual>
      <origin
        xyz="0 0 0"
        rpy="0 0 0" />
      <geometry>
        <mesh
          filename="package://bobcat_gazebo/meshes_bobcat_with_boggies/back_cylinder.STL" />
      </geometry>
      <material
        name="">
        <color
          rgba="0.647058823529412 0.619607843137255 0.588235294117647 1" />
      </material>
    </visual>
    <collision>
      <origin
        xyz="0 0 0"
        rpy="0 0 0" />
      <geometry>
        <mesh
          filename="package://bobcat_gazebo/meshes_bobcat_with_boggies/back_cylinder.STL" />
      </geometry>
    </collision>
  </link>
  <joint
    name="back_cylinder_joint"
    type="revolute">
    <origin
      xyz="-1.8135 0 0.2184"
      rpy="3.1416 0.022723 3.1416" />
    <parent
      link="body" />
    <child
      link="back_cylinder" />
    <axis
      xyz="0 -1 0" />
    <limit
      lower="-1.57"
      upper="1.57"
      effort="1000000"
      velocity="100" />
  </joint>
  <link
    name="back_shaft">
    <inertial>
      <origin
        xyz="-2.58270335118382E-08 -1.00362882275717E-08 -0.410041203350049"
        rpy="0 0 0" />
      <mass
        value="20.3671262440331" />
      <inertia
        ixx="6.9354474818675"
        ixy="-8.50361804045835E-07"
        ixz="1.66262764667025E-08"
        iyy="1.70473686662649"
        iyz="-7.7897617271109E-09"
        izz="5.23557764730923" />
    </inertial>
    <visual>
      <origin
        xyz="0 0 0"
        rpy="0 0 0" />
      <geometry>
        <mesh
          filename="package://bobcat_gazebo/meshes_bobcat_with_boggies/back_shaft.STL" />
      </geometry>
      <material
        name="">
        <color
          rgba="0.647058823529412 0.619607843137255 0.588235294117647 1" />
      </material>
    </visual>
    <collision>
      <origin
        xyz="0 0 0"
        rpy="0 0 0" />
      <geometry>
        <mesh
          filename="package://bobcat_gazebo/meshes_bobcat_with_boggies/back_shaft.STL" />
      </geometry>
    </collision>
  </link>
  <joint
    name="back_shaft_joint"
    type="prismatic">
    <origin
      xyz="-2.30172933915587 -0.00782184290609522 0.958904172892967"
      rpy="5.69861261054555E-16 0.233763223694335 4.35656639144668E-16" />
    <parent
      link="back_cylinder" />
    <child
      link="back_shaft" />
    <axis
      xyz="0 0 1" />
    <limit
      lower="-0.2"
      upper="1"
      effort="1000000"
      velocity="100" />
  </joint>
-->
  <link
    name="cabin">
    <inertial>
      <origin
        xyz="-0.703383758858147 -5.9738745365398E-08 0.728168999004174"
        rpy="0 0 0" />
      <mass
        value="170.536978174608" />
      <inertia
        ixx="47.5324551502959"
        ixy="-2.68037260713062E-07"
        ixz="2.90716782094081"
        iyy="51.8152402788837"
        iyz="-7.51490205561408E-07"
        izz="40.2060058300988" />
    </inertial>
    <visual>
      <origin
        xyz="0 0 0"
        rpy="0 0 0" />
      <geometry>
        <mesh
          filename="package://bobcat_gazebo/meshes_bobcat_with_boggies/cabin.STL" />
      </geometry>
      <material
        name="">
        <color
          rgba="0.894117647058823 0.913725490196078 0.929411764705882 1" />
      </material>
    </visual>
    <collision>
      <origin
        xyz="0 0 0"
        rpy="0 0 0" />
      <geometry>
        <mesh
          filename="package://bobcat_gazebo/meshes_bobcat_with_boggies/cabin.STL" />
      </geometry>
    </collision>
  </link>
  <joint
    name="cabin_joint"
    type="fixed">
    <origin
      xyz="-0.93811 -0.0078218 0.018062"
      rpy="3.1416 0.022723 3.1416" />
    <parent
      link="body" />
    <child
      link="cabin" />
    <axis
      xyz="0 0 0" />
  </joint>
  <link
    name="lbeo">
    <inertial>
      <origin
        xyz="-0.515302553626326 -0.0399859214694492 -0.987896561704231"
        rpy="0 0 0" />
      <mass
        value="3031.30986423935" />
      <inertia
        ixx="1614.65721495538"
        ixy="0.425789392013575"
        ixz="-29.9520475229002"
        iyy="2820.01927817486"
        iyz="-2.73196715635795"
        izz="2181.25247133787" />
    </inertial>
    <visual>
      <origin
        xyz="0 0 0"
        rpy="0 0 0" />
      <geometry>
        <mesh
          filename="package://bobcat_gazebo/meshes_bobcat_with_boggies/lbeo.STL" />
      </geometry>
      <material
        name="">
        <color
          rgba="1 1 1 1" />
      </material>
    </visual>
    <collision>
      <origin
        xyz="0 0 0"
        rpy="0 0 0" />
      <geometry>
        <mesh
          filename="package://bobcat_gazebo/meshes_bobcat_with_boggies/lbeo.STL" />
      </geometry>
    </collision>
  </link>
  <joint
    name="lbeo_joint"
    type="fixed">
    <origin
      xyz="-0.182576501522493 0.0400917833253838 1.24930392081653"
      rpy="0 -5.96744875736022E-16 0" />
    <parent
      link="cabin" />
    <child
      link="lbeo" />
    <axis
      xyz="0 0 0" />
  </joint>
  <link
    name="left_sick">
    <inertial>
      <origin
        xyz="-0.895463397324872 0.593038268596059 0.206879057396064"
        rpy="0 0 0" />
      <mass
        value="3031.30986423935" />
      <inertia
        ixx="2820.01927817486"
        ixy="-0.425789392013507"
        ixz="-2.73196715635778"
        iyy="1614.65721495538"
        iyz="29.9520475228994"
        izz="2181.25247133787" />
    </inertial>
    <visual>
      <origin
        xyz="0 0 0"
        rpy="0 0 0" />
      <geometry>
        <mesh
          filename="package://bobcat_gazebo/meshes_bobcat_with_boggies/left_sick.STL" />
      </geometry>
      <material
        name="">
        <color
          rgba="1 1 1 1" />
      </material>
    </visual>
    <collision>
      <origin
        xyz="0 0 0"
        rpy="0 0 0" />
      <geometry>
        <mesh
          filename="package://bobcat_gazebo/meshes_bobcat_with_boggies/left_sick.STL" />
      </geometry>
    </collision>
  </link>
  <joint
    name="left_sick_joint"
    type="fixed">
    <origin
      xyz="-0.83206 0.88775 -0.03407"
      rpy="3.1189 0 1.5708" />
    <parent
      link="body" />
    <child
      link="left_sick" />
    <axis
      xyz="0 0 0" />
  </joint>
  <link
    name="right_sick">
    <inertial>
      <origin
        xyz="-0.895869136339588 -0.593651976322574 0.206883092844691"
        rpy="0 0 0" />
      <mass
        value="3031.30986423935" />
      <inertia
        ixx="2820.01927817486"
        ixy="-0.425789392013603"
        ixz="2.73196715635778"
        iyy="1614.65721495539"
        iyz="-29.9520475228994"
        izz="2181.25247133787" />
    </inertial>
    <visual>
      <origin
        xyz="0 0 0"
        rpy="0 0 0" />
      <geometry>
        <mesh
          filename="package://bobcat_gazebo/meshes_bobcat_with_boggies/right_sick.STL" />
      </geometry>
      <material
        name="">
        <color
          rgba="1 1 1 1" />
      </material>
    </visual>
    <collision>
      <origin
        xyz="0 0 0"
        rpy="0 0 0" />
      <geometry>
        <mesh
          filename="package://bobcat_gazebo/meshes_bobcat_with_boggies/right_sick.STL" />
      </geometry>
    </collision>
  </link>
  <joint
    name="right_sick_joint"
    type="fixed">
    <origin
      xyz="-0.83267 -0.90359 -0.03408"
      rpy="-3.1189 0 -1.5708" />
    <parent
      link="body" />
    <child
      link="right_sick" />
    <axis
      xyz="0 0 0" />
  </joint>
  <link
    name="front_sick">
    <inertial>
      <origin
        xyz="-1.07217600812911 -0.00771598105016058 0.823330158924513"
        rpy="0 0 0" />
      <mass
        value="3031.30986423935" />
      <inertia
        ixx="1614.65721495538"
        ixy="0.425789392013492"
        ixz="-29.9520475228995"
        iyy="2820.01927817486"
        iyz="-2.73196715635794"
        izz="2181.25247133787" />
    </inertial>
    <visual>
      <origin
        xyz="0 0 0"
        rpy="0 0 0" />
      <geometry>
        <mesh
          filename="package://bobcat_gazebo/meshes_bobcat_with_boggies/front_sick.STL" />
      </geometry>
      <material
        name="">
        <color
          rgba="1 1 1 1" />
      </material>
    </visual>
    <collision>
      <origin
        xyz="0 0 0"
        rpy="0 0 0" />
      <geometry>
        <mesh
          filename="package://bobcat_gazebo/meshes_bobcat_with_boggies/front_sick.STL" />
      </geometry>
    </collision>
  </link>
  <joint
    name="front_sick_joint"
    type="fixed">
    <origin
      xyz="-1.3251 0 0.57134"
      rpy="3.1416 0.022723 3.1416" />
    <parent
      link="body" />
    <child
      link="front_sick" />
    <axis
      xyz="0 0 0" />
  </joint>
  <link
    name="supporter_hinge">
    <inertial>
      <origin
        xyz="-0.00782184290609577 -0.73876201940083 -0.418677619126881"
        rpy="0 0 0" />
      <mass
        value="1.68280499902572" />
      <inertia
        ixx="0.00017338446849968"
        ixy="3.86060024987903E-36"
        ixz="-2.03600395133694E-35"
        iyy="0.427476987948354"
        iyz="6.62173824469288E-37"
        izz="0.427476987948354" />
    </inertial>
    <visual>
      <origin
        xyz="0 0 0"
        rpy="0 0 0" />
      <geometry>
        <mesh
          filename="package://bobcat_gazebo/meshes_bobcat_with_boggies/supporter_hinge.STL" />
      </geometry>
      <material
        name="">
        <color
          rgba="0.647058823529412 0.619607843137255 0.588235294117647 1" />
      </material>
    </visual>
    <collision>
      <origin
        xyz="0 0 0"
        rpy="0 0 0" />
      <geometry>
        <mesh
          filename="package://bobcat_gazebo/meshes_bobcat_with_boggies/supporter_hinge.STL" />
      </geometry>
    </collision>
  </link>
  <joint
    name="supporter_hinge_joint"
    type="fixed">
    <origin
      xyz="-0.31547 0 0.68593"
      rpy="1.5708 0 1.5708" />
    <parent
      link="body" />
    <child
      link="supporter_hinge" />
    <axis
      xyz="0 0 0" />
  </joint>
  <link
    name="front_right_boggie">
    <inertial>
      <origin
        xyz="-0.072989545637314 0 0"
        rpy="0 0 0" />
      <mass
        value="3.90657046473891" />
      <inertia
        ixx="0.0402750730112348"
        ixy="-1.95495404144972E-19"
        ixz="-3.8871286104849E-19"
        iyy="0.0265900500882693"
        iyz="6.78191046434944E-18"
        izz="0.0265900500882693" />
    </inertial>
    <visual>
      <origin
        xyz="0 0 0"
        rpy="0 0 0" />
      <geometry>
        <mesh
          filename="package://bobcat_gazebo/meshes_bobcat_with_boggies/front_right_boggie.STL" />
      </geometry>
      <material
        name="">
        <color
          rgba="0.792156862745098 0.819607843137255 0.933333333333333 1" />
      </material>
    </visual>
<!--
    <collision>
      <origin
        xyz="0 0 0"
        rpy="0 0 0" />
      <geometry>
        <mesh
          filename="package://bobcat_gazebo/meshes_bobcat_with_boggies/front_right_boggie.STL" />
      </geometry>
    </collision>
-->

    <collision>
      <origin
        xyz="-0.1 0 0"
        rpy="0 1.5708 0" />
      <geometry>
        <cylinder length="0.5" radius="0.1" 
          />
      </geometry>
    </collision>

    <collision>
      <origin
        xyz="0.12 0 0"
        rpy="0 1.5708 0" />
      <geometry>
        <cylinder length="0.02" radius="0.17" 
          />
      </geometry>
    </collision>

    <collision>
      <origin
        xyz="-0.265 0 0"
        rpy="0 1.5708 0" />
      <geometry>
        <cylinder length="0.02" radius="0.17" 
          />

      </geometry>
    </collision>

  </link>
  <joint
    name="front_right_boggie_joint"
    type="continuous">
    <origin
      xyz="-0.86922 -0.79782 0.57019"
      rpy="1.5708 0 -1.5708" />
    <parent
      link="body" />
    <child
      link="front_right_boggie" />
    <axis
      xyz="-1 0 0" />

  </joint>
  <link
    name="back_right_boggie">
    <inertial>
      <origin
        xyz="-0.0729895456373141 0 0"
        rpy="0 0 0" />
      <mass
        value="3.90657046473891" />
      <inertia
        ixx="0.0402750730112348"
        ixy="-6.18564037846812E-22"
        ixz="4.99160466967745E-18"
        iyy="0.0265900500882693"
        iyz="3.6043016557644E-20"
        izz="0.0265900500882693" />
    </inertial>
    <visual>
      <origin
        xyz="0 0 0"
        rpy="0 0 0" />
      <geometry>
        <mesh
          filename="package://bobcat_gazebo/meshes_bobcat_with_boggies/back_right_boggie.STL" />
      </geometry>
      <material
        name="">
        <color
          rgba="0.792156862745098 0.819607843137255 0.933333333333333 1" />
      </material>
    </visual>
<!--
    <collision>
      <origin
        xyz="0 0 0"
        rpy="0 0 0" />
      <geometry>
        <mesh
          filename="package://bobcat_gazebo/meshes_bobcat_with_boggies/back_right_boggie.STL" />
      </geometry>
    </collision>
-->

    <collision>
      <origin
        xyz="-0.1 0 0"
        rpy="0 1.5708 0" />
      <geometry>
        <cylinder length="0.5" radius="0.1" 
          />
      </geometry>
    </collision>

     <collision>
      <origin
        xyz="0.12 0 0"
        rpy="0 1.5708 0" />
      <geometry>
        <cylinder length="0.02" radius="0.17" 
          />
      </geometry>
    </collision>

    <collision>
      <origin
        xyz="-0.265 0 0"
        rpy="0 1.5708 0" />
      <geometry>
        <cylinder length="0.02" radius="0.17" 
          />

      </geometry>
    </collision>

  </link>
  <joint
    name="back_right_boggie_joint"
    type="continuous">
    <origin
      xyz="0.39857 -0.79782 0.57019"
      rpy="1.5708 0 -1.5708" />
    <parent
      link="body" />
    <child
      link="back_right_boggie" />
    <axis
      xyz="-1 0 0" />

  </joint>
  <link
    name="front_left_boggie">
    <inertial>
      <origin
        xyz="-0.072989545637314 2.22044604925031E-16 0"
        rpy="0 0 0" />
      <mass
        value="3.90657046473891" />
      <inertia
        ixx="0.0402750730112348"
        ixy="-7.48894709617106E-18"
        ixz="-5.75771465104378E-19"
        iyy="0.0265900500882693"
        iyz="1.19262238973405E-18"
        izz="0.0265900500882693" />
    </inertial>
    <visual>
      <origin
        xyz="0 0 0"
        rpy="0 0 0" />
      <geometry>
        <mesh
          filename="package://bobcat_gazebo/meshes_bobcat_with_boggies/front_left_boggie.STL" />
      </geometry>
      <material
        name="">
        <color
          rgba="0.792156862745098 0.819607843137255 0.933333333333333 1" />
      </material>
    </visual>
<!--
    <collision>
      <origin
        xyz="0 0 0"
        rpy="0 0 0" />
      <geometry>
        <mesh
          filename="package://bobcat_gazebo/meshes_bobcat_with_boggies/front_left_boggie.STL" />
      </geometry>
    </collision>
-->
    <collision>
      <origin
        xyz="0.1 0 0"
        rpy="0 1.5708 0" />
      <geometry>
        <cylinder length="0.5" radius="0.1" 
          />
      </geometry>
    </collision>


    <collision>
      <origin
        xyz="0.12 0 0"
        rpy="0 1.5708 0" />
      <geometry>
        <cylinder length="0.02" radius="0.17" 
          />
      </geometry>
    </collision>

    <collision>
      <origin
        xyz="-0.265 0 0"
        rpy="0 1.5708 0" />
      <geometry>
        <cylinder length="0.02" radius="0.17" 
          />

      </geometry>
    </collision>


  </link>
  <joint
    name="front_left_boggie_joint"
    type="continuous">
    <origin
      xyz="-0.86922 0.79218 0.57019"
      rpy="-0.022723 -2.5348E-29 1.5708" />
    <parent
      link="body" />
    <child
      link="front_left_boggie" />
    <axis
      xyz="1 0 0" />

  </joint>
  <link
    name="back_left_boggie">
    <inertial>
      <origin
        xyz="-0.072989545637314 0 0"
        rpy="0 0 0" />
      <mass
        value="3.90657046473891" />
      <inertia
        ixx="0.0402750730112348"
        ixy="8.65586547893248E-18"
        ixz="-2.0885755126839E-19"
        iyy="0.0265900500882693"
        iyz="1.30104260698261E-18"
        izz="0.0265900500882693" />
    </inertial>
    <visual>
      <origin
        xyz="0 0 0"
        rpy="0 0 0" />
      <geometry>
        <mesh
          filename="package://bobcat_gazebo/meshes_bobcat_with_boggies/back_left_boggie.STL" />
      </geometry>
      <material
        name="">
        <color
          rgba="0.792156862745098 0.819607843137255 0.933333333333333 1" />
      </material>
    </visual>
<!--
    <collision>
      <origin
        xyz="0 0 0"
        rpy="0 0 0" />
      <geometry>
        <mesh
          filename="package://bobcat_gazebo/meshes_bobcat_with_boggies/back_left_boggie.STL" />
      </geometry>
    </collision>
-->

    <collision>
      <origin
        xyz="0.1 0 0"
        rpy="0 1.5708 0" />
      <geometry>
        <cylinder length="0.5" radius="0.1" 
          />
      </geometry>
    </collision>

    <collision>
      <origin
        xyz="0.12 0 0"
        rpy="0 1.5708 0" />
      <geometry>
        <cylinder length="0.02" radius="0.17" 
          />
      </geometry>
    </collision>

    <collision>
      <origin
        xyz="-0.265 0 0"
        rpy="0 1.5708 0" />
      <geometry>
        <cylinder length="0.02" radius="0.17" 
          />

      </geometry>
    </collision>

  </link>
  <joint
    name="back_left_boggie_joint"
    type="continuous">
    <origin
      xyz="0.39857 0.79218 0.57019"
      rpy="-0.022723 -2.5348E-29 1.5708" />
    <parent
      link="body" />
    <child
      link="back_left_boggie" />
    <axis
      xyz="-1 0 0" />

  </joint>



 <!-- Transmissions for ROS Control -->
  <transmission name="tran1">
    <type>transmission_interface/SimpleTransmission</type>
    <joint name="right_wheel_joint"/>
    <actuator name="motor1">
      <hardwareInterface>EffortJointInterface</hardwareInterface>
      <mechanicalReduction>1</mechanicalReduction>
    </actuator>
  </transmission>

  <transmission name="tran2">
    <type>transmission_interface/SimpleTransmission</type>
    <joint name="left_wheel_joint"/>
    <actuator name="motor2">
      <hardwareInterface>EffortJointInterface</hardwareInterface>
      <mechanicalReduction>1</mechanicalReduction>
    </actuator>
  </transmission>


  <transmission name="tran5">
    <type>transmission_interface/SimpleTransmission</type>
    <joint name="base_arm_joint"/>
    <actuator name="motor5">
      <hardwareInterface>EffortJointInterface</hardwareInterface>
      <mechanicalReduction>1</mechanicalReduction>
    </actuator>
  </transmission>

  <transmission name="tran6">
    <type>transmission_interface/SimpleTransmission</type>
    <joint name="main_arm_joint"/>
    <actuator name="motor6">
      <hardwareInterface>EffortJointInterface</hardwareInterface>
      <mechanicalReduction>1</mechanicalReduction>
    </actuator>
  </transmission>
<!--
  <transmission name="tran7">
    <type>transmission_interface/SimpleTransmission</type>
    <joint name="back_shaft_joint"/>
    <actuator name="motor7">
      <hardwareInterface>EffortJointInterface</hardwareInterface>
      <mechanicalReduction>1</mechanicalReduction>
    </actuator>
  </transmission>
-->
  <transmission name="tran8">
    <type>transmission_interface/SimpleTransmission</type>
    <joint name="supporter_joint"/>
    <actuator name="motor8">
      <hardwareInterface>EffortJointInterface</hardwareInterface>
      <mechanicalReduction>1</mechanicalReduction>
    </actuator>
  </transmission>
<!--
  <transmission name="tran9">
    <type>transmission_interface/SimpleTransmission</type>
    <joint name="front_cylinder_joint"/>
    <actuator name="motor9">
      <hardwareInterface>EffortJointInterface</hardwareInterface>
      <mechanicalReduction>1</mechanicalReduction>
    </actuator>
  </transmission>
-->
  <transmission name="tran10">
    <type>transmission_interface/SimpleTransmission</type>
    <joint name="loader_joint"/>
    <actuator name="motor10">
      <hardwareInterface>EffortJointInterface</hardwareInterface>
      <mechanicalReduction>1</mechanicalReduction>
    </actuator>
  </transmission>
<!--
  <transmission name="tran11">
    <type>transmission_interface/SimpleTransmission</type>
    <joint name="front_shaft_joint"/>
    <actuator name="motor11">
      <hardwareInterface>EffortJointInterface</hardwareInterface>
      <mechanicalReduction>1</mechanicalReduction>
    </actuator>
  </transmission>
-->
  <transmission name="tran12">
    <type>transmission_interface/SimpleTransmission</type>
    <joint name="brackets_joint"/>
    <actuator name="motor12">
      <hardwareInterface>EffortJointInterface</hardwareInterface>
      <mechanicalReduction>1</mechanicalReduction>
    </actuator>
  </transmission>
<!--
  <transmission name="tran12">
    <type>transmission_interface/SimpleTransmission</type>
    <joint name="back_cylinder_joint"/>
    <actuator name="motor12">
      <hardwareInterface>EffortJointInterface</hardwareInterface>
      <mechanicalReduction>1</mechanicalReduction>
    </actuator>
  </transmission>
-->
  <!-- ros_control plugin -->
 <gazebo>
    <plugin name="gazebo_chain_plugin" filename="libchain_pagebo_plugin.so">
      <robotNamespace>/Sahar</robotNamespace>
      <link1>back_shaft</link1>
      <link2>main_arm</link2>
      <joint>back_shaft_sheker</joint>
    </plugin>
  </gazebo>
 <gazebo>
    <plugin name="gazebo_chain_plugin" filename="libchain_pagebo_plugin.so">
      <robotNamespace>/Sahar</robotNamespace>
      <link1>front_shaft</link1>
      <link2>loader</link2>
      <joint>front_shaft_sheker</joint>
    </plugin>
  </gazebo>
  <gazebo>

    <plugin name="gazebo_ros_control" filename="libgazebo_ros_control.so">
      <robotNamespace>/Sahar</robotNamespace>
    </plugin>
  </gazebo>
  <gazebo reference="body">
    <mu1>1</mu1>
    <mu2>1</mu2>
    <selfCollide>true</selfCollide>
    <material>Gazebo/Wood</material>
  </gazebo>
  <gazebo reference="right_wheel">
    <mu1>0.5</mu1>
    <mu2>0.5</mu2>
    <selfCollide>true</selfCollide>
    <material>Gazebo/Grey</material>
  </gazebo>
  <gazebo reference="left_wheel">
    <mu1>0.5</mu1>
    <mu2>0.5</mu2>
    <selfCollide>true</selfCollide>
    <material>Gazebo/Grey</material>
  </gazebo>
 
  <gazebo reference="base_arm">
    <material>Gazebo/Grey</material>
  </gazebo>
  <gazebo reference="main_arm">
    <material>Gazebo/PaintedWall</material>
  </gazebo>
<!-- -->
  <gazebo reference="back_shaft">
    <material>Gazebo/Black</material>
  </gazebo>

  <gazebo reference="supporter">
    <mu1>1</mu1>
    <mu2>1</mu2>
    <selfCollide>true</selfCollide>
    <material>Gazebo/GreyTransparent</material>
  </gazebo>
  <gazebo reference="front_cylinder">
    <material>Gazebo/BlueTransparent</material>
  </gazebo>
  <gazebo reference="loader">
    <mu1>1</mu1>
    <mu2>1</mu2>
    <selfCollide>true</selfCollide>
    <material>Gazebo/Gold</material>
  </gazebo>
  <gazebo reference="front_shaft">
    <material>Gazebo/Black</material>
  </gazebo>
<!--	-->
  <gazebo reference="back_cylinder">
    <material>Gazebo/BlueTransparent</material>
  </gazebo>

  <gazebo reference="brackets">
    <mu1>1</mu1>
    <mu2>1</mu2>
    <selfCollide>true</selfCollide>
    <material>Gazebo/Grey</material>
  </gazebo>
  <gazebo reference="Ibeo">
    <material>Gazebo/Grey</material>
  </gazebo>
  <gazebo reference="left_sick">
    <material>Gazebo/Grey</material>
  </gazebo>
  <gazebo reference="right_sick">
    <material>Gazebo/Grey</material>
  </gazebo>
  <gazebo reference="front_sick">
    <material>Gazebo/Grey</material>
  </gazebo>
</robot>






