<?xml version="1.0"?>
<robot
  name="bobcat">
  <link
    name="base_link">
<inertial>
      <origin
        xyz="-0.0542 -8.757E-07 0.38055"
        rpy="0 0 0" />
      <mass
        value="9161.7" />
      <inertia
        ixx="1579.1"
        ixy="-0.13779"
        ixz="-129.86"
        iyy="3177.4"
        iyz="0.05397"
        izz="3249.5" />
    </inertial>
    <visual>
      <origin
        xyz="0 0 0"
        rpy="0 0 0" />
      <geometry>
        <mesh
          filename="package://bobcat/meshes/base_link.STL" />
      </geometry>
      <material
        name="">
        <color
          rgba="0.64706 0.61961 0.58824 1" />
      </material>
    </visual>
    <collision>
      <origin
        xyz="0 0 0"
        rpy="0 0 0" />
      <geometry>
        <mesh
          filename="package://bobcat/meshes/base_link_lite.STL" />
      </geometry>
    </collision>
  </link>
  <link
    name="front_right_wheel">
    <inertial>
      <origin
        xyz="4.9298E-10 0.19683 -1.7765E-10"
        rpy="0 0 0" />
      <mass
        value="170.06" />
      <inertia
        ixx="4.8784"
        ixy="5.0832E-08"
        ixz="-1.4131E-08"
        iyy="7.9419"
        iyz="-3.4326E-08"
        izz="4.8784" />
    </inertial>
    <visual>
      <origin
        xyz="0 0 0"
        rpy="0 0 0" />
      <geometry>
        <mesh
          filename="package://bobcat/meshes/front_right_wheel.STL" />
      </geometry>
      <material
        name="">
        <color
          rgba="0.75294 0.75294 0.75294 1" />
      </material>
    </visual>
    <collision>
      <origin
        xyz="0 0 0"
        rpy="0 0 0" />
      <geometry>
        <mesh
          filename="package://bobcat/meshes/front_right_wheel_lite.STL" />
      </geometry>
    </collision>
  </link>
  <joint
    name="front_right_wheel_joint"
    type="continuous">
    <origin
      xyz="0.635 0.45 0.15"
      rpy="0 0 0" />
    <parent
      link="base_link" />
    <child
      link="front_right_wheel" />
    <axis
      xyz="0 1 0" />
  </joint>
  <link
    name="front_left_wheel">
    <inertial>
      <origin
        xyz="5.8923E-10 -0.19683 8.4566E-10"
        rpy="0 0 0" />
      <mass
        value="170.06" />
      <inertia
        ixx="4.8784"
        ixy="3.6671E-08"
        ixz="3.8767E-08"
        iyy="7.9419"
        iyz="-9.8471E-09"
        izz="4.8784" />
    </inertial>
    <visual>
      <origin
        xyz="0 0 0"
        rpy="0 0 0" />
      <geometry>
        <mesh
          filename="package://bobcat/meshes/front_left_wheel.STL" />
      </geometry>
      <material
        name="">
        <color
          rgba="0.75294 0.75294 0.75294 1" />
      </material>
    </visual>
    <collision>
      <origin
        xyz="0 0 0"
        rpy="0 0 0" />
      <geometry>
        <mesh
          filename="package://bobcat/meshes/front_left_wheel_lite.STL" />
      </geometry>
    </collision>
  </link>
  <joint
    name="front_left_wheel_joint"
    type="continuous">
    <origin
      xyz="0.635 -0.45 0.15"
      rpy="0 0 0" />
    <parent
      link="base_link" />
    <child
      link="front_left_wheel" />
    <axis
      xyz="0 1 0" />
  </joint>
  <link
    name="back_right_wheel">
    <inertial>
      <origin
        xyz="-8.4105E-10 0.19683 1.5353E-09"
        rpy="0 0 0" />
      <mass
        value="170.06" />
      <inertia
        ixx="4.8784"
        ixy="-1.31E-08"
        ixz="5.071E-08"
        iyy="7.9419"
        iyz="-8.1131E-09"
        izz="4.8784" />
    </inertial>
    <visual>
      <origin
        xyz="0 0 0"
        rpy="0 0 0" />
      <geometry>
        <mesh
          filename="package://bobcat/meshes/back_right_wheel.STL" />
      </geometry>
      <material
        name="">
        <color
          rgba="0.75294 0.75294 0.75294 1" />
      </material>
    </visual>
    <collision>
      <origin
        xyz="0 0 0"
        rpy="0 0 0" />
      <geometry>
        <mesh
          filename="package://bobcat/meshes/back_right_wheel_lite.STL" />
      </geometry>
    </collision>
  </link>
  <joint
    name="back_right_wheel_joint"
    type="continuous">
    <origin
      xyz="-0.395 0.45 0.15"
      rpy="0 0 0" />
    <parent
      link="base_link" />
    <child
      link="back_right_wheel" />
    <axis
      xyz="0 1 0" />
  </joint>
  <link
    name="back_left_wheel">
    <inertial>
      <origin
        xyz="-1.6691E-10 -0.19683 4.2956E-10"
        rpy="0 0 0" />
      <mass
        value="170.06" />
      <inertia
        ixx="4.8784"
        ixy="-2.8059E-08"
        ixz="3.0702E-08"
        iyy="7.9419"
        iyz="1.6507E-08"
        izz="4.8784" />
    </inertial>
    <visual>
      <origin
        xyz="0 0 0"
        rpy="0 0 0" />
      <geometry>
        <mesh
          filename="package://bobcat/meshes/back_left_wheel.STL" />
      </geometry>
      <material
        name="">
        <color
          rgba="0.75294 0.75294 0.75294 1" />
      </material>
    </visual>
    <collision>
      <origin
        xyz="0 0 0"
        rpy="0 0 0" />
      <geometry>
        <mesh
          filename="package://bobcat/meshes/back_left_wheel_lite.STL" />
      </geometry>
    </collision>
  </link>
  <joint
    name="back_left_wheel_joint"
    type="continuous">
    <origin
      xyz="-0.395 -0.45 0.15"
      rpy="0 0 0" />
    <parent
      link="base_link" />
    <child
      link="back_left_wheel" />
    <axis
      xyz="0 1 0" />
  </joint>
  <link
    name="back_arm_link">
    <inertial>
      <origin
        xyz="0.7322 -5.5055E-15 0.063839"
        rpy="0 0 0" />
      <mass
        value="191.11" />
      <inertia
        ixx="58.345"
        ixy="-1.1548E-13"
        ixz="2.5353"
        iyy="29.721"
        iyz="9.3132E-14"
        izz="87.205" />
    </inertial>
    <visual>
      <origin
        xyz="0 0 0"
        rpy="0 0 0" />
      <geometry>
        <mesh
          filename="package://bobcat/meshes/back_arm_link.STL" />
      </geometry>
      <material
        name="">
        <color
          rgba="0.64706 0.61961 0.58824 1" />
      </material>
    </visual>
    <collision>
      <origin
        xyz="0 0 0"
        rpy="0 0 0" />
      <geometry>
        <mesh
          filename="package://bobcat/meshes/back_arm_link.STL" />
      </geometry>
    </collision>
  </link>
  <joint
    name="back_arm_joint"
    type="revolute">
    <origin
      xyz="-0.71905 0 1.275"
      rpy="0 0 0" />
    <parent
      link="base_link" />
    <child
      link="back_arm_link" />
    <axis
      xyz="0 1 0" />
    <limit
      lower="-1.57"
      upper="1.57"
      effort="1000000"
      velocity="100" />
  </joint>
  <link
    name="front_arm_link">
    <inertial>
      <origin
        xyz="0.32018 -2.5195E-15 -0.16102"
        rpy="0 0 0" />
      <mass
        value="46.532" />
      <inertia
        ixx="15.078"
        ixy="3.5569E-14"
        ixz="-1.1602"
        iyy="2.9183"
        iyz="-5.4505E-15"
        izz="16.182" />
    </inertial>
    <visual>
      <origin
        xyz="0 0 0"
        rpy="0 0 0" />
      <geometry>
        <mesh
          filename="package://bobcat/meshes/front_arm_link.STL" />
      </geometry>
      <material
        name="">
        <color
          rgba="0.64706 0.61961 0.58824 1" />
      </material>
    </visual>
    <collision>
      <origin
        xyz="0 0 0"
        rpy="0 0 0" />
      <geometry>
        <mesh
          filename="package://bobcat/meshes/front_arm_link.STL" />
      </geometry>
    </collision>
  </link>
  <joint
    name="front_arm_joint"
    type="revolute">
    <origin
      xyz="1.31 0 0.11421"
      rpy="0 0 0" />
    <parent
      link="back_arm_link" />
    <child
      link="front_arm_link" />
    <axis
      xyz="0 1 0" />
    <limit
      lower="-1.57"
      upper="1.57"
      effort="1000000"
      velocity="100" />
  </joint>
  <link
    name="loader_link">
    <inertial>
      <origin
        xyz="0.24647 -4.5803E-06 -0.25248"
        rpy="0 0 0" />
      <mass
        value="26.475" />
      <inertia
        ixx="7445.7"
        ixy="-6.2842E-02"
        ixz="-421.29"
        iyy="2326"
        iyz="5.4359E-03"
        izz="8101.6" />
    </inertial>
    <visual>
      <origin
        xyz="0 0 0"
        rpy="0 0 0" />
      <geometry>
        <mesh
          filename="package://bobcat/meshes/loader_link.STL" />
      </geometry>
      <material
        name="">
        <color
          rgba="0.79216 0.81961 0.93333 1" />
      </material>
    </visual>
    <collision>
      <origin
        xyz="0 0 0"
        rpy="0 0 0" />
      <geometry>
        <mesh
          filename="package://bobcat/meshes/loader_link_lite.STL" />
      </geometry>
    </collision>
  </link>
  <joint
    name="loader_joint"
    type="revolute">
    <origin
      xyz="0.64041 0 -0.45384"
      rpy="0 0 0" />
    <parent
      link="front_arm_link" />
    <child
      link="loader_link" />
    <axis
      xyz="0 1 0" />
    <limit
      lower="-1.57"
      upper="1.57"
      effort="1000000"
      velocity="100" />
  </joint>
  <link
    name="shaft_Link">
    <inertial>
      <origin
        xyz="-0.37305 7.1449E-08 -0.16375"
        rpy="0 0 0" />
      <mass
        value="20.495" />
      <inertia
        ixx="6.4841"
        ixy="-4.7376E-08"
        ixz="0.6339"
        iyy="1.7274"
        iyz="-4.1652E-08"
        izz="7.65" />
    </inertial>
    <visual>
      <origin
        xyz="0 0 0"
        rpy="0 0 0" />
      <geometry>
        <mesh
          filename="package://bobcat/meshes/shaft_Link.STL" />
      </geometry>
      <material
        name="">
        <color
          rgba="0.79216 0.81961 0.93333 1" />
      </material>
    </visual>
    <collision>
      <origin
        xyz="0 0 0"
        rpy="0 0 0" />
      <geometry>
        <mesh
          filename="package://bobcat/meshes/shaft_Link.STL" />
      </geometry>
    </collision>
  </link>
  <joint
    name="shaft_joint"
    type="revolute">
    <origin
      xyz="0.070057 0 -0.12038"
      rpy="0 0 0" />
    <parent
      link="front_arm_link" />
    <child
      link="shaft_Link" />
    <axis
      xyz="0 1 0" />
    <limit
      lower="-1.57"
      upper="1.57"
      effort="10000000"
      velocity="100" />
  </joint>
  <link
    name="cylinder_link">
    <inertial>
      <origin
        xyz="0.41596 -1.1057E-07 0.18258"
        rpy="0 0 0" />
      <mass
        value="31.116" />
      <inertia
        ixx="9.826"
        ixy="1.0103E-06"
        ixz="0.88868"
        iyy="2.437"
        iyz="4.4459E-07"
        izz="11.46" />
    </inertial>
    <visual>
      <origin
        xyz="0 0 0"
        rpy="0 0 0" />
      <geometry>
        <mesh
          filename="package://bobcat/meshes/cylinder_link.STL" />
      </geometry>
      <material
        name="">
        <color
          rgba="0.79216 0.81961 0.93333 1" />
      </material>
    </visual>
    <collision>
      <origin
        xyz="0 0 0"
        rpy="0 0 0" />
      <geometry>
        <mesh
          filename="package://bobcat/meshes/cylinder_link.STL" />
      </geometry>
    </collision>
  </link>
  <joint
    name="cylinder_joint"
    type="revolute">
    <origin
      xyz="-0.44801 0 0.78201"
      rpy="0 0 0" />
    <parent
      link="base_link" />
    <child
      link="cylinder_link" />
    <axis
      xyz="0 1 0" />
    <limit
      lower="-1.57"
      upper="1.57"
      effort="10000000"
      velocity="100" />
  </joint>


  <!-- Transmissions for ROS Control -->
  <transmission name="tran1">
    <type>transmission_interface/SimpleTransmission</type>
    <joint name="front_right_wheel_joint"/>
    <actuator name="motor1">
      <hardwareInterface>EffortJointInterface</hardwareInterface>
      <mechanicalReduction>1</mechanicalReduction>
    </actuator>
  </transmission>

  <transmission name="tran2">
    <type>transmission_interface/SimpleTransmission</type>
    <joint name="front_left_wheel_joint"/>
    <actuator name="motor2">
      <hardwareInterface>EffortJointInterface</hardwareInterface>
      <mechanicalReduction>1</mechanicalReduction>
    </actuator>
  </transmission>

  <transmission name="tran3">
    <type>transmission_interface/SimpleTransmission</type>
    <joint name="back_right_wheel_joint"/>
    <actuator name="motor3">
      <hardwareInterface>EffortJointInterface</hardwareInterface>
      <mechanicalReduction>1</mechanicalReduction>
    </actuator>
  </transmission>

  <transmission name="tran4">
    <type>transmission_interface/SimpleTransmission</type>
    <joint name="back_left_wheel_joint"/>
    <actuator name="motor4">
      <hardwareInterface>EffortJointInterface</hardwareInterface>
      <mechanicalReduction>1</mechanicalReduction>
    </actuator>
  </transmission>

  <transmission name="tran5">
    <type>transmission_interface/SimpleTransmission</type>
    <joint name="back_arm_joint"/>
    <actuator name="motor5">
      <hardwareInterface>EffortJointInterface</hardwareInterface>
      <mechanicalReduction>1</mechanicalReduction>
    </actuator>
  </transmission>

  <transmission name="tran6">
    <type>transmission_interface/SimpleTransmission</type>
    <joint name="front_arm_joint"/>
    <actuator name="motor6">
      <hardwareInterface>EffortJointInterface</hardwareInterface>
      <mechanicalReduction>1</mechanicalReduction>
    </actuator>
  </transmission>

  <transmission name="tran7">
    <type>transmission_interface/SimpleTransmission</type>
    <joint name="loader_joint"/>
    <actuator name="motor7">
      <hardwareInterface>EffortJointInterface</hardwareInterface>
      <mechanicalReduction>1</mechanicalReduction>
    </actuator>
  </transmission>

  <transmission name="tran8">
    <type>transmission_interface/SimpleTransmission</type>
    <joint name="shaft_joint"/>
    <actuator name="motor8">
      <hardwareInterface>EffortJointInterface</hardwareInterface>
      <mechanicalReduction>1</mechanicalReduction>
    </actuator>
  </transmission>

  <transmission name="tran9">
    <type>transmission_interface/SimpleTransmission</type>
    <joint name="cylinder_joint"/>
    <actuator name="motor9">
      <hardwareInterface>EffortJointInterface</hardwareInterface>
      <mechanicalReduction>1</mechanicalReduction>
    </actuator>
  </transmission>

  <!-- ros_control plugin -->
  <gazebo>
    <plugin name="gazebo_ros_control" filename="libgazebo_ros_control.so">
      <robotNamespace>/bobcat</robotNamespace>
    </plugin>
  </gazebo>
  <gazebo reference="base_link">
    <mu1>1</mu1>
    <mu2>1</mu2>
    <selfCollide>true</selfCollide>
  </gazebo>
  <gazebo reference="front_right_wheel">
    <mu1>1</mu1>
    <mu2>1</mu2>
    <selfCollide>true</selfCollide>
  </gazebo>
  <gazebo reference="front_left_wheel">
    <mu1>1</mu1>
    <mu2>1</mu2>
    <selfCollide>true</selfCollide>
  </gazebo>
  <gazebo reference="back_right_wheel">
    <mu1>1</mu1>
    <mu2>1</mu2>
    <selfCollide>true</selfCollide>
  </gazebo>
  <gazebo reference="back_left_wheel">
    <mu1>1</mu1>
    <mu2>1</mu2>
  </gazebo>
  <gazebo reference="back_arm_link">
    <mu1>1</mu1>
    <mu2>1</mu2>
    <selfCollide>true</selfCollide>
  </gazebo>
  <gazebo reference="front_arm_link">
    <mu1>1</mu1>
    <mu2>1</mu2>
    <selfCollide>true</selfCollide>
  </gazebo>
  <gazebo reference="loader_link">
    <mu1>1</mu1>
    <mu2>1</mu2>
    <selfCollide>true</selfCollide>
  </gazebo>
  <gazebo reference="shaft_Link">
    <mu1>1</mu1>
    <mu2>1</mu2>
    <selfCollide>true</selfCollide>
  </gazebo>
  <gazebo reference="cylinder_link">
    <mu1>1</mu1>
    <mu2>1</mu2>
    <selfCollide>true</selfCollide>
  </gazebo>
</robot>
