<?xml version="1.0"?>
<robot
  name="bobcat">
  <link
    name="base_link">
    <inertial>
      <origin
        xyz="-0.0542001598231326 -8.75695251125423E-07 0.380552945194303"
        rpy="0 0 0" />
      <mass
        value="9161.66794584788" />
      <inertia
        ixx="1579.1370200902"
        ixy="-0.137788807132031"
        ixz="-129.860891078581"
        iyy="3177.4343628128"
        iyz="0.0539701913411233"
        izz="3249.48952429426" />
    </inertial>
    <visual>
      <origin
        xyz="0 0 0"
        rpy="0 0 0" />
      <geometry>
        <mesh
          filename="package://bobcat/meshes/base_link.STL" />
      </geometry>
      <material
        name="">
        <color
          rgba="0.647058823529412 0.619607843137255 0.588235294117647 1" />
      </material>
    </visual>
    <collision>
      <origin
        xyz="0 0 0"
        rpy="0 0 0" />
      <geometry>
        <mesh
          filename="package://bobcat/meshes/base_link_lite.STL" />
      </geometry>
    </collision>
  </link>
  <link
    name="front_left_wheel">
    <inertial>
      <origin
        xyz="4.92984764122184E-10 0.196834616555977 -1.7764559268052E-10"
        rpy="0 0 0" />
      <mass
        value="170.056035393948" />
      <inertia
        ixx="4.87838948787587"
        ixy="5.08321276894812E-08"
        ixz="-1.41306935529031E-08"
        iyy="7.94189509045945"
        iyz="-3.43255624217112E-08"
        izz="4.87838961018562" />
    </inertial>
    <visual>
      <origin
        xyz="0 0 0"
        rpy="0 0 0" />
      <geometry>
        <mesh
          filename="package://bobcat/meshes/front_left_wheel.STL" />
      </geometry>
      <material
        name="">
        <color
          rgba="0.752941176470588 0.752941176470588 0.752941176470588 1" />
      </material>
    </visual>
    <collision>
      <origin
        xyz="0 0 0"
        rpy="0 0 0" />
      <geometry>
        <mesh
          filename="package://bobcat/meshes/front_left_wheel_lite.STL" />
      </geometry>
    </collision>
  </link>
  <joint
    name="front_left_wheel_joint"
    type="continuous">
    <origin
      xyz="0.635 0.45 0.15"
      rpy="0 0 0" />
    <parent
      link="base_link" />
    <child
      link="front_left_wheel" />
    <axis
      xyz="0 1 0" />
  </joint>
  <link
    name="front_right_wheel">
    <inertial>
      <origin
        xyz="5.89234661063642E-10 -0.1968346162357 8.45663844506461E-10"
        rpy="0 0 0" />
      <mass
        value="170.056034960479" />
      <inertia
        ixx="4.87838950001766"
        ixy="3.6671326619912E-08"
        ixz="3.87666434432245E-08"
        iyy="7.94189506344536"
        iyz="-9.8471047053675E-09"
        izz="4.87838955667488" />
    </inertial>
    <visual>
      <origin
        xyz="0 0 0"
        rpy="0 0 0" />
      <geometry>
        <mesh
          filename="package://bobcat/meshes/front_right_wheel.STL" />
      </geometry>
      <material
        name="">
        <color
          rgba="0.752941176470588 0.752941176470588 0.752941176470588 1" />
      </material>
    </visual>
    <collision>
      <origin
        xyz="0 0 0"
        rpy="0 0 0" />
      <geometry>
        <mesh
          filename="package://bobcat/meshes/front_right_wheel_lite.STL" />
      </geometry>
    </collision>
  </link>
  <joint
    name="front_right_wheel_joint"
    type="continuous">
    <origin
      xyz="0.635 -0.45 0.15"
      rpy="0 0 0" />
    <parent
      link="base_link" />
    <child
      link="front_right_wheel" />
    <axis
      xyz="0 1 0" />
  </joint>
  <link
    name="back_left_wheel">
    <inertial>
      <origin
        xyz="-8.41048120037158E-10 0.196834617187431 1.53527776602935E-09"
        rpy="0 0 0" />
      <mass
        value="170.056034196706" />
      <inertia
        ixx="4.87838950015278"
        ixy="-1.31000627972032E-08"
        ixz="5.07097384543192E-08"
        iyy="7.94189498940387"
        iyz="-8.11313475559273E-09"
        izz="4.87838951430754" />
    </inertial>
    <visual>
      <origin
        xyz="0 0 0"
        rpy="0 0 0" />
      <geometry>
        <mesh
          filename="package://bobcat/meshes/back_left_wheel.STL" />
      </geometry>
      <material
        name="">
        <color
          rgba="0.752941176470588 0.752941176470588 0.752941176470588 1" />
      </material>
    </visual>
    <collision>
      <origin
        xyz="0 0 0"
        rpy="0 0 0" />
      <geometry>
        <mesh
          filename="package://bobcat/meshes/back_left_wheel_lite.STL" />
      </geometry>
    </collision>
  </link>
  <joint
    name="back_left_wheel_joint"
    type="continuous">
    <origin
      xyz="-0.395 0.45 0.15"
      rpy="0 0 0" />
    <parent
      link="base_link" />
    <child
      link="back_left_wheel" />
    <axis
      xyz="0 1 0" />
  </joint>
  <link
    name="back_right_wheel">
    <inertial>
      <origin
        xyz="-1.66906211074291E-10 -0.196834617778821 4.29557611703046E-10"
        rpy="0 0 0" />
      <mass
        value="170.056034996978" />
      <inertia
        ixx="4.87838959400998"
        ixy="-2.8058508010656E-08"
        ixz="3.07021991101146E-08"
        iyy="7.9418950392662"
        iyz="1.65069761406403E-08"
        izz="4.87838949682166" />
    </inertial>
    <visual>
      <origin
        xyz="0 0 0"
        rpy="0 0 0" />
      <geometry>
        <mesh
          filename="package://bobcat/meshes/back_right_wheel.STL" />
      </geometry>
      <material
        name="">
        <color
          rgba="0.752941176470588 0.752941176470588 0.752941176470588 1" />
      </material>
    </visual>
    <collision>
      <origin
        xyz="0 0 0"
        rpy="0 0 0" />
      <geometry>
        <mesh
          filename="package://bobcat/meshes/back_right_wheel_lite.STL" />
      </geometry>
    </collision>
  </link>
  <joint
    name="back_right_wheel_joint"
    type="continuous">
    <origin
      xyz="-0.395 -0.45 0.15"
      rpy="0 0 0" />
    <parent
      link="base_link" />
    <child
      link="back_right_wheel" />
    <axis
      xyz="0 1 0" />
  </joint>
  <link
    name="back_arm_link">
    <inertial>
      <origin
        xyz="0.732198441390495 -8.74169241214766E-15 0.0638390833375868"
        rpy="0 0 0" />
      <mass
        value="191.112053822971" />
      <inertia
        ixx="58.3445239627317"
        ixy="-1.37584388326673E-13"
        ixz="2.53529571300744"
        iyy="29.7214682126312"
        iyz="1.04753879182073E-13"
        izz="87.2045127184149" />
    </inertial>
    <visual>
      <origin
        xyz="0 0 0"
        rpy="0 0 0" />
      <geometry>
        <mesh
          filename="package://bobcat/meshes/back_arm_link.STL" />
      </geometry>
      <material
        name="">
        <color
          rgba="0.647058823529412 0.619607843137255 0.588235294117647 1" />
      </material>
    </visual>
    <collision>
      <origin
        xyz="0 0 0"
        rpy="0 0 0" />
      <geometry>
        <mesh
          filename="package://bobcat/meshes/back_arm_link.STL" />
      </geometry>
    </collision>
  </link>
  <joint
    name="back_arm_joint"
    type="revolute">
    <origin
      xyz="-0.71905 0 1.275"
      rpy="0 0 0" />
    <parent
      link="base_link" />
    <child
      link="back_arm_link" />
    <axis
      xyz="0 1 0" />
    <limit
      lower="-1.57"
      upper="1.57"
      effort="1000000"
      velocity="100" />
  </joint>
  <link
    name="front_arm_link">
    <inertial>
      <origin
        xyz="0.32017896499508 -4.19921680120978E-15 -0.161022775977494"
        rpy="0 0 0" />
      <mass
        value="46.5323086623519" />
      <inertia
        ixx="15.0776481293711"
        ixy="3.01179860928389E-14"
        ixz="-1.16024943805148"
        iyy="2.91829700907568"
        iyz="-1.47227133659515E-15"
        izz="16.1819270089877" />
    </inertial>
    <visual>
      <origin
        xyz="0 0 0"
        rpy="0 0 0" />
      <geometry>
        <mesh
          filename="package://bobcat/meshes/front_arm_link.STL" />
      </geometry>
      <material
        name="">
        <color
          rgba="0.647058823529412 0.619607843137255 0.588235294117647 1" />
      </material>
    </visual>
    <collision>
      <origin
        xyz="0 0 0"
        rpy="0 0 0" />
      <geometry>
        <mesh
          filename="package://bobcat/meshes/front_arm_link.STL" />
      </geometry>
    </collision>
  </link>
  <joint
    name="front_arm_joint"
    type="revolute">
    <origin
      xyz="1.31 0 0.11421"
      rpy="0 0 0" />
    <parent
      link="back_arm_link" />
    <child
      link="front_arm_link" />
    <axis
      xyz="0 1 0" />
    <limit
      lower="-1.57"
      upper="1.57"
      effort="1000000"
      velocity="100" />
  </joint>
  <link
    name="loader_link">
    <inertial>
      <origin
        xyz="0.234528811759279 -6.02692015319463E-07 -0.253163010892011"
        rpy="0 0 0" />
      <mass
        value="201.206004462732" />
      <inertia
        ixx="56.6105684970583"
        ixy="-6.42902628370138E-05"
        ixz="-3.09625562108269"
        iyy="16.6112301998233"
        iyz="5.35363722506524E-06"
        izz="60.3103509975138" />
    </inertial>
    <visual>
      <origin
        xyz="0 0 0"
        rpy="0 0 0" />
      <geometry>
        <mesh
          filename="package://bobcat/meshes/loader_link.STL" />
      </geometry>
      <material
        name="">
        <color
          rgba="0.792156862745098 0.819607843137255 0.933333333333333 1" />
      </material>
    </visual>
    <collision>
      <origin
        xyz="0 0 0"
        rpy="0 0 0" />
      <geometry>
        <mesh
          filename="package://bobcat/meshes/loader_link_lite.STL" />
      </geometry>
    </collision>
  </link>
  <joint
    name="loader_joint"
    type="revolute">
    <origin
      xyz="0.64041 0 -0.45384"
      rpy="0 0 0" />
    <parent
      link="front_arm_link" />
    <child
      link="loader_link" />
    <axis
      xyz="0 1 0" />
    <limit
      lower="-1.57"
      upper="1.57"
      effort="1000000"
      velocity="100" />
  </joint>
  <link
    name="shaft_Link">
    <inertial>
      <origin
        xyz="-0.373054566281847 7.14485475445692E-08 -0.163750795014162"
        rpy="0 0 0" />
      <mass
        value="20.4951804812521" />
      <inertia
        ixx="6.48410099721522"
        ixy="-4.73763096218993E-08"
        ixz="0.633895998686677"
        iyy="1.72744563541114"
        iyz="-4.16522830063576E-08"
        izz="7.64998593361989" />
    </inertial>
    <visual>
      <origin
        xyz="0 0 0"
        rpy="0 0 0" />
      <geometry>
        <mesh
          filename="package://bobcat/meshes/shaft_Link.STL" />
      </geometry>
      <material
        name="">
        <color
          rgba="0.792156862745098 0.819607843137255 0.933333333333333 1" />
      </material>
    </visual>
    <collision>
      <origin
        xyz="0 0 0"
        rpy="0 0 0" />
      <geometry>
        <mesh
          filename="package://bobcat/meshes/shaft_Link.STL" />
      </geometry>
    </collision>
  </link>
  <joint
    name="shaft_joint"
    type="revolute">
    <origin
      xyz="0.070057 0 -0.12038"
      rpy="0 0 0" />
    <parent
      link="front_arm_link" />
    <child
      link="shaft_Link" />
    <axis
      xyz="0 1 0" />
    <limit
      lower="-1.57"
      upper="1.57"
      effort="1000000"
      velocity="100" />
  </joint>
  <link
    name="cylinder_link">
    <inertial>
      <origin
        xyz="0.415960966621125 -1.10568805711445E-07 0.182584566190524"
        rpy="0 0 0" />
      <mass
        value="31.1157427018809" />
      <inertia
        ixx="9.82595615735609"
        ixy="1.01025685103964E-06"
        ixz="0.888684358928562"
        iyy="2.43703543425772"
        iyz="4.4459166977269E-07"
        izz="11.4604619029493" />
    </inertial>
    <visual>
      <origin
        xyz="0 0 0"
        rpy="0 0 0" />
      <geometry>
        <mesh
          filename="package://bobcat/meshes/cylinder_link.STL" />
      </geometry>
      <material
        name="">
        <color
          rgba="0.792156862745098 0.819607843137255 0.933333333333333 1" />
      </material>
    </visual>
    <collision>
      <origin
        xyz="0 0 0"
        rpy="0 0 0" />
      <geometry>
        <mesh
          filename="package://bobcat/meshes/cylinder_link.STL" />
      </geometry>
    </collision>
  </link>
  <joint
    name="cylinder_joint"
    type="revolute">
    <origin
      xyz="-0.44801 0 0.78201"
      rpy="0 0 0" />
    <parent
      link="base_link" />
    <child
      link="cylinder_link" />
    <axis
      xyz="0 1 0" />
    <limit
      lower="-1.57"
      upper="1.57"
      effort="1000000"
      velocity="100" />
  </joint>



  <!-- Transmissions for ROS Control -->
  <transmission name="tran1">
    <type>transmission_interface/SimpleTransmission</type>
    <joint name="front_right_wheel_joint"/>
    <actuator name="motor1">
      <hardwareInterface>EffortJointInterface</hardwareInterface>
      <mechanicalReduction>1</mechanicalReduction>
    </actuator>
  </transmission>

  <transmission name="tran2">
    <type>transmission_interface/SimpleTransmission</type>
    <joint name="front_left_wheel_joint"/>
    <actuator name="motor2">
      <hardwareInterface>EffortJointInterface</hardwareInterface>
      <mechanicalReduction>1</mechanicalReduction>
    </actuator>
  </transmission>

  <transmission name="tran3">
    <type>transmission_interface/SimpleTransmission</type>
    <joint name="back_right_wheel_joint"/>
    <actuator name="motor3">
      <hardwareInterface>EffortJointInterface</hardwareInterface>
      <mechanicalReduction>1</mechanicalReduction>
    </actuator>
  </transmission>

  <transmission name="tran4">
    <type>transmission_interface/SimpleTransmission</type>
    <joint name="back_left_wheel_joint"/>
    <actuator name="motor4">
      <hardwareInterface>EffortJointInterface</hardwareInterface>
      <mechanicalReduction>1</mechanicalReduction>
    </actuator>
  </transmission>

  <transmission name="tran5">
    <type>transmission_interface/SimpleTransmission</type>
    <joint name="back_arm_joint"/>
    <actuator name="motor5">
      <hardwareInterface>EffortJointInterface</hardwareInterface>
      <mechanicalReduction>1</mechanicalReduction>
    </actuator>
  </transmission>

  <transmission name="tran6">
    <type>transmission_interface/SimpleTransmission</type>
    <joint name="front_arm_joint"/>
    <actuator name="motor6">
      <hardwareInterface>EffortJointInterface</hardwareInterface>
      <mechanicalReduction>1</mechanicalReduction>
    </actuator>
  </transmission>

  <transmission name="tran7">
    <type>transmission_interface/SimpleTransmission</type>
    <joint name="loader_joint"/>
    <actuator name="motor7">
      <hardwareInterface>EffortJointInterface</hardwareInterface>
      <mechanicalReduction>1</mechanicalReduction>
    </actuator>
  </transmission>

  <transmission name="tran8">
    <type>transmission_interface/SimpleTransmission</type>
    <joint name="shaft_joint"/>
    <actuator name="motor8">
      <hardwareInterface>EffortJointInterface</hardwareInterface>
      <mechanicalReduction>1</mechanicalReduction>
    </actuator>
  </transmission>

  <transmission name="tran9">
    <type>transmission_interface/SimpleTransmission</type>
    <joint name="cylinder_joint"/>
    <actuator name="motor9">
      <hardwareInterface>EffortJointInterface</hardwareInterface>
      <mechanicalReduction>1</mechanicalReduction>
    </actuator>
  </transmission>

  <!-- ros_control plugin -->
  <gazebo>
    <plugin name="gazebo_ros_control" filename="libgazebo_ros_control.so">
      <robotNamespace>/bobcat</robotNamespace>
    </plugin>
  </gazebo>
  <gazebo reference="base_link">
    <mu1>1</mu1>
    <mu2>1</mu2>
    <selfCollide>true</selfCollide>
  </gazebo>
  <gazebo reference="front_right_wheel">
    <mu1>1</mu1>
    <mu2>1</mu2>
    <selfCollide>true</selfCollide>
  </gazebo>
  <gazebo reference="front_left_wheel">
    <mu1>1</mu1>
    <mu2>1</mu2>
    <selfCollide>true</selfCollide>
  </gazebo>
  <gazebo reference="back_right_wheel">
    <mu1>1</mu1>
    <mu2>1</mu2>
    <selfCollide>true</selfCollide>
  </gazebo>
  <gazebo reference="back_left_wheel">
    <mu1>1</mu1>
    <mu2>1</mu2>
  </gazebo>
  <gazebo reference="back_arm_link">
    <mu1>1</mu1>
    <mu2>1</mu2>
    <selfCollide>true</selfCollide>
  </gazebo>
  <gazebo reference="front_arm_link">
    <mu1>1</mu1>
    <mu2>1</mu2>
    <selfCollide>true</selfCollide>
  </gazebo>
  <gazebo reference="loader_link">
    <mu1>1</mu1>
    <mu2>1</mu2>
    <selfCollide>true</selfCollide>
  </gazebo>
  <gazebo reference="shaft_Link">
    <mu1>1</mu1>
    <mu2>1</mu2>
    <selfCollide>true</selfCollide>
  </gazebo>
  <gazebo reference="cylinder_link">
    <mu1>1</mu1>
    <mu2>1</mu2>
    <selfCollide>true</selfCollide>
  </gazebo>
</robot>
