<?xml version="1.0"?>
<robot
  name="bobcat">
  <link
    name="body">
    <inertial>
      <origin
        xyz="-0.890714078986241 0.000176354230843779 0.525609535873677"
        rpy="0 0 0" />
      <mass
        value="5018.57981030941" />
      <inertia
        ixx="1272.55944993386"
        ixy="0.308979936767991"
        ixz="-158.353301657466"
        iyy="2264.90693597666"
        iyz="-0.107097171125965"
        izz="2025.98192908188" />
    </inertial>
    <visual>
      <origin
        xyz="0 0 0"
        rpy="0 0 0" />
      <geometry>
        <mesh
          filename="package://bobcat/meshes/body.STL" />
      </geometry>
      <material
        name="">
        <color
          rgba="0.647058823529412 0.619607843137255 0.588235294117647 1" />
      </material>
    </visual>
    <collision>
      <origin
        xyz="0 0 0"
        rpy="0 0 0" />
      <geometry>
        <mesh
          filename="package://bobcat/meshes/body_lite.STL" />
      </geometry>
    </collision>
  </link>
  <link
    name="front_left_wheel">
    <inertial>
      <origin
        xyz="2.0502E-07 0.19645 -3.6566E-09"
        rpy="0 0 0" />
      <mass
        value="1113.6" />
      <inertia
        ixx="57.645"
        ixy="-0.0001268"
        ixz="0.00024451"
        iyy="96.158"
        iyz="-4.2461E-05"
        izz="57.645" />
    </inertial>
    <visual>
      <origin
        xyz="0 0 0"
        rpy="0 0 0" />
      <geometry>
        <mesh
          filename="package://bobcat/meshes/front_left_wheel.STL" />
      </geometry>
      <material
        name="">
        <color
          rgba="0.64706 0.61961 0.58824 1" />
      </material>
    </visual>
    <collision>
      <origin
        xyz="0 0 0"
        rpy="0 0 0" />
      <geometry>
        <mesh
          filename="package://bobcat/meshes/front_left_wheel_lite.STL" />
      </geometry>
    </collision>
  </link>
  <joint
    name="front_left_wheel_joint"
    type="continuous">
    <origin
      xyz="-0.22722 0.47558 0.125"
      rpy="0 0 0" />
    <parent
      link="body" />
    <child
      link="front_left_wheel" />
    <axis
      xyz="0 1 0" />
  </joint>
  <link
    name="front_right_wheel">
    <inertial>
      <origin
        xyz="-2.0519E-07 -0.19645 -4.3198E-09"
        rpy="0 0 0" />
      <mass
        value="1113.6" />
      <inertia
        ixx="57.645"
        ixy="-0.00012695"
        ixz="-0.00024494"
        iyy="96.158"
        iyz="4.2098E-05"
        izz="57.645" />
    </inertial>
    <visual>
      <origin
        xyz="0 0 0"
        rpy="0 0 0" />
      <geometry>
        <mesh
          filename="package://bobcat/meshes/front_right_wheel.STL" />
      </geometry>
      <material
        name="">
        <color
          rgba="0.64706 0.61961 0.58824 1" />
      </material>
    </visual>
    <collision>
      <origin
        xyz="0 0 0"
        rpy="0 0 0" />
      <geometry>
        <mesh
          filename="package://bobcat/meshes/front_right_wheel_lite.STL" />
      </geometry>
    </collision>
  </link>
  <joint
    name="front_right_wheel_joint"
    type="continuous">
    <origin
      xyz="-0.22722 -0.47558 0.125"
      rpy="0 0 0" />
    <parent
      link="body" />
    <child
      link="front_right_wheel" />
    <axis
      xyz="0 1 0" />
  </joint>
  <link
    name="back_left_wheel">
    <inertial>
      <origin
        xyz="7.7344E-08 0.19645 1.8868E-07"
        rpy="0 0 0" />
      <mass
        value="1113.6" />
      <inertia
        ixx="57.645"
        ixy="-9.3672E-06"
        ixz="-0.00022863"
        iyy="96.158"
        iyz="-0.00013365"
        izz="57.645" />
    </inertial>
    <visual>
      <origin
        xyz="0 0 0"
        rpy="0 0 0" />
      <geometry>
        <mesh
          filename="package://bobcat/meshes/back_left_wheel.STL" />
      </geometry>
      <material
        name="">
        <color
          rgba="0.64706 0.61961 0.58824 1" />
      </material>
    </visual>
    <collision>
      <origin
        xyz="0 0 0"
        rpy="0 0 0" />
      <geometry>
        <mesh
          filename="package://bobcat/meshes/back_left_wheel_lite.STL" />
      </geometry>
    </collision>
  </link>
  <joint
    name="back_left_wheel_joint"
    type="continuous">
    <origin
      xyz="-1.227 0.47558 0.14772"
      rpy="0 0 0" />
    <parent
      link="body" />
    <child
      link="back_left_wheel" />
    <axis
      xyz="0 1 0" />
  </joint>
  <link
    name="back_right_wheel">
    <inertial>
      <origin
        xyz="-1.4894E-07 -0.19645 1.3751E-07"
        rpy="0 0 0" />
      <mass
        value="1113.6" />
      <inertia
        ixx="57.645"
        ixy="-6.7699E-05"
        ixz="4.3277E-05"
        iyy="96.158"
        iyz="0.00011578"
        izz="57.645" />
    </inertial>
    <visual>
      <origin
        xyz="0 0 0"
        rpy="0 0 0" />
      <geometry>
        <mesh
          filename="package://bobcat/meshes/back_right_wheel.STL" />
      </geometry>
      <material
        name="">
        <color
          rgba="0.64706 0.61961 0.58824 1" />
      </material>
    </visual>
    <collision>
      <origin
        xyz="0 0 0"
        rpy="0 0 0" />
      <geometry>
        <mesh
          filename="package://bobcat/meshes/back_right_wheel_lite.STL" />
      </geometry>
    </collision>
  </link>
  <joint
    name="back_right_wheel_joint"
    type="continuous">
    <origin
      xyz="-1.227 -0.47558 0.14772"
      rpy="0 0 0" />
    <parent
      link="body" />
    <child
      link="back_right_wheel" />
    <axis
      xyz="0 1 0" />
  </joint>
  <link
    name="base_arm">
    <inertial>
      <origin
        xyz="0.014506 1.7898E-12 0.26493"
        rpy="0 0 0" />
      <mass
        value="194.91" />
      <inertia
        ixx="50.887"
        ixy="-2.8544E-11"
        ixz="-0.036345"
        iyy="4.8017"
        iyz="6.6458E-13"
        izz="47.261" />
    </inertial>
    <visual>
      <origin
        xyz="0 0 0"
        rpy="0 0 0" />
      <geometry>
        <mesh
          filename="package://bobcat/meshes/base_arm.STL" />
      </geometry>
      <material
        name="">
        <color
          rgba="0.64706 0.61961 0.58824 1" />
      </material>
    </visual>
    <collision>
      <origin
        xyz="0 0 0"
        rpy="0 0 0" />
      <geometry>
        <mesh
          filename="package://bobcat/meshes/base_arm.STL" />
      </geometry>
    </collision>
  </link>
  <joint
    name="base_arm_joint"
    type="revolute">
    <origin
      xyz="-1.9776 0 1.1773"
      rpy="0 0 0" />
    <parent
      link="body" />
    <child
      link="base_arm" />
    <axis
      xyz="0 1 0" />
    <limit
      lower="-1.57"
      upper="1.57"
      effort="1000000"
      velocity="100" />
  </joint>
  <link
    name="main_arm">
    <inertial>
      <origin
        xyz="1.1716 -4.5368E-07 0.63315"
        rpy="0 0 0" />
      <mass
        value="1074.1" />
      <inertia
        ixx="467.94"
        ixy="0.00031534"
        ixz="254.42"
        iyy="629.34"
        iyz="0.00021799"
        izz="702.88" />
    </inertial>
    <visual>
      <origin
        xyz="0 0 0"
        rpy="0 0 0" />
      <geometry>
        <mesh
          filename="package://bobcat/meshes/main_arm.STL" />
      </geometry>
      <material
        name="">
        <color
          rgba="0.64706 0.61961 0.58824 1" />
      </material>
    </visual>
    <collision>
      <origin
        xyz="0 0 0"
        rpy="0 0 0" />
      <geometry>
        <mesh
          filename="package://bobcat/meshes/main_arm_lite.STL" />
      </geometry>
    </collision>
  </link>
  <joint
    name="main_arm_joint"
    type="revolute">
    <origin
      xyz="0.1148 0 0.55987"
      rpy="0 0 0" />
    <parent
      link="base_arm" />
    <child
      link="main_arm" />
    <axis
      xyz="0 1 0" />
    <limit
      lower="-1.57"
      upper="1.57"
      effort="1000000"
      velocity="100" />
  </joint>
  <link
    name="back_shaft">
    <inertial>
      <origin
        xyz="-0.134 -4.4364E-09 -0.38753"
        rpy="0 0 0" />
      <mass
        value="20.367" />
      <inertia
        ixx="6.7539"
        ixy="-8.065E-07"
        ixz="0.52501"
        iyy="1.7047"
        iyz="2.7525E-07"
        izz="5.4171" />
    </inertial>
    <visual>
      <origin
        xyz="0 0 0"
        rpy="0 0 0" />
      <geometry>
        <mesh
          filename="package://bobcat/meshes/back_shaft.STL" />
      </geometry>
      <material
        name="">
        <color
          rgba="0.64706 0.61961 0.58824 1" />
      </material>
    </visual>
    <collision>
      <origin
        xyz="0 0 0"
        rpy="0 0 0" />
      <geometry>
        <mesh
          filename="package://bobcat/meshes/back_shaft.STL" />
      </geometry>
    </collision>
  </link>
  <joint
    name="back_shaft_joint"
    type="revolute">
    <origin
      xyz="0.55726 0 -0.049822"
      rpy="0 0 0" />
    <parent
      link="main_arm" />
    <child
      link="back_shaft" />
    <axis
      xyz="0 1 0" />
    <limit
      lower="-1.57"
      upper="1.57"
      effort="1000000"
      velocity="100" />
  </joint>
  <link
    name="supporter">
    <inertial>
      <origin
        xyz="0.28839 -2.1264E-15 -0.42905"
        rpy="0 0 0" />
      <mass
        value="65.29" />
      <inertia
        ixx="21.343"
        ixy="-3.0065E-13"
        ixz="-3.0481"
        iyy="6.6127"
        iyz="-1.4833E-13"
        izz="18.857" />
    </inertial>
    <visual>
      <origin
        xyz="0 0 0"
        rpy="0 0 0" />
      <geometry>
        <mesh
          filename="package://bobcat/meshes/supporter.STL" />
      </geometry>
      <material
        name="">
        <color
          rgba="0.64706 0.61961 0.58824 1" />
      </material>
    </visual>
    <collision>
      <origin
        xyz="0 0 0"
        rpy="0 0 0" />
      <geometry>
        <mesh
          filename="package://bobcat/meshes/supporter.STL" />
      </geometry>
    </collision>
  </link>
  <joint
    name="supporter_joint"
    type="revolute">
    <origin
      xyz="0.9624 0 -0.18092"
      rpy="0 0 0" />
    <parent
      link="main_arm" />
    <child
      link="supporter" />
    <axis
      xyz="0 1 0" />
    <limit
      lower="-1.57"
      upper="1.57"
      effort="1000000"
      velocity="100" />
  </joint>
  <link
    name="front_cylinder">
    <inertial>
      <origin
        xyz="0.23385 1.5712E-08 0.01923"
        rpy="0 0 0" />
      <mass
        value="24.149" />
      <inertia
        ixx="3.5653"
        ixy="-7.5512E-08"
        ixz="0.075956"
        iyy="0.95412"
        iyz="-1.8758E-09"
        izz="4.4827" />
    </inertial>
    <visual>
      <origin
        xyz="0 0 0"
        rpy="0 0 0" />
      <geometry>
        <mesh
          filename="package://bobcat/meshes/front_cylinder.STL" />
      </geometry>
      <material
        name="">
        <color
          rgba="0.64706 0.61961 0.58824 1" />
      </material>
    </visual>
    <collision>
      <origin
        xyz="0 0 0"
        rpy="0 0 0" />
      <geometry>
        <mesh
          filename="package://bobcat/meshes/front_cylinder.STL" />
      </geometry>
    </collision>
  </link>
  <joint
    name="front_cylinder_joint"
    type="revolute">
    <origin
      xyz="1.6497 0 0.97689"
      rpy="0 0 0" />
    <parent
      link="main_arm" />
    <child
      link="front_cylinder" />
    <axis
      xyz="0 1 0" />
    <limit
      lower="-1.57"
      upper="1.57"
      effort="1000000"
      velocity="100" />
  </joint>
  <link
    name="loader">
    <inertial>
      <origin
        xyz="0.37894 2.2445E-15 0.067409"
        rpy="0 0 0" />
      <mass
        value="570.61" />
      <inertia
        ixx="170.82"
        ixy="6.6993E-14"
        ixz="-9.0404"
        iyy="53.839"
        iyz="-2.504E-14"
        izz="186.78" />
    </inertial>
    <visual>
      <origin
        xyz="0 0 0"
        rpy="0 0 0" />
      <geometry>
        <mesh
          filename="package://bobcat/meshes/loader.STL" />
      </geometry>
      <material
        name="">
        <color
          rgba="0.64706 0.61961 0.58824 1" />
      </material>
    </visual>
    <collision>
      <origin
        xyz="0 0 0"
        rpy="0 0 0" />
      <geometry>
        <mesh
          filename="package://bobcat/meshes/loader.STL" />
      </geometry>
    </collision>
  </link>
  <joint
    name="loader_joint"
    type="revolute">
    <origin
      xyz="2.4733 0 0.84274"
      rpy="0 0 0" />
    <parent
      link="main_arm" />
    <child
      link="loader" />
    <axis
      xyz="0 1 0" />
    <limit
      lower="-1.57"
      upper="1.57"
      effort="1000000"
      velocity="100" />
    <dynamics
      damping="0.001"
      friction="0.001" />
  </joint>
  <link
    name="front_shaft">
    <inertial>
      <origin
        xyz="-0.21435 -4.6153E-08 -0.017626"
        rpy="0 0 0" />
      <mass
        value="12.378" />
      <inertia
        ixx="1.8193"
        ixy="2.4455E-08"
        ixz="0.028747"
        iyy="0.3554"
        iyz="-2.2658E-08"
        izz="2.1665" />
    </inertial>
    <visual>
      <origin
        xyz="0 0 0"
        rpy="0 0 0" />
      <geometry>
        <mesh
          filename="package://bobcat/meshes/front_shaft.STL" />
      </geometry>
      <material
        name="">
        <color
          rgba="0.64706 0.61961 0.58824 1" />
      </material>
    </visual>
    <collision>
      <origin
        xyz="0 0 0"
        rpy="0 0 0" />
      <geometry>
        <mesh
          filename="package://bobcat/meshes/front_shaft.STL" />
      </geometry>
    </collision>
  </link>
  <joint
    name="front_shaft_joint"
    type="revolute">
    <origin
      xyz="0.14741 0 0.214"
      rpy="0 0 0" />
    <parent
      link="loader" />
    <child
      link="front_shaft" />
    <axis
      xyz="0 1 0" />
    <limit
      lower="-1.57"
      upper="1.57"
      effort="1000000"
      velocity="100" />
  </joint>
  <link
    name="back_cylinder">
    <inertial>
      <origin
        xyz="0.14985 5.3154E-08 0.43337"
        rpy="0 0 0" />
      <mass
        value="30.817" />
      <inertia
        ixx="10.039"
        ixy="-2.1671E-07"
        ixz="0.72763"
        iyy="2.3798"
        iyz="-5.4633E-07"
        izz="8.1867" />
    </inertial>
    <visual>
      <origin
        xyz="0 0 0"
        rpy="0 0 0" />
      <geometry>
        <mesh
          filename="package://bobcat/meshes/back_cylinder.STL" />
      </geometry>
      <material
        name="">
        <color
          rgba="0.64706 0.61961 0.58824 1" />
      </material>
    </visual>
    <collision>
      <origin
        xyz="0 0 0"
        rpy="0 0 0" />
      <geometry>
        <mesh
          filename="package://bobcat/meshes/back_cylinder.STL" />
      </geometry>
    </collision>
  </link>
  <joint
    name="back_cylinder_joint"
    type="revolute">
    <origin
      xyz="-1.8135 0 0.2184"
      rpy="0 0 0" />
    <parent
      link="body" />
    <child
      link="back_cylinder" />
    <axis
      xyz="0 1 0" />
    <limit
      lower="-1.57"
      upper="1.57"
      effort="1000000"
      velocity="100" />
  </joint>


  <!-- Transmissions for ROS Control -->
  <transmission name="tran1">
    <type>transmission_interface/SimpleTransmission</type>
    <joint name="front_right_wheel_joint"/>
    <actuator name="motor1">
      <hardwareInterface>EffortJointInterface</hardwareInterface>
      <mechanicalReduction>1</mechanicalReduction>
    </actuator>
  </transmission>

  <transmission name="tran2">
    <type>transmission_interface/SimpleTransmission</type>
    <joint name="front_left_wheel_joint"/>
    <actuator name="motor2">
      <hardwareInterface>EffortJointInterface</hardwareInterface>
      <mechanicalReduction>1</mechanicalReduction>
    </actuator>
  </transmission>

  <transmission name="tran3">
    <type>transmission_interface/SimpleTransmission</type>
    <joint name="back_right_wheel_joint"/>
    <actuator name="motor3">
      <hardwareInterface>EffortJointInterface</hardwareInterface>
      <mechanicalReduction>1</mechanicalReduction>
    </actuator>
  </transmission>

  <transmission name="tran4">
    <type>transmission_interface/SimpleTransmission</type>
    <joint name="back_left_wheel_joint"/>
    <actuator name="motor4">
      <hardwareInterface>EffortJointInterface</hardwareInterface>
      <mechanicalReduction>1</mechanicalReduction>
    </actuator>
  </transmission>

  <transmission name="tran5">
    <type>transmission_interface/SimpleTransmission</type>
    <joint name="base_arm_joint"/>
    <actuator name="motor5">
      <hardwareInterface>EffortJointInterface</hardwareInterface>
      <mechanicalReduction>1</mechanicalReduction>
    </actuator>
  </transmission>

  <transmission name="tran6">
    <type>transmission_interface/SimpleTransmission</type>
    <joint name="main_arm_joint"/>
    <actuator name="motor6">
      <hardwareInterface>EffortJointInterface</hardwareInterface>
      <mechanicalReduction>1</mechanicalReduction>
    </actuator>
  </transmission>

  <transmission name="tran7">
    <type>transmission_interface/SimpleTransmission</type>
    <joint name="back_shaft_joint"/>
    <actuator name="motor7">
      <hardwareInterface>EffortJointInterface</hardwareInterface>
      <mechanicalReduction>1</mechanicalReduction>
    </actuator>
  </transmission>

  <transmission name="tran8">
    <type>transmission_interface/SimpleTransmission</type>
    <joint name="supporter_joint"/>
    <actuator name="motor8">
      <hardwareInterface>EffortJointInterface</hardwareInterface>
      <mechanicalReduction>1</mechanicalReduction>
    </actuator>
  </transmission>

  <transmission name="tran9">
    <type>transmission_interface/SimpleTransmission</type>
    <joint name="front_cylinder_joint"/>
    <actuator name="motor9">
      <hardwareInterface>EffortJointInterface</hardwareInterface>
      <mechanicalReduction>1</mechanicalReduction>
    </actuator>
  </transmission>

  <transmission name="tran10">
    <type>transmission_interface/SimpleTransmission</type>
    <joint name="loader_joint"/>
    <actuator name="motor10">
      <hardwareInterface>EffortJointInterface</hardwareInterface>
      <mechanicalReduction>1</mechanicalReduction>
    </actuator>
  </transmission>

  <transmission name="tran11">
    <type>transmission_interface/SimpleTransmission</type>
    <joint name="front_shaft_joint"/>
    <actuator name="motor11">
      <hardwareInterface>EffortJointInterface</hardwareInterface>
      <mechanicalReduction>1</mechanicalReduction>
    </actuator>
  </transmission>

  <transmission name="tran12">
    <type>transmission_interface/SimpleTransmission</type>
    <joint name="back_cylinder_joint"/>
    <actuator name="motor12">
      <hardwareInterface>EffortJointInterface</hardwareInterface>
      <mechanicalReduction>1</mechanicalReduction>
    </actuator>
  </transmission>

  <!-- ros_control plugin -->
  <gazebo>
    <plugin name="gazebo_ros_control" filename="libgazebo_ros_control.so">
      <robotNamespace>/bobcat</robotNamespace>
    </plugin>
  </gazebo>
  <gazebo reference="body">
    <mu1>1</mu1>
    <mu2>1</mu2>
    <selfCollide>true</selfCollide>
  </gazebo>
  <gazebo reference="front_right_wheel">
    <mu1>1</mu1>
    <mu2>1</mu2>
    <selfCollide>true</selfCollide>
  </gazebo>
  <gazebo reference="front_left_wheel">
    <mu1>1</mu1>
    <mu2>1</mu2>
    <selfCollide>true</selfCollide>
  </gazebo>
  <gazebo reference="back_right_wheel">
    <mu1>1</mu1>
    <mu2>1</mu2>
    <selfCollide>true</selfCollide>
  </gazebo>
  <gazebo reference="back_left_wheel">
    <mu1>1</mu1>
    <mu2>1</mu2>
  </gazebo>
  <gazebo reference="base_arm">
    <mu1>1</mu1>
    <mu2>1</mu2>
    <selfCollide>true</selfCollide>
  </gazebo>
  <gazebo reference="main_arm">
    <mu1>1</mu1>
    <mu2>1</mu2>
    <selfCollide>true</selfCollide>
  </gazebo>
  <gazebo reference="back_shaft">
    <mu1>1</mu1>
    <mu2>1</mu2>
    <selfCollide>true</selfCollide>
  </gazebo>
  <gazebo reference="supporter">
    <mu1>1</mu1>
    <mu2>1</mu2>
    <selfCollide>true</selfCollide>
  </gazebo>
  <gazebo reference="front_cylinder">
    <mu1>1</mu1>
    <mu2>1</mu2>
    <selfCollide>true</selfCollide>
  </gazebo>
  <gazebo reference="loader">
    <mu1>1</mu1>
    <mu2>1</mu2>
    <selfCollide>true</selfCollide>
  </gazebo>
  <gazebo reference="front_shaft">
    <mu1>1</mu1>
    <mu2>1</mu2>
    <selfCollide>true</selfCollide>
  </gazebo>
  <gazebo reference="back_cylinder">
    <mu1>1</mu1>
    <mu2>1</mu2>
    <selfCollide>true</selfCollide>
  </gazebo>
</robot>
