<?xml version="1.0"?>
<robot
  name="Sahar">
  <link
    name="body">
    <inertial>
      <origin
        xyz="-0.890714078986241 0.000176354230843794 0.525609535873677"
        rpy="0 0 0" />
      <mass
        value="2112.2632057713" />
      <inertia
        ixx="330.451427275626"
        ixy="0.1258707518716585"
        ixz="-85.8115001993615"
        iyy="750.047261721269"
        iyz="-0.001202697501709275"
        izz="817.534535636717" />
    </inertial>
    <visual>
      <origin
        xyz="0 0 0"
        rpy="0 0 0" />
      <geometry>
        <mesh
          filename="package://bobcat/meshes/body.STL" />
      </geometry>
      <material
        name="">
        <color
          rgba="0.647058823529412 0.619607843137255 0.588235294117647 0.5" />
      </material>
    </visual>
    <collision>
      <origin
        xyz="0 0 0"
        rpy="0 0 0" />
      <geometry>
        <mesh
          filename="package://bobcat/meshes/body.STL" />
      </geometry>
    </collision>
  </link>
  <link
    name="front_left_wheel">
    <inertial>
      <origin
        xyz="2.0502E-07 0.19645 -3.6566E-09"
        rpy="0 0 0" />
      <mass
        value="333.358058377662" />
      <inertia
        ixx="17.076451771348393"
        ixy="-0.0000402018623479272"
        ixz="0.0000757982020811204"
        iyy="29.61581234283818"
        iyz="-0.66419529835185E-05"
        izz="17.076451812789907" />
    </inertial>
    <visual>
      <origin
        xyz="0 0 0"
        rpy="0 0 0" />
      <geometry>
        <mesh
          filename="package://bobcat/meshes/front_left_wheel.STL" />
      </geometry>
      <material
        name="">
        <color
          rgba="0.64706 0.61961 0.58824 1" />
      </material>
    </visual>
    <collision>
      <origin
        xyz="0 0 0"
        rpy="0 0 0" />
      <geometry>
        <mesh
          filename="package://bobcat/meshes/front_left_wheel_lite.stl" />
      </geometry>
    </collision>
  </link>
  <joint
    name="front_left_wheel_joint"
    type="continuous">
    <origin
      xyz="-0.22722 0.47558 0.125"
      rpy="0 2.1164E-16 0" />
    <parent
      link="body" />
    <child
      link="front_left_wheel" />
    <axis
      xyz="0 1 0" />
  </joint>
  <link
    name="front_right_wheel">
    <inertial>
      <origin
        xyz="-2.0519E-07 -0.19645 -4.3198E-09"
        rpy="0 0 0" />
      <mass
        value="333.358057183995" />
      <inertia
        ixx="17.076452573211751"
        ixy="-0.0000366953981898767"
        ixz="-0.0000754939559210241"
        iyy="29.61581234970523"
        iyz="1.220983077663846E-05"
        izz="17.076451008669259" />
    </inertial>
    <visual>
      <origin
        xyz="0 0 0"
        rpy="0 0 0" />
      <geometry>
        <mesh
          filename="package://bobcat/meshes/front_right_wheel.STL" />
      </geometry>
      <material
        name="">
        <color
          rgba="0.64706 0.61961 0.58824 1" />
      </material>
    </visual>
    <collision>
      <origin
        xyz="0 0 0"
        rpy="0 0 0" />
      <geometry>
        <mesh
          filename="package://bobcat/meshes/front_right_wheel_lite.stl" />
      </geometry>
    </collision>
  </link>
  <joint
    name="front_right_wheel_joint"
    type="continuous">
    <origin
      xyz="-0.22722 -0.47558 0.125"
      rpy="0 2.1164E-16 0" />
    <parent
      link="body" />
    <child
      link="front_right_wheel" />
    <axis
      xyz="0 1 0" />
  </joint>
  <link
    name="back_left_wheel">
    <inertial>
      <origin
        xyz="7.7344E-08 0.19645 1.8868E-07"
        rpy="0 0 0" />
      <mass
        value="333.35805719188" />
      <inertia
        ixx="17.076452970123344"
        ixy="-2.7936718473607865E-06"
        ixz="-0.0000668628917564486"
        iyy="29.61581228201546"
        iyz="-0.0000133650614295266"
        izz="17.076450606340583" />
    </inertial>
    <visual>
      <origin
        xyz="0 0 0"
        rpy="0 0 0" />
      <geometry>
        <mesh
          filename="package://bobcat/meshes/back_left_wheel.STL" />
      </geometry>
      <material
        name="">
        <color
          rgba="0.64706 0.61961 0.58824 1" />
      </material>
    </visual>
    <collision>
      <origin
        xyz="0 0 0"
        rpy="0 0 0" />
      <geometry>
        <mesh
          filename="package://bobcat/meshes/back_left_wheel_lite.stl" />
      </geometry>
    </collision>
  </link>
  <joint
    name="back_left_wheel_joint"
    type="continuous">
    <origin
      xyz="-1.227 0.47558 0.14772"
      rpy="0 2.1164E-16 0" />
    <parent
      link="body" />
    <child
      link="back_left_wheel" />
    <axis
      xyz="0 1 0" />
  </joint>
  <link
    name="back_right_wheel">
    <inertial>
      <origin
        xyz="-1.4894E-07 -0.19645 1.3751E-07"
        rpy="0 0 0" />
      <mass
        value="333.36" />
      <inertia
        ixx="17.07645"
        ixy="-1.87699E-05"
        ixz="1.23277E-05"
        iyy="29.6158"
        iyz="0.000031578"
        izz="17.07645" />
    </inertial>
    <visual>
      <origin
        xyz="0 0 0"
        rpy="0 0 0" />
      <geometry>
        <mesh
          filename="package://bobcat/meshes/back_right_wheel.STL" />
      </geometry>
      <material
        name="">
        <color
          rgba="0.64706 0.61961 0.58824 1" />
      </material>
    </visual>
    <collision>
      <origin
        xyz="0 0 0"
        rpy="0 0 0" />
      <geometry>
        <mesh
          filename="package://bobcat/meshes/back_right_wheel_lite.stl" />
      </geometry>
    </collision>
  </link>
  <joint
    name="back_right_wheel_joint"
    type="continuous">
    <origin
      xyz="-1.227 -0.47558 0.14772"
      rpy="0 2.1164E-16 0" />
    <parent
      link="body" />
    <child
      link="back_right_wheel" />
    <axis
      xyz="0 1 0" />
  </joint>
  <link
    name="base_arm">
    <inertial>
      <origin
        xyz="0.066509 1.9771E-12 0.25686"
        rpy="0 0 0" />
      <mass
        value="194.91" />
      <inertia
        ixx="50.76"
        ixy="-2.9264E-11"
        ixz="0.66798"
        iyy="4.8017"
        iyz="7.0403E-12"
        izz="47.388" />
    </inertial>
    <visual>
      <origin
        xyz="0 0 0"
        rpy="0 0 0" />
      <geometry>
        <mesh
          filename="package://bobcat/meshes/base_arm.STL" />
      </geometry>
      <material
        name="">
        <color
          rgba="0.64706 0.61961 0.58824 1" />
      </material>
    </visual>
    <collision>
      <origin
        xyz="0 0 0"
        rpy="0 0 0" />
      <geometry>
        <mesh
          filename="package://bobcat/meshes/base_arm.STL" />
      </geometry>
    </collision>
  </link>
  <joint
    name="base_arm_joint"
    type="revolute">
    <origin
      xyz="-1.9776 0 1.1773"
      rpy="0 2.1164E-16 0" />
    <parent
      link="body" />
    <child
      link="base_arm" />
    <axis
      xyz="0 1 0" />
    <limit
      lower="0"
      upper="0"
      effort="1000000"
      velocity="100" />
  </joint>
  <link
    name="main_arm">
    <inertial>
      <origin
        xyz="1.1865 -4.0206E-07 -0.60466"
        rpy="0 0 0" />
      <mass
        value="369.05" />
      <inertia
        ixx="133.74"
        ixy="0.00012791"
        ixz="-68.753"
        iyy="216.24"
        iyz="-4.6593E-05"
        izz="268.55" />
    </inertial>
    <visual>
      <origin
        xyz="0 0 0"
        rpy="0 0 0" />
      <geometry>
        <mesh
          filename="package://bobcat/meshes/main_arm.STL" />
      </geometry>
      <material
        name="">
        <color
          rgba="0.89412 0.91373 0.92941 1" />
      </material>
    </visual>
    <collision>
      <origin
        xyz="0 0 0"
        rpy="0 0 0" />
      <geometry>
        <mesh
          filename="package://bobcat/meshes/main_arm.STL" />
      </geometry>
    </collision>
  </link>
  <joint
    name="main_arm_joint"
    type="revolute">
    <origin
      xyz="0.22304 0 0.5262"
      rpy="0 -2.1164E-16 0" />
    <parent
      link="base_arm" />
    <child
      link="main_arm" />
    <axis
      xyz="0 1 0" />
    <limit
      lower="0"
      upper="0"
      effort="1000000"
      velocity="100" />
  </joint>
  <link
    name="supporter">
    <inertial>
      <origin
        xyz="0.51341 -4.9085E-16 -0.060486"
        rpy="0 0 0" />
      <mass
        value="65.29" />
      <inertia
        ixx="16.898"
        ixy="-2.3004E-13"
        ixz="-0.76501"
        iyy="6.6127"
        iyz="-2.4072E-13"
        izz="23.301" />
    </inertial>
    <visual>
      <origin
        xyz="0 0 0"
        rpy="0 0 0" />
      <geometry>
        <mesh
          filename="package://bobcat/meshes/supporter.STL" />
      </geometry>
      <material
        name="">
        <color
          rgba="0.64706 0.61961 0.58824 1" />
      </material>
    </visual>
    <collision>
      <origin
        xyz="0 0 0"
        rpy="0 0 0" />
      <geometry>
        <mesh
          filename="package://bobcat/meshes/supporter.STL" />
      </geometry>
    </collision>
  </link>
  <joint
    name="supporter_joint"
    type="revolute">
    <origin
      xyz="0.39771 0 -0.89486"
      rpy="0 8.0491E-16 0" />
    <parent
      link="main_arm" />
    <child
      link="supporter" />
    <axis
      xyz="0 1 0" />
    <limit
      lower="0"
      upper="0"
      effort="1000000"
      velocity="100" />
  </joint>
  <link
    name="front_cylinder">
    <inertial>
      <origin
        xyz="0.16022 1.6587E-08 -0.17142"
        rpy="0 0 0" />
      <mass
        value="24.149" />
      <inertia
        ixx="4.0554"
        ixy="-4.9938E-08"
        ixz="-0.46391"
        iyy="0.95412"
        iyz="6.094E-08"
        izz="3.9926" />
    </inertial>
    <visual>
      <origin
        xyz="0 0 0"
        rpy="0 0 0" />
      <geometry>
        <mesh
          filename="package://bobcat/meshes/front_cylinder.STL" />
      </geometry>
      <material
        name="">
        <color
          rgba="0.64706 0.61961 0.58824 1" />
      </material>
    </visual>
    <collision>
      <origin
        xyz="0 0 0"
        rpy="0 0 0" />
      <geometry>
        <mesh
          filename="package://bobcat/meshes/front_cylinder.STL" />
      </geometry>
    </collision>
  </link>
  <joint
    name="front_cylinder_joint"
    type="revolute">
    <origin
      xyz="1.741 0 -0.80293"
      rpy="0 8.0491E-16 0" />
    <parent
      link="main_arm" />
    <child
      link="front_cylinder" />
    <axis
      xyz="0 1 0" />
    <limit
      lower="-1.57"
      upper="1.57"
      effort="1000000"
      velocity="100" />
  </joint>
  <link
    name="front_shaft">
    <inertial>
      <origin
        xyz="9.4954E-07 8.3283E-07 -0.19417"
        rpy="0 0 0" />
      <mass
        value="13.711" />
      <inertia
        ixx="2.4234"
        ixy="-2.5882E-07"
        ixz="1.3728E-06"
        iyy="0.41181"
        iyz="1.3005E-06"
        izz="2.0158" />
    </inertial>
    <visual>
      <origin
        xyz="0 0 0"
        rpy="0 0 0" />
      <geometry>
        <mesh
          filename="package://bobcat/meshes/front_shaft.STL" />
      </geometry>
      <material
        name="">
        <color
          rgba="0.64706 0.61961 0.58824 1" />
      </material>
    </visual>
    <collision>
      <origin
        xyz="0 0 0"
        rpy="0 0 0" />
      <geometry>
        <mesh
          filename="package://bobcat/meshes/front_shaft.STL" />
      </geometry>
    </collision>
  </link>
  <joint
    name="front_shaft_joint"
    type="prismatic">
    <origin
      xyz="0.50479 0 -0.54009"
      rpy="-3.1416 0.75163 -3.1416" />
    <parent
      link="front_cylinder" />
    <child
      link="front_shaft" />
    <axis
      xyz="0 0 1" />
    <limit
      lower="0"
      upper="0"
      effort="1000000"
      velocity="100" />
  </joint>
  <link
    name="loader">
    <inertial>
      <origin
        xyz="0.37894 2.192E-15 0.067409"
        rpy="0 0 0" />
      <mass
        value="196.06" />
      <inertia
        ixx="58.693"
        ixy="1.2282E-14"
        ixz="-3.1063"
        iyy="18.499"
        iyz="-4.2535E-15"
        izz="64.178" />
    </inertial>
    <visual>
      <origin
        xyz="0 0 0"
        rpy="0 0 0" />
      <geometry>
        <mesh
          filename="package://bobcat/meshes/loader.STL" />
      </geometry>
      <material
        name="">
        <color
          rgba="0.89412 0.91373 0.92941 1" />
      </material>
    </visual>
    <collision>
      <origin
        xyz="0 0 0"
        rpy="0 0 0" />
      <geometry>
        <mesh
          filename="package://bobcat/meshes/loader.STL" />
      </geometry>
    </collision>
  </link>
  <joint
    name="loader_joint"
    type="revolute">
    <origin
      xyz="2.0984 0 -1.557"
      rpy="0 2.5362E-15 0" />
    <parent
      link="main_arm" />
    <child
      link="loader" />
    <axis
      xyz="0 1 0" />
    <limit
      lower="0"
      upper="0"
      effort="1000000"
      velocity="100" />
  </joint>
  <link
    name="brackets">
    <inertial>
      <origin
        xyz="0.14213 -1.579E-16 0.33109"
        rpy="0 0 0" />
      <mass
        value="12.857" />
      <inertia
        ixx="2.9339"
        ixy="-2.9653E-16"
        ixz="0.23718"
        iyy="0.67251"
        iyz="3.0656E-16"
        izz="2.738" />
    </inertial>
    <visual>
      <origin
        xyz="0 0 0"
        rpy="0 0 0" />
      <geometry>
        <mesh
          filename="package://bobcat/meshes/brackets.STL" />
      </geometry>
      <material
        name="">
        <color
          rgba="0.79216 0.81961 0.93333 1" />
      </material>
    </visual>
    <collision>
      <origin
        xyz="0 0 0"
        rpy="0 0 0" />
      <geometry>
        <mesh
          filename="package://bobcat/meshes/brackets.STL" />
      </geometry>
    </collision>
  </link>
  <joint
    name="brackets_joint"
    type="revolute">
    <origin
      xyz="0.33833 0 0.49449"
      rpy="0 0 0" />
    <parent
      link="loader" />
    <child
      link="brackets" />
    <axis
      xyz="0 1 0" />
    <limit
      lower="0"
      upper="1"
      effort="1000000"
      velocity="1000000" />
  </joint>
  <link
    name="back_cylinder">
    <inertial>
      <origin
        xyz="0.14567 5.3127E-08 0.43479"
        rpy="0 0 0" />
      <mass
        value="30.817" />
      <inertia
        ixx="10.053"
        ixy="-2.1135E-07"
        ixz="0.70965"
        iyy="2.3798"
        iyz="-5.4817E-07"
        izz="8.1729" />
    </inertial>
    <visual>
      <origin
        xyz="0 0 0"
        rpy="0 0 0" />
      <geometry>
        <mesh
          filename="package://bobcat/meshes/back_cylinder.STL" />
      </geometry>
      <material
        name="">
        <color
          rgba="0.64706 0.61961 0.58824 1" />
      </material>
    </visual>
    <collision>
      <origin
        xyz="0 0 0"
        rpy="0 0 0" />
      <geometry>
        <mesh
          filename="package://bobcat/meshes/back_cylinder.STL" />
      </geometry>
    </collision>
  </link>
  <joint
    name="back_cylinder_joint"
    type="revolute">
    <origin
      xyz="-1.8135 0 0.2184"
      rpy="0 8.0491E-16 0" />
    <parent
      link="body" />
    <child
      link="back_cylinder" />
    <axis
      xyz="0 1 0" />
    <limit
      lower="-1.57"
      upper="1.57"
      effort="1000000"
      velocity="100" />
  </joint>
  <link
    name="back_shaft">
    <inertial>
      <origin
        xyz="-1.2324E-08 -4.788E-09 -0.41004"
        rpy="0 0 0" />
      <mass
        value="20.367" />
      <inertia
        ixx="6.9354"
        ixy="-8.5203E-07"
        ixz="7.9714E-09"
        iyy="1.7047"
        iyz="-3.6983E-09"
        izz="5.2356" />
    </inertial>
    <visual>
      <origin
        xyz="0 0 0"
        rpy="0 0 0" />
      <geometry>
        <mesh
          filename="package://bobcat/meshes/back_shaft.STL" />
      </geometry>
      <material
        name="">
        <color
          rgba="0.64706 0.61961 0.58824 1" />
      </material>
    </visual>
    <collision>
      <origin
        xyz="0 0 0"
        rpy="0 0 0" />
      <geometry>
        <mesh
          filename="package://bobcat/meshes/back_shaft.STL" />
      </geometry>
    </collision>
  </link>
  <joint
    name="back_shaft_joint"
    type="prismatic">
    <origin
      xyz="0.33441 0 0.99813"
      rpy="-5.7722E-16 0.32328 -4.9954E-16" />
    <parent
      link="back_cylinder" />
    <child
      link="back_shaft" />
    <axis
      xyz="0 0 1" />
    <limit
      lower="-0.2"
      upper="1"
      effort="1000000"
      velocity="100" />
  </joint>
<link
    name="cabin">
    <inertial>
      <origin
        xyz="-0.70338 -5.738E-08 0.72817"
        rpy="0 0 0" />
      <mass
        value="496.33" />
      <inertia
        ixx="138.34"
        ixy="-1.1017E-06"
        ixz="8.4609"
        iyy="150.8"
        iyz="-2.3341E-06"
        izz="117.01" />
    </inertial>
    <visual>
      <origin
        xyz="0 0 0"
        rpy="0 0 0" />
      <geometry>
        <mesh
          filename="package://bobcat/meshes/cabin.STL" />
      </geometry>
      <material
        name="">
        <color
          rgba="0.64706 0.61961 0.58824 1" />
      </material>
    </visual>
    <collision>
      <origin
        xyz="0 0 0"
        rpy="0 0 0" />
      <geometry>
        <mesh
          filename="package://bobcat/meshes/cabin.STL" />
      </geometry>
    </collision>
  </link>
  <joint
    name="cabin_joint"
    type="fixed">
    <origin
      xyz="-0.11317 0 0.61042"
      rpy="0 8.0491E-16 0" />
    <parent
      link="body" />
    <child
      link="cabin" />
    <axis
      xyz="0 1 0" />
  </joint>
  <link
    name="Ibeo">
    <inertial>
      <origin
        xyz="-0.50455 -0.03223 -1.3338"
        rpy="0 0 0" />
      <mass
        value="10.460" />
      <inertia
        ixx="8.1287"
        ixy="0"
        ixz="0.55289"
        iyy="8.9548"
        iyz="0"
        izz="6.4192" />
    </inertial>
    <visual>
      <origin
        xyz="0 0 0"
        rpy="0 0 0" />
      <geometry>
        <mesh
          filename="package://bobcat/meshes/Ibeo.STL" />
      </geometry>
      <material
        name="">
        <color
          rgba="1 1 1 1" />
      </material>
    </visual>
    <collision>
      <origin
        xyz="0 0 0"
        rpy="0 0 0" />
      <geometry>
        <mesh
          filename="package://bobcat/meshes/Ibeo_lite.stl" />
      </geometry>
    </collision>
  </link>
  <joint
    name="Ibeo_joint"
    type="fixed">
    <origin
      xyz="-0.18258 0.03227 1.2493"
      rpy="1.570796327 -5.9328E-16 1.570796327" />
    <parent
      link="cabin" />
    <child
      link="Ibeo" />
    <axis
      xyz="0 0 0" />
  </joint>
  <link
    name="left_sick">
    <inertial>
      <origin
        xyz="-0.89565 0.58058 -0.24712"
        rpy="0 0 0" />
      <mass
        value="10.642" />
      <inertia
        ixx="5.5107"
        ixy="-0.00022597"
        ixz="0.000019765"
        iyy="4.5364"
        iyz="0.67063"
        izz="6.5674" />
    </inertial>
    <visual>
      <origin
        xyz="0 0 0"
        rpy="0 0 0" />
      <geometry>
        <mesh
          filename="package://bobcat/meshes/left_sick.STL" />
      </geometry>
      <material
        name="">
        <color
          rgba="0.79216 0.81961 0.93333 1" />
      </material>
    </visual>
    <collision>
      <origin
        xyz="0 0 0"
        rpy="0 0 0" />
      <geometry>
        <mesh
          filename="package://bobcat/meshes/left_sick_lite.stl" />
      </geometry>
    </collision>
  </link>
  <joint
    name="left_sick_joint"
    type="fixed">
    <origin
      xyz="-0.21801 0.89557 0.66494"
      rpy="1.5708 0 1.5708" />
    <parent
      link="body" />
    <child
      link="left_sick" />
    <axis
      xyz="0 -1 0" />
  </joint>
  <link
    name="right_sick">
    <inertial>
      <origin
        xyz="-0.89568 -0.58119 -0.24712"
        rpy="0 0 0" />
      <mass
        value="10.642" />
      <inertia
        ixx="5.5107"
        ixy="-0.00022597"
        ixz="-0.000019765"
        iyy="4.5364"
        iyz="-0.67063"
        izz="6.5674" />
    </inertial>
    <visual>
      <origin
        xyz="0 0 0"
        rpy="0 0 0" />
      <geometry>
        <mesh
          filename="package://bobcat/meshes/right_sick.STL" />
      </geometry>
      <material
        name="">
        <color
          rgba="0.79216 0.81961 0.93333 1" />
      </material>
    </visual>
    <collision>
      <origin
        xyz="0 0 0"
        rpy="0 0 0" />
      <geometry>
        <mesh
          filename="package://bobcat/meshes/right_sick_lite.stl" />
      </geometry>
    </collision>
  </link>
  <joint
    name="right_sick_joint"
    type="fixed">
    <origin
      xyz="-0.2174 -0.89576 0.66494"
      rpy="1.5708 0 1.5708" />
    <parent
      link="body" />
    <child
      link="right_sick" />
    <axis
      xyz="0 -1 0" />
  </joint>
  <link
    name="front_sick">
    <inertial>
      <origin
        xyz="-0.89885 0.00019572 0.43638"
        rpy="0 0 0" />
      <mass
        value="4.5223" />
      <inertia
        ixx="0.77018"
        ixy="0.00031619"
        ixz="-0.20002"
        iyy="1.747"
        iyz="-0.0000281"
        izz="1.9059" />
    </inertial>
    <visual>
      <origin
        xyz="0 0 0"
        rpy="0 0 0" />
      <geometry>
        <mesh
          filename="package://bobcat/meshes/front_sick.STL" />
      </geometry>
      <material
        name="">
        <color
          rgba="0.64706 0.61961 0.58824 1" />
      </material>
    </visual>
    <collision>
      <origin
        xyz="0 0 0"
        rpy="0 0 0" />
      <geometry>
        <mesh
          filename="package://bobcat/meshes/front_sick_lite.stl" />
      </geometry>
    </collision>
  </link>
  <joint
    name="front_sick_joint"
    type="fixed">
    <origin
      xyz="0.26113 0 0.048493"
      rpy="1.5708 0 1.5708" />
    <parent
      link="body" />
    <child
      link="front_sick" />
    <axis
      xyz="0 1 0" />
  </joint>
  <link
    name="supporter_hinge">
    <inertial>
      <origin
        xyz="-6.2676E-16 -2.2204E-16 1.1102E-16"
        rpy="0 0 0" />
      <mass
        value="1.6828" />
      <inertia
        ixx="0.00017338"
        ixy="-6.163E-33"
        ixz="-1.9205E-35"
        iyy="0.42748"
        iyz="6.6217E-37"
        izz="0.42748" />
    </inertial>
    <visual>
      <origin
        xyz="0 0 0"
        rpy="0 0 0" />
      <geometry>
        <mesh
          filename="package://bobcat/meshes/supporter_hinge.STL" />
      </geometry>
      <material
        name="">
        <color
          rgba="0.64706 0.61961 0.58824 1" />
      </material>
    </visual>
    <collision>
      <origin
        xyz="0 0 0"
        rpy="0 0 0" />
      <geometry>
        <mesh
          filename="package://bobcat/meshes/supporter_hinge.STL" />
      </geometry>
    </collision>
  </link>
  <joint
    name="supporter_hinge_joint"
    type="fixed">
    <origin
      xyz="-0.31547 0 0.68593"
      rpy="1.5708 0 1.5708" />
    <parent
      link="body" />
    <child
      link="supporter_hinge" />
    <axis
      xyz="1 0 0" />
  </joint>


 <!-- Transmissions for ROS Control -->
  <transmission name="tran1">
    <type>transmission_interface/SimpleTransmission</type>
    <joint name="front_right_wheel_joint"/>
    <actuator name="motor1">
      <hardwareInterface>EffortJointInterface</hardwareInterface>
      <mechanicalReduction>1</mechanicalReduction>
    </actuator>
  </transmission>

  <transmission name="tran2">
    <type>transmission_interface/SimpleTransmission</type>
    <joint name="front_left_wheel_joint"/>
    <actuator name="motor2">
      <hardwareInterface>EffortJointInterface</hardwareInterface>
      <mechanicalReduction>1</mechanicalReduction>
    </actuator>
  </transmission>

  <transmission name="tran3">
    <type>transmission_interface/SimpleTransmission</type>
    <joint name="back_right_wheel_joint"/>
    <actuator name="motor3">
      <hardwareInterface>EffortJointInterface</hardwareInterface>
      <mechanicalReduction>1</mechanicalReduction>
    </actuator>
  </transmission>

  <transmission name="tran4">
    <type>transmission_interface/SimpleTransmission</type>
    <joint name="back_left_wheel_joint"/>
    <actuator name="motor4">
      <hardwareInterface>EffortJointInterface</hardwareInterface>
      <mechanicalReduction>1</mechanicalReduction>
    </actuator>
  </transmission>

  <transmission name="tran5">
    <type>transmission_interface/SimpleTransmission</type>
    <joint name="base_arm_joint"/>
    <actuator name="motor5">
      <hardwareInterface>EffortJointInterface</hardwareInterface>
      <mechanicalReduction>1</mechanicalReduction>
    </actuator>
  </transmission>

  <transmission name="tran6">
    <type>transmission_interface/SimpleTransmission</type>
    <joint name="main_arm_joint"/>
    <actuator name="motor6">
      <hardwareInterface>EffortJointInterface</hardwareInterface>
      <mechanicalReduction>1</mechanicalReduction>
    </actuator>
  </transmission>

  <transmission name="tran7">
    <type>transmission_interface/SimpleTransmission</type>
    <joint name="back_shaft_joint"/>
    <actuator name="motor7">
      <hardwareInterface>EffortJointInterface</hardwareInterface>
      <mechanicalReduction>1</mechanicalReduction>
    </actuator>
  </transmission>

  <transmission name="tran8">
    <type>transmission_interface/SimpleTransmission</type>
    <joint name="supporter_joint"/>
    <actuator name="motor8">
      <hardwareInterface>EffortJointInterface</hardwareInterface>
      <mechanicalReduction>1</mechanicalReduction>
    </actuator>
  </transmission>

  <transmission name="tran9">
    <type>transmission_interface/SimpleTransmission</type>
    <joint name="front_cylinder_joint"/>
    <actuator name="motor9">
      <hardwareInterface>EffortJointInterface</hardwareInterface>
      <mechanicalReduction>1</mechanicalReduction>
    </actuator>
  </transmission>

  <transmission name="tran10">
    <type>transmission_interface/SimpleTransmission</type>
    <joint name="loader_joint"/>
    <actuator name="motor10">
      <hardwareInterface>EffortJointInterface</hardwareInterface>
      <mechanicalReduction>1</mechanicalReduction>
    </actuator>
  </transmission>

  <transmission name="tran11">
    <type>transmission_interface/SimpleTransmission</type>
    <joint name="front_shaft_joint"/>
    <actuator name="motor11">
      <hardwareInterface>EffortJointInterface</hardwareInterface>
      <mechanicalReduction>1</mechanicalReduction>
    </actuator>
  </transmission>

  <transmission name="tran12">
    <type>transmission_interface/SimpleTransmission</type>
    <joint name="brackets_joint"/>
    <actuator name="motor12">
      <hardwareInterface>EffortJointInterface</hardwareInterface>
      <mechanicalReduction>1</mechanicalReduction>
    </actuator>
  </transmission>

  <transmission name="tran12">
    <type>transmission_interface/SimpleTransmission</type>
    <joint name="back_cylinder_joint"/>
    <actuator name="motor12">
      <hardwareInterface>EffortJointInterface</hardwareInterface>
      <mechanicalReduction>1</mechanicalReduction>
    </actuator>
  </transmission>

  <!-- ros_control plugin -->
 <gazebo>
    <plugin name="gazebo_chain_plugin" filename="libchain_pagebo_plugin.so">
      <robotNamespace>/Sahar</robotNamespace>
      <link1>back_shaft</link1>
      <link2>main_arm</link2>
      <joint>back_shaft_sheker</joint>
    </plugin>
  </gazebo>
 <gazebo>
    <plugin name="gazebo_chain_plugin" filename="libchain_pagebo_plugin.so">
      <robotNamespace>/Sahar</robotNamespace>
      <link1>front_shaft</link1>
      <link2>loader</link2>
      <joint>front_shaft_sheker</joint>
    </plugin>
  </gazebo>
  <gazebo>
    <plugin name="gazebo_ros_control" filename="libgazebo_ros_control.so">
      <robotNamespace>/Sahar</robotNamespace>
    </plugin>
  </gazebo>
  <gazebo reference="body">
    <mu1>1</mu1>
    <mu2>1</mu2>
    <selfCollide>true</selfCollide>
    <material>Gazebo/Wood</material>
  </gazebo>
  <gazebo reference="front_right_wheel">
    <mu1>1</mu1>
    <mu2>1</mu2>
    <selfCollide>true</selfCollide>
    <material>Gazebo/Grey</material>
  </gazebo>
  <gazebo reference="front_left_wheel">
    <mu1>1</mu1>
    <mu2>1</mu2>
    <selfCollide>true</selfCollide>
    <material>Gazebo/Grey</material>
  </gazebo>
  <gazebo reference="back_right_wheel">
    <mu1>1</mu1>
    <mu2>1</mu2>
    <selfCollide>true</selfCollide>
    <material>Gazebo/Grey</material>
  </gazebo>
  <gazebo reference="back_left_wheel">
    <mu1>1</mu1>
    <mu2>1</mu2>
    <material>Gazebo/Grey</material>
  </gazebo>
  <gazebo reference="base_arm">
    <material>Gazebo/Grey</material>
  </gazebo>
  <gazebo reference="main_arm">
    <material>Gazebo/PaintedWall</material>
  </gazebo>
  <gazebo reference="back_shaft">
    <material>Gazebo/Black</material>
  </gazebo>
  <gazebo reference="supporter">
    <mu1>1</mu1>
    <mu2>1</mu2>
    <selfCollide>true</selfCollide>
    <material>Gazebo/GreyTransparent</material>
  </gazebo>
  <gazebo reference="front_cylinder">
    <material>Gazebo/BlueTransparent</material>
  </gazebo>
  <gazebo reference="loader">
    <mu1>1</mu1>
    <mu2>1</mu2>
    <selfCollide>true</selfCollide>
    <material>Gazebo/Gold</material>
  </gazebo>
  <gazebo reference="front_shaft">
    <material>Gazebo/Black</material>
  </gazebo>
  <gazebo reference="back_cylinder">
    <material>Gazebo/BlueTransparent</material>
  </gazebo>
  <gazebo reference="brackets">
    <mu1>1</mu1>
    <mu2>1</mu2>
    <selfCollide>true</selfCollide>
    <material>Gazebo/Grey</material>
  </gazebo>
  <gazebo reference="Ibeo">
    <material>Gazebo/Grey</material>
  </gazebo>
  <gazebo reference="left_sick">
    <material>Gazebo/Grey</material>
  </gazebo>
  <gazebo reference="right_sick">
    <material>Gazebo/Grey</material>
  </gazebo>
  <gazebo reference="front_sick">
    <material>Gazebo/Grey</material>
  </gazebo>
</robot>

